Workbook
Name Dilimleyici_Kazı_Boyu_için_Kullan: #N/A
Name Dilimleyici_Ø_14__lük_Zemin_Çivisi: #N/A
Name Dilimleyici_Ø_26__lık_Zemin_Çivisi: #N/A
Name Dilimleyici_Tip: #N/A
Name Dilimleyici_Tip1: #N/A
Name Dilimleyici_Tip11: #N/A
Name Dilimleyici_Tutanak_Genel_No__Elle: #N/A
Name Dilimleyici_Tutanak_Genel_No__Elle1: #N/A
Name Dilimleyici_Tutanak_Genel_No__Elle2: #N/A
Name Dilimleyici_Tutanak_Genel_No__Elle3: #N/A
Name Dilimleyici_Tutanak_Özel_No__Elle: #N/A
Name Dilimleyici_Tutanak_Özel_No__Elle1: #N/A
Name Dilimleyici_Tutanak_Özel_No__Elle11: #N/A
Name Dilimleyici_Tutanak_Özel_No__Elle2: #N/A
Name Dilimleyici_Umbrella_Arch: #N/A
Name Dilimleyici_Yeri: #N/A
Name Dilimleyici_Yeri1: #N/A
Name Dilimleyici_Yeri11: #N/A

Sheet TUTANAK
A2: TUTANAK
L3: Tutanak Tarihi-1 | M3: {=+TEXT(MIN(IF(DATA!A:A=D6,DATA!L:L)),"gg.aa.yyyy")} -> 01.04.2026
A4: Tutanak Konusu | C4: : | D4: =+DATA!F3&" "&DATA!G3&" "&DATA!I3&" ("&DATA!J3&") "&" '"&DATA!H3&"' Tipi Tünel İmalatları" -> S06-Barbaros İstasyonu Hat-1 KY 3.Aşama (Alt Yarı) 'P1' Tipi Tünel İmalatları | L4: Tutanak Tarihi-2 | M4: {=+TEXT(MAX(IF(DATA!A:A=D6,DATA!L:L)),"gg.aa.yyyy")} -> 16.04.2026
A6: Tutanak No | B6: Genel | C6: : | D6: 2026.04-003 | J6: Elle
B7: Özel | C7: : | D7: S06.H1.KY.P1.A3.003 | J7: Elle
A8: Tutanak Tarihi | C8: : | D8: 46142 | J8: Elle
A9: Tutanak Konusu | C9: : | D9: NATM Tünel İmalatı
A10: Tutanak Ekleri | C10: : | D10: =+IF('KAZI-İKSA'!A14<>0,1,0) -> 1 | E10: İksa, Püskürtme Betonu Ve Hasır Çelik İcmali
D11: =+IF(BULON!C15<>0,TUTANAK!D10+1,TUTANAK!D10) -> 2 | E11: Bulon İcmali
E13: Zemin Çivisi İcmali
E14: Tünel Ayna İcmali
A16: İşin Adı | C16: : | D16: Kirazlı-Halkalı Üniversite Metro Hattı İnşaat Ve Elektromekanik İşler İle M1 Hattı Elektromekanik Sistemleri Yapım İşi
A19: Yüklenicinin Adı | C19: : | D19: Kalyon-Özgün Metro İnşaatı Adi Ortaklığı Ticari İşletmesi
A20: Sözleşme Tarihi | C20: : | D20: 45639
A21: İşe Başlama Tarihi | C21: : | D21: 45653
A22: Sözleşmeye Göre İşin Süresi | C22: : | D22: 1440 Gün
A23: Sözleşmeye Göre İşin Bitiş Tarihi | C23: : | D23: 47093
A25: =+"'Kirazlı-Halkalı Üniversite Metro Hattı İnşaat Ve Elektromekanik İşler İle M1 Hattı Elektromekanik Sistemleri Yapım İşi' İşinde NATM Tünellerin yapımı sırasında "&M3&" - "&M4&" tarihleri arasında Şartnamesine uygun olarak yapılan imalatlar ekli tablolarda belirtilmiştir." -> 'Kirazlı-Halkalı Üniversite Metro Hattı İnşaat Ve Elektromekanik İşler İle M1 Hattı Elektromekanik Sistemleri Yapım İşi' İşinde NATM Tünellerin yapımı sırasında 01.04.2026 - 16.04.2026 tarihleri arasında Şartnamesine uygun olarak yapılan imalatlar ekli tablolarda belirtilmiştir.
A29: =+"İş bu tutanak "&TEXT(D8,"gg.aa.yyyy")&" tarihinde taraflarca 6 nüsha olarak imzalanmıştır." -> İş bu tutanak 30.04.2026 tarihinde taraflarca 6 nüsha olarak imzalanmıştır.

Sheet KAZI-İKSA
A2: KİRAZLI-HALKALI ÜNİVERSİTE METRO HATTI İNŞAAT VE ELEKTROMEKANİK İŞLER İLE
A3: M1 HATTI ELEKTROMEKANİK SİSTEMLERİ YAPIM İŞİ
A4: =+"İKSA, PÜSKÜRTME BETONU VE HASIR ÇELİK İCMALİ (" & TUTANAK!$M$3& "-"& TUTANAK!$M$4& ")" -> İKSA, PÜSKÜRTME BETONU VE HASIR ÇELİK İCMALİ (01.04.2026-16.04.2026)
A5: =+DATA!H3 -> P1
H6: Tutanak Ek No: | I6: =+TUTANAK!$D$10 -> 1
A7: İmalatın Yeri: | B7: =+DATA!$F$3&" "&DATA!$G$3&" "&DATA!$H$3&" Tüneli "&DATA!$I$3&" ("&DATA!$J$3&")" -> S06-Barbaros İstasyonu Hat-1 KY P1 Tüneli 3.Aşama (Alt Yarı)
A8: Tutanak Genel No: | B8: =+TUTANAK!$D$6 -> 2026.04-003
A9: Tutanak Özel No: | B9: =+TUTANAK!$D$7 -> S06.H1.KY.P1.A3.003
A10: Tutanak Tarihi: | B10: =+TUTANAK!$D$8 -> 46142
A13: ATF No | B13: Tarih | C13: Kilometre | D13: Çelik Hasır | E13: Püskürtme Betonu | F13: İksa Tipi | G13: Geçici İnvert Çelik İksa HEB160 | H13: Kalıcı Çelik İksa HEB200
A14: KDO-NATM-S06-1171 | B14: 46113 | C14: 1308.44 | D14: Q589/589-Çift Kat | E14: 30 cm atıldı | F14: Umbrella-3 | H14: 1
A15: KDO-NATM-S06-1171 | B15: 46113 | C15: 1309.19 | D15: Q589/589-Çift Kat | E15: 30 cm atıldı | F15: Umbrella-2 | H15: 1
A16: KDO-NATM-S06-1171 | B16: 46113 | C16: 1309.94 | D16: Q589/589-Çift Kat | E16: 30 cm atıldı | F16: Umbrella-1 | H16: 1
A17: KDO-NATM-S06-1200 | B17: 46127 | C17: 1310.69 | D17: Q589/589-Çift Kat | E17: 30 cm atıldı | F17: Umbrella-6 | H17: 1
A18: KDO-NATM-S06-1200 | B18: 46127 | C18: 1311.44 | D18: Q589/589-Çift Kat | E18: 30 cm atıldı | F18: Umbrella-5 | H18: 1
A19: KDO-NATM-S06-1200 | B19: 46127 | C19: 1312.19 | D19: Q589/589-Çift Kat | E19: 30 cm atıldı | F19: Umbrella-4 | H19: 1
A20: KDO-NATM-S06-1204 | B20: 46128 | C20: 1312.94 | D20: Q589/589-Çift Kat | E20: 30 cm atıldı | F20: Umbrella-3 | H20: 1
A21: KDO-NATM-S06-1204 | B21: 46128 | C21: 1313.69 | D21: Q589/589-Çift Kat | E21: 30 cm atıldı | F21: Umbrella-2 | H21: 1
A22: KDO-NATM-S06-1204 | B22: 46128 | C22: 1314.44 | D22: Q589/589-Çift Kat | E22: 30 cm atıldı | F22: Umbrella-1 | H22: 1
A23: KDO-NATM-S06-1204 | B23: 46128 | C23: 1315.19 | D23: Q589/589-Çift Kat | E23: 30 cm atıldı | F23: (boş)
A24: TBT-NATM-S06-241 | B24: 46119 | C24: 1296.82 | D24: (boş) | E24: (boş) | F24: (boş)
A25: TBT-NATM-S06-241 | B25: 46119 | C25: 1297.57 | D25: (boş) | E25: (boş) | F25: (boş)
A26: TBT-NATM-S06-241 | B26: 46119 | C26: 1298.32 | D26: (boş) | E26: (boş) | F26: (boş)
A27: TBT-NATM-S06-241 | B27: 46119 | C27: 1299.07 | D27: (boş) | E27: (boş) | F27: (boş)
A28: TBT-NATM-S06-241 | B28: 46119 | C28: 1299.82 | D28: (boş) | E28: (boş) | F28: (boş)
A29: TBT-NATM-S06-241 | B29: 46119 | C29: 1300.57 | D29: (boş) | E29: (boş) | F29: (boş)
A30: TBT-NATM-S06-241 | B30: 46119 | C30: 1301.32 | D30: (boş) | E30: (boş) | F30: (boş)
A31: TBT-NATM-S06-241 | B31: 46119 | C31: 1302.07 | D31: (boş) | E31: (boş) | F31: (boş)
A32: TBT-NATM-S06-241 | B32: 46119 | C32: 1302.82 | D32: (boş) | E32: (boş) | F32: (boş)
A33: TBT-NATM-S06-241 | B33: 46119 | C33: 1303.57 | D33: (boş) | E33: (boş) | F33: (boş)
A34: TBT-NATM-S06-241 | B34: 46119 | C34: 1304.32 | D34: (boş) | E34: (boş) | F34: (boş)
... A56: TBT-NATM-S06-242 | B56: 46119 | C56: 1296.07 | D56: (boş) | E56: (boş) | F56: (boş)
A57: Genel Toplam | H57: 9

Sheet BULON
C2: KİRAZLI-HALKALI ÜNİVERSİTE METRO HATTI İNŞAAT VE ELEKTROMEKANİK İŞLER İLE
C3: M1 HATTI ELEKTROMEKANİK SİSTEMLERİ YAPIM İŞİ
C4: =+"BULON İCMALİ (" & TUTANAK!$M$3& "-"& TUTANAK!$M$4& ")" -> BULON İCMALİ (01.04.2026-16.04.2026)
C5: P1
H6: Tutanak Ek No: | I6: =+TUTANAK!$D$11 -> 2
C7: İmalatın Yeri: | D7: =+DATA!$F$3&" "&DATA!$G$3&" "&DATA!$H$3&" Tüneli "&DATA!$I$3&" ("&DATA!$J$3&")" -> S06-Barbaros İstasyonu Hat-1 KY P1 Tüneli 3.Aşama (Alt Yarı)
C8: Tutanak Genel No: | D8: =+TUTANAK!$D$6 -> 2026.04-003
C9: Tutanak Özel No: | D9: =+TUTANAK!$D$7 -> S06.H1.KY.P1.A3.003
C10: Tutanak Tarihi: | D10: =+TUTANAK!$D$8 -> 46142
C13: ATF No | D13: Tarih | E13: Kilometre | F13: 4 mt Kaya Bulonu (adet) | G13: 6 mt Kaya Bulonu (adet) | H13: 8 mt Kaya Bulonu (adet)
C14: KDO-NATM-S06-1171 | D14: 46113 | E14: 1308.44
C15: KDO-NATM-S06-1171 | D15: 46113 | E15: 1309.94
C16: KDO-NATM-S06-1171 | D16: 46113 | E16: 1309.19
C17: KDO-NATM-S06-1200 | D17: 46127 | E17: 1312.19
C18: KDO-NATM-S06-1200 | D18: 46127 | E18: 1311.44
C19: KDO-NATM-S06-1200 | D19: 46127 | E19: 1310.69
C20: KDO-NATM-S06-1204 | D20: 46128 | E20: 1315.19
C21: KDO-NATM-S06-1204 | D21: 46128 | E21: 1314.44
C22: KDO-NATM-S06-1204 | D22: 46128 | E22: 1313.69
C23: KDO-NATM-S06-1204 | D23: 46128 | E23: 1312.94
C24: TBT-NATM-S06-241 | D24: 46119 | E24: 1310.32 | H24: 3
C25: TBT-NATM-S06-241 | D25: 46119 | E25: 1309.57 | H25: 3
C26: TBT-NATM-S06-241 | D26: 46119 | E26: 1308.82 | H26: 3
C27: TBT-NATM-S06-241 | D27: 46119 | E27: 1308.07 | H27: 3
C28: TBT-NATM-S06-241 | D28: 46119 | E28: 1307.32 | H28: 3
C29: TBT-NATM-S06-241 | D29: 46119 | E29: 1306.57 | H29: 3
C30: TBT-NATM-S06-241 | D30: 46119 | E30: 1305.82 | H30: 3
C31: TBT-NATM-S06-241 | D31: 46119 | E31: 1305.07 | H31: 3
C32: TBT-NATM-S06-241 | D32: 46119 | E32: 1304.32 | H32: 3
C33: TBT-NATM-S06-241 | D33: 46119 | E33: 1303.57 | H33: 3
C34: TBT-NATM-S06-241 | D34: 46119 | E34: 1302.82 | H34: 3
C35: TBT-NATM-S06-241 | D35: 46119 | E35: 1302.07 | H35: 3
... C56: TBT-NATM-S06-242 | D56: 46119 | E56: 1286.32 | H56: 3
C57: Genel Toplam (adet) | H57: 99

Sheet UMBRELLA ARCH
C2: KİRAZLI-HALKALI ÜNİVERSİTE METRO HATTI İNŞAAT VE ELEKTROMEKANİK İŞLER İLE
C3: M1 HATTI ELEKTROMEKANİK SİSTEMLERİ YAPIM İŞİ
C4: =+"UMBRELLA ARCH İCMALİ (" & TUTANAK!$M$3& "-"& TUTANAK!$M$4& ")" -> UMBRELLA ARCH İCMALİ (01.04.2026-16.04.2026)
C5: P1
G6: Tutanak Ek No: | H6: =+TUTANAK!$D$12 -> 0
D7: İmalatın Yeri: | E7: =+DATA!$F$3&" "&DATA!$G$3&" "&DATA!$H$3&" Tüneli "&DATA!$I$3&" ("&DATA!$J$3&")" -> S06-Barbaros İstasyonu Hat-1 KY P1 Tüneli 3.Aşama (Alt Yarı)
D8: Tutanak Genel No: | E8: =+TUTANAK!$D$6 -> 2026.04-003
D9: Tutanak Özel No: | E9: =+TUTANAK!$D$7 -> S06.H1.KY.P1.A3.003
D10: Tutanak Tarihi: | E10: =+TUTANAK!$D$8 -> 46142
D14: ATF No | E14: Tarih | F14: Kilometre | G14: Umbrella Arch (metre)
D15: KDO-NATM-S07-141 | E15: 45874 | F15: 2119.6 | G15: 423
D16: Genel Toplam (metre) | G16: 423

Sheet ZEMİN ÇİVİSİ
C2: KİRAZLI-HALKALI ÜNİVERSİTE METRO HATTI İNŞAAT VE ELEKTROMEKANİK İŞLER İLE
C3: M1 HATTI ELEKTROMEKANİK SİSTEMLERİ YAPIM İŞİ
C4: =+"ZEMİN ÇİVİSİ İCMALİ (" & TUTANAK!$M$3& "-"& TUTANAK!$M$4& ")" -> ZEMİN ÇİVİSİ İCMALİ (01.04.2026-16.04.2026)
C5: P1
G6: Tutanak Ek No: | H6: =+TUTANAK!$D$13 -> 0
C7: İmalatın Yeri: | D7: =+DATA!$F$3&" "&DATA!$G$3&" "&DATA!$H$3&" Tüneli "&DATA!$I$3&" ("&DATA!$J$3&")" -> S06-Barbaros İstasyonu Hat-1 KY P1 Tüneli 3.Aşama (Alt Yarı)
C8: Tutanak Genel No: | D8: =+TUTANAK!$D$6 -> 2026.04-003
C9: Tutanak Özel No: | D9: =+TUTANAK!$D$7 -> S06.H1.KY.P1.A3.003
C10: Tutanak Tarihi: | D10: =+TUTANAK!$D$8 -> 46142
C13: ATF No | D13: Tarih | E13: Kilometre | F13: Ø 14 'lük Zemin Çivisi (metre) | G13: Ø 26 'lık Zemin Çivisi (metre)
C14: KDO-NATM-S07-141 | D14: 45874 | E14: 2119.6 | F14: 162
C15: Genel Toplam (metre) | F15: 162

Sheet AYNA
A2: KİRAZLI-HALKALI ÜNİVERSİTE METRO HATTI İNŞAAT VE ELEKTROMEKANİK İŞLER İLE
A3: M1 HATTI ELEKTROMEKANİK SİSTEMLERİ YAPIM İŞİ
A4: =+"AYNA İCMALİ (" & TUTANAK!$M$3& "-"& TUTANAK!$M$4& ")" -> AYNA İCMALİ (01.04.2026-16.04.2026)
A5: P1
G6: Tutanak Ek No: | H6: =+TUTANAK!$D$14 -> 0
A7: İmalatın Yeri: | C7: =+DATA!$F$3&" "&DATA!$G$3&" "&DATA!$H$3&" Tüneli "&DATA!$I$3&" ("&DATA!$J$3&")" -> S06-Barbaros İstasyonu Hat-1 KY P1 Tüneli 3.Aşama (Alt Yarı)
A8: Tutanak Genel No: | C8: =+TUTANAK!$D$6 -> 2026.04-003
A9: Tutanak Özel No: | C9: =+TUTANAK!$D$7 -> S06.H1.KY.P1.A3.003
A10: Tutanak Tarihi: | C10: =+TUTANAK!$D$8 -> 46142
B13: AYNA İMALATLARI
A14: Sıra No | C14: Km | D14: Yeri | F14: Çelik Hasır | G14: Püskürtme Betonu
A15: 1 | C15: 2118.1 | D15: Üst Yarı | E15: 4 | G15: 5 cm atıldı
A16: 2 | C16: 2118.1 | D16: Üst Yarı | E16: 4 | F16: Q221/221 Tek Kat | G16: 15 cm atıldı 8 m²
A17: 3 | C17: 2118.85 | D17: Üst Yarı | E17: 5 | G17: 5 cm atıldı
A18: 4 | C18: 2119.6 | D18: Üst Yarı | E18: 6 | F18: Q221/221 Tek Kat | G18: 15 cm atıldı
A19: 5 | C19: 2120.35 | D19: Üst Yarı | E19: 1 | G19: 5 cm atıldı
A20: 6 | C20: 2121.1 | D20: Üst Yarı | E20: 2 | G20: 5 cm atıldı
A21: 7 | C21: 2121.1 | D21: Üst Yarı | E21: 2 | F21: Q221/221 Tek Kat | G21: 15 cm atıldı 8 m²
A22: 8 | C22: 2121.85 | D22: Üst Yarı | E22: 3 | G22: 5 cm atıldı
A23: 9 | C23: 2122.6 | D23: Üst Yarı | E23: 4 | G23: 5 cm atıldı
A24: 10 | C24: 2122.6 | D24: Üst Yarı | E24: 4 | F24: Q221/221 Tek Kat | G24: 15 cm atıldı 6 m²
A25: 11 | C25: 2123.35 | D25: Üst Yarı | E25: 5 | G25: 5 cm atıldı
A26: 12 | C26: 2124.48 | D26: Üst Yarı | E26: 6 | F26: Q589/589 Çift Kat | G26: 30 cm atıldı

Sheet DATA
A1: Tutanak Genel No (Elle) | B1: Tutanak Özel No (Elle) | C1: Kazı Boyu için Kullan | D1: Ödeme | E1: Tip | F1: Şantiye Adı Yeri | G1: Tünel Adı | H1: Tünel Tipi | I1: Aşama | J1: Yeri | K1: ATF No | L1: Tarih | M1: Kilometre | N1: Açıklama | O1: Açıklama-2 | P1: Kazı | Q1: Çelik Hasır | R1: Püskürtme Betonu | S1: Çelik İksa HEB160 | T1: Çelik İksa HEB200 | U1: S | V1: Umbrella Arch | W1: Boru Süren | X1: S | Y1: 3 mt Kaya Bulonu | Z1: 4 mt Kaya Bulonu | AA1: 5 mt Kaya Bulonu | AB1: 6 mt Kaya Bulonu | AC1: 8 mt Kaya Bulonu | AD1: S | AE1: Ø 14 'lük Zemin Çivisi | AF1: Ø 26 'lık Zemin Çivisi | AG1: Pah Donatısı
A2: 2026.03-006 | B2: S06.H1.KY.P1.A3.002 | C2: FALSE | E2: KAZI-PÜS-H.ÇELİK | F2: S06-Barbaros İstasyonu | G2: Hat-1 KY | H2: P1 | I2: 3.Aşama | J2: Alt Yarı | K2: KDO-NATM-S06-1166 | L2: 46112 | M2: 1308.44 | N2: KALICI | O2: Umbrella-3 | P2: Tamamlandı | Q2: Q589/589-Çift Kat | R2: 30 cm atıldı
B3: S06.H1.KY.P1.A3.001 | C3: FALSE | E3: KAZI-PÜS-H.ÇELİK | F3: S06-Barbaros İstasyonu | G3: Hat-1 KY | H3: P1 | I3: 3.Aşama | J3: Alt Yarı | K3: KDO-NATM-S06-1013 | L3: 46074 | M3: 1315.19 | P3: Tamamlandı | Q3: Q589/589-Çift Kat | R3: 30 cm atıldı
B4: S06.H1.KY.P1.A3.001 | C4: FALSE | E4: KAZI-PÜS-H.ÇELİK | F4: S06-Barbaros İstasyonu | G4: Hat-1 KY | H4: P1 | I4: 3.Aşama | J4: Alt Yarı | K4: KDO-NATM-S06-1013 | L4: 46074 | M4: 1314.44 | N4: KALICI | O4: Umbrella-1 | P4: Tamamlandı | Q4: Q589/589-Çift Kat | R4: 30 cm atıldı | T4: 1
B5: S06.H1.KY.P1.A3.001 | C5: FALSE | E5: KAZI-PÜS-H.ÇELİK | F5: S06-Barbaros İstasyonu | G5: Hat-1 KY | H5: P1 | I5: 3.Aşama | J5: Alt Yarı | K5: KDO-NATM-S06-1013 | L5: 46074 | M5: 1313.69 | N5: KALICI | O5: Umbrella-2 | P5: Tamamlandı | Q5: Q589/589-Çift Kat | R5: 30 cm atıldı | T5: 1
B6: S06.H1.KY.P1.A3.001 | C6: FALSE | E6: KAZI-PÜS-H.ÇELİK | F6: S06-Barbaros İstasyonu | G6: Hat-1 KY | H6: P1 | I6: 3.Aşama | J6: Alt Yarı | K6: KDO-NATM-S06-1013 | L6: 46074 | M6: 1312.94 | N6: KALICI | O6: Umbrella-3 | P6: Tamamlandı | Q6: Q589/589-Çift Kat | R6: 30 cm atıldı | T6: 1
B7: S06.H1.KY.P1.A3.001 | C7: FALSE | E7: KAZI-PÜS-H.ÇELİK | F7: S06-Barbaros İstasyonu | G7: Hat-1 KY | H7: P1 | I7: 3.Aşama | J7: Alt Yarı | K7: KDO-NATM-S06-1013 | L7: 46074 | M7: 1312.19 | N7: KALICI | O7: Umbrella-4 | P7: Tamamlandı | Q7: Q589/589-Çift Kat | R7: 30 cm atıldı | T7: 1
B8: S06.H1.KY.P1.A3.001 | C8: FALSE | E8: KAZI-PÜS-H.ÇELİK | F8: S06-Barbaros İstasyonu | G8: Hat-1 KY | H8: P1 | I8: 3.Aşama | J8: Alt Yarı | K8: KDO-NATM-S06-1013 | L8: 46074 | M8: 1311.44 | N8: KALICI | O8: Umbrella-5 | P8: Tamamlandı | Q8: Q589/589-Çift Kat | R8: 30 cm atıldı | T8: 1
B9: S06.H1.KY.P1.A3.001 | C9: FALSE | E9: KAZI-PÜS-H.ÇELİK | F9: S06-Barbaros İstasyonu | G9: Hat-1 KY | H9: P1 | I9: 3.Aşama | J9: Alt Yarı | K9: KDO-NATM-S06-1013 | L9: 46074 | M9: 1310.69 | N9: KALICI | O9: Umbrella-6 | P9: Tamamlandı | Q9: Q589/589-Çift Kat | R9: 30 cm atıldı | T9: 1
B10: S06.H1.KY.P1.A3.001 | C10: FALSE | E10: KAZI-PÜS-H.ÇELİK | F10: S06-Barbaros İstasyonu | G10: Hat-1 KY | H10: P1 | I10: 3.Aşama | J10: Alt Yarı | K10: KDO-NATM-S06-1013 | L10: 46074 | M10: 1309.94 | N10: KALICI | O10: Umbrella-1 | P10: Tamamlandı | Q10: Q589/589-Çift Kat | R10: 30 cm atıldı | T10: 1
B11: S06.H1.KY.P1.A3.001 | C11: FALSE | E11: KAZI-PÜS-H.ÇELİK | F11: S06-Barbaros İstasyonu | G11: Hat-1 KY | H11: P1 | I11: 3.Aşama | J11: Alt Yarı | K11: KDO-NATM-S06-1013 | L11: 46074 | M11: 1309.19 | N11: KALICI | O11: Umbrella-2 | P11: Tamamlandı | Q11: Q589/589-Çift Kat | R11: 30 cm atıldı | T11: 1
A12: 2026.03-006 | B12: S06.H1.KY.P1.A3.002 | C12: FALSE | E12: KAZI-PÜS-H.ÇELİK | F12: S06-Barbaros İstasyonu | G12: Hat-1 KY | H12: P1 | I12: 3.Aşama | J12: Alt Yarı | K12: KDO-NATM-S06-1166 | L12: 46112 | M12: 1308.44 | N12: KALICI | O12: Umbrella-3 | P12: Tamamlandı | Q12: Q589/589-Çift Kat | R12: 30 cm atıldı
A13: 2026.03-006 | B13: S06.H1.KY.P1.A3.002 | C13: FALSE | E13: KAZI-PÜS-H.ÇELİK | F13: S06-Barbaros İstasyonu | G13: Hat-1 KY | H13: P1 | I13: 3.Aşama | J13: Alt Yarı | K13: KDO-NATM-S06-1166 | L13: 46112 | M13: 1307.69 | N13: KALICI | O13: Umbrella-4 | P13: Tamamlandı | Q13: Q589/589-Çift Kat | R13: 30 cm atıldı | T13: 1
A14: 2026.03-006 | B14: S06.H1.KY.P1.A3.002 | C14: FALSE | E14: KAZI-PÜS-H.ÇELİK | F14: S06-Barbaros İstasyonu | G14: Hat-1 KY | H14: P1 | I14: 3.Aşama | J14: Alt Yarı | K14: KDO-NATM-S06-1166 | L14: 46112 | M14: 1306.94 | N14: KALICI | O14: Umbrella-5 | P14: Tamamlandı | Q14: Q589/589-Çift Kat | R14: 30 cm atıldı | T14: 1
A15: 2026.03-006 | B15: S06.H1.KY.P1.A3.002 | C15: FALSE | E15: KAZI-PÜS-H.ÇELİK | F15: S06-Barbaros İstasyonu | G15: Hat-1 KY | H15: P1 | I15: 3.Aşama | J15: Alt Yarı | K15: KDO-NATM-S06-1166 | L15: 46112 | M15: 1306.19 | N15: KALICI | O15: Umbrella-6 | P15: Tamamlandı | Q15: Q589/589-Çift Kat | R15: 30 cm atıldı | T15: 1
A16: 2026.03-006 | B16: S06.H1.KY.P1.A3.002 | C16: FALSE | E16: KAZI-PÜS-H.ÇELİK | F16: S06-Barbaros İstasyonu | G16: Hat-1 KY | H16: P1 | I16: 3.Aşama | J16: Alt Yarı | K16: KDO-NATM-S06-1166 | L16: 46112 | M16: 1305.44 | N16: KALICI | O16: Umbrella-1 | P16: Tamamlandı | Q16: Q589/589-Çift Kat | R16: 30 cm atıldı | T16: 1
A17: 2026.03-006 | B17: S06.H1.KY.P1.A3.002 | C17: FALSE | E17: KAZI-PÜS-H.ÇELİK | F17: S06-Barbaros İstasyonu | G17: Hat-1 KY | H17: P1 | I17: 3.Aşama | J17: Alt Yarı | K17: KDO-NATM-S06-1167 | L17: 46112 | M17: 1304.69 | N17: KALICI | O17: Umbrella-2 | P17: Tamamlandı | Q17: Q589/589-Çift Kat | R17: 30 cm atıldı | T17: 1
A18: 2026.03-006 | B18: S06.H1.KY.P1.A3.002 | C18: FALSE | E18: KAZI-PÜS-H.ÇELİK | F18: S06-Barbaros İstasyonu | G18: Hat-1 KY | H18: P1 | I18: 3.Aşama | J18: Alt Yarı | K18: KDO-NATM-S06-1167 | L18: 46112 | M18: 1303.94 | N18: KALICI | O18: Umbrella-3 | P18: Tamamlandı | Q18: Q589/589-Çift Kat | R18: 30 cm atıldı | T18: 1
A19: 2026.03-006 | B19: S06.H1.KY.P1.A3.002 | C19: FALSE | E19: KAZI-PÜS-H.ÇELİK | F19: S06-Barbaros İstasyonu | G19: Hat-1 KY | H19: P1 | I19: 3.Aşama | J19: Alt Yarı | K19: KDO-NATM-S06-1159 | L19: 46111 | M19: 1303.19 | N19: KALICI | O19: Umbrella-4 | P19: Tamamlandı | Q19: Q589/589-Çift Kat | R19: 30 cm atıldı | T19: 1
A20: 2026.03-006 | B20: S06.H1.KY.P1.A3.002 | C20: FALSE | E20: KAZI-PÜS-H.ÇELİK | F20: S06-Barbaros İstasyonu | G20: Hat-1 KY | H20: P1 | I20: 3.Aşama | J20: Alt Yarı | K20: KDO-NATM-S06-1159 | L20: 46111 | M20: 1302.44 | N20: KALICI | O20: Umbrella-5 | P20: Tamamlandı | Q20: Q589/589-Çift Kat | R20: 30 cm atıldı | T20: 1
A21: 2026.03-006 | B21: S06.H1.KY.P1.A3.002 | C21: FALSE | E21: KAZI-PÜS-H.ÇELİK | F21: S06-Barbaros İstasyonu | G21: Hat-1 KY | H21: P1 | I21: 3.Aşama | J21: Alt Yarı | K21: KDO-NATM-S06-1159 | L21: 46111 | M21: 1301.69 | N21: KALICI | O21: Umbrella-6 | P21: Tamamlandı | Q21: Q589/589-Çift Kat | R21: 30 cm atıldı | T21: 1
A22: 2026.03-006 | B22: S06.H1.KY.P1.A3.002 | C22: FALSE | E22: KAZI-PÜS-H.ÇELİK | F22: S06-Barbaros İstasyonu | G22: Hat-1 KY | H22: P1 | I22: 3.Aşama | J22: Alt Yarı | K22: KDO-NATM-S06-1154 | L22: 46110 | M22: 1300.94 | N22: KALICI | O22: Umbrella-1 | P22: Tamamlandı | Q22: Q589/589-Çift Kat | R22: 30 cm atıldı | T22: 1
A23: 2026.03-006 | B23: S06.H1.KY.P1.A3.002 | C23: FALSE | E23: KAZI-PÜS-H.ÇELİK | F23: S06-Barbaros İstasyonu | G23: Hat-1 KY | H23: P1 | I23: 3.Aşama | J23: Alt Yarı | K23: KDO-NATM-S06-1154 | L23: 46110 | M23: 1300.19 | N23: KALICI | O23: Umbrella-2 | P23: Tamamlandı | Q23: Q589/589-Çift Kat | R23: 30 cm atıldı | T23: 1
A24: 2026.03-006 | B24: S06.H1.KY.P1.A3.002 | C24: FALSE | E24: KAZI-PÜS-H.ÇELİK | F24: S06-Barbaros İstasyonu | G24: Hat-1 KY | H24: P1 | I24: 3.Aşama | J24: Alt Yarı | K24: KDO-NATM-S06-1154 | L24: 46110 | M24: 1299.44 | N24: KALICI | O24: Umbrella-3 | P24: Tamamlandı | Q24: Q589/589-Çift Kat | R24: 30 cm atıldı | T24: 1
... A100: 2026.02-008 | B100: S06.H1.KY.P1.A3.001 | C100: FALSE | E100: KAZI-PÜS-H.ÇELİK | F100: S06-Barbaros İstasyonu | G100: Hat-1 KY | H100: P1 | I100: 3.Aşama | J100: Alt Yarı | K100: KDO-NATM-S06-1012 | L100: 46074 | M100: 1242.86 | N100: KALICI | O100: Umbrella-6 | P100: Tamamlandı | Q100: Q589/589-Çift Kat | R100: 30 cm atıldı | T100: 1
A101: 2026.02-008 | B101: S06.H1.KY.P1.A3.001 | C101: FALSE | E101: KAZI-PÜS-H.ÇELİK | F101: S06-Barbaros İstasyonu | G101: Hat-1 KY | H101: P1 | I101: 3.Aşama | J101: Alt Yarı | K101: KDO-NATM-S06-1013 | L101: 46074 | M101: 1242,56 Kör Ayna | N101: KALICI | O101: Umbrella-6 | P101: Tamamlandı | Q101: Q589/589-Çift Kat | R101: 30 cm atıldı
A104: 2026.03-006 | B104: S06.H1.KY.P1.A3.002 | C104: FALSE | E104: KAZI-PÜS-H.ÇELİK | F104: S06-Barbaros İstasyonu | G104: Hat-1 KY | H104: P1 | I104: 3.Aşama | J104: Alt Yarı | K104: TBT-NATM-S06-204 | L104: 46092 | M104: 1255.57 | N104: 0.75 | AC104: 3
A105: 2026.03-006 | B105: S06.H1.KY.P1.A3.002 | C105: FALSE | E105: KAZI-PÜS-H.ÇELİK | F105: S06-Barbaros İstasyonu | G105: Hat-1 KY | H105: P1 | I105: 3.Aşama | J105: Alt Yarı | K105: TBT-NATM-S06-204 | L105: 46092 | M105: =+M104-N104 -> 1254.82 | N105: 0.75 | AC105: 3
A106: 2026.03-006 | B106: S06.H1.KY.P1.A3.002 | C106: FALSE | E106: KAZI-PÜS-H.ÇELİK | F106: S06-Barbaros İstasyonu | G106: Hat-1 KY | H106: P1 | I106: 3.Aşama | J106: Alt Yarı | K106: TBT-NATM-S06-204 | L106: 46092 | M106: =+M105-N105 -> 1254.07 | N106: 0.75 | AC106: 3
A107: 2026.03-006 | B107: S06.H1.KY.P1.A3.002 | C107: FALSE | E107: KAZI-PÜS-H.ÇELİK | F107: S06-Barbaros İstasyonu | G107: Hat-1 KY | H107: P1 | I107: 3.Aşama | J107: Alt Yarı | K107: TBT-NATM-S06-204 | L107: 46092 | M107: =+M106-N106 -> 1253.32 | N107: 0.75 | AC107: 3
A108: 2026.03-006 | B108: S06.H1.KY.P1.A3.002 | C108: FALSE | E108: KAZI-PÜS-H.ÇELİK | F108: S06-Barbaros İstasyonu | G108: Hat-1 KY | H108: P1 | I108: 3.Aşama | J108: Alt Yarı | K108: TBT-NATM-S06-204 | L108: 46092 | M108: =+M107-N107 -> 1252.57 | N108: 0.75 | AC108: 3
A109: 2026.03-006 | B109: S06.H1.KY.P1.A3.002 | C109: FALSE | E109: KAZI-PÜS-H.ÇELİK | F109: S06-Barbaros İstasyonu | G109: Hat-1 KY | H109: P1 | I109: 3.Aşama | J109: Alt Yarı | K109: TBT-NATM-S06-204 | L109: 46092 | M109: =+M108-N108 -> 1251.82 | N109: 0.75 | AC109: 3
A110: 2026.03-006 | B110: S06.H1.KY.P1.A3.002 | C110: FALSE | E110: KAZI-PÜS-H.ÇELİK | F110: S06-Barbaros İstasyonu | G110: Hat-1 KY | H110: P1 | I110: 3.Aşama | J110: Alt Yarı | K110: TBT-NATM-S06-204 | L110: 46092 | M110: =+M109-N109 -> 1251.07 | N110: 0.75 | AC110: 3
A111: 2026.03-006 | B111: S06.H1.KY.P1.A3.002 | C111: FALSE | E111: KAZI-PÜS-H.ÇELİK | F111: S06-Barbaros İstasyonu | G111: Hat-1 KY | H111: P1 | I111: 3.Aşama | J111: Alt Yarı | K111: TBT-NATM-S06-204 | L111: 46092 | M111: =+M110-N110 -> 1250.32 | N111: 0.75 | AC111: 3
A112: 2026.03-006 | B112: S06.H1.KY.P1.A3.002 | C112: FALSE | E112: KAZI-PÜS-H.ÇELİK | F112: S06-Barbaros İstasyonu | G112: Hat-1 KY | H112: P1 | I112: 3.Aşama | J112: Alt Yarı | K112: TBT-NATM-S06-204 | L112: 46092 | M112: =+M111-N111 -> 1249.57 | N112: 0.75 | AC112: 3
A113: 2026.03-006 | B113: S06.H1.KY.P1.A3.002 | C113: FALSE | E113: KAZI-PÜS-H.ÇELİK | F113: S06-Barbaros İstasyonu | G113: Hat-1 KY | H113: P1 | I113: 3.Aşama | J113: Alt Yarı | K113: TBT-NATM-S06-204 | L113: 46092 | M113: =+M112-N112 -> 1248.82 | N113: 0.75 | AC113: 3
A114: 2026.03-006 | B114: S06.H1.KY.P1.A3.002 | C114: FALSE | E114: KAZI-PÜS-H.ÇELİK | F114: S06-Barbaros İstasyonu | G114: Hat-1 KY | H114: P1 | I114: 3.Aşama | J114: Alt Yarı | K114: TBT-NATM-S06-204 | L114: 46092 | M114: =+M113-N113 -> 1248.07 | N114: 0.75 | AC114: 3
A115: 2026.03-006 | B115: S06.H1.KY.P1.A3.002 | C115: FALSE | E115: KAZI-PÜS-H.ÇELİK | F115: S06-Barbaros İstasyonu | G115: Hat-1 KY | H115: P1 | I115: 3.Aşama | J115: Alt Yarı | K115: TBT-NATM-S06-204 | L115: 46092 | M115: =+M114-N114 -> 1247.32 | N115: 0.75 | AC115: 3
A116: 2026.03-006 | B116: S06.H1.KY.P1.A3.002 | C116: FALSE | E116: KAZI-PÜS-H.ÇELİK | F116: S06-Barbaros İstasyonu | G116: Hat-1 KY | H116: P1 | I116: 3.Aşama | J116: Alt Yarı | K116: TBT-NATM-S06-204 | L116: 46092 | M116: =+M115-N115 -> 1246.57 | N116: 0.75 | AC116: 3
... A119: 2026.03-006 | B119: S06.H1.KY.P1.A3.002 | C119: FALSE | E119: KAZI-PÜS-H.ÇELİK | F119: S06-Barbaros İstasyonu | G119: Hat-1 KY | H119: P1 | I119: 3.Aşama | J119: Alt Yarı | K119: TBT-NATM-S06-204 | L119: 46092 | M119: =+M118-N118 -> 1244.32 | N119: 0.75 | AC119: 3
...

Sheet AYNA TAKİP
A1: Dönemi | B1: Hk No | C1: Sıra No | D1: Km | E1: Yeri | G1: Çelik Hasır | H1: Püskürtme Betonu | J1: Kalınlık | K1: Alan | L1: Hasır
A2: 45839 | B2: 3 | C2: 1 | D2: 2101.61 | E2: Üst Yarı | F2: 1 | H2: 5 cm atıldı | J2: 0.05 | K2: 27.35
A3: 45839 | B3: 3 | C3: =+C2+1 -> 2 | D3: 2102.36 | E3: Üst Yarı | F3: 2 | H3: 5 cm atıldı | J3: 0.05 | K3: 28.106
A4: 45839 | B4: 3 | C4: =+C3+1 -> 3 | D4: 2103.11 | E4: Üst Yarı | F4: 3 | H4: 5 cm atıldı | J4: 0.05 | K4: 28.879
A5: 45839 | B5: 3 | C5: =+C4+1 -> 4 | D5: 2103.11 | E5: Üst Yarı | F5: 3 | G5: Q221/221 Tek Kat | H5: 15 cm atıldı 8 m² | J5: 0.15 | K5: 8 | L5: =+K5*3.47/1000 -> 0.02776
A6: 45839 | B6: 3 | C6: =+C5+1 -> 5 | D6: 2103.86 | E6: Üst Yarı | F6: 4 | H6: 5 cm atıldı | J6: 0.05 | K6: 29.536
A7: 45839 | B7: 3 | C7: =+C6+1 -> 6 | D7: 2104.61 | E7: Üst Yarı | F7: 5 | H7: 5 cm atıldı | J7: 0.05 | K7: 30.158
A8: 45839 | B8: 3 | C8: =+C7+1 -> 7 | D8: 2105.36 | E8: Üst Yarı | F8: 6 | G8: Q221/221 Tek Kat | H8: 15 cm atıldı | J8: 0.15 | K8: 30.868 | L8: =0.3*416.54/1000 -> 0.124962
A9: 45839 | B9: 3 | C9: =+C8+1 -> 8 | D9: 2106.11 | E9: Üst Yarı | F9: 1 | H9: 5 cm atıldı | J9: 0.05 | K9: 27.35
A10: 45839 | B10: 3 | C10: =+C9+1 -> 9 | D10: 2106.86 | E10: Üst Yarı | F10: 2 | H10: 5 cm atıldı | J10: 0.05 | K10: 28.106
A11: 45839 | B11: 3 | C11: =+C10+1 -> 10 | D11: 2107.61 | E11: Üst Yarı | F11: 3 | H11: 5 cm atıldı | J11: 0.05 | K11: 28.879
A12: 45839 | B12: 3 | C12: =+C11+1 -> 11 | D12: 2107.61 | E12: Üst Yarı | F12: 3 | G12: Q221/221 Tek Kat | H12: 15 cm atıldı 8 m² | J12: 0.15 | K12: 8 | L12: =+K12*3.47/1000 -> 0.02776
A13: 45839 | B13: 3 | C13: =+C12+1 -> 12 | D13: 2108.36 | E13: Üst Yarı | F13: 4 | H13: 5 cm atıldı | J13: 0.05 | K13: 29.536
A14: 45839 | B14: 3 | C14: =+C13+1 -> 13 | D14: 2109.11 | E14: Üst Yarı | F14: 5 | H14: 5 cm atıldı | J14: 0.05 | K14: 30.158
A15: 45839 | B15: 3 | C15: =+C14+1 -> 14 | D15: 2109.86 | E15: Üst Yarı | F15: 6 | G15: Q221/221 Tek Kat | H15: 15 cm atıldı | J15: 0.15 | K15: 30.868 | L15: =0.3*416.54/1000 -> 0.124962
A16: 45839 | B16: 3 | C16: =+C15+1 -> 15 | D16: 2110.61 | E16: Üst Yarı | F16: 1 | H16: 5 cm atıldı | J16: 0.05 | K16: 27.35
A17: 45839 | B17: 3 | C17: =+C16+1 -> 16 | D17: 2111.36 | E17: Üst Yarı | F17: 2 | H17: 5 cm atıldı | J17: 0.05 | K17: 28.106
A18: 45839 | B18: 3 | C18: =+C17+1 -> 17 | D18: 2112.11 | E18: Üst Yarı | F18: 3 | H18: 5 cm atıldı | J18: 0.05 | K18: 28.879
A19: 45839 | B19: 3 | C19: =+C18+1 -> 18 | D19: 2112.11 | E19: Üst Yarı | F19: 3 | G19: Q221/221 Tek Kat | H19: 15 cm atıldı 8 m² | J19: 0.15 | K19: 8 | L19: =+K19*3.47/1000 -> 0.02776
A20: 45839 | B20: 3 | C20: =+C19+1 -> 19 | D20: 2112.86 | E20: Üst Yarı | F20: 4 | H20: 5 cm atıldı | J20: 0.05 | K20: 29.536
A21: 45839 | B21: 3 | C21: =+C20+1 -> 20 | D21: 2113.61 | E21: Üst Yarı | F21: 5 | H21: 5 cm atıldı | J21: 0.05 | K21: 30.158
A22: 45839 | B22: 3 | C22: =+C21+1 -> 21 | D22: 2114.36 | E22: Üst Yarı | F22: 6 | G22: Q221/221 Tek Kat | H22: 15 cm atıldı | J22: 0.15 | K22: 30.868 | L22: =0.3*416.54/1000 -> 0.124962
A23: 45839 | B23: 3 | C23: =+C22+1 -> 22 | D23: 2115.18 | E23: Üst Yarı | F23: 6 | H23: 5 cm atıldı | J23: 0.05 | K23: 30.868
A24: 45839 | B24: 3 | C24: =+C23+1 -> 23 | D24: 2115.85 | E24: Üst Yarı | F24: 1 | H24: 5 cm atıldı | J24: 0.05 | K24: 27.35
A25: 45839 | B25: 3 | C25: =+C24+1 -> 24 | D25: 2116.6 | E25: Üst Yarı | F25: 2 | H25: 5 cm atıldı | J25: 0.05 | K25: 28.106
A26: 45839 | B26: 3 | C26: =+C25+1 -> 25 | D26: 2117.35 | E26: Üst Yarı | F26: 3 | H26: 5 cm atıldı | J26: 0.05 | K26: 28.879
A27: 45839 | B27: 3 | C27: =+C26+1 -> 26 | D27: 2117.35 | E27: Üst Yarı | F27: 3 | G27: Q221/221 Tek Kat | H27: 15 cm atıldı 8 m² | J27: 0.15 | K27: 8 | L27: =+K27*3.47/1000 -> 0.02776
A28: 45870 | B28: 3 | C28: =+C27+1 -> 27 | D28: 2118.1 | E28: Üst Yarı | F28: 4 | H28: 5 cm atıldı | J28: 0.05 | K28: 29.536
A29: 45870 | B29: 3 | C29: =+C28+1 -> 28 | D29: 2118.1 | E29: Üst Yarı | F29: 4 | G29: Q221/221 Tek Kat | H29: 15 cm atıldı 8 m² | J29: 0.15 | K29: 8 | L29: =+K29*3.47/1000 -> 0.02776
A30: 45870 | B30: 3 | C30: =+C29+1 -> 29 | D30: 2118.85 | E30: Üst Yarı | F30: 5 | H30: 5 cm atıldı | J30: 0.05 | K30: 30.158
A31: 45870 | B31: 3 | C31: =+C30+1 -> 30 | D31: 2119.6 | E31: Üst Yarı | F31: 6 | G31: Q221/221 Tek Kat | H31: 15 cm atıldı | J31: 0.15 | K31: 30.868 | L31: =0.3*416.54/1000 -> 0.124962
A32: 45870 | B32: 3 | C32: =+C31+1 -> 31 | D32: 2120.35 | E32: Üst Yarı | F32: 1 | H32: 5 cm atıldı | J32: 0.05 | K32: 27.35
A33: 45870 | B33: 3 | C33: =+C32+1 -> 32 | D33: 2121.1 | E33: Üst Yarı | F33: 2 | H33: 5 cm atıldı | J33: 0.05 | K33: 28.106
A34: 45870 | B34: 3 | C34: =+C33+1 -> 33 | D34: 2121.1 | E34: Üst Yarı | F34: 2 | G34: Q221/221 Tek Kat | H34: 15 cm atıldı 8 m² | J34: 0.15 | K34: 8 | L34: =+K34*3.47/1000 -> 0.02776
A35: 45870 | B35: 3 | C35: =+C34+1 -> 34 | D35: 2121.85 | E35: Üst Yarı | F35: 3 | H35: 5 cm atıldı | J35: 0.05 | K35: 28.879
A36: 45870 | B36: 3 | C36: =+C35+1 -> 35 | D36: 2122.6 | E36: Üst Yarı | F36: 4 | H36: 5 cm atıldı | J36: 0.05 | K36: 29.536
A37: 45870 | B37: 3 | C37: =+C36+1 -> 36 | D37: 2122.6 | E37: Üst Yarı | F37: 4 | G37: Q221/221 Tek Kat | H37: 15 cm atıldı 6 m² | J37: 0.15 | K37: 6 | L37: =+K37*3.47/1000 -> 0.02082
A38: 45870 | B38: 3 | C38: =+C37+1 -> 37 | D38: 2123.35 | E38: Üst Yarı | F38: 5 | H38: 5 cm atıldı | J38: 0.05 | K38: 30.158
A39: 45870 | B39: 3 | C39: =+C38+1 -> 38 | D39: 2124.48 | E39: Üst Yarı | F39: 6 | G39: Q589/589 Çift Kat | H39: 30 cm atıldı | J39: 0.3 | K39: 30.868 | L39: =0.3*1008.66/1000 -> 0.302598

Sheet Kontrol
E2: KM1 | F2: =+_xlfn.MINIFS(DATA!M:M,DATA!Q:Q,"Q589/589-Çift Kat") -> 1242.86 | G2: =+_xlfn.MINIFS(DATA!M:M,DATA!Q:Q,"3xQ221/221-Çift Kat") -> 0
E3: KM2 | F3: =+_xlfn.MAXIFS(DATA!M:M,DATA!Q:Q,"Q589/589-Çift Kat")+0.3 -> 1315.49 | G3: =+_xlfn.MAXIFS(DATA!M:M,DATA!Q:Q,"3xQ221/221-Çift Kat") -> 0 | I3: Aynadan dolayı ilave ilerleme var
A4: İş Kalemi No | B4: Açıklama | C4: Birimi | D4: Birim Fiyat | E4: Toplam | F4: Kalıcı | G4: Geçici | H4: Ayna
A5: 018 | B5: Geleneksel (NATM) Tünel Kazısı | C5: m³ | D5: 5075 | E5: =ROUND(SUM(F5:H5),3) -> 2181.336 | F5: =+ROUND(ABS(F2-F3)*29.15,3) -> 2117.165 | G5: =+ROUND(ABS(G2-G3)*1.149,3) -> 0 | H5: =+SUMPRODUCT('AYNA TAKİP'!J1:J38,'AYNA TAKİP'!K1:K38) -> 64.17145
A6: 019.A | B6: Kazıdan çıkan veya Ariyetten alınan malzeme ile geri dolgu yapılması | C6: m³ | D6: 600 | E6: =ROUND(SUM(F6:H6),3) -> 0
A7: 019.B | B7: Kum, Çakıl, Kırma Tas ve Benzeri Malzeme ile Dolgu Yapılması | C7: m³ | D7: 1500 | E7: =ROUND(SUM(F7:H7),3) -> 0
A8: 020 | B8: Püskürtme Beton (Tünel ve Şaftlarda) | C8: m³ | D8: 15334 | E8: =ROUND(SUM(F8:H8),3) -> 270.971 | F8: =+ROUND(ABS(F2-F3)*3.022,3)*0.9 -> 197.5392 | G8: =+ROUND(ABS(G2-G3)*1.149,3) -> 0 | H8: =+SUMPRODUCT('AYNA TAKİP'!J:J,'AYNA TAKİP'!K:K) -> 73.43185
A9: 021.A | B9: Delgi boyu =< 30m | C9: m | D9: 248
A10: 021.B | B10: Delgi boyu > 30m | C10: m | D10: 371
A11: 022.A | B11: L=3 m Kaya Bulonu | C11: adet | D11: 2250 | E11: =+SUM(DATA!Y:Y) -> 0
A12: 022.B | B12: L=4 m Kaya Bulonu | C12: adet | D12: 8000 | E12: =+SUM(DATA!Z:Z) -> 0
A13: 022.C | B13: L=5 m Kaya Bulonu | C13: adet | D13: 8288 | E13: =+SUM(DATA!AA:AA) -> 0
A14: 022.D | B14: L=6 m Kaya Bulonu | C14: adet | D14: 12000 | E14: =+SUM(DATA!AB:AB) -> 0
A15: 022.E | B15: L=8 m Kaya Bulonu | C15: adet | D15: 28000 | E15: =+SUM(DATA!AC:AC) -> 270
A16: 023.A | B16: 125 mm Delik İçine 14 mm Kalınlığında S420a ile Zemin Çivisi Teşkili | C16: m | D16: 375 | E16: =+SUM(DATA!AE:AE) -> 0
A17: 023.B | B17: 125 mm Delik İçine 26 mm Kalınlığında S420a ile Zemin Çivisi Teşkili | C17: m | D17: 388 | E17: =+SUM(DATA!AF:AF) -> 0
A18: 024 | B18: Çelik İksa (Tünel ve Şaftlarda) | C18: ton | D18: 102000 | E18: =ROUND(SUM(F18:G18),3) -> 77.614 | F18: =SUMIFS(DATA!T:T,DATA!N:N,"KALICI",DATA!O:O,"Umbrella-1")*0.713518+SUMIFS(DATA!T:T,DATA!N:N,"KALICI",DATA!O:O,"Umbrella-2")*0.71664+SUMIFS(DATA!T:T,DATA!N:N,"KALICI",DATA!O:O,"Umbrella-3")*0.729202+SUMIFS(DATA!T:T,DATA!N:N,"KALICI",DATA!O:O,"Umbrella-4")*0.74693+SUMIFS(DATA!T:T,DATA!N:N,"KALICI",DATA!O:O,"Umbrella-5")*0.75958+SUMIFS(DATA!T:T,DATA!N:N,"KALICI",DATA!O:O,"Umbrella-6")*0.770217 -> 77.613854 | G18: =SUMIFS(DATA!S:S,DATA!N:N,"GEÇİCİ",DATA!O:O,"Umbrella-1")*0.210818+SUMIFS(DATA!S:S,DATA!N:N,"GEÇİCİ",DATA!O:O,"Umbrella-2")*0.215206+SUMIFS(DATA!S:S,DATA!N:N,"GEÇİCİ",DATA!O:O,"Umbrella-3")*0.217336+SUMIFS(DATA!S:S,DATA!N:N,"GEÇİCİ",DATA!O:O,"Umbrella-4")*0.216782+SUMIFS(DATA!S:S,DATA!N:N,"GEÇİCİ",DATA!O:O,"Umbrella-5")*0.21691+SUMIFS(DATA!S:S,DATA!N:N,"GEÇİCİ",DATA!O:O,"Umbrella-6")*0.218869 -> 0
A19: 025 | B19: Umbrella Arch Yapılması | C19: m | D19: 3400 | E19: =+SUM(DATA!V:V) -> 0
A20: 026.A | B20: Tünel ve şaftlarda su yalıtımı, birim ağırlığı >=500 g/metrekare geotekstil keçe | C20: m² | D20: 510
A21: 026.B | B21: Tünel ve şaftlarda su yalıtımı, 2mm kalınlıklı PVC membran | C21: m² | D21: 1200
A22: 027 | B22: Su Tutucular (Tünel ve Şaftlarda) | C22: m | D22: 2160
A23: 028.A | B23: Kalıp (invert ve şaft için) | C23: m² | D23: 4150
A24: 028.B | B24: Kalıp (duvar ve kemer İçin) | C24: m² | D24: 1500
A25: 028.C | B25: Tip Kesit Dışı Konstrüksiyon Kalıbı, Tünel Alın Kalıbı | C25: m² | D25: 500
A26: 029.A | B26: C16 Beton İmali ve Dökülmesi (Tünel ve Şaftlarda) | C26: m³ | D26: 6030
A27: 029.B | B27: C30 Beton İmali ve Dökülmesi (Tünel ve Şaftlarda) Tünel kaplaması, invert ve şaftlardaki alt döşeme | C27: m³ | D27: 10355
A28: 029.C | B28: C30 Beton İmali ve Dökülmesi (Tünel ve Şaftlarda) Yan duvarlar, kemer | C28: m³ | D28: 10355
A29: 029.D | B29: Diğer Kesit Dışındaki Yapıların Betonu C30 | C29: m³ | D29: 10355
A30: 030.A | B30: Çelik Donatı (S220 ) | C30: ton | D30: 46250 | E30: =ROUND(SUM(F30:G30),3) -> 3.882 | F30: =ROUND(SUM(DATA!T:T)*(20*0.888*1.5+9*1.208*0.95)/1000,3) -> 3.882
A31: 030.B | B31: Çelik Donatı (S420a ) | C31: ton | D31: 92500 | E31: =ROUND(SUM(F31:G31),3) -> 0 | F31: =+ROUND(COUNTIFS(DATA!AG:AG,"30 adet L=2m Ø12 Demir montajı yapıldı.")*30*0.888*2/1000,3) -> 0
A32: 030.C | B32: Çelik hasır (S500 ) | C32: ton | D32: 97333 | E32: =ROUND(SUM(F32:H32),3) -> 21.54 | F32: =ROUND(SUM(DATA!T:T)*0.195718,3) -> 20.55 | G32: =ROUND(SUM(DATA!S:S)*0.11171,3) -> 0 | H32: =+SUM('AYNA TAKİP'!L:L) -> 0.989826
A33: 030.D | B33: Paslanmaz Çelik Plaka | C33: kg | D33: 150
A34: 030.E | B34: Block-out Kutusu | C34: kg | D34: 180
E35: =+SUMPRODUCT(D5:D34,E5:E34) -> 32978073
