Workbook
Name Dilimleyici_Kazı_Boyu_için_Kullan: #N/A
Name Dilimleyici_Ø_14__lük_Zemin_Çivisi: #N/A
Name Dilimleyici_Ø_26__lık_Zemin_Çivisi: #N/A
Name Dilimleyici_Tip: #N/A
Name Dilimleyici_Tip1: #N/A
Name Dilimleyici_Tip11: #N/A
Name Dilimleyici_Tutanak_Genel_No__Elle: #N/A
Name Dilimleyici_Tutanak_Genel_No__Elle1: #N/A
Name Dilimleyici_Tutanak_Genel_No__Elle2: #N/A
Name Dilimleyici_Tutanak_Genel_No__Elle3: #N/A
Name Dilimleyici_Tutanak_Özel_No__Elle: #N/A
Name Dilimleyici_Tutanak_Özel_No__Elle1: #N/A
Name Dilimleyici_Tutanak_Özel_No__Elle11: #N/A
Name Dilimleyici_Tutanak_Özel_No__Elle2: #N/A
Name Dilimleyici_Umbrella_Arch: #N/A
Name Dilimleyici_Yeri: #N/A
Name Dilimleyici_Yeri1: #N/A
Name Dilimleyici_Yeri11: #N/A

Sheet TUTANAK
A2: TUTANAK
L3: Tutanak Tarihi-1 | M3: {=+TEXT(MIN(IF(DATA!A:A=D6,DATA!L:L)),"gg.aa.yyyy")} -> 01.04.2026
A4: Tutanak Konusu | C4: : | D4: =+DATA!F3&" "&DATA!G3&" "&DATA!I3&" ("&DATA!J3&") "&" '"&DATA!H3&"' Tipi Tünel İmalatları" -> S06-Barbaros İstasyonu Hat-2 HY 4.Aşama (Alt Yarı) 'P1' Tipi Tünel İmalatları | L4: Tutanak Tarihi-2 | M4: {=+TEXT(MAX(IF(DATA!A:A=D6,DATA!L:L)),"gg.aa.yyyy")} -> 30.04.2026
A6: Tutanak No | B6: Genel | C6: : | D6: 2026.04-006 | J6: Elle
B7: Özel | C7: : | D7: S06.H2.HY.P1.A4.002 | J7: Elle
A8: Tutanak Tarihi | C8: : | D8: 46142 | J8: Elle
A9: Tutanak Konusu | C9: : | D9: NATM Tünel İmalatı
A10: Tutanak Ekleri | C10: : | D10: 1 | E10: İksa, Püskürtme Betonu Ve Hasır Çelik İcmali
D11: 2 | E11: Bulon İcmali
A16: İşin Adı | C16: : | D16: Kirazlı-Halkalı Üniversite Metro Hattı İnşaat Ve Elektromekanik İşler İle M1 Hattı Elektromekanik Sistemleri Yapım İşi
A19: Yüklenicinin Adı | C19: : | D19: Kalyon-Özgün Metro İnşaatı Adi Ortaklığı Ticari İşletmesi
A20: Sözleşme Tarihi | C20: : | D20: 45639
A21: İşe Başlama Tarihi | C21: : | D21: 45653
A22: Sözleşmeye Göre İşin Süresi | C22: : | D22: 1440 Gün
A23: Sözleşmeye Göre İşin Bitiş Tarihi | C23: : | D23: 47093
A25: =+"'Kirazlı-Halkalı Üniversite Metro Hattı İnşaat Ve Elektromekanik İşler İle M1 Hattı Elektromekanik Sistemleri Yapım İşi' İşinde NATM Tünellerin yapımı sırasında "&M3&" - "&M4&" tarihleri arasında Şartnamesine uygun olarak yapılan imalatlar ekli tablolarda belirtilmiştir." -> 'Kirazlı-Halkalı Üniversite Metro Hattı İnşaat Ve Elektromekanik İşler İle M1 Hattı Elektromekanik Sistemleri Yapım İşi' İşinde NATM Tünellerin yapımı sırasında 01.04.2026 - 30.04.2026 tarihleri arasında Şartnamesine uygun olarak yapılan imalatlar ekli tablolarda belirtilmiştir.
A29: =+"İş bu tutanak "&TEXT(D8,"gg.aa.yyyy")&" tarihinde taraflarca 6 nüsha olarak imzalanmıştır." -> İş bu tutanak 30.04.2026 tarihinde taraflarca 6 nüsha olarak imzalanmıştır.

Sheet KAZI-İKSA
A2: KİRAZLI-HALKALI ÜNİVERSİTE METRO HATTI İNŞAAT VE ELEKTROMEKANİK İŞLER İLE
A3: M1 HATTI ELEKTROMEKANİK SİSTEMLERİ YAPIM İŞİ
A4: =+"İKSA, PÜSKÜRTME BETONU VE HASIR ÇELİK İCMALİ (" & TUTANAK!$M$3& "-"& TUTANAK!$M$4& ")" -> İKSA, PÜSKÜRTME BETONU VE HASIR ÇELİK İCMALİ (01.04.2026-30.04.2026)
A5: =+DATA!H3 -> P1
H6: Tutanak Ek No: | I6: =+TUTANAK!$D$10 -> 1
A7: İmalatın Yeri: | B7: =+DATA!$F$3&" "&DATA!$G$3&" "&DATA!$H$3&" Tüneli "&DATA!$I$3&" ("&DATA!$J$3&")" -> S06-Barbaros İstasyonu Hat-2 HY P1 Tüneli 4.Aşama (Alt Yarı)
A8: Tutanak Genel No: | B8: =+TUTANAK!$D$6 -> 2026.04-006
A9: Tutanak Özel No: | B9: =+TUTANAK!$D$7 -> S06.H2.HY.P1.A4.002
A10: Tutanak Tarihi: | B10: =+TUTANAK!$D$8 -> 46142
A13: ATF No | B13: Tarih | C13: Kilometre | D13: Çelik Hasır | E13: Püskürtme Betonu | F13: İksa Tipi | G13: Geçici İnvert Çelik İksa HEB160 | H13: Kalıcı Çelik İksa HEB200
A14: KDO-NATM-S06-1174 | B14: 46113 | C14: 1395.29 | D14: Q589/589-Çift Kat | E14: 30 cm atıldı | F14: Umbrella-4 | H14: 1
A15: KDO-NATM-S06-1174 | B15: 46113 | C15: 1396.04 | D15: Q589/589-Çift Kat | E15: 30 cm atıldı | F15: Umbrella-5 | H15: 1
A16: KDO-NATM-S06-1174 | B16: 46113 | C16: 1396.79 | D16: Q589/589-Çift Kat | E16: 30 cm atıldı | F16: Umbrella-6 | H16: 1
A17: KDO-NATM-S06-1178 | B17: 46114 | C17: 1393.04 | D17: Q589/589-Çift Kat | E17: 30 cm atıldı | F17: Umbrella-1 | H17: 1
A18: KDO-NATM-S06-1178 | B18: 46114 | C18: 1393.79 | D18: Q589/589-Çift Kat | E18: 30 cm atıldı | F18: Umbrella-2 | H18: 1
A19: KDO-NATM-S06-1178 | B19: 46114 | C19: 1394.54 | D19: Q589/589-Çift Kat | E19: 30 cm atıldı | F19: Umbrella-3 | H19: 1
A20: KDO-NATM-S06-1182 | B20: 46115 | C20: 1388.54 | D20: Q589/589-Çift Kat | E20: 30 cm atıldı | F20: Umbrella-1 | H20: 1
A21: KDO-NATM-S06-1182 | B21: 46115 | C21: 1389.29 | D21: Q589/589-Çift Kat | E21: 30 cm atıldı | F21: Umbrella-2 | H21: 1
A22: KDO-NATM-S06-1182 | B22: 46115 | C22: 1390.04 | D22: Q589/589-Çift Kat | E22: 30 cm atıldı | F22: Umbrella-3 | H22: 1
A23: KDO-NATM-S06-1182 | B23: 46115 | C23: 1390.79 | D23: Q589/589-Çift Kat | E23: 30 cm atıldı | F23: Umbrella-4 | H23: 1
A24: KDO-NATM-S06-1183 | B24: 46115 | C24: 1391.54 | D24: Q589/589-Çift Kat | E24: 30 cm atıldı | F24: Umbrella-5 | H24: 1
A25: KDO-NATM-S06-1183 | B25: 46115 | C25: 1392.29 | D25: Q589/589-Çift Kat | E25: 30 cm atıldı | F25: Umbrella-6 | H25: 1
... A64: KDO-NATM-S06-1224 | B64: 46135 | C64: 1360.79 | D64: Q589/589-Çift Kat | E64: 30 cm atıldı | F64: Umbrella-6 | H64: 1
A65: KDO-NATM-S06-1226 | B65: 46136 | C65: 1356.66 | D65: Q589/589-Çift Kat | E65: 30 cm atıldı | F65: (boş)
A66: KDO-NATM-S06-1226 | B66: 46136 | C66: 1357.04 | D66: Q589/589-Çift Kat | E66: 30 cm atıldı | F66: Umbrella-1 | H66: 1
A67: KDO-NATM-S06-1226 | B67: 46136 | C67: 1357.79 | D67: Q589/589-Çift Kat | E67: 30 cm atıldı | F67: Umbrella-2 | H67: 1
A68: KDO-NATM-S06-1226 | B68: 46136 | C68: 1358.54 | D68: Q589/589-Çift Kat | E68: 30 cm atıldı | F68: Umbrella-3 | H68: 1
A69: Genel Toplam | H69: 54

Sheet BULON
C2: KİRAZLI-HALKALI ÜNİVERSİTE METRO HATTI İNŞAAT VE ELEKTROMEKANİK İŞLER İLE
C3: M1 HATTI ELEKTROMEKANİK SİSTEMLERİ YAPIM İŞİ
C4: =+"BULON İCMALİ (" & TUTANAK!$M$3& "-"& TUTANAK!$M$4& ")" -> BULON İCMALİ (01.04.2026-30.04.2026)
C5: P1
H6: Tutanak Ek No: | I6: =+TUTANAK!$D$11 -> 2
C7: İmalatın Yeri: | D7: =+DATA!$F$3&" "&DATA!$G$3&" "&DATA!$H$3&" Tüneli "&DATA!$I$3&" ("&DATA!$J$3&")" -> S06-Barbaros İstasyonu Hat-2 HY P1 Tüneli 4.Aşama (Alt Yarı)
C8: Tutanak Genel No: | D8: =+TUTANAK!$D$6 -> 2026.04-006
C9: Tutanak Özel No: | D9: =+TUTANAK!$D$7 -> S06.H2.HY.P1.A4.002
C10: Tutanak Tarihi: | D10: =+TUTANAK!$D$8 -> 46142
C13: ATF No | D13: Tarih | E13: Kilometre | F13: 4 mt Kaya Bulonu (adet) | G13: 6 mt Kaya Bulonu (adet) | H13: 8 mt Kaya Bulonu (adet)
C14: TBT-NATM-S06-249 | D14: 46120 | E14: 1385.17 | H14: 3
C15: TBT-NATM-S06-249 | D15: 46120 | E15: 1385.92 | H15: 3
C16: TBT-NATM-S06-249 | D16: 46120 | E16: 1394.92 | H16: 3
C17: TBT-NATM-S06-249 | D17: 46120 | E17: 1395.67 | H17: 3
C18: TBT-NATM-S06-249 | D18: 46120 | E18: 1396.42 | H18: 3
C19: TBT-NATM-S06-249 | D19: 46120 | E19: 1397.17 | H19: 3
C20: TBT-NATM-S06-249 | D20: 46120 | E20: 1397.92 | H20: 3
C21: TBT-NATM-S06-249 | D21: 46120 | E21: 1398.67 | H21: 3
C22: TBT-NATM-S06-249 | D22: 46120 | E22: 1399.42 | H22: 3
C23: TBT-NATM-S06-249 | D23: 46120 | E23: 1400.17 | H23: 3
C24: TBT-NATM-S06-249 | D24: 46120 | E24: 1400.92 | H24: 3
C25: TBT-NATM-S06-249 | D25: 46120 | E25: 1401.67 | H25: 3
... C49: TBT-NATM-S06-253 | D49: 46142 | E49: 1384.42 | H49: 3
C50: Genel Toplam (adet) | H50: 108

Sheet UMBRELLA ARCH
C2: KİRAZLI-HALKALI ÜNİVERSİTE METRO HATTI İNŞAAT VE ELEKTROMEKANİK İŞLER İLE
C3: M1 HATTI ELEKTROMEKANİK SİSTEMLERİ YAPIM İŞİ
C4: =+"UMBRELLA ARCH İCMALİ (" & TUTANAK!$M$3& "-"& TUTANAK!$M$4& ")" -> UMBRELLA ARCH İCMALİ (01.04.2026-30.04.2026)
C5: P1
G6: Tutanak Ek No: | H6: =+TUTANAK!$D$12 -> 0
D7: İmalatın Yeri: | E7: =+DATA!$F$3&" "&DATA!$G$3&" "&DATA!$H$3&" Tüneli "&DATA!$I$3&" ("&DATA!$J$3&")" -> S06-Barbaros İstasyonu Hat-2 HY P1 Tüneli 4.Aşama (Alt Yarı)
D8: Tutanak Genel No: | E8: =+TUTANAK!$D$6 -> 2026.04-006
D9: Tutanak Özel No: | E9: =+TUTANAK!$D$7 -> S06.H2.HY.P1.A4.002
D10: Tutanak Tarihi: | E10: =+TUTANAK!$D$8 -> 46142
D14: ATF No | E14: Tarih | F14: Kilometre | G14: Umbrella Arch (metre)
D15: KDO-NATM-S07-141 | E15: 45874 | F15: 2119.6 | G15: 423
D16: Genel Toplam (metre) | G16: 423

Sheet ZEMİN ÇİVİSİ
C2: KİRAZLI-HALKALI ÜNİVERSİTE METRO HATTI İNŞAAT VE ELEKTROMEKANİK İŞLER İLE
C3: M1 HATTI ELEKTROMEKANİK SİSTEMLERİ YAPIM İŞİ
C4: =+"ZEMİN ÇİVİSİ İCMALİ (" & TUTANAK!$M$3& "-"& TUTANAK!$M$4& ")" -> ZEMİN ÇİVİSİ İCMALİ (01.04.2026-30.04.2026)
C5: P1
G6: Tutanak Ek No: | H6: =+TUTANAK!$D$13 -> 0
C7: İmalatın Yeri: | D7: =+DATA!$F$3&" "&DATA!$G$3&" "&DATA!$H$3&" Tüneli "&DATA!$I$3&" ("&DATA!$J$3&")" -> S06-Barbaros İstasyonu Hat-2 HY P1 Tüneli 4.Aşama (Alt Yarı)
C8: Tutanak Genel No: | D8: =+TUTANAK!$D$6 -> 2026.04-006
C9: Tutanak Özel No: | D9: =+TUTANAK!$D$7 -> S06.H2.HY.P1.A4.002
C10: Tutanak Tarihi: | D10: =+TUTANAK!$D$8 -> 46142
C13: ATF No | D13: Tarih | E13: Kilometre | F13: Ø 14 'lük Zemin Çivisi (metre) | G13: Ø 26 'lık Zemin Çivisi (metre)
C14: KDO-NATM-S07-141 | D14: 45874 | E14: 2119.6 | F14: 162
C15: Genel Toplam (metre) | F15: 162

Sheet AYNA
A2: KİRAZLI-HALKALI ÜNİVERSİTE METRO HATTI İNŞAAT VE ELEKTROMEKANİK İŞLER İLE
A3: M1 HATTI ELEKTROMEKANİK SİSTEMLERİ YAPIM İŞİ
A4: =+"AYNA İCMALİ (" & TUTANAK!$M$3& "-"& TUTANAK!$M$4& ")" -> AYNA İCMALİ (01.04.2026-30.04.2026)
A5: P1
G6: Tutanak Ek No: | H6: =+TUTANAK!$D$14 -> 0
A7: İmalatın Yeri: | C7: =+DATA!$F$3&" "&DATA!$G$3&" "&DATA!$H$3&" Tüneli "&DATA!$I$3&" ("&DATA!$J$3&")" -> S06-Barbaros İstasyonu Hat-2 HY P1 Tüneli 4.Aşama (Alt Yarı)
A8: Tutanak Genel No: | C8: =+TUTANAK!$D$6 -> 2026.04-006
A9: Tutanak Özel No: | C9: =+TUTANAK!$D$7 -> S06.H2.HY.P1.A4.002
A10: Tutanak Tarihi: | C10: =+TUTANAK!$D$8 -> 46142
B13: AYNA İMALATLARI
A14: Sıra No | C14: Km | D14: Yeri | F14: Çelik Hasır | G14: Püskürtme Betonu
A15: 1 | C15: 1438.24 | D15: Üst Yarı | E15: Tip - 6 Geçici İksa | F15: Q589/589 Çift Kat | G15: 30 cm atıldı

Sheet DATA
A1: Tutanak Genel No (Elle) | B1: Tutanak Özel No (Elle) | C1: Kazı Boyu için Kullan | D1: Ödeme | E1: Tip | F1: Şantiye Adı Yeri | G1: Tünel Adı | H1: Tünel Tipi | I1: Aşama | J1: Yeri | K1: ATF No | L1: Tarih | M1: Kilometre | N1: Açıklama | O1: Açıklama-2 | P1: Kazı | Q1: Çelik Hasır | R1: Püskürtme Betonu | S1: Çelik İksa HEB160 | T1: Çelik İksa HEB200 | U1: S | V1: Umbrella Arch | W1: Boru Süren | X1: S | Y1: 3 mt Kaya Bulonu | Z1: 4 mt Kaya Bulonu | AA1: 5 mt Kaya Bulonu | AB1: 6 mt Kaya Bulonu | AC1: 8 mt Kaya Bulonu | AD1: S | AE1: Ø 14 'lük Zemin Çivisi | AF1: Ø 26 'lık Zemin Çivisi | AG1: Pah Donatısı
C2: =AND(A2=[1]TUTANAK!$D$6,P2="Tamamlandı") -> FALSE | E2: =+IF(OR(P2<>""),"KAZI-PÜS-H.ÇELİK",IF(AND(SUM(V2:W2)>0,SUM(AE2:AF2)=0),"SÜREN",IF(SUM(Y2:AC2)>0,"BULON",IF(SUM(AE2:AF2)>0,"ZEMİN ÇİVİSİ")))) -> FALSE | F2: S06-Barbaros İstasyonu | G2: Hat-2 HY | H2: P1 | I2: 4.Aşama | J2: Alt Yarı | K2: KDO-NATM-S06-1103 | L2: 46094 | M2: 1357.04
A3: 2026.04-006 | B3: S06.H2.HY.P1.A4.002 | C3: =AND(A3=[1]TUTANAK!$D$6,P3="Tamamlandı") -> FALSE | E3: =+IF(OR(P3<>""),"KAZI-PÜS-H.ÇELİK",IF(AND(SUM(V3:W3)>0,SUM(AE3:AF3)=0),"SÜREN",IF(SUM(Y3:AC3)>0,"BULON",IF(SUM(AE3:AF3)>0,"ZEMİN ÇİVİSİ")))) -> KAZI-PÜS-H.ÇELİK | F3: S06-Barbaros İstasyonu | G3: Hat-2 HY | H3: P1 | I3: 4.Aşama | J3: Alt Yarı | K3: KDO-NATM-S06-1226 | L3: 46136 | M3: =1357.04-0.38 -> 1356.66 | P3: Tamamlandı | Q3: Q589/589-Çift Kat | R3: 30 cm atıldı
A4: 2026.04-006 | B4: S06.H2.HY.P1.A4.002 | C4: =AND(A4=[1]TUTANAK!$D$6,P4="Tamamlandı") -> FALSE | E4: =+IF(OR(P4<>""),"KAZI-PÜS-H.ÇELİK",IF(AND(SUM(V4:W4)>0,SUM(AE4:AF4)=0),"SÜREN",IF(SUM(Y4:AC4)>0,"BULON",IF(SUM(AE4:AF4)>0,"ZEMİN ÇİVİSİ")))) -> KAZI-PÜS-H.ÇELİK | F4: S06-Barbaros İstasyonu | G4: Hat-2 HY | H4: P1 | I4: 4.Aşama | J4: Alt Yarı | K4: KDO-NATM-S06-1226 | L4: 46136 | M4: 1357.04 | N4: KALICI | O4: Umbrella-1 | P4: Tamamlandı | Q4: Q589/589-Çift Kat | R4: 30 cm atıldı | T4: 1
A5: 2026.04-006 | B5: S06.H2.HY.P1.A4.002 | C5: =AND(A5=[1]TUTANAK!$D$6,P5="Tamamlandı") -> FALSE | E5: =+IF(OR(P5<>""),"KAZI-PÜS-H.ÇELİK",IF(AND(SUM(V5:W5)>0,SUM(AE5:AF5)=0),"SÜREN",IF(SUM(Y5:AC5)>0,"BULON",IF(SUM(AE5:AF5)>0,"ZEMİN ÇİVİSİ")))) -> KAZI-PÜS-H.ÇELİK | F5: S06-Barbaros İstasyonu | G5: Hat-2 HY | H5: P1 | I5: 4.Aşama | J5: Alt Yarı | K5: KDO-NATM-S06-1226 | L5: 46136 | M5: 1357.79 | N5: KALICI | O5: Umbrella-2 | P5: Tamamlandı | Q5: Q589/589-Çift Kat | R5: 30 cm atıldı | T5: 1
A6: 2026.04-006 | B6: S06.H2.HY.P1.A4.002 | C6: =AND(A6=[1]TUTANAK!$D$6,P6="Tamamlandı") -> FALSE | E6: =+IF(OR(P6<>""),"KAZI-PÜS-H.ÇELİK",IF(AND(SUM(V6:W6)>0,SUM(AE6:AF6)=0),"SÜREN",IF(SUM(Y6:AC6)>0,"BULON",IF(SUM(AE6:AF6)>0,"ZEMİN ÇİVİSİ")))) -> KAZI-PÜS-H.ÇELİK | F6: S06-Barbaros İstasyonu | G6: Hat-2 HY | H6: P1 | I6: 4.Aşama | J6: Alt Yarı | K6: KDO-NATM-S06-1226 | L6: 46136 | M6: 1358.54 | N6: KALICI | O6: Umbrella-3 | P6: Tamamlandı | Q6: Q589/589-Çift Kat | R6: 30 cm atıldı | T6: 1
A7: 2026.04-006 | B7: S06.H2.HY.P1.A4.002 | C7: =AND(A7=[1]TUTANAK!$D$6,P7="Tamamlandı") -> FALSE | E7: =+IF(OR(P7<>""),"KAZI-PÜS-H.ÇELİK",IF(AND(SUM(V7:W7)>0,SUM(AE7:AF7)=0),"SÜREN",IF(SUM(Y7:AC7)>0,"BULON",IF(SUM(AE7:AF7)>0,"ZEMİN ÇİVİSİ")))) -> KAZI-PÜS-H.ÇELİK | F7: S06-Barbaros İstasyonu | G7: Hat-2 HY | H7: P1 | I7: 4.Aşama | J7: Alt Yarı | K7: KDO-NATM-S06-1224 | L7: 46135 | M7: 1359.29 | N7: KALICI | O7: Umbrella-4 | P7: Tamamlandı | Q7: Q589/589-Çift Kat | R7: 30 cm atıldı | T7: 1
A8: 2026.04-006 | B8: S06.H2.HY.P1.A4.002 | C8: =AND(A8=[1]TUTANAK!$D$6,P8="Tamamlandı") -> FALSE | E8: =+IF(OR(P8<>""),"KAZI-PÜS-H.ÇELİK",IF(AND(SUM(V8:W8)>0,SUM(AE8:AF8)=0),"SÜREN",IF(SUM(Y8:AC8)>0,"BULON",IF(SUM(AE8:AF8)>0,"ZEMİN ÇİVİSİ")))) -> KAZI-PÜS-H.ÇELİK | F8: S06-Barbaros İstasyonu | G8: Hat-2 HY | H8: P1 | I8: 4.Aşama | J8: Alt Yarı | K8: KDO-NATM-S06-1224 | L8: 46135 | M8: 1360.04 | N8: KALICI | O8: Umbrella-5 | P8: Tamamlandı | Q8: Q589/589-Çift Kat | R8: 30 cm atıldı | T8: 1
A9: 2026.04-006 | B9: S06.H2.HY.P1.A4.002 | C9: =AND(A9=[1]TUTANAK!$D$6,P9="Tamamlandı") -> FALSE | E9: =+IF(OR(P9<>""),"KAZI-PÜS-H.ÇELİK",IF(AND(SUM(V9:W9)>0,SUM(AE9:AF9)=0),"SÜREN",IF(SUM(Y9:AC9)>0,"BULON",IF(SUM(AE9:AF9)>0,"ZEMİN ÇİVİSİ")))) -> KAZI-PÜS-H.ÇELİK | F9: S06-Barbaros İstasyonu | G9: Hat-2 HY | H9: P1 | I9: 4.Aşama | J9: Alt Yarı | K9: KDO-NATM-S06-1224 | L9: 46135 | M9: 1360.79 | N9: KALICI | O9: Umbrella-6 | P9: Tamamlandı | Q9: Q589/589-Çift Kat | R9: 30 cm atıldı | T9: 1
A10: 2026.04-006 | B10: S06.H2.HY.P1.A4.002 | C10: =AND(A10=[1]TUTANAK!$D$6,P10="Tamamlandı") -> FALSE | E10: =+IF(OR(P10<>""),"KAZI-PÜS-H.ÇELİK",IF(AND(SUM(V10:W10)>0,SUM(AE10:AF10)=0),"SÜREN",IF(SUM(Y10:AC10)>0,"BULON",IF(SUM(AE10:AF10)>0,"ZEMİN ÇİVİSİ")))) -> KAZI-PÜS-H.ÇELİK | F10: S06-Barbaros İstasyonu | G10: Hat-2 HY | H10: P1 | I10: 4.Aşama | J10: Alt Yarı | K10: KDO-NATM-S06-1223 | L10: 46134 | M10: 1361.54 | N10: KALICI | O10: Umbrella-1 | P10: Tamamlandı | Q10: Q589/589-Çift Kat | R10: 30 cm atıldı | T10: 1
A11: 2026.04-006 | B11: S06.H2.HY.P1.A4.002 | C11: =AND(A11=[1]TUTANAK!$D$6,P11="Tamamlandı") -> FALSE | E11: =+IF(OR(P11<>""),"KAZI-PÜS-H.ÇELİK",IF(AND(SUM(V11:W11)>0,SUM(AE11:AF11)=0),"SÜREN",IF(SUM(Y11:AC11)>0,"BULON",IF(SUM(AE11:AF11)>0,"ZEMİN ÇİVİSİ")))) -> KAZI-PÜS-H.ÇELİK | F11: S06-Barbaros İstasyonu | G11: Hat-2 HY | H11: P1 | I11: 4.Aşama | J11: Alt Yarı | K11: KDO-NATM-S06-1223 | L11: 46134 | M11: 1362.29 | N11: KALICI | O11: Umbrella-2 | P11: Tamamlandı | Q11: Q589/589-Çift Kat | R11: 30 cm atıldı | T11: 1
A12: 2026.04-006 | B12: S06.H2.HY.P1.A4.002 | C12: =AND(A12=[1]TUTANAK!$D$6,P12="Tamamlandı") -> FALSE | E12: =+IF(OR(P12<>""),"KAZI-PÜS-H.ÇELİK",IF(AND(SUM(V12:W12)>0,SUM(AE12:AF12)=0),"SÜREN",IF(SUM(Y12:AC12)>0,"BULON",IF(SUM(AE12:AF12)>0,"ZEMİN ÇİVİSİ")))) -> KAZI-PÜS-H.ÇELİK | F12: S06-Barbaros İstasyonu | G12: Hat-2 HY | H12: P1 | I12: 4.Aşama | J12: Alt Yarı | K12: KDO-NATM-S06-1223 | L12: 46134 | M12: 1363.04 | N12: KALICI | O12: Umbrella-3 | P12: Tamamlandı | Q12: Q589/589-Çift Kat | R12: 30 cm atıldı | T12: 1
A13: 2026.04-006 | B13: S06.H2.HY.P1.A4.002 | C13: =AND(A13=[1]TUTANAK!$D$6,P13="Tamamlandı") -> FALSE | E13: =+IF(OR(P13<>""),"KAZI-PÜS-H.ÇELİK",IF(AND(SUM(V13:W13)>0,SUM(AE13:AF13)=0),"SÜREN",IF(SUM(Y13:AC13)>0,"BULON",IF(SUM(AE13:AF13)>0,"ZEMİN ÇİVİSİ")))) -> KAZI-PÜS-H.ÇELİK | F13: S06-Barbaros İstasyonu | G13: Hat-2 HY | H13: P1 | I13: 4.Aşama | J13: Alt Yarı | K13: KDO-NATM-S06-1221 | L13: 46133 | M13: 1363.79 | N13: KALICI | O13: Umbrella-4 | P13: Tamamlandı | Q13: Q589/589-Çift Kat | R13: 30 cm atıldı | T13: 1
A14: 2026.04-006 | B14: S06.H2.HY.P1.A4.002 | C14: =AND(A14=[1]TUTANAK!$D$6,P14="Tamamlandı") -> FALSE | E14: =+IF(OR(P14<>""),"KAZI-PÜS-H.ÇELİK",IF(AND(SUM(V14:W14)>0,SUM(AE14:AF14)=0),"SÜREN",IF(SUM(Y14:AC14)>0,"BULON",IF(SUM(AE14:AF14)>0,"ZEMİN ÇİVİSİ")))) -> KAZI-PÜS-H.ÇELİK | F14: S06-Barbaros İstasyonu | G14: Hat-2 HY | H14: P1 | I14: 4.Aşama | J14: Alt Yarı | K14: KDO-NATM-S06-1221 | L14: 46133 | M14: 1364.54 | N14: KALICI | O14: Umbrella-5 | P14: Tamamlandı | Q14: Q589/589-Çift Kat | R14: 30 cm atıldı | T14: 1
A15: 2026.04-006 | B15: S06.H2.HY.P1.A4.002 | C15: =AND(A15=[1]TUTANAK!$D$6,P15="Tamamlandı") -> FALSE | E15: =+IF(OR(P15<>""),"KAZI-PÜS-H.ÇELİK",IF(AND(SUM(V15:W15)>0,SUM(AE15:AF15)=0),"SÜREN",IF(SUM(Y15:AC15)>0,"BULON",IF(SUM(AE15:AF15)>0,"ZEMİN ÇİVİSİ")))) -> KAZI-PÜS-H.ÇELİK | F15: S06-Barbaros İstasyonu | G15: Hat-2 HY | H15: P1 | I15: 4.Aşama | J15: Alt Yarı | K15: KDO-NATM-S06-1221 | L15: 46133 | M15: 1365.29 | N15: KALICI | O15: Umbrella-6 | P15: Tamamlandı | Q15: Q589/589-Çift Kat | R15: 30 cm atıldı | T15: 1
... A57: 2026.04-006 | B57: S06.H2.HY.P1.A4.002 | C57: =AND(A57=[1]TUTANAK!$D$6,P57="Tamamlandı") -> FALSE | E57: =+IF(OR(P57<>""),"KAZI-PÜS-H.ÇELİK",IF(AND(SUM(V57:W57)>0,SUM(AE57:AF57)=0),"SÜREN",IF(SUM(Y57:AC57)>0,"BULON",IF(SUM(AE57:AF57)>0,"ZEMİN ÇİVİSİ")))) -> KAZI-PÜS-H.ÇELİK | F57: S06-Barbaros İstasyonu | G57: Hat-2 HY | H57: P1 | I57: 4.Aşama | J57: Alt Yarı | K57: KDO-NATM-S06-1174 | L57: 46113 | M57: 1396.79 | N57: KALICI | O57: Umbrella-6 | P57: Tamamlandı | Q57: Q589/589-Çift Kat | R57: 30 cm atıldı | T57: 1
A60: 2026.04-006 | B60: S06.H2.HY.P1.A4.002 | C60: =AND(A60=[1]TUTANAK!$D$6,P60="Tamamlandı") -> FALSE | E60: =+IF(OR(P60<>""),"KAZI-PÜS-H.ÇELİK",IF(AND(SUM(V60:W60)>0,SUM(AE60:AF60)=0),"SÜREN",IF(SUM(Y60:AC60)>0,"BULON",IF(SUM(AE60:AF60)>0,"ZEMİN ÇİVİSİ")))) -> BULON | F60: S06-Barbaros İstasyonu | G60: Hat-2 HY | H60: P1 | I60: 4.Aşama | J60: Alt Yarı | K60: TBT-NATM-S06-249 | L60: 46120 | M60: 1385.17 | N60: 0.75 | AC60: 3
A61: 2026.04-006 | B61: S06.H2.HY.P1.A4.002 | C61: =AND(A61=[1]TUTANAK!$D$6,P61="Tamamlandı") -> FALSE | E61: =+IF(OR(P61<>""),"KAZI-PÜS-H.ÇELİK",IF(AND(SUM(V61:W61)>0,SUM(AE61:AF61)=0),"SÜREN",IF(SUM(Y61:AC61)>0,"BULON",IF(SUM(AE61:AF61)>0,"ZEMİN ÇİVİSİ")))) -> BULON | F61: S06-Barbaros İstasyonu | G61: Hat-2 HY | H61: P1 | I61: 4.Aşama | J61: Alt Yarı | K61: TBT-NATM-S06-249 | L61: 46120 | M61: =+M60+N60 -> 1385.92 | N61: 0.75 | AC61: 3
A62: 2026.04-006 | B62: S06.H2.HY.P1.A4.002 | C62: =AND(A62=[1]TUTANAK!$D$6,P62="Tamamlandı") -> FALSE | E62: =+IF(OR(P62<>""),"KAZI-PÜS-H.ÇELİK",IF(AND(SUM(V62:W62)>0,SUM(AE62:AF62)=0),"SÜREN",IF(SUM(Y62:AC62)>0,"BULON",IF(SUM(AE62:AF62)>0,"ZEMİN ÇİVİSİ")))) -> BULON | F62: S06-Barbaros İstasyonu | G62: Hat-2 HY | H62: P1 | I62: 4.Aşama | J62: Alt Yarı | K62: TBT-NATM-S06-249 | L62: 46120 | M62: 1394.92 | N62: 0.75 | AC62: 3
A63: 2026.04-006 | B63: S06.H2.HY.P1.A4.002 | C63: =AND(A63=[1]TUTANAK!$D$6,P63="Tamamlandı") -> FALSE | E63: =+IF(OR(P63<>""),"KAZI-PÜS-H.ÇELİK",IF(AND(SUM(V63:W63)>0,SUM(AE63:AF63)=0),"SÜREN",IF(SUM(Y63:AC63)>0,"BULON",IF(SUM(AE63:AF63)>0,"ZEMİN ÇİVİSİ")))) -> BULON | F63: S06-Barbaros İstasyonu | G63: Hat-2 HY | H63: P1 | I63: 4.Aşama | J63: Alt Yarı | K63: TBT-NATM-S06-249 | L63: 46120 | M63: =+M62+N62 -> 1395.67 | N63: 0.75 | AC63: 3
A64: 2026.04-006 | B64: S06.H2.HY.P1.A4.002 | C64: =AND(A64=[1]TUTANAK!$D$6,P64="Tamamlandı") -> FALSE | E64: =+IF(OR(P64<>""),"KAZI-PÜS-H.ÇELİK",IF(AND(SUM(V64:W64)>0,SUM(AE64:AF64)=0),"SÜREN",IF(SUM(Y64:AC64)>0,"BULON",IF(SUM(AE64:AF64)>0,"ZEMİN ÇİVİSİ")))) -> BULON | F64: S06-Barbaros İstasyonu | G64: Hat-2 HY | H64: P1 | I64: 4.Aşama | J64: Alt Yarı | K64: TBT-NATM-S06-249 | L64: 46120 | M64: =+M63+N63 -> 1396.42 | N64: 0.75 | AC64: 3
A65: 2026.04-006 | B65: S06.H2.HY.P1.A4.002 | C65: =AND(A65=[1]TUTANAK!$D$6,P65="Tamamlandı") -> FALSE | E65: =+IF(OR(P65<>""),"KAZI-PÜS-H.ÇELİK",IF(AND(SUM(V65:W65)>0,SUM(AE65:AF65)=0),"SÜREN",IF(SUM(Y65:AC65)>0,"BULON",IF(SUM(AE65:AF65)>0,"ZEMİN ÇİVİSİ")))) -> BULON | F65: S06-Barbaros İstasyonu | G65: Hat-2 HY | H65: P1 | I65: 4.Aşama | J65: Alt Yarı | K65: TBT-NATM-S06-249 | L65: 46120 | M65: =+M64+N64 -> 1397.17 | N65: 0.75 | AC65: 3
A66: 2026.04-006 | B66: S06.H2.HY.P1.A4.002 | C66: =AND(A66=[1]TUTANAK!$D$6,P66="Tamamlandı") -> FALSE | E66: =+IF(OR(P66<>""),"KAZI-PÜS-H.ÇELİK",IF(AND(SUM(V66:W66)>0,SUM(AE66:AF66)=0),"SÜREN",IF(SUM(Y66:AC66)>0,"BULON",IF(SUM(AE66:AF66)>0,"ZEMİN ÇİVİSİ")))) -> BULON | F66: S06-Barbaros İstasyonu | G66: Hat-2 HY | H66: P1 | I66: 4.Aşama | J66: Alt Yarı | K66: TBT-NATM-S06-249 | L66: 46120 | M66: =+M65+N65 -> 1397.92 | N66: 0.75 | AC66: 3
A67: 2026.04-006 | B67: S06.H2.HY.P1.A4.002 | C67: =AND(A67=[1]TUTANAK!$D$6,P67="Tamamlandı") -> FALSE | E67: =+IF(OR(P67<>""),"KAZI-PÜS-H.ÇELİK",IF(AND(SUM(V67:W67)>0,SUM(AE67:AF67)=0),"SÜREN",IF(SUM(Y67:AC67)>0,"BULON",IF(SUM(AE67:AF67)>0,"ZEMİN ÇİVİSİ")))) -> BULON | F67: S06-Barbaros İstasyonu | G67: Hat-2 HY | H67: P1 | I67: 4.Aşama | J67: Alt Yarı | K67: TBT-NATM-S06-249 | L67: 46120 | M67: =+M66+N66 -> 1398.67 | N67: 0.75 | AC67: 3
A68: 2026.04-006 | B68: S06.H2.HY.P1.A4.002 | C68: =AND(A68=[1]TUTANAK!$D$6,P68="Tamamlandı") -> FALSE | E68: =+IF(OR(P68<>""),"KAZI-PÜS-H.ÇELİK",IF(AND(SUM(V68:W68)>0,SUM(AE68:AF68)=0),"SÜREN",IF(SUM(Y68:AC68)>0,"BULON",IF(SUM(AE68:AF68)>0,"ZEMİN ÇİVİSİ")))) -> BULON | F68: S06-Barbaros İstasyonu | G68: Hat-2 HY | H68: P1 | I68: 4.Aşama | J68: Alt Yarı | K68: TBT-NATM-S06-249 | L68: 46120 | M68: =+M67+N67 -> 1399.42 | N68: 0.75 | AC68: 3
A69: 2026.04-006 | B69: S06.H2.HY.P1.A4.002 | C69: =AND(A69=[1]TUTANAK!$D$6,P69="Tamamlandı") -> FALSE | E69: =+IF(OR(P69<>""),"KAZI-PÜS-H.ÇELİK",IF(AND(SUM(V69:W69)>0,SUM(AE69:AF69)=0),"SÜREN",IF(SUM(Y69:AC69)>0,"BULON",IF(SUM(AE69:AF69)>0,"ZEMİN ÇİVİSİ")))) -> BULON | F69: S06-Barbaros İstasyonu | G69: Hat-2 HY | H69: P1 | I69: 4.Aşama | J69: Alt Yarı | K69: TBT-NATM-S06-249 | L69: 46120 | M69: =+M68+N68 -> 1400.17 | N69: 0.75 | AC69: 3
A70: 2026.04-006 | B70: S06.H2.HY.P1.A4.002 | C70: =AND(A70=[1]TUTANAK!$D$6,P70="Tamamlandı") -> FALSE | E70: =+IF(OR(P70<>""),"KAZI-PÜS-H.ÇELİK",IF(AND(SUM(V70:W70)>0,SUM(AE70:AF70)=0),"SÜREN",IF(SUM(Y70:AC70)>0,"BULON",IF(SUM(AE70:AF70)>0,"ZEMİN ÇİVİSİ")))) -> BULON | F70: S06-Barbaros İstasyonu | G70: Hat-2 HY | H70: P1 | I70: 4.Aşama | J70: Alt Yarı | K70: TBT-NATM-S06-249 | L70: 46120 | M70: =+M69+N69 -> 1400.92 | N70: 0.75 | AC70: 3
A71: 2026.04-006 | B71: S06.H2.HY.P1.A4.002 | C71: =AND(A71=[1]TUTANAK!$D$6,P71="Tamamlandı") -> FALSE | E71: =+IF(OR(P71<>""),"KAZI-PÜS-H.ÇELİK",IF(AND(SUM(V71:W71)>0,SUM(AE71:AF71)=0),"SÜREN",IF(SUM(Y71:AC71)>0,"BULON",IF(SUM(AE71:AF71)>0,"ZEMİN ÇİVİSİ")))) -> BULON | F71: S06-Barbaros İstasyonu | G71: Hat-2 HY | H71: P1 | I71: 4.Aşama | J71: Alt Yarı | K71: TBT-NATM-S06-249 | L71: 46120 | M71: =+M70+N70 -> 1401.67 | N71: 0.75 | AC71: 3
A72: 2026.04-006 | B72: S06.H2.HY.P1.A4.002 | C72: =AND(A72=[1]TUTANAK!$D$6,P72="Tamamlandı") -> FALSE | E72: =+IF(OR(P72<>""),"KAZI-PÜS-H.ÇELİK",IF(AND(SUM(V72:W72)>0,SUM(AE72:AF72)=0),"SÜREN",IF(SUM(Y72:AC72)>0,"BULON",IF(SUM(AE72:AF72)>0,"ZEMİN ÇİVİSİ")))) -> BULON | F72: S06-Barbaros İstasyonu | G72: Hat-2 HY | H72: P1 | I72: 4.Aşama | J72: Alt Yarı | K72: TBT-NATM-S06-249 | L72: 46120 | M72: =+M71+N71 -> 1402.42 | N72: 0.75 | AC72: 3
A73: 2026.04-006 | B73: S06.H2.HY.P1.A4.002 | C73: =AND(A73=[1]TUTANAK!$D$6,P73="Tamamlandı") -> FALSE | E73: =+IF(OR(P73<>""),"KAZI-PÜS-H.ÇELİK",IF(AND(SUM(V73:W73)>0,SUM(AE73:AF73)=0),"SÜREN",IF(SUM(Y73:AC73)>0,"BULON",IF(SUM(AE73:AF73)>0,"ZEMİN ÇİVİSİ")))) -> BULON | F73: S06-Barbaros İstasyonu | G73: Hat-2 HY | H73: P1 | I73: 4.Aşama | J73: Alt Yarı | K73: TBT-NATM-S06-249 | L73: 46120 | M73: =+M72+N72 -> 1403.17 | N73: 0.75 | AC73: 3
A74: 2026.04-006 | B74: S06.H2.HY.P1.A4.002 | C74: =AND(A74=[1]TUTANAK!$D$6,P74="Tamamlandı") -> FALSE | E74: =+IF(OR(P74<>""),"KAZI-PÜS-H.ÇELİK",IF(AND(SUM(V74:W74)>0,SUM(AE74:AF74)=0),"SÜREN",IF(SUM(Y74:AC74)>0,"BULON",IF(SUM(AE74:AF74)>0,"ZEMİN ÇİVİSİ")))) -> BULON | F74: S06-Barbaros İstasyonu | G74: Hat-2 HY | H74: P1 | I74: 4.Aşama | J74: Alt Yarı | K74: TBT-NATM-S06-249 | L74: 46120 | M74: =+M73+N73 -> 1403.92 | N74: 0.75 | AC74: 3
... A78: 2026.04-006 | B78: S06.H2.HY.P1.A4.002 | C78: =AND(A78=[1]TUTANAK!$D$6,P78="Tamamlandı") -> FALSE | E78: =+IF(OR(P78<>""),"KAZI-PÜS-H.ÇELİK",IF(AND(SUM(V78:W78)>0,SUM(AE78:AF78)=0),"SÜREN",IF(SUM(Y78:AC78)>0,"BULON",IF(SUM(AE78:AF78)>0,"ZEMİN ÇİVİSİ")))) -> BULON | F78: S06-Barbaros İstasyonu | G78: Hat-2 HY | H78: P1 | I78: 4.Aşama | J78: Alt Yarı | K78: TBT-NATM-S06-249 | L78: 46120 | M78: =+M77+N77 -> 1406.92 | N78: 0.75 | AC78: 3
A79: 2026.04-006 | B79: S06.H2.HY.P1.A4.002 | C79: =AND(A79=[1]TUTANAK!$D$6,P79="Tamamlandı") -> FALSE | E79: =+IF(OR(P79<>""),"KAZI-PÜS-H.ÇELİK",IF(AND(SUM(V79:W79)>0,SUM(AE79:AF79)=0),"SÜREN",IF(SUM(Y79:AC79)>0,"BULON",IF(SUM(AE79:AF79)>0,"ZEMİN ÇİVİSİ")))) -> BULON | F79: S06-Barbaros İstasyonu | G79: Hat-2 HY | H79: P1 | I79: 4.Aşama | J79: Alt Yarı | K79: TBT-NATM-S06-250 | L79: 46120 | M79: 1407.67 | N79: 0.75 | AC79: 3
A80: 2026.04-006 | B80: S06.H2.HY.P1.A4.002 | C80: =AND(A80=[1]TUTANAK!$D$6,P80="Tamamlandı") -> FALSE | E80: =+IF(OR(P80<>""),"KAZI-PÜS-H.ÇELİK",IF(AND(SUM(V80:W80)>0,SUM(AE80:AF80)=0),"SÜREN",IF(SUM(Y80:AC80)>0,"BULON",IF(SUM(AE80:AF80)>0,"ZEMİN ÇİVİSİ")))) -> BULON | F80: S06-Barbaros İstasyonu | G80: Hat-2 HY | H80: P1 | I80: 4.Aşama | J80: Alt Yarı | K80: TBT-NATM-S06-250 | L80: 46120 | M80: =+M79+N79 -> 1408.42 | N80: 0.75 | AC80: 3
A81: 2026.04-006 | B81: S06.H2.HY.P1.A4.002 | C81: =AND(A81=[1]TUTANAK!$D$6,P81="Tamamlandı") -> FALSE | E81: =+IF(OR(P81<>""),"KAZI-PÜS-H.ÇELİK",IF(AND(SUM(V81:W81)>0,SUM(AE81:AF81)=0),"SÜREN",IF(SUM(Y81:AC81)>0,"BULON",IF(SUM(AE81:AF81)>0,"ZEMİN ÇİVİSİ")))) -> BULON | F81: S06-Barbaros İstasyonu | G81: Hat-2 HY | H81: P1 | I81: 4.Aşama | J81: Alt Yarı | K81: TBT-NATM-S06-250 | L81: 46120 | M81: 1409.17 | N81: 0.75 | AC81: 3
A82: 2026.04-006 | B82: S06.H2.HY.P1.A4.002 | C82: =AND(A82=[1]TUTANAK!$D$6,P82="Tamamlandı") -> FALSE | E82: =+IF(OR(P82<>""),"KAZI-PÜS-H.ÇELİK",IF(AND(SUM(V82:W82)>0,SUM(AE82:AF82)=0),"SÜREN",IF(SUM(Y82:AC82)>0,"BULON",IF(SUM(AE82:AF82)>0,"ZEMİN ÇİVİSİ")))) -> BULON | F82: S06-Barbaros İstasyonu | G82: Hat-2 HY | H82: P1 | I82: 4.Aşama | J82: Alt Yarı | K82: TBT-NATM-S06-250 | L82: 46120 | M82: =+M81+N81 -> 1409.92 | N82: 0.75 | AC82: 3
A83: 2026.04-006 | B83: S06.H2.HY.P1.A4.002 | C83: =AND(A83=[1]TUTANAK!$D$6,P83="Tamamlandı") -> FALSE | E83: =+IF(OR(P83<>""),"KAZI-PÜS-H.ÇELİK",IF(AND(SUM(V83:W83)>0,SUM(AE83:AF83)=0),"SÜREN",IF(SUM(Y83:AC83)>0,"BULON",IF(SUM(AE83:AF83)>0,"ZEMİN ÇİVİSİ")))) -> BULON | F83: S06-Barbaros İstasyonu | G83: Hat-2 HY | H83: P1 | I83: 4.Aşama | J83: Alt Yarı | K83: TBT-NATM-S06-250 | L83: 46120 | M83: 1410.67 | N83: 0.75 | AC83: 3
A84: 2026.04-006 | B84: S06.H2.HY.P1.A4.002 | C84: =AND(A84=[1]TUTANAK!$D$6,P84="Tamamlandı") -> FALSE | E84: =+IF(OR(P84<>""),"KAZI-PÜS-H.ÇELİK",IF(AND(SUM(V84:W84)>0,SUM(AE84:AF84)=0),"SÜREN",IF(SUM(Y84:AC84)>0,"BULON",IF(SUM(AE84:AF84)>0,"ZEMİN ÇİVİSİ")))) -> BULON | F84: S06-Barbaros İstasyonu | G84: Hat-2 HY | H84: P1 | I84: 4.Aşama | J84: Alt Yarı | K84: TBT-NATM-S06-250 | L84: 46120 | M84: =+M83+N83 -> 1411.42 | N84: 0.75 | AC84: 3
A85: 2026.04-006 | B85: S06.H2.HY.P1.A4.002 | C85: =AND(A85=[1]TUTANAK!$D$6,P85="Tamamlandı") -> FALSE | E85: =+IF(OR(P85<>""),"KAZI-PÜS-H.ÇELİK",IF(AND(SUM(V85:W85)>0,SUM(AE85:AF85)=0),"SÜREN",IF(SUM(Y85:AC85)>0,"BULON",IF(SUM(AE85:AF85)>0,"ZEMİN ÇİVİSİ")))) -> BULON | F85: S06-Barbaros İstasyonu | G85: Hat-2 HY | H85: P1 | I85: 4.Aşama | J85: Alt Yarı | K85: TBT-NATM-S06-250 | L85: 46120 | M85: 1412.17 | N85: 0.75 | AC85: 3
A86: 2026.04-006 | B86: S06.H2.HY.P1.A4.002 | C86: =AND(A86=[1]TUTANAK!$D$6,P86="Tamamlandı") -> FALSE | E86: =+IF(OR(P86<>""),"KAZI-PÜS-H.ÇELİK",IF(AND(SUM(V86:W86)>0,SUM(AE86:AF86)=0),"SÜREN",IF(SUM(Y86:AC86)>0,"BULON",IF(SUM(AE86:AF86)>0,"ZEMİN ÇİVİSİ")))) -> BULON | F86: S06-Barbaros İstasyonu | G86: Hat-2 HY | H86: P1 | I86: 4.Aşama | J86: Alt Yarı | K86: TBT-NATM-S06-250 | L86: 46120 | M86: =+M85+N85 -> 1412.92 | N86: 0.75 | AC86: 3
...

Sheet AYNA TAKİP
A1: Dönemi | B1: Hk No | C1: Sıra No | D1: Km | E1: Yeri | G1: Çelik Hasır | H1: Püskürtme Betonu | J1: Kalınlık | K1: Alan | L1: Hasır
A2: 45839 | B2: 3 | C2: 1 | D2: 2101.61 | E2: Üst Yarı | F2: 1 | H2: 5 cm atıldı | J2: 0.05 | K2: 27.35
A3: 45839 | B3: 3 | C3: =+C2+1 -> 2 | D3: 2102.36 | E3: Üst Yarı | F3: 2 | H3: 5 cm atıldı | J3: 0.05 | K3: 28.106
A4: 45839 | B4: 3 | C4: =+C3+1 -> 3 | D4: 2103.11 | E4: Üst Yarı | F4: 3 | H4: 5 cm atıldı | J4: 0.05 | K4: 28.879
A5: 45839 | B5: 3 | C5: =+C4+1 -> 4 | D5: 2103.11 | E5: Üst Yarı | F5: 3 | G5: Q221/221 Tek Kat | H5: 15 cm atıldı 8 m² | J5: 0.15 | K5: 8 | L5: =+K5*3.47/1000 -> 0.02776
A6: 45839 | B6: 3 | C6: =+C5+1 -> 5 | D6: 2103.86 | E6: Üst Yarı | F6: 4 | H6: 5 cm atıldı | J6: 0.05 | K6: 29.536
A7: 45839 | B7: 3 | C7: =+C6+1 -> 6 | D7: 2104.61 | E7: Üst Yarı | F7: 5 | H7: 5 cm atıldı | J7: 0.05 | K7: 30.158
A8: 45839 | B8: 3 | C8: =+C7+1 -> 7 | D8: 2105.36 | E8: Üst Yarı | F8: 6 | G8: Q221/221 Tek Kat | H8: 15 cm atıldı | J8: 0.15 | K8: 30.868 | L8: =0.3*416.54/1000 -> 0.124962
A9: 45839 | B9: 3 | C9: =+C8+1 -> 8 | D9: 2106.11 | E9: Üst Yarı | F9: 1 | H9: 5 cm atıldı | J9: 0.05 | K9: 27.35
A10: 45839 | B10: 3 | C10: =+C9+1 -> 9 | D10: 2106.86 | E10: Üst Yarı | F10: 2 | H10: 5 cm atıldı | J10: 0.05 | K10: 28.106
A11: 45839 | B11: 3 | C11: =+C10+1 -> 10 | D11: 2107.61 | E11: Üst Yarı | F11: 3 | H11: 5 cm atıldı | J11: 0.05 | K11: 28.879
A12: 45839 | B12: 3 | C12: =+C11+1 -> 11 | D12: 2107.61 | E12: Üst Yarı | F12: 3 | G12: Q221/221 Tek Kat | H12: 15 cm atıldı 8 m² | J12: 0.15 | K12: 8 | L12: =+K12*3.47/1000 -> 0.02776
A13: 45839 | B13: 3 | C13: =+C12+1 -> 12 | D13: 2108.36 | E13: Üst Yarı | F13: 4 | H13: 5 cm atıldı | J13: 0.05 | K13: 29.536
A14: 45839 | B14: 3 | C14: =+C13+1 -> 13 | D14: 2109.11 | E14: Üst Yarı | F14: 5 | H14: 5 cm atıldı | J14: 0.05 | K14: 30.158
A15: 45839 | B15: 3 | C15: =+C14+1 -> 14 | D15: 2109.86 | E15: Üst Yarı | F15: 6 | G15: Q221/221 Tek Kat | H15: 15 cm atıldı | J15: 0.15 | K15: 30.868 | L15: =0.3*416.54/1000 -> 0.124962
A16: 45839 | B16: 3 | C16: =+C15+1 -> 15 | D16: 2110.61 | E16: Üst Yarı | F16: 1 | H16: 5 cm atıldı | J16: 0.05 | K16: 27.35
A17: 45839 | B17: 3 | C17: =+C16+1 -> 16 | D17: 2111.36 | E17: Üst Yarı | F17: 2 | H17: 5 cm atıldı | J17: 0.05 | K17: 28.106
A18: 45839 | B18: 3 | C18: =+C17+1 -> 17 | D18: 2112.11 | E18: Üst Yarı | F18: 3 | H18: 5 cm atıldı | J18: 0.05 | K18: 28.879
A19: 45839 | B19: 3 | C19: =+C18+1 -> 18 | D19: 2112.11 | E19: Üst Yarı | F19: 3 | G19: Q221/221 Tek Kat | H19: 15 cm atıldı 8 m² | J19: 0.15 | K19: 8 | L19: =+K19*3.47/1000 -> 0.02776
A20: 45839 | B20: 3 | C20: =+C19+1 -> 19 | D20: 2112.86 | E20: Üst Yarı | F20: 4 | H20: 5 cm atıldı | J20: 0.05 | K20: 29.536
A21: 45839 | B21: 3 | C21: =+C20+1 -> 20 | D21: 2113.61 | E21: Üst Yarı | F21: 5 | H21: 5 cm atıldı | J21: 0.05 | K21: 30.158
A22: 45839 | B22: 3 | C22: =+C21+1 -> 21 | D22: 2114.36 | E22: Üst Yarı | F22: 6 | G22: Q221/221 Tek Kat | H22: 15 cm atıldı | J22: 0.15 | K22: 30.868 | L22: =0.3*416.54/1000 -> 0.124962
A23: 45839 | B23: 3 | C23: =+C22+1 -> 22 | D23: 2115.18 | E23: Üst Yarı | F23: 6 | H23: 5 cm atıldı | J23: 0.05 | K23: 30.868
A24: 45839 | B24: 3 | C24: =+C23+1 -> 23 | D24: 2115.85 | E24: Üst Yarı | F24: 1 | H24: 5 cm atıldı | J24: 0.05 | K24: 27.35
A25: 45839 | B25: 3 | C25: =+C24+1 -> 24 | D25: 2116.6 | E25: Üst Yarı | F25: 2 | H25: 5 cm atıldı | J25: 0.05 | K25: 28.106
A26: 45839 | B26: 3 | C26: =+C25+1 -> 25 | D26: 2117.35 | E26: Üst Yarı | F26: 3 | H26: 5 cm atıldı | J26: 0.05 | K26: 28.879
A27: 45839 | B27: 3 | C27: =+C26+1 -> 26 | D27: 2117.35 | E27: Üst Yarı | F27: 3 | G27: Q221/221 Tek Kat | H27: 15 cm atıldı 8 m² | J27: 0.15 | K27: 8 | L27: =+K27*3.47/1000 -> 0.02776
A28: 45870 | B28: 3 | C28: =+C27+1 -> 27 | D28: 2118.1 | E28: Üst Yarı | F28: 4 | H28: 5 cm atıldı | J28: 0.05 | K28: 29.536
A29: 45870 | B29: 3 | C29: =+C28+1 -> 28 | D29: 2118.1 | E29: Üst Yarı | F29: 4 | G29: Q221/221 Tek Kat | H29: 15 cm atıldı 8 m² | J29: 0.15 | K29: 8 | L29: =+K29*3.47/1000 -> 0.02776
A30: 45870 | B30: 3 | C30: =+C29+1 -> 29 | D30: 2118.85 | E30: Üst Yarı | F30: 5 | H30: 5 cm atıldı | J30: 0.05 | K30: 30.158
A31: 45870 | B31: 3 | C31: =+C30+1 -> 30 | D31: 2119.6 | E31: Üst Yarı | F31: 6 | G31: Q221/221 Tek Kat | H31: 15 cm atıldı | J31: 0.15 | K31: 30.868 | L31: =0.3*416.54/1000 -> 0.124962
A32: 45870 | B32: 3 | C32: =+C31+1 -> 31 | D32: 2120.35 | E32: Üst Yarı | F32: 1 | H32: 5 cm atıldı | J32: 0.05 | K32: 27.35
A33: 45870 | B33: 3 | C33: =+C32+1 -> 32 | D33: 2121.1 | E33: Üst Yarı | F33: 2 | H33: 5 cm atıldı | J33: 0.05 | K33: 28.106
A34: 45870 | B34: 3 | C34: =+C33+1 -> 33 | D34: 2121.1 | E34: Üst Yarı | F34: 2 | G34: Q221/221 Tek Kat | H34: 15 cm atıldı 8 m² | J34: 0.15 | K34: 8 | L34: =+K34*3.47/1000 -> 0.02776
A35: 45870 | B35: 3 | C35: =+C34+1 -> 34 | D35: 2121.85 | E35: Üst Yarı | F35: 3 | H35: 5 cm atıldı | J35: 0.05 | K35: 28.879
A36: 45870 | B36: 3 | C36: =+C35+1 -> 35 | D36: 2122.6 | E36: Üst Yarı | F36: 4 | H36: 5 cm atıldı | J36: 0.05 | K36: 29.536
A37: 45870 | B37: 3 | C37: =+C36+1 -> 36 | D37: 2122.6 | E37: Üst Yarı | F37: 4 | G37: Q221/221 Tek Kat | H37: 15 cm atıldı 6 m² | J37: 0.15 | K37: 6 | L37: =+K37*3.47/1000 -> 0.02082
A38: 45870 | B38: 3 | C38: =+C37+1 -> 37 | D38: 2123.35 | E38: Üst Yarı | F38: 5 | H38: 5 cm atıldı | J38: 0.05 | K38: 30.158
A39: 45870 | B39: 3 | C39: =+C38+1 -> 38 | D39: 2124.48 | E39: Üst Yarı | F39: 6 | G39: Q589/589 Çift Kat | H39: 30 cm atıldı | J39: 0.3 | K39: 30.868 | L39: =0.3*1008.66/1000 -> 0.302598

Sheet Kontrol
E2: KM1 | F2: =+_xlfn.MINIFS(DATA!M:M,DATA!Q:Q,"Q589/589-Çift Kat") -> 1356.66 | G2: =+_xlfn.MINIFS(DATA!M:M,DATA!Q:Q,"3xQ221/221-Çift Kat") -> 0
E3: KM2 | F3: =+_xlfn.MAXIFS(DATA!M:M,DATA!Q:Q,"Q589/589-Çift Kat")+0.3 -> 1438.54 | G3: =+_xlfn.MAXIFS(DATA!M:M,DATA!Q:Q,"3xQ221/221-Çift Kat") -> 0 | I3: Aynadan dolayı ilave ilerleme var
A4: İş Kalemi No | B4: Açıklama | C4: Birimi | D4: Birim Fiyat | E4: Toplam | F4: Kalıcı | G4: Geçici | H4: Ayna
A5: 018 | B5: Geleneksel (NATM) Tünel Kazısı | C5: m³ | D5: 5075 | E5: =ROUND(SUM(F5:H5),3) -> 2450.973 | F5: =+ROUND(ABS(F2-F3)*29.15,3) -> 2386.802 | G5: =+ROUND(ABS(G2-G3)*1.149,3) -> 0 | H5: =+SUMPRODUCT('AYNA TAKİP'!J1:J38,'AYNA TAKİP'!K1:K38) -> 64.17145
A6: 019.A | B6: Kazıdan çıkan veya Ariyetten alınan malzeme ile geri dolgu yapılması | C6: m³ | D6: 600 | E6: =ROUND(SUM(F6:H6),3) -> 0
A7: 019.B | B7: Kum, Çakıl, Kırma Tas ve Benzeri Malzeme ile Dolgu Yapılması | C7: m³ | D7: 1500 | E7: =ROUND(SUM(F7:H7),3) -> 0
A8: 020 | B8: Püskürtme Beton (Tünel ve Şaftlarda) | C8: m³ | D8: 15334 | E8: =ROUND(SUM(F8:H8),3) -> 296.129 | F8: =+ROUND(ABS(F2-F3)*3.022,3)*0.9 -> 222.6969 | G8: =+ROUND(ABS(G2-G3)*1.149,3) -> 0 | H8: =+SUMPRODUCT('AYNA TAKİP'!J:J,'AYNA TAKİP'!K:K) -> 73.43185
A9: 021.A | B9: Delgi boyu =< 30m | C9: m | D9: 248
A10: 021.B | B10: Delgi boyu > 30m | C10: m | D10: 371
A11: 022.A | B11: L=3 m Kaya Bulonu | C11: adet | D11: 2250 | E11: =+SUM(DATA!Y:Y) -> 0
A12: 022.B | B12: L=4 m Kaya Bulonu | C12: adet | D12: 8000 | E12: =+SUM(DATA!Z:Z) -> 0
A13: 022.C | B13: L=5 m Kaya Bulonu | C13: adet | D13: 8288 | E13: =+SUM(DATA!AA:AA) -> 0
A14: 022.D | B14: L=6 m Kaya Bulonu | C14: adet | D14: 12000 | E14: =+SUM(DATA!AB:AB) -> 0
A15: 022.E | B15: L=8 m Kaya Bulonu | C15: adet | D15: 28000 | E15: =+SUM(DATA!AC:AC) -> 174
A16: 023.A | B16: 125 mm Delik İçine 14 mm Kalınlığında S420a ile Zemin Çivisi Teşkili | C16: m | D16: 375 | E16: =+SUM(DATA!AE:AE) -> 0
A17: 023.B | B17: 125 mm Delik İçine 26 mm Kalınlığında S420a ile Zemin Çivisi Teşkili | C17: m | D17: 388 | E17: =+SUM(DATA!AF:AF) -> 0
A18: 024 | B18: Çelik İksa (Tünel ve Şaftlarda) | C18: ton | D18: 102000 | E18: =ROUND(SUM(F18:G18),3) -> 80.62 | F18: =SUMIFS(DATA!T:T,DATA!N:N,"KALICI",DATA!O:O,"Umbrella-1")*0.713518+SUMIFS(DATA!T:T,DATA!N:N,"KALICI",DATA!O:O,"Umbrella-2")*0.71664+SUMIFS(DATA!T:T,DATA!N:N,"KALICI",DATA!O:O,"Umbrella-3")*0.729202+SUMIFS(DATA!T:T,DATA!N:N,"KALICI",DATA!O:O,"Umbrella-4")*0.74693+SUMIFS(DATA!T:T,DATA!N:N,"KALICI",DATA!O:O,"Umbrella-5")*0.75958+SUMIFS(DATA!T:T,DATA!N:N,"KALICI",DATA!O:O,"Umbrella-6")*0.770217 -> 80.619783 | G18: =SUMIFS(DATA!S:S,DATA!N:N,"GEÇİCİ",DATA!O:O,"Umbrella-1")*0.210818+SUMIFS(DATA!S:S,DATA!N:N,"GEÇİCİ",DATA!O:O,"Umbrella-2")*0.215206+SUMIFS(DATA!S:S,DATA!N:N,"GEÇİCİ",DATA!O:O,"Umbrella-3")*0.217336+SUMIFS(DATA!S:S,DATA!N:N,"GEÇİCİ",DATA!O:O,"Umbrella-4")*0.216782+SUMIFS(DATA!S:S,DATA!N:N,"GEÇİCİ",DATA!O:O,"Umbrella-5")*0.21691+SUMIFS(DATA!S:S,DATA!N:N,"GEÇİCİ",DATA!O:O,"Umbrella-6")*0.218869 -> 0
A19: 025 | B19: Umbrella Arch Yapılması | C19: m | D19: 3400 | E19: =+SUM(DATA!V:V) -> 0
A20: 026.A | B20: Tünel ve şaftlarda su yalıtımı, birim ağırlığı >=500 g/metrekare geotekstil keçe | C20: m² | D20: 510
A21: 026.B | B21: Tünel ve şaftlarda su yalıtımı, 2mm kalınlıklı PVC membran | C21: m² | D21: 1200
A22: 027 | B22: Su Tutucular (Tünel ve Şaftlarda) | C22: m | D22: 2160
A23: 028.A | B23: Kalıp (invert ve şaft için) | C23: m² | D23: 4150
A24: 028.B | B24: Kalıp (duvar ve kemer İçin) | C24: m² | D24: 1500
A25: 028.C | B25: Tip Kesit Dışı Konstrüksiyon Kalıbı, Tünel Alın Kalıbı | C25: m² | D25: 500
A26: 029.A | B26: C16 Beton İmali ve Dökülmesi (Tünel ve Şaftlarda) | C26: m³ | D26: 6030
A27: 029.B | B27: C30 Beton İmali ve Dökülmesi (Tünel ve Şaftlarda) Tünel kaplaması, invert ve şaftlardaki alt döşeme | C27: m³ | D27: 10355
A28: 029.C | B28: C30 Beton İmali ve Dökülmesi (Tünel ve Şaftlarda) Yan duvarlar, kemer | C28: m³ | D28: 10355
A29: 029.D | B29: Diğer Kesit Dışındaki Yapıların Betonu C30 | C29: m³ | D29: 10355
A30: 030.A | B30: Çelik Donatı (S220 ) | C30: ton | D30: 46250 | E30: =ROUND(SUM(F30:G30),3) -> 4.03 | F30: =ROUND(SUM(DATA!T:T)*(20*0.888*1.5+9*1.208*0.95)/1000,3) -> 4.03
A31: 030.B | B31: Çelik Donatı (S420a ) | C31: ton | D31: 92500 | E31: =ROUND(SUM(F31:G31),3) -> 0 | F31: =+ROUND(COUNTIFS(DATA!AG:AG,"30 adet L=2m Ø12 Demir montajı yapıldı.")*30*0.888*2/1000,3) -> 0
A32: 030.C | B32: Çelik hasır (S500 ) | C32: ton | D32: 97333 | E32: =ROUND(SUM(F32:H32),3) -> 22.323 | F32: =ROUND(SUM(DATA!T:T)*0.195718,3) -> 21.333 | G32: =ROUND(SUM(DATA!S:S)*0.11171,3) -> 0 | H32: =+SUM('AYNA TAKİP'!L:L) -> 0.989826
A33: 030.D | B33: Paslanmaz Çelik Plaka | C33: kg | D33: 150
A34: 030.E | B34: Block-out Kutusu | C34: kg | D34: 180
E35: =+SUMPRODUCT(D5:D34,E5:E34) -> 32433922
