Workbook
Name AMN_PRV: Metraj!$AC$2
Name AMN_THS: Metraj!$AD$2
Name AMN_TOT: Metraj!$AE$2

Sheet Kapak
A5: T.C.
A6: İSTANBUL BÜYÜKŞEHİR BELEDİYESİ
A7: Raylı Sistem Dairesi Başkanlığı Avrupa Yakası Raylı Sistem Şube Müdürlüğü
A12: Kirazlı-Halkalı Üniversite Metro Hattı İnşaat Ve Elektromekanik İşler İle M1 Hattı Elektromekanik Sistemleri Yapım İşi
A24: =+İcmal!C15 -> 6
A28: Metraj - 1.B - S06 - Barbaros-Hat-1-B1 Bağlantı-1 P2 Yönü Alt Yarı Aşaması (B1-106)
A33: METRAJLAR

Sheet İcmal
O1: =+Liste!H485 -> 2538910.3
A5: T.C.
A6: İSTANBUL BÜYÜKŞEHİR BELEDİYESİ
A7: Raylı Sistem Dairesi Başkanlığı Avrupa Yakası Raylı Sistem Şube Müdürlüğü
A10: Kirazlı-Halkalı Üniversite Metro Hattı İnşaat Ve Elektromekanik İşler İle M1 Hattı Elektromekanik Sistemleri Yapım İşi
A12: =+Kapak!A28 -> Metraj - 1.B - S06 - Barbaros-Hat-1-B1 Bağlantı-1 P2 Yönü Alt Yarı Aşaması (B1-106)
B15: Hakediş No: | C15: =+[3]Veri!$C$21 -> 6
B16: Hakediş Tarihi: | C16: =+[3]Veri!$C$22 -> 46142
P18: Dönem | Q18: Dönem | R18: Dönem | S18: Dönem | T18: Dönem | U18: Dönem | V18: Dönem | W18: Dönem | X18: Dönem | Y18: Dönem | Z18: Dönem | AA18: Dönem | AB18: Dönem | AC18: Dönem | AD18: Dönem | AE18: Dönem | AF18: Dönem | AG18: Dönem | AH18: Dönem | AI18: Dönem
B19: POZ NO | C19: BİRİM FİYAT ADI | J19: BİRİM | K19: ÖNCEKİ HAKEDİŞ MİKTARI | L19: BU HAKEDİŞ MİKTARI | M19: TOPLAM HAKEDİŞ MİKTARI | P19: 0525 | Q19: 0625 | R19: 0725 | S19: 0825 | T19: 0925 | U19: 1025 | V19: 1125 | W19: 1225 | X19: 0126 | Y19: 0226 | Z19: 0326 | AA19: 0426 | AB19: 0526 | AC19: 0626 | AD19: 0726 | AE19: 0826 | AF19: 0926 | AG19: 1026 | AH19: 1126 | AI19: 1226
B20: 018 | C20: =+VLOOKUP(B20,Liste!B:E,2,FALSE) -> Geleneksel (NATM) Tünel Kazısı | J20: =+VLOOKUP(B20,Liste!B:E,3,FALSE) -> m³ | K20: 83.764 | L20: =+M20-K20 -> 0 | M20: =+IFERROR(VLOOKUP(B20,Metraj!B:P,15,FALSE),"0") -> 83.764 | X20: 0 | Z20: 83.764 | AA20: =$M20-SUM($P20:Z20) -> 0 | AB20: =$M20-SUM($P20:AA20) -> 0 | AC20: =$M20-SUM($P20:AB20) -> 0 | AD20: =$M20-SUM($P20:AC20) -> 0 | AE20: =$M20-SUM($P20:AD20) -> 0 | AF20: =$M20-SUM($P20:AE20) -> 0 | AG20: =$M20-SUM($P20:AF20) -> 0 | AH20: =$M20-SUM($P20:AG20) -> 0 | AI20: =$M20-SUM($P20:AH20) -> 0
B21: 019.A | C21: =+VLOOKUP(B21,Liste!B:E,2,FALSE) -> Kazıdan çıkan veya Ariyetten alınan malzeme ile geri dolgu yapılması | J21: =+VLOOKUP(B21,Liste!B:E,3,FALSE) -> m³ | K21: 0 | L21: 0 | M21: =+IFERROR(VLOOKUP(B21,Metraj!B:P,15,FALSE),"0") -> 0 | X21: 0 | Z21: 0 | AA21: =$M21-SUM($P21:Z21) -> 0 | AB21: =$M21-SUM($P21:AA21) -> 0 | AC21: =$M21-SUM($P21:AB21) -> 0 | AD21: =$M21-SUM($P21:AC21) -> 0 | AE21: =$M21-SUM($P21:AD21) -> 0 | AF21: =$M21-SUM($P21:AE21) -> 0 | AG21: =$M21-SUM($P21:AF21) -> 0 | AH21: =$M21-SUM($P21:AG21) -> 0 | AI21: =$M21-SUM($P21:AH21) -> 0
B22: 019.B | C22: =+VLOOKUP(B22,Liste!B:E,2,FALSE) -> Kum, Çakıl, Kırma Tas ve Benzeri Malzeme ile Dolgu Yapılması | J22: =+VLOOKUP(B22,Liste!B:E,3,FALSE) -> m³ | K22: 0 | L22: =+M22-K22 -> 0 | M22: =+IFERROR(VLOOKUP(B22,Metraj!B:P,15,FALSE),"0") -> 0 | X22: 0 | Z22: 0 | AA22: =$M22-SUM($P22:Z22) -> 0 | AB22: =$M22-SUM($P22:AA22) -> 0 | AC22: =$M22-SUM($P22:AB22) -> 0 | AD22: =$M22-SUM($P22:AC22) -> 0 | AE22: =$M22-SUM($P22:AD22) -> 0 | AF22: =$M22-SUM($P22:AE22) -> 0 | AG22: =$M22-SUM($P22:AF22) -> 0 | AH22: =$M22-SUM($P22:AG22) -> 0 | AI22: =$M22-SUM($P22:AH22) -> 0
B23: 020 | C23: =+VLOOKUP(B23,Liste!B:E,2,FALSE) -> Püskürtme Beton (Tünel ve Şaftlarda) | J23: =+VLOOKUP(B23,Liste!B:E,3,FALSE) -> m³ | K23: 21.932 | L23: =+M23-K23 -> 0 | M23: =+IFERROR(VLOOKUP(B23,Metraj!B:P,15,FALSE),"0") -> 21.932 | X23: 0 | Z23: 21.932 | AA23: =$M23-SUM($P23:Z23) -> 0 | AB23: =$M23-SUM($P23:AA23) -> 0 | AC23: =$M23-SUM($P23:AB23) -> 0 | AD23: =$M23-SUM($P23:AC23) -> 0 | AE23: =$M23-SUM($P23:AD23) -> 0 | AF23: =$M23-SUM($P23:AE23) -> 0 | AG23: =$M23-SUM($P23:AF23) -> 0 | AH23: =$M23-SUM($P23:AG23) -> 0 | AI23: =$M23-SUM($P23:AH23) -> 0
B24: 021.A | C24: =+VLOOKUP(B24,Liste!B:E,2,FALSE) -> Delgi boyu =< 30m | J24: =+VLOOKUP(B24,Liste!B:E,3,FALSE) -> m | K24: 0 | L24: =+M24-K24 -> 0 | M24: =+IFERROR(VLOOKUP(B24,Metraj!B:P,15,FALSE),"0") -> 0 | X24: 0 | Z24: 0 | AA24: =$M24-SUM($P24:Z24) -> 0 | AB24: =$M24-SUM($P24:AA24) -> 0 | AC24: =$M24-SUM($P24:AB24) -> 0 | AD24: =$M24-SUM($P24:AC24) -> 0 | AE24: =$M24-SUM($P24:AD24) -> 0 | AF24: =$M24-SUM($P24:AE24) -> 0 | AG24: =$M24-SUM($P24:AF24) -> 0 | AH24: =$M24-SUM($P24:AG24) -> 0 | AI24: =$M24-SUM($P24:AH24) -> 0
B25: 021.B | C25: =+VLOOKUP(B25,Liste!B:E,2,FALSE) -> Delgi boyu > 30m | J25: =+VLOOKUP(B25,Liste!B:E,3,FALSE) -> m | K25: 0 | L25: =+M25-K25 -> 0 | M25: =+IFERROR(VLOOKUP(B25,Metraj!B:P,15,FALSE),"0") -> 0 | X25: 0 | Z25: 0 | AA25: =$M25-SUM($P25:Z25) -> 0 | AB25: =$M25-SUM($P25:AA25) -> 0 | AC25: =$M25-SUM($P25:AB25) -> 0 | AD25: =$M25-SUM($P25:AC25) -> 0 | AE25: =$M25-SUM($P25:AD25) -> 0 | AF25: =$M25-SUM($P25:AE25) -> 0 | AG25: =$M25-SUM($P25:AF25) -> 0 | AH25: =$M25-SUM($P25:AG25) -> 0 | AI25: =$M25-SUM($P25:AH25) -> 0
B26: 022.A | C26: =+VLOOKUP(B26,Liste!B:E,2,FALSE) -> L=3 m Kaya Bulonu | J26: =+VLOOKUP(B26,Liste!B:E,3,FALSE) -> adet | K26: 0 | L26: =+M26-K26 -> 0 | M26: =+IFERROR(VLOOKUP(B26,Metraj!B:P,15,FALSE),"0") -> 0 | X26: 0 | Z26: 0 | AA26: =$M26-SUM($P26:Z26) -> 0 | AB26: =$M26-SUM($P26:AA26) -> 0 | AC26: =$M26-SUM($P26:AB26) -> 0 | AD26: =$M26-SUM($P26:AC26) -> 0 | AE26: =$M26-SUM($P26:AD26) -> 0 | AF26: =$M26-SUM($P26:AE26) -> 0 | AG26: =$M26-SUM($P26:AF26) -> 0 | AH26: =$M26-SUM($P26:AG26) -> 0 | AI26: =$M26-SUM($P26:AH26) -> 0
B27: 022.B | C27: =+VLOOKUP(B27,Liste!B:E,2,FALSE) -> L=4 m Kaya Bulonu | J27: =+VLOOKUP(B27,Liste!B:E,3,FALSE) -> adet | K27: 0 | L27: =+M27-K27 -> 0 | M27: =+IFERROR(VLOOKUP(B27,Metraj!B:P,15,FALSE),"0") -> 0 | X27: 0 | Z27: 0 | AA27: =$M27-SUM($P27:Z27) -> 0 | AB27: =$M27-SUM($P27:AA27) -> 0 | AC27: =$M27-SUM($P27:AB27) -> 0 | AD27: =$M27-SUM($P27:AC27) -> 0 | AE27: =$M27-SUM($P27:AD27) -> 0 | AF27: =$M27-SUM($P27:AE27) -> 0 | AG27: =$M27-SUM($P27:AF27) -> 0 | AH27: =$M27-SUM($P27:AG27) -> 0 | AI27: =$M27-SUM($P27:AH27) -> 0
B28: 022.C | C28: =+VLOOKUP(B28,Liste!B:E,2,FALSE) -> L=5 m Kaya Bulonu | J28: =+VLOOKUP(B28,Liste!B:E,3,FALSE) -> adet | K28: 0 | L28: =+M28-K28 -> 0 | M28: =+IFERROR(VLOOKUP(B28,Metraj!B:P,15,FALSE),"0") -> 0 | X28: 0 | Z28: 0 | AA28: =$M28-SUM($P28:Z28) -> 0 | AB28: =$M28-SUM($P28:AA28) -> 0 | AC28: =$M28-SUM($P28:AB28) -> 0 | AD28: =$M28-SUM($P28:AC28) -> 0 | AE28: =$M28-SUM($P28:AD28) -> 0 | AF28: =$M28-SUM($P28:AE28) -> 0 | AG28: =$M28-SUM($P28:AF28) -> 0 | AH28: =$M28-SUM($P28:AG28) -> 0 | AI28: =$M28-SUM($P28:AH28) -> 0
B29: 022.D | C29: =+VLOOKUP(B29,Liste!B:E,2,FALSE) -> L=6 m Kaya Bulonu | J29: =+VLOOKUP(B29,Liste!B:E,3,FALSE) -> adet | K29: 0 | L29: =+M29-K29 -> 0 | M29: =+IFERROR(VLOOKUP(B29,Metraj!B:P,15,FALSE),"0") -> 0 | X29: 0 | Z29: 0 | AA29: =$M29-SUM($P29:Z29) -> 0 | AB29: =$M29-SUM($P29:AA29) -> 0 | AC29: =$M29-SUM($P29:AB29) -> 0 | AD29: =$M29-SUM($P29:AC29) -> 0 | AE29: =$M29-SUM($P29:AD29) -> 0 | AF29: =$M29-SUM($P29:AE29) -> 0 | AG29: =$M29-SUM($P29:AF29) -> 0 | AH29: =$M29-SUM($P29:AG29) -> 0 | AI29: =$M29-SUM($P29:AH29) -> 0
B30: 022.E | C30: =+VLOOKUP(B30,Liste!B:E,2,FALSE) -> L=8 m Kaya Bulonu | J30: =+VLOOKUP(B30,Liste!B:E,3,FALSE) -> adet | K30: 22 | L30: =+M30-K30 -> 22 | M30: =+IFERROR(VLOOKUP(B30,Metraj!B:P,15,FALSE),"0") -> 44 | X30: 22 | Z30: 0 | AA30: =$M30-SUM($P30:Z30) -> 22 | AB30: =$M30-SUM($P30:AA30) -> 0 | AC30: =$M30-SUM($P30:AB30) -> 0 | AD30: =$M30-SUM($P30:AC30) -> 0 | AE30: =$M30-SUM($P30:AD30) -> 0 | AF30: =$M30-SUM($P30:AE30) -> 0 | AG30: =$M30-SUM($P30:AF30) -> 0 | AH30: =$M30-SUM($P30:AG30) -> 0 | AI30: =$M30-SUM($P30:AH30) -> 0
B31: 023.A | C31: =+VLOOKUP(B31,Liste!B:E,2,FALSE) -> 125 mm Delik İçine 14 mm Kalınlığında S420a ile Zemin Çivisi Teşkili | J31: =+VLOOKUP(B31,Liste!B:E,3,FALSE) -> m | K31: 0 | L31: =+M31-K31 -> 0 | M31: =+IFERROR(VLOOKUP(B31,Metraj!B:P,15,FALSE),"0") -> 0 | X31: 0 | Z31: 0 | AA31: =$M31-SUM($P31:Z31) -> 0 | AB31: =$M31-SUM($P31:AA31) -> 0 | AC31: =$M31-SUM($P31:AB31) -> 0 | AD31: =$M31-SUM($P31:AC31) -> 0 | AE31: =$M31-SUM($P31:AD31) -> 0 | AF31: =$M31-SUM($P31:AE31) -> 0 | AG31: =$M31-SUM($P31:AF31) -> 0 | AH31: =$M31-SUM($P31:AG31) -> 0 | AI31: =$M31-SUM($P31:AH31) -> 0
B32: 023.B | C32: =+VLOOKUP(B32,Liste!B:E,2,FALSE) -> 125 mm Delik İçine 26 mm Kalınlığında S420a ile Zemin Çivisi Teşkili | J32: =+VLOOKUP(B32,Liste!B:E,3,FALSE) -> m | K32: 0 | L32: =+M32-K32 -> 0 | M32: =+IFERROR(VLOOKUP(B32,Metraj!B:P,15,FALSE),"0") -> 0 | X32: 0 | Z32: 0 | AA32: =$M32-SUM($P32:Z32) -> 0 | AB32: =$M32-SUM($P32:AA32) -> 0 | AC32: =$M32-SUM($P32:AB32) -> 0 | AD32: =$M32-SUM($P32:AC32) -> 0 | AE32: =$M32-SUM($P32:AD32) -> 0 | AF32: =$M32-SUM($P32:AE32) -> 0 | AG32: =$M32-SUM($P32:AF32) -> 0 | AH32: =$M32-SUM($P32:AG32) -> 0 | AI32: =$M32-SUM($P32:AH32) -> 0
B33: 024 | C33: =+VLOOKUP(B33,Liste!B:E,2,FALSE) -> Çelik İksa (Tünel ve Şaftlarda) | J33: =+VLOOKUP(B33,Liste!B:E,3,FALSE) -> ton | K33: 4.383 | L33: =+M33-K33 -> 0 | M33: =+IFERROR(VLOOKUP(B33,Metraj!B:P,15,FALSE),"0") -> 4.383 | X33: 0 | Z33: 4.383 | AA33: =$M33-SUM($P33:Z33) -> 0 | AB33: =$M33-SUM($P33:AA33) -> 0 | AC33: =$M33-SUM($P33:AB33) -> 0 | AD33: =$M33-SUM($P33:AC33) -> 0 | AE33: =$M33-SUM($P33:AD33) -> 0 | AF33: =$M33-SUM($P33:AE33) -> 0 | AG33: =$M33-SUM($P33:AF33) -> 0 | AH33: =$M33-SUM($P33:AG33) -> 0 | AI33: =$M33-SUM($P33:AH33) -> 0
B34: 025 | C34: =+VLOOKUP(B34,Liste!B:E,2,FALSE) -> Umbrella Arch Yapılması | J34: =+VLOOKUP(B34,Liste!B:E,3,FALSE) -> m | K34: 0 | L34: =+M34-K34 -> 0 | M34: =+IFERROR(VLOOKUP(B34,Metraj!B:P,15,FALSE),"0") -> 0 | X34: 0 | Z34: 0 | AA34: =$M34-SUM($P34:Z34) -> 0 | AB34: =$M34-SUM($P34:AA34) -> 0 | AC34: =$M34-SUM($P34:AB34) -> 0 | AD34: =$M34-SUM($P34:AC34) -> 0 | AE34: =$M34-SUM($P34:AD34) -> 0 | AF34: =$M34-SUM($P34:AE34) -> 0 | AG34: =$M34-SUM($P34:AF34) -> 0 | AH34: =$M34-SUM($P34:AG34) -> 0 | AI34: =$M34-SUM($P34:AH34) -> 0
B35: 026.A | C35: =+VLOOKUP(B35,Liste!B:E,2,FALSE) -> Tünel ve şaftlarda su yalıtımı, birim ağırlığı >=500 g/metrekare geotekstil keçe | J35: =+VLOOKUP(B35,Liste!B:E,3,FALSE) -> m² | K35: 0 | L35: =+M35-K35 -> 0 | M35: =+IFERROR(VLOOKUP(B35,Metraj!B:P,15,FALSE),"0") -> 0 | X35: 0 | Z35: 0 | AA35: =$M35-SUM($P35:Z35) -> 0 | AB35: =$M35-SUM($P35:AA35) -> 0 | AC35: =$M35-SUM($P35:AB35) -> 0 | AD35: =$M35-SUM($P35:AC35) -> 0 | AE35: =$M35-SUM($P35:AD35) -> 0 | AF35: =$M35-SUM($P35:AE35) -> 0 | AG35: =$M35-SUM($P35:AF35) -> 0 | AH35: =$M35-SUM($P35:AG35) -> 0 | AI35: =$M35-SUM($P35:AH35) -> 0
B36: 026.B | C36: =+VLOOKUP(B36,Liste!B:E,2,FALSE) -> Tünel ve şaftlarda su yalıtımı, 2mm kalınlıklı PVC membran | J36: =+VLOOKUP(B36,Liste!B:E,3,FALSE) -> m² | K36: 0 | L36: =+M36-K36 -> 0 | M36: =+IFERROR(VLOOKUP(B36,Metraj!B:P,15,FALSE),"0") -> 0 | X36: 0 | Z36: 0 | AA36: =$M36-SUM($P36:Z36) -> 0 | AB36: =$M36-SUM($P36:AA36) -> 0 | AC36: =$M36-SUM($P36:AB36) -> 0 | AD36: =$M36-SUM($P36:AC36) -> 0 | AE36: =$M36-SUM($P36:AD36) -> 0 | AF36: =$M36-SUM($P36:AE36) -> 0 | AG36: =$M36-SUM($P36:AF36) -> 0 | AH36: =$M36-SUM($P36:AG36) -> 0 | AI36: =$M36-SUM($P36:AH36) -> 0
B37: 027 | C37: =+VLOOKUP(B37,Liste!B:E,2,FALSE) -> Su Tutucular (Tünel ve Şaftlarda) | J37: =+VLOOKUP(B37,Liste!B:E,3,FALSE) -> m | K37: 0 | L37: =+M37-K37 -> 0 | M37: =+IFERROR(VLOOKUP(B37,Metraj!B:P,15,FALSE),"0") -> 0 | X37: 0 | Z37: 0 | AA37: =$M37-SUM($P37:Z37) -> 0 | AB37: =$M37-SUM($P37:AA37) -> 0 | AC37: =$M37-SUM($P37:AB37) -> 0 | AD37: =$M37-SUM($P37:AC37) -> 0 | AE37: =$M37-SUM($P37:AD37) -> 0 | AF37: =$M37-SUM($P37:AE37) -> 0 | AG37: =$M37-SUM($P37:AF37) -> 0 | AH37: =$M37-SUM($P37:AG37) -> 0 | AI37: =$M37-SUM($P37:AH37) -> 0
B38: 028.A | C38: =+VLOOKUP(B38,Liste!B:E,2,FALSE) -> Kalıp (invert ve şaft için) | J38: =+VLOOKUP(B38,Liste!B:E,3,FALSE) -> m² | K38: 0 | L38: =+M38-K38 -> 0 | M38: =+IFERROR(VLOOKUP(B38,Metraj!B:P,15,FALSE),"0") -> 0 | X38: 0 | Z38: 0 | AA38: =$M38-SUM($P38:Z38) -> 0 | AB38: =$M38-SUM($P38:AA38) -> 0 | AC38: =$M38-SUM($P38:AB38) -> 0 | AD38: =$M38-SUM($P38:AC38) -> 0 | AE38: =$M38-SUM($P38:AD38) -> 0 | AF38: =$M38-SUM($P38:AE38) -> 0 | AG38: =$M38-SUM($P38:AF38) -> 0 | AH38: =$M38-SUM($P38:AG38) -> 0 | AI38: =$M38-SUM($P38:AH38) -> 0
B39: 028.B | C39: =+VLOOKUP(B39,Liste!B:E,2,FALSE) -> Kalıp (duvar ve kemer İçin) | J39: =+VLOOKUP(B39,Liste!B:E,3,FALSE) -> m² | K39: 0 | L39: =+M39-K39 -> 0 | M39: =+IFERROR(VLOOKUP(B39,Metraj!B:P,15,FALSE),"0") -> 0 | X39: 0 | Z39: 0 | AA39: =$M39-SUM($P39:Z39) -> 0 | AB39: =$M39-SUM($P39:AA39) -> 0 | AC39: =$M39-SUM($P39:AB39) -> 0 | AD39: =$M39-SUM($P39:AC39) -> 0 | AE39: =$M39-SUM($P39:AD39) -> 0 | AF39: =$M39-SUM($P39:AE39) -> 0 | AG39: =$M39-SUM($P39:AF39) -> 0 | AH39: =$M39-SUM($P39:AG39) -> 0 | AI39: =$M39-SUM($P39:AH39) -> 0
B40: 028.C | C40: =+VLOOKUP(B40,Liste!B:E,2,FALSE) -> Tip Kesit Dışı Konstrüksiyon Kalıbı, Tünel Alın Kalıbı | J40: =+VLOOKUP(B40,Liste!B:E,3,FALSE) -> m² | K40: 0 | L40: =+M40-K40 -> 0 | M40: =+IFERROR(VLOOKUP(B40,Metraj!B:P,15,FALSE),"0") -> 0 | X40: 0 | Z40: 0 | AA40: =$M40-SUM($P40:Z40) -> 0 | AB40: =$M40-SUM($P40:AA40) -> 0 | AC40: =$M40-SUM($P40:AB40) -> 0 | AD40: =$M40-SUM($P40:AC40) -> 0 | AE40: =$M40-SUM($P40:AD40) -> 0 | AF40: =$M40-SUM($P40:AE40) -> 0 | AG40: =$M40-SUM($P40:AF40) -> 0 | AH40: =$M40-SUM($P40:AG40) -> 0 | AI40: =$M40-SUM($P40:AH40) -> 0
B41: 029.A | C41: =+VLOOKUP(B41,Liste!B:E,2,FALSE) -> C16 Beton İmali ve Dökülmesi (Tünel ve Şaftlarda) | J41: =+VLOOKUP(B41,Liste!B:E,3,FALSE) -> m³ | K41: 0 | L41: =+M41-K41 -> 0 | M41: =+IFERROR(VLOOKUP(B41,Metraj!B:P,15,FALSE),"0") -> 0 | X41: 0 | Z41: 0 | AA41: =$M41-SUM($P41:Z41) -> 0 | AB41: =$M41-SUM($P41:AA41) -> 0 | AC41: =$M41-SUM($P41:AB41) -> 0 | AD41: =$M41-SUM($P41:AC41) -> 0 | AE41: =$M41-SUM($P41:AD41) -> 0 | AF41: =$M41-SUM($P41:AE41) -> 0 | AG41: =$M41-SUM($P41:AF41) -> 0 | AH41: =$M41-SUM($P41:AG41) -> 0 | AI41: =$M41-SUM($P41:AH41) -> 0
B42: 029.B | C42: =+VLOOKUP(B42,Liste!B:E,2,FALSE) -> C30 Beton İmali ve Dökülmesi (Tünel ve Şaftlarda) Tünel kaplaması, invert ve şaftlardaki alt döşeme | J42: =+VLOOKUP(B42,Liste!B:E,3,FALSE) -> m³ | K42: 0 | L42: =+M42-K42 -> 0 | M42: =+IFERROR(VLOOKUP(B42,Metraj!B:P,15,FALSE),"0") -> 0 | X42: 0 | Z42: 0 | AA42: =$M42-SUM($P42:Z42) -> 0 | AB42: =$M42-SUM($P42:AA42) -> 0 | AC42: =$M42-SUM($P42:AB42) -> 0 | AD42: =$M42-SUM($P42:AC42) -> 0 | AE42: =$M42-SUM($P42:AD42) -> 0 | AF42: =$M42-SUM($P42:AE42) -> 0 | AG42: =$M42-SUM($P42:AF42) -> 0 | AH42: =$M42-SUM($P42:AG42) -> 0 | AI42: =$M42-SUM($P42:AH42) -> 0
B43: 029.C | C43: =+VLOOKUP(B43,Liste!B:E,2,FALSE) -> C30 Beton İmali ve Dökülmesi (Tünel ve Şaftlarda) Yan duvarlar, kemer | J43: =+VLOOKUP(B43,Liste!B:E,3,FALSE) -> m³ | K43: 0 | L43: =+M43-K43 -> 0 | M43: =+IFERROR(VLOOKUP(B43,Metraj!B:P,15,FALSE),"0") -> 0 | X43: 0 | Z43: 0 | AA43: =$M43-SUM($P43:Z43) -> 0 | AB43: =$M43-SUM($P43:AA43) -> 0 | AC43: =$M43-SUM($P43:AB43) -> 0 | AD43: =$M43-SUM($P43:AC43) -> 0 | AE43: =$M43-SUM($P43:AD43) -> 0 | AF43: =$M43-SUM($P43:AE43) -> 0 | AG43: =$M43-SUM($P43:AF43) -> 0 | AH43: =$M43-SUM($P43:AG43) -> 0 | AI43: =$M43-SUM($P43:AH43) -> 0
B44: 029.D | C44: =+VLOOKUP(B44,Liste!B:E,2,FALSE) -> Diğer Kesit Dışındaki Yapıların Betonu C30 | J44: =+VLOOKUP(B44,Liste!B:E,3,FALSE) -> m³ | K44: 0 | L44: =+M44-K44 -> 0 | M44: =+IFERROR(VLOOKUP(B44,Metraj!B:P,15,FALSE),"0") -> 0 | X44: 0 | Z44: 0 | AA44: =$M44-SUM($P44:Z44) -> 0 | AB44: =$M44-SUM($P44:AA44) -> 0 | AC44: =$M44-SUM($P44:AB44) -> 0 | AD44: =$M44-SUM($P44:AC44) -> 0 | AE44: =$M44-SUM($P44:AD44) -> 0 | AF44: =$M44-SUM($P44:AE44) -> 0 | AG44: =$M44-SUM($P44:AF44) -> 0 | AH44: =$M44-SUM($P44:AG44) -> 0 | AI44: =$M44-SUM($P44:AH44) -> 0
B45: 030.A | C45: =+VLOOKUP(B45,Liste!B:E,2,FALSE) -> Çelik Donatı (S220 ) | J45: =+VLOOKUP(B45,Liste!B:E,3,FALSE) -> ton | K45: 0.087 | L45: =+M45-K45 -> 0 | M45: =+IFERROR(VLOOKUP(B45,Metraj!B:P,15,FALSE),"0") -> 0.087 | X45: 0 | Z45: 0.087 | AA45: =$M45-SUM($P45:Z45) -> 0 | AB45: =$M45-SUM($P45:AA45) -> 0 | AC45: =$M45-SUM($P45:AB45) -> 0 | AD45: =$M45-SUM($P45:AC45) -> 0 | AE45: =$M45-SUM($P45:AD45) -> 0 | AF45: =$M45-SUM($P45:AE45) -> 0 | AG45: =$M45-SUM($P45:AF45) -> 0 | AH45: =$M45-SUM($P45:AG45) -> 0 | AI45: =$M45-SUM($P45:AH45) -> 0
B46: 030.B | C46: =+VLOOKUP(B46,Liste!B:E,2,FALSE) -> Çelik Donatı (S420a ) | J46: =+VLOOKUP(B46,Liste!B:E,3,FALSE) -> ton | K46: 0 | L46: =+M46-K46 -> 0 | M46: =+IFERROR(VLOOKUP(B46,Metraj!B:P,15,FALSE),"0") -> 0 | X46: 0 | Z46: 0 | AA46: =$M46-SUM($P46:Z46) -> 0 | AB46: =$M46-SUM($P46:AA46) -> 0 | AC46: =$M46-SUM($P46:AB46) -> 0 | AD46: =$M46-SUM($P46:AC46) -> 0 | AE46: =$M46-SUM($P46:AD46) -> 0 | AF46: =$M46-SUM($P46:AE46) -> 0 | AG46: =$M46-SUM($P46:AF46) -> 0 | AH46: =$M46-SUM($P46:AG46) -> 0 | AI46: =$M46-SUM($P46:AH46) -> 0
B47: 030.C | C47: =+VLOOKUP(B47,Liste!B:E,2,FALSE) -> Çelik hasır (S500 ) | J47: =+VLOOKUP(B47,Liste!B:E,3,FALSE) -> ton | K47: 0.97 | L47: =+M47-K47 -> 0 | M47: =+IFERROR(VLOOKUP(B47,Metraj!B:P,15,FALSE),"0") -> 0.97 | X47: 0 | Z47: 0.97 | AA47: =$M47-SUM($P47:Z47) -> 0 | AB47: =$M47-SUM($P47:AA47) -> 0 | AC47: =$M47-SUM($P47:AB47) -> 0 | AD47: =$M47-SUM($P47:AC47) -> 0 | AE47: =$M47-SUM($P47:AD47) -> 0 | AF47: =$M47-SUM($P47:AE47) -> 0 | AG47: =$M47-SUM($P47:AF47) -> 0 | AH47: =$M47-SUM($P47:AG47) -> 0 | AI47: =$M47-SUM($P47:AH47) -> 0
B48: 030.D | C48: =+VLOOKUP(B48,Liste!B:E,2,FALSE) -> Paslanmaz Çelik Plaka | J48: =+VLOOKUP(B48,Liste!B:E,3,FALSE) -> kg | K48: 0 | L48: =+M48-K48 -> 0 | M48: =+IFERROR(VLOOKUP(B48,Metraj!B:P,15,FALSE),"0") -> 0 | X48: 0 | Z48: 0 | AA48: =$M48-SUM($P48:Z48) -> 0 | AB48: =$M48-SUM($P48:AA48) -> 0 | AC48: =$M48-SUM($P48:AB48) -> 0 | AD48: =$M48-SUM($P48:AC48) -> 0 | AE48: =$M48-SUM($P48:AD48) -> 0 | AF48: =$M48-SUM($P48:AE48) -> 0 | AG48: =$M48-SUM($P48:AF48) -> 0 | AH48: =$M48-SUM($P48:AG48) -> 0 | AI48: =$M48-SUM($P48:AH48) -> 0
B49: 030.E | C49: =+VLOOKUP(B49,Liste!B:E,2,FALSE) -> Block-out Kutusu | J49: =+VLOOKUP(B49,Liste!B:E,3,FALSE) -> kg | K49: 0 | L49: =+M49-K49 -> 0 | M49: =+IFERROR(VLOOKUP(B49,Metraj!B:P,15,FALSE),"0") -> 0 | X49: 0 | Z49: 0 | AA49: =$M49-SUM($P49:Z49) -> 0 | AB49: =$M49-SUM($P49:AA49) -> 0 | AC49: =$M49-SUM($P49:AB49) -> 0 | AD49: =$M49-SUM($P49:AC49) -> 0 | AE49: =$M49-SUM($P49:AD49) -> 0 | AF49: =$M49-SUM($P49:AE49) -> 0 | AG49: =$M49-SUM($P49:AF49) -> 0 | AH49: =$M49-SUM($P49:AG49) -> 0 | AI49: =$M49-SUM($P49:AH49) -> 0

Sheet Metraj
AC1: Önceki Hakediş | AD1: Bu Hakediş Tutarı | AE1: Kümülatif Hakediş
A2: T.C. | AC2: =+SUM(AC17:AC1000) -> 1922910.3 | AD2: =+SUM(AD17:AD1000) -> 616000 | AE2: =+SUM(AE17:AE1000) -> 2538910.3
A3: İSTANBUL BÜYÜKŞEHİR BELEDİYESİ
A4: Raylı Sistem Dairesi Başkanlığı Avrupa Yakası Raylı Sistem Şube Müdürlüğü
A7: Kirazlı-Halkalı Üniversite Metro Hattı İnşaat Ve Elektromekanik İşler İle M1 Hattı Elektromekanik Sistemleri Yapım İşi
A9: =+Kapak!A28 -> Metraj - 1.B - S06 - Barbaros-Hat-1-B1 Bağlantı-1 P2 Yönü Alt Yarı Aşaması (B1-106)
A11: Metraj Sayfası
B13: Hakediş No: | C13: =+İcmal!C15 -> 6
B14: Hakediş Tarihi: | C14: =+İcmal!C16 -> 46142
B16: POZ NO | D16: BİRİM FİYAT ADI | M16: BİRİM | N16: ÖNCEKİ HAKEDİŞ MİKTARI | O16: BU HAKEDİŞ MİKTARI | P16: TOPLAM HAKEDİŞ MİKTARI
B17: 018 | D17: =+VLOOKUP(B17,[1]Liste!B:E,2,FALSE) -> Geleneksel (NATM) Tünel Kazısı | M17: =+VLOOKUP(B17,[1]Liste!B:E,3,FALSE) -> m³ | N17: 83.764 | O17: =+P17-N17 -> 0 | P17: =+ROUND(SUM(P18:P28),3) -> 83.764 | AA17: =+VLOOKUP(B17,[2]Liste!$B$2:$F$483,5,FALSE) -> 5075 | AC17: =+AA17*N17 -> 425102.3 | AD17: =+AA17*O17 -> 0 | AE17: =+AA17*P17 -> 425102.3
B18: Alt Yarı İmalatları
B19: Hk No | C19: Tutanak Genel No | D19: Tutanak Özel No | H19: KM1 | I19: KM2 | J19: Yeri | K19: Benzer | L19: Boyu | M19: Açıklama | O19: Alanı | P19: Miktarı
B20: 5 | C20: 2026.03-002 | D20: S06.H2.B1.BAĞ1-P2.A-002 | H20: 5.41 | I20: 12.41 | J20: Alt Yarı | K20: 1 | L20: 0.75 | M20: P1 - 1 Nolu Tip İksa | O20: 11.966 | P20: =+ROUND(PRODUCT(K20:O20),3) -> 8.975 | R20: =+L20*K20 -> 0.75
B21: 5 | C21: 2026.03-002 | D21: S06.H2.B1.BAĞ1-P2.A-002 | H21: 5.41 | I21: 12.41 | J21: Alt Yarı | K21: 1 | L21: 0.75 | M21: P1 - 2 Nolu Tip İksa | O21: 11.966 | P21: =+ROUND(PRODUCT(K21:O21),3) -> 8.975 | R21: =+L21*K21 -> 0.75
B22: 5 | C22: 2026.03-002 | D22: S06.H2.B1.BAĞ1-P2.A-002 | H22: 5.41 | I22: 12.41 | J22: Alt Yarı | K22: 1 | L22: 0.5 | M22: P1 - 3 Nolu Tip İksa | O22: 11.966 | P22: =+ROUND(PRODUCT(K22:O22),3) -> 5.983 | R22: =+L22*K22 -> 0.5
B23: 5 | C23: 2026.03-002 | D23: S06.H2.B1.BAĞ1-P2.A-002 | H23: 5.41 | I23: 12.41 | J23: Alt Yarı | K23: 1 | L23: 0.75 | M23: P1 - 3 Nolu Tip İksa | O23: 11.966 | P23: =+ROUND(PRODUCT(K23:O23),3) -> 8.975 | R23: =+L23*K23 -> 0.75
B24: 5 | C24: 2026.03-002 | D24: S06.H2.B1.BAĞ1-P2.A-002 | H24: 5.41 | I24: 12.41 | J24: Alt Yarı | K24: 1 | L24: 0.5 | M24: P1 - 4 Nolu Tip İksa | O24: 11.966 | P24: =+ROUND(PRODUCT(K24:O24),3) -> 5.983 | R24: =+L24*K24 -> 0.5
B25: 5 | C25: 2026.03-002 | D25: S06.H2.B1.BAĞ1-P2.A-002 | H25: 5.41 | I25: 12.41 | J25: Alt Yarı | K25: 1 | L25: 0.75 | M25: P1 - 4 Nolu Tip İksa | O25: 11.966 | P25: =+ROUND(PRODUCT(K25:O25),3) -> 8.975 | R25: =+L25*K25 -> 0.75
B26: 5 | C26: 2026.03-002 | D26: S06.H2.B1.BAĞ1-P2.A-002 | H26: 5.41 | I26: 12.41 | J26: Alt Yarı | K26: 2 | L26: 0.75 | M26: P1 - 5 Nolu Tip İksa | O26: 11.966 | P26: =+ROUND(PRODUCT(K26:O26),3) -> 17.949 | R26: =+L26*K26 -> 1.5
B27: 5 | C27: 2026.03-002 | D27: S06.H2.B1.BAĞ1-P2.A-002 | H27: 5.41 | I27: 12.41 | J27: Alt Yarı | K27: 2 | L27: 0.75 | M27: P1 - 6 Nolu Tip İksa | O27: 11.966 | P27: =+ROUND(PRODUCT(K27:O27),3) -> 17.949 | R27: =+L27*K27 -> 1.5
B30: POZ NO | D30: BİRİM FİYAT ADI | M30: BİRİM | N30: ÖNCEKİ HAKEDİŞ MİKTARI | O30: BU HAKEDİŞ MİKTARI | P30: TOPLAM HAKEDİŞ MİKTARI
B31: 020 | D31: =+VLOOKUP(B31,[1]Liste!B:E,2,FALSE) -> Püskürtme Beton (Tünel ve Şaftlarda) | M31: =+VLOOKUP(B31,[1]Liste!B:E,3,FALSE) -> m³ | N31: 21.932 | O31: =+P31-N31 -> 0 | P31: =+ROUND(SUM(P32:P46),3) -> 21.932 | AA31: =+VLOOKUP(B31,[2]Liste!$B$2:$F$483,5,FALSE) -> 15334 | AC31: =+AA31*N31 -> 336305.29 | AD31: =+AA31*O31 -> 0 | AE31: =+AA31*P31 -> 336305.29
B32: Alt Yarı İmalatları
B33: Hk No | C33: Tutanak Genel No | D33: Tutanak Özel No | H33: KM1 | I33: KM2 | J33: Yeri | K33: Benzer | L33: Kontak Enj. Kesintisi | M33: Boyu | N33: Açıklama | O33: Alanı | P33: Miktarı
B34: 5 | C34: 2026.03-002 | D34: S06.H2.B1.BAĞ1-P2.A-002 | H34: 5.41 | I34: 12.41 | J34: Alt Yarı | K34: 1 | L34: 0.9 | M34: 0.75 | N34: P1 - 1 Nolu Tip İksa | O34: 2.62 | P34: =+ROUND(PRODUCT(K34:O34),3) -> 1.769 | R34: =+M34*K34 -> 0.75
B35: 5 | C35: 2026.03-002 | D35: S06.H2.B1.BAĞ1-P2.A-002 | H35: 5.41 | I35: 12.41 | J35: Alt Yarı | K35: 1 | L35: 0.9 | M35: 0.75 | N35: P1 - 2 Nolu Tip İksa | O35: 2.62 | P35: =+ROUND(PRODUCT(K35:O35),3) -> 1.769 | R35: =+M35*K35 -> 0.75
B36: 5 | C36: 2026.03-002 | D36: S06.H2.B1.BAĞ1-P2.A-002 | H36: 5.41 | I36: 12.41 | J36: Alt Yarı | K36: 1 | L36: 0.9 | M36: 0.5 | N36: P1 - 3 Nolu Tip İksa | O36: 2.62 | P36: =+ROUND(PRODUCT(K36:O36),3) -> 1.179 | R36: =+M36*K36 -> 0.5
B37: 5 | C37: 2026.03-002 | D37: S06.H2.B1.BAĞ1-P2.A-002 | H37: 5.41 | I37: 12.41 | J37: Alt Yarı | K37: 1 | L37: 0.9 | M37: 0.75 | N37: P1 - 3 Nolu Tip İksa | O37: 2.62 | P37: =+ROUND(PRODUCT(K37:O37),3) -> 1.769 | R37: =+M37*K37 -> 0.75
B38: 5 | C38: 2026.03-002 | D38: S06.H2.B1.BAĞ1-P2.A-002 | H38: 5.41 | I38: 12.41 | J38: Alt Yarı | K38: 1 | L38: 0.9 | M38: 0.5 | N38: P1 - 4 Nolu Tip İksa | O38: 2.62 | P38: =+ROUND(PRODUCT(K38:O38),3) -> 1.179 | R38: =+M38*K38 -> 0.5
B39: 5 | C39: 2026.03-002 | D39: S06.H2.B1.BAĞ1-P2.A-002 | H39: 5.41 | I39: 12.41 | J39: Alt Yarı | K39: 1 | L39: 0.9 | M39: 0.75 | N39: P1 - 4 Nolu Tip İksa | O39: 2.62 | P39: =+ROUND(PRODUCT(K39:O39),3) -> 1.769 | R39: =+M39*K39 -> 0.75
B40: 5 | C40: 2026.03-002 | D40: S06.H2.B1.BAĞ1-P2.A-002 | H40: 5.41 | I40: 12.41 | J40: Alt Yarı | K40: 2 | L40: 0.9 | M40: 0.75 | N40: P1 - 5 Nolu Tip İksa | O40: 2.62 | P40: =+ROUND(PRODUCT(K40:O40),3) -> 3.537 | R40: =+M40*K40 -> 1.5
B41: 5 | C41: 2026.03-002 | D41: S06.H2.B1.BAĞ1-P2.A-002 | H41: 5.41 | I41: 12.41 | J41: Alt Yarı | K41: 2 | L41: 0.9 | M41: 0.75 | N41: P1 - 6 Nolu Tip İksa | O41: 2.62 | P41: =+ROUND(PRODUCT(K41:O41),3) -> 3.537 | R41: =+M41*K41 -> 1.5
B42: 5 | C42: 2026.03-002 | D42: S06.H2.B1.BAĞ1-P2.A-002 | H42: 5.41 | I42: 12.41 | J42: Alt Yarı | K42: 1 | L42: 0.1 | M42: =+I42-H42 -> 7 | N42: Kontak Enjeksiyon | O42: 2.62 | P42: =+ROUND(PRODUCT(K42:O42),3) -> 1.834 | R42: =+M42*K42 -> 7
B43: Ayna Emniyet Shotcrete
B44: Hk No | C44: Tutanak Genel No | D44: Ayna Kesit Tipi | I44: Kalınlık | J44: Yeri | K44: Benzer | L44: Eni | M44: Boyu | N44: Yüksekliği | O44: Alanı | P44: Miktarı
B45: 5 | C45: 2026.03-002 | D45: 6 Nolu İksa Tipi Ayna | I45: 30 | J45: Üst Yarı | K45: 1 | M45: =+I45/100 -> 0.3 | O45: 11.966 | P45: =+ROUND(PRODUCT(K45:O45),3) -> 3.59
B48: POZ NO | D48: BİRİM FİYAT ADI | M48: BİRİM | N48: ÖNCEKİ HAKEDİŞ MİKTARI | O48: BU HAKEDİŞ MİKTARI | P48: TOPLAM HAKEDİŞ MİKTARI
B49: 022.D | D49: =+VLOOKUP(B49,[1]Liste!B:E,2,FALSE) -> L=6 m Kaya Bulonu | M49: =+VLOOKUP(B49,[1]Liste!B:E,3,FALSE) -> adet | N49: =+[1]İcmal!K29 -> 0 | O49: =+[1]İcmal!L29 -> 0 | P49: =+SUM(P50:P52) -> 0
B50: Hk No | C50: Tutanak Genel No | D50: Tutanak Özel No | K50: Benzer | O50: Adeti | P50: Miktarı
...

Sheet Liste
A1: Sıra No | B1: İş Kalemi No | C1: Açıklama | D1: Birimi | E1: Miktarı | F1: Birim Fiyat | G1: Tutar
A2: 1 | B2: 001 | C2: Binaların Yıkılması | D2: m² | E2: 4600 | F2: 500 | G2: =+E2*F2 -> 2300000
A3: 2 | B3: 002.A | C3: Demirli ve Demirsiz Betonun Kompresörle Kırılması | D3: m³ | E3: 528.66 | F3: 4063 | G3: =+E3*F3 -> 2147945.6
A4: 3 | B4: 002.B | C4: Demirli ve Demirsiz Betonun Ekskavatör veya Benzeri İş Makinesi ile Kırılması | D4: m³ | E4: 550.69 | F4: 2000 | G4: =+E4*F4 -> 1101380
A5: 4 | B5: 002.C | C5: Karot Delme ve Beton Kesme Makineları ile Her Türlü Betonun Kesilmesi | D5: m³ | E5: 440.55 | F5: 10500 | G5: =+E5*F5 -> 4625775
A6: 5 | B6: 003 | C6: Her tip zeminde ve kayada, her derinlikte kazı yapılması (nakliye, döküm ve kazı sırasındaki drenaj dahil) (Açık Alanda) | D6: m³ | E6: 175497.85 | F6: 1485 | G6: =+E6*F6 -> 2.6061431e+08
A7: 6 | B7: 004.A | C7: Kazıdan Çıkan veya Ariyetten Alınan Malzeme ile Dolgu Yapılması | D7: m³ | E7: 26184.71 | F7: 300 | G7: =+E7*F7 -> 7855413
A8: 7 | B8: 004.B | C8: Kum, Çakıl, Kırma Tas ve Benzeri Malzeme ile Dolgu Yapılması | D8: m³ | E8: 27657.96 | F8: 1500 | G8: =+E8*F8 -> 41486940
A9: 8 | B9: 005 | C9: Püskürtme Beton (Açık alanda) | D9: m³ | E9: 1734 | F9: 17500 | G9: =+E9*F9 -> 30345000
A10: 9 | B10: 006.A | C10: 125 mm Delik İçine 14 mm Kalınlığında S420a ile Zemin Çivisi Teşkili | D10: m | E10: 1884 | F10: 1050 | G10: =+E10*F10 -> 1978200
A11: 10 | B11: 006.B | C11: 125 mm Delik İçine 26 mm Kalınlığında S420a ile Zemin Çivisi Teşkili | D11: m | E11: 960 | F11: 1200 | G11: =+E11*F11 -> 1152000
A12: 11 | B12: 007.A | C12: L=3 m Kaya Bulonu | D12: adet | E12: 530 | F12: 2475 | G12: =+E12*F12 -> 1311750
A13: 12 | B13: 007.B | C13: L=4 m Kaya Bulonu | D13: adet | E13: 408 | F13: 3900 | G13: =+E13*F13 -> 1591200
... A49: 48 | B49: 017.E | C49: Halkalı Üniversite İstasyonu Mimari ve İnce İşleri Tasarım Hizmetleri | D49: set | E49: 1 | F49: 4205377 | G49: =+E49*F49 -> 4205377
A50: 49 | B50: 018 | C50: Geleneksel (NATM) Tünel Kazısı | D50: m³ | E50: 186392.65 | F50: 5075 | G50: =+E50*F50 -> 9.459427e+08 | H50: =+İcmal!M20 -> 83.764
A51: 50 | B51: 019.A | C51: Kazıdan çıkan veya Ariyetten alınan malzeme ile geri dolgu yapılması | D51: m³ | E51: 910 | F51: 600 | G51: =+E51*F51 -> 546000 | H51: =+İcmal!M21 -> 0
A52: 51 | B52: 019.B | C52: Kum, Çakıl, Kırma Tas ve Benzeri Malzeme ile Dolgu Yapılması | D52: m³ | E52: 1785 | F52: 1500 | G52: =+E52*F52 -> 2677500 | H52: =+İcmal!M22 -> 0
A53: 52 | B53: 020 | C53: Püskürtme Beton (Tünel ve Şaftlarda) | D53: m³ | E53: 38798.59 | F53: 15334 | G53: =+E53*F53 -> 5.9493758e+08 | H53: =+İcmal!M23 -> 21.932
A54: 53 | B54: 021.A | C54: Delgi boyu =< 30m | D54: m | E54: 19569.89 | F54: 248 | G54: =+E54*F54 -> 4853332.7 | H54: =+İcmal!M24 -> 0
A55: 54 | B55: 021.B | C55: Delgi boyu > 30m | D55: m | E55: 10655.78 | F55: 371 | G55: =+E55*F55 -> 3953294.4 | H55: =+İcmal!M25 -> 0
A56: 55 | B56: 022.A | C56: L=3 m Kaya Bulonu | D56: adet | E56: 800 | F56: 2250 | G56: =+E56*F56 -> 1800000 | H56: =+İcmal!M26 -> 0
A57: 56 | B57: 022.B | C57: L=4 m Kaya Bulonu | D57: adet | E57: 2466.42 | F57: 8000 | G57: =+E57*F57 -> 19731360 | H57: =+İcmal!M27 -> 0
A58: 57 | B58: 022.C | C58: L=5 m Kaya Bulonu | D58: adet | E58: 2401.3 | F58: 8288 | G58: =+E58*F58 -> 19901974 | H58: =+İcmal!M28 -> 0
A59: 58 | B59: 022.D | C59: L=6 m Kaya Bulonu | D59: adet | E59: 2970 | F59: 12000 | G59: =+E59*F59 -> 35640000 | H59: =+İcmal!M29 -> 0
A60: 59 | B60: 022.E | C60: L=8 m Kaya Bulonu | D60: adet | E60: 7008.23 | F60: 28000 | G60: =+E60*F60 -> 196230440 | H60: =+İcmal!M30 -> 44
A61: 60 | B61: 023.A | C61: 125 mm Delik İçine 14 mm Kalınlığında S420a ile Zemin Çivisi Teşkili | D61: m | E61: 156606.89 | F61: 375 | G61: =+E61*F61 -> 58727584 | H61: =+İcmal!M31 -> 0
... A79: 78 | B79: 030.E | C79: Block-out Kutusu | D79: kg | E79: 4500 | F79: 180 | G79: =+E79*F79 -> 810000 | H79: =+İcmal!M49 -> 0
A80: 79 | B80: 031 | C80: TBM/EPB Tünel İnşaatı | D80: m | E80: 8960.47 | F80: 340200 | G80: =+E80*F80 -> 3048351894
A81: 80 | B81: 032 | C81: Araştırma Sondajı Yapılması ve Raporları | D81: m | E81: 2750 | F81: 3750 | G81: =+E81*F81 -> 10312500
A82: 81 | B82: 033 | C82: Geomekanik İzleme Aletleri temini ve montajı | D82: set | E82: 1 | F82: 108000000 | G82: =+E82*F82 -> 108000000
A83: 82 | B83: 034 | C83: Geomekanik İzleme için ölçümlerin okunması, işlenmesi, sunumu ve değerlendirilmesi | D83: set | E83: 1 | F83: 42000000 | G83: =+E83*F83 -> 42000000
A84: 83 | B84: 101 | C84: Çimento Esaslı Sürme Su Yalıtımı Yapılması | D84: m² | E84: 3033.68 | F84: 1040 | G84: =+E84*F84 -> 3155027.2
A85: 84 | B85: 102 | C85: SCR.01 - Şap | D85: m² | E85: 23957.52 | F85: 988 | G85: =+E85*F85 -> 23670030
A86: 85 | B86: 103 | C86: Tesviye Tabakası Yapılması | D86: m³ | E86: 958.3 | F86: 4072 | G86: =+E86*F86 -> 3902197.6
A87: 86 | B87: 104.A | C87: PA.01 - 60x60 granit seramik zemin kaplama- Gri (RAL 7026) | D87: m² | E87: 23920.44 | F87: 1849 | G87: =+E87*F87 -> 44228894
A88: 87 | B88: 104.B | C88: PA.02 - 30x30 granit seramik zemin kaplama- Gri (RAL 7026) | D88: m² | E88: 3058.14 | F88: 1849 | G88: =+E88*F88 -> 5654500.9
A89: 88 | B89: 104.C | C89: PA.02B - 30x30 granit seramik duvar kaplama- Gri (RAL 7026) | D89: m² | E89: 3419.9 | F89: 1849 | G89: =+E89*F89 -> 6323395.1
A90: 89 | B90: 105.A | C90: PA.03 - 40x40cm Açık Gri Porselen Karo (Granit seramik)- Dur İkaz/uyarı karosu , Seramik Yapıştırma Harcı dahil | D90: m² | E90: 880.44 | F90: 3999 | G90: =+E90*F90 -> 3520879.6
A91: 90 | B91: 105.B | C91: PA.04 - 40x40cm Açık Gri Porselen Karo (Granit seramik)- Klavuz/yönlendirme Seramik Yapıştırma Harcı | D91: m² | E91: 1076.47 | F91: 3999 | G91: =+E91*F91 -> 4304803.5
... A483: 482 | B483: 1200 | C483: Faturalı Giderler | D483: adet | E483: 1 | F483: 75000000 | G483: =+E483*F483 -> 75000000
...
