Workbook
Name AMN_PRV: Metraj!$AC$2
Name AMN_THS: Metraj!$AD$2
Name AMN_TOT: Metraj!$AE$2

Sheet Kapak
A5: T.C.
A6: İSTANBUL BÜYÜKŞEHİR BELEDİYESİ
A7: Raylı Sistem Dairesi Başkanlığı Avrupa Yakası Raylı Sistem Şube Müdürlüğü
A12: Kirazlı-Halkalı Üniversite Metro Hattı İnşaat Ve Elektromekanik İşler İle M1 Hattı Elektromekanik Sistemleri Yapım İşi
A24: =+İcmal!C15 -> 6
A28: Barbaros İstasyonu Hat - 2 Kirazlı Yönü P1 Tüneli 4.Aşama
A33: METRAJLAR

Sheet İcmal
N1: =+Liste!H485 -> 20807278
A5: T.C.
A6: İSTANBUL BÜYÜKŞEHİR BELEDİYESİ
A7: Raylı Sistem Dairesi Başkanlığı Avrupa Yakası Raylı Sistem Şube Müdürlüğü
A10: Kirazlı-Halkalı Üniversite Metro Hattı İnşaat Ve Elektromekanik İşler İle M1 Hattı Elektromekanik Sistemleri Yapım İşi
A12: =+Kapak!A28 -> Barbaros İstasyonu Hat - 2 Kirazlı Yönü P1 Tüneli 4.Aşama
B15: Hakediş No: | C15: =+[3]Veri!$C$21 -> 6
B16: Hakediş Tarihi: | C16: =+[3]Veri!$C$22 -> 46142
O18: Dönem | P18: Dönem | Q18: Dönem | R18: Dönem | S18: Dönem | T18: Dönem | U18: Dönem | V18: Dönem | W18: Dönem | X18: Dönem | Y18: Dönem | Z18: Dönem | AA18: Dönem | AB18: Dönem | AC18: Dönem | AD18: Dönem | AE18: Dönem | AF18: Dönem | AG18: Dönem | AH18: Dönem
B19: POZ NO | C19: BİRİM FİYAT ADI | I19: BİRİM | J19: ÖNCEKİ HAKEDİŞ MİKTARI | K19: BU HAKEDİŞ MİKTARI | L19: TOPLAM HAKEDİŞ MİKTARI | O19: 0525 | P19: 0625 | Q19: 0725 | R19: 0825 | S19: 0925 | T19: 1025 | U19: 1125 | V19: 1225 | W19: 0126 | X19: 0226 | Y19: 0326 | Z19: 0426 | AA19: 0526 | AB19: 0626 | AC19: 0726 | AD19: 0826 | AE19: 0926 | AF19: 1026 | AG19: 1126 | AH19: 1226
B20: 018 | C20: =+VLOOKUP(B20,Liste!B:E,2,FALSE) -> Geleneksel (NATM) Tünel Kazısı | I20: m³ | J20: 799.034 | K20: =+L20-J20 -> 158.213 | L20: =+IFERROR(VLOOKUP(B20,Metraj!B:P,15,FALSE),"0") -> 957.247 | W20: 191.908 | X20: 528.145 | Y20: 78.981 | Z20: =$L20-SUM($O20:Y20) -> 158.213 | AA20: =$L20-SUM($O20:Z20) -> 0 | AB20: =$L20-SUM($O20:AA20) -> 0 | AC20: =$L20-SUM($O20:AB20) -> 0 | AD20: =$L20-SUM($O20:AC20) -> 0 | AE20: =$L20-SUM($O20:AD20) -> 0 | AF20: =$L20-SUM($O20:AE20) -> 0 | AG20: =$L20-SUM($O20:AF20) -> 0 | AH20: =$L20-SUM($O20:AG20) -> 0
B21: 019.A | C21: =+VLOOKUP(B21,Liste!B:E,2,FALSE) -> Kazıdan çıkan veya Ariyetten alınan malzeme ile geri dolgu yapılması | I21: m³ | K21: =+L21-J21 -> #VALUE! | L21: =+IFERROR(VLOOKUP(B21,Metraj!B:P,15,FALSE),"") | W21: 0 | X21: 0 | Y21: 0 | Z21: =+IFERROR($L21-SUM($O21:Y21),0) -> 0 | AA21: =+IFERROR($L21-SUM($O21:Z21),0) -> 0 | AB21: =+IFERROR($L21-SUM($O21:AA21),0) -> 0 | AC21: =+IFERROR($L21-SUM($O21:AB21),0) -> 0 | AD21: =+IFERROR($L21-SUM($O21:AC21),0) -> 0 | AE21: =+IFERROR($L21-SUM($O21:AD21),0) -> 0 | AF21: =+IFERROR($L21-SUM($O21:AE21),0) -> 0 | AG21: =+IFERROR($L21-SUM($O21:AF21),0) -> 0 | AH21: =+IFERROR($L21-SUM($O21:AG21),0) -> 0
B22: 019.B | C22: =+VLOOKUP(B22,Liste!B:E,2,FALSE) -> Kum, Çakıl, Kırma Tas ve Benzeri Malzeme ile Dolgu Yapılması | I22: m³ | K22: =+L22-J22 -> #VALUE! | L22: =+IFERROR(VLOOKUP(B22,Metraj!B:P,15,FALSE),"") | W22: 0 | X22: 0 | Y22: 0 | Z22: =+IFERROR($L22-SUM($O22:Y22),0) -> 0 | AA22: =+IFERROR($L22-SUM($O22:Z22),0) -> 0 | AB22: =+IFERROR($L22-SUM($O22:AA22),0) -> 0 | AC22: =+IFERROR($L22-SUM($O22:AB22),0) -> 0 | AD22: =+IFERROR($L22-SUM($O22:AC22),0) -> 0 | AE22: =+IFERROR($L22-SUM($O22:AD22),0) -> 0 | AF22: =+IFERROR($L22-SUM($O22:AE22),0) -> 0 | AG22: =+IFERROR($L22-SUM($O22:AF22),0) -> 0 | AH22: =+IFERROR($L22-SUM($O22:AG22),0) -> 0
B23: 020 | C23: =+VLOOKUP(B23,Liste!B:E,2,FALSE) -> Püskürtme Beton (Tünel ve Şaftlarda) | I23: m³ | J23: 141.551 | K23: =+L23-J23 -> 27.158 | L23: =+IFERROR(VLOOKUP(B23,Metraj!B:P,15,FALSE),"0") -> 168.709 | W23: 33.459 | X23: 82.066 | Y23: 26.026 | Z23: =$L23-SUM($O23:Y23) -> 27.158 | AA23: =$L23-SUM($O23:Z23) -> 0 | AB23: =$L23-SUM($O23:AA23) -> 0 | AC23: =$L23-SUM($O23:AB23) -> 0 | AD23: =$L23-SUM($O23:AC23) -> 0 | AE23: =$L23-SUM($O23:AD23) -> 0 | AF23: =$L23-SUM($O23:AE23) -> 0 | AG23: =$L23-SUM($O23:AF23) -> 0 | AH23: =$L23-SUM($O23:AG23) -> 0
B24: 021.A | C24: =+VLOOKUP(B24,Liste!B:E,2,FALSE) -> Delgi boyu =< 30m | I24: m | K24: =+L24-J24 -> #VALUE! | L24: =+IFERROR(VLOOKUP(B24,Metraj!B:P,15,FALSE),"") | W24: 0 | X24: 0 | Y24: 0 | Z24: =+IFERROR($L24-SUM($O24:Y24),0) -> 0 | AA24: =+IFERROR($L24-SUM($O24:Z24),0) -> 0 | AB24: =+IFERROR($L24-SUM($O24:AA24),0) -> 0 | AC24: =+IFERROR($L24-SUM($O24:AB24),0) -> 0 | AD24: =+IFERROR($L24-SUM($O24:AC24),0) -> 0 | AE24: =+IFERROR($L24-SUM($O24:AD24),0) -> 0 | AF24: =+IFERROR($L24-SUM($O24:AE24),0) -> 0 | AG24: =+IFERROR($L24-SUM($O24:AF24),0) -> 0 | AH24: =+IFERROR($L24-SUM($O24:AG24),0) -> 0
B25: 021.B | C25: =+VLOOKUP(B25,Liste!B:E,2,FALSE) -> Delgi boyu > 30m | I25: m | K25: =+L25-J25 -> #VALUE! | L25: =+IFERROR(VLOOKUP(B25,Metraj!B:P,15,FALSE),"") | W25: 0 | X25: 0 | Y25: 0 | Z25: =+IFERROR($L25-SUM($O25:Y25),0) -> 0 | AA25: =+IFERROR($L25-SUM($O25:Z25),0) -> 0 | AB25: =+IFERROR($L25-SUM($O25:AA25),0) -> 0 | AC25: =+IFERROR($L25-SUM($O25:AB25),0) -> 0 | AD25: =+IFERROR($L25-SUM($O25:AC25),0) -> 0 | AE25: =+IFERROR($L25-SUM($O25:AD25),0) -> 0 | AF25: =+IFERROR($L25-SUM($O25:AE25),0) -> 0 | AG25: =+IFERROR($L25-SUM($O25:AF25),0) -> 0 | AH25: =+IFERROR($L25-SUM($O25:AG25),0) -> 0
B26: 022.A | C26: =+VLOOKUP(B26,Liste!B:E,2,FALSE) -> L=3 m Kaya Bulonu | I26: adet | K26: =+L26-J26 -> #VALUE! | L26: =+IFERROR(VLOOKUP(B26,Metraj!B:P,15,FALSE),"") | W26: 0 | X26: 0 | Y26: 0 | Z26: =+IFERROR($L26-SUM($O26:Y26),0) -> 0 | AA26: =+IFERROR($L26-SUM($O26:Z26),0) -> 0 | AB26: =+IFERROR($L26-SUM($O26:AA26),0) -> 0 | AC26: =+IFERROR($L26-SUM($O26:AB26),0) -> 0 | AD26: =+IFERROR($L26-SUM($O26:AC26),0) -> 0 | AE26: =+IFERROR($L26-SUM($O26:AD26),0) -> 0 | AF26: =+IFERROR($L26-SUM($O26:AE26),0) -> 0 | AG26: =+IFERROR($L26-SUM($O26:AF26),0) -> 0 | AH26: =+IFERROR($L26-SUM($O26:AG26),0) -> 0
B27: 022.B | C27: =+VLOOKUP(B27,Liste!B:E,2,FALSE) -> L=4 m Kaya Bulonu | I27: adet | J27: 0 | K27: =+L27-J27 -> 0 | L27: =+IFERROR(VLOOKUP(B27,Metraj!B:P,15,FALSE),"0") -> 0 | W27: 0 | X27: 0 | Y27: 0 | Z27: =$L27-SUM($O27:Y27) -> 0 | AA27: =$L27-SUM($O27:Z27) -> 0 | AB27: =$L27-SUM($O27:AA27) -> 0 | AC27: =$L27-SUM($O27:AB27) -> 0 | AD27: =$L27-SUM($O27:AC27) -> 0 | AE27: =$L27-SUM($O27:AD27) -> 0 | AF27: =$L27-SUM($O27:AE27) -> 0 | AG27: =$L27-SUM($O27:AF27) -> 0 | AH27: =$L27-SUM($O27:AG27) -> 0
B28: 022.C | C28: =+VLOOKUP(B28,Liste!B:E,2,FALSE) -> L=5 m Kaya Bulonu | I28: adet | K28: =+L28-J28 -> #VALUE! | L28: =+IFERROR(VLOOKUP(B28,Metraj!B:P,15,FALSE),"") | W28: 0 | X28: 0 | Y28: 0 | Z28: =+IFERROR($L28-SUM($O28:Y28),0) -> 0 | AA28: =+IFERROR($L28-SUM($O28:Z28),0) -> 0 | AB28: =+IFERROR($L28-SUM($O28:AA28),0) -> 0 | AC28: =+IFERROR($L28-SUM($O28:AB28),0) -> 0 | AD28: =+IFERROR($L28-SUM($O28:AC28),0) -> 0 | AE28: =+IFERROR($L28-SUM($O28:AD28),0) -> 0 | AF28: =+IFERROR($L28-SUM($O28:AE28),0) -> 0 | AG28: =+IFERROR($L28-SUM($O28:AF28),0) -> 0 | AH28: =+IFERROR($L28-SUM($O28:AG28),0) -> 0
B29: 022.D | C29: =+VLOOKUP(B29,Liste!B:E,2,FALSE) -> L=6 m Kaya Bulonu | I29: adet | K29: =+L29-J29 -> #VALUE! | L29: =+IFERROR(VLOOKUP(B29,Metraj!B:P,15,FALSE),"") | W29: 0 | X29: 0 | Y29: 0 | Z29: =+IFERROR($L29-SUM($O29:Y29),0) -> 0 | AA29: =+IFERROR($L29-SUM($O29:Z29),0) -> 0 | AB29: =+IFERROR($L29-SUM($O29:AA29),0) -> 0 | AC29: =+IFERROR($L29-SUM($O29:AB29),0) -> 0 | AD29: =+IFERROR($L29-SUM($O29:AC29),0) -> 0 | AE29: =+IFERROR($L29-SUM($O29:AD29),0) -> 0 | AF29: =+IFERROR($L29-SUM($O29:AE29),0) -> 0 | AG29: =+IFERROR($L29-SUM($O29:AF29),0) -> 0 | AH29: =+IFERROR($L29-SUM($O29:AG29),0) -> 0
B30: 022.E | C30: =+VLOOKUP(B30,Liste!B:E,2,FALSE) -> L=8 m Kaya Bulonu | I30: adet | J30: 270 | K30: =+L30-J30 -> 0 | L30: =+IFERROR(VLOOKUP(B30,Metraj!B:P,15,FALSE),"0") -> 270 | W30: 18 | X30: 171 | Y30: 81 | Z30: =$L30-SUM($O30:Y30) -> 0 | AA30: =$L30-SUM($O30:Z30) -> 0 | AB30: =$L30-SUM($O30:AA30) -> 0 | AC30: =$L30-SUM($O30:AB30) -> 0 | AD30: =$L30-SUM($O30:AC30) -> 0 | AE30: =$L30-SUM($O30:AD30) -> 0 | AF30: =$L30-SUM($O30:AE30) -> 0 | AG30: =$L30-SUM($O30:AF30) -> 0 | AH30: =$L30-SUM($O30:AG30) -> 0
B31: 023.A | C31: =+VLOOKUP(B31,Liste!B:E,2,FALSE) -> 125 mm Delik İçine 14 mm Kalınlığında S420a ile Zemin Çivisi Teşkili | I31: m | J31: 0 | K31: =+L31-J31 -> 0 | L31: =+IFERROR(VLOOKUP(B31,Metraj!B:P,15,FALSE),"0") -> 0 | W31: 0 | X31: 0 | Y31: 0 | Z31: =$L31-SUM($O31:Y31) -> 0 | AA31: =$L31-SUM($O31:Z31) -> 0 | AB31: =$L31-SUM($O31:AA31) -> 0 | AC31: =$L31-SUM($O31:AB31) -> 0 | AD31: =$L31-SUM($O31:AC31) -> 0 | AE31: =$L31-SUM($O31:AD31) -> 0 | AF31: =$L31-SUM($O31:AE31) -> 0 | AG31: =$L31-SUM($O31:AF31) -> 0 | AH31: =$L31-SUM($O31:AG31) -> 0
B32: 023.B | C32: =+VLOOKUP(B32,Liste!B:E,2,FALSE) -> 125 mm Delik İçine 26 mm Kalınlığında S420a ile Zemin Çivisi Teşkili | I32: m | K32: =+L32-J32 -> #VALUE! | L32: =+IFERROR(VLOOKUP(B32,Metraj!B:P,15,FALSE),"") | W32: 0 | X32: 0 | Y32: 0 | Z32: =+IFERROR($L32-SUM($O32:Y32),0) -> 0 | AA32: =+IFERROR($L32-SUM($O32:Z32),0) -> 0 | AB32: =+IFERROR($L32-SUM($O32:AA32),0) -> 0 | AC32: =+IFERROR($L32-SUM($O32:AB32),0) -> 0 | AD32: =+IFERROR($L32-SUM($O32:AC32),0) -> 0 | AE32: =+IFERROR($L32-SUM($O32:AD32),0) -> 0 | AF32: =+IFERROR($L32-SUM($O32:AE32),0) -> 0 | AG32: =+IFERROR($L32-SUM($O32:AF32),0) -> 0 | AH32: =+IFERROR($L32-SUM($O32:AG32),0) -> 0
B33: 024 | C33: =+VLOOKUP(B33,Liste!B:E,2,FALSE) -> Çelik İksa (Tünel ve Şaftlarda) | I33: ton | J33: 41.752 | K33: =+L33-J33 -> 2.752 | L33: =+IFERROR(VLOOKUP(B33,Metraj!B:P,15,FALSE),"0") -> 44.504 | W33: 10.125 | X33: 27.52 | Y33: 4.107 | Z33: =$L33-SUM($O33:Y33) -> 2.752 | AA33: =$L33-SUM($O33:Z33) -> 0 | AB33: =$L33-SUM($O33:AA33) -> 0 | AC33: =$L33-SUM($O33:AB33) -> 0 | AD33: =$L33-SUM($O33:AC33) -> 0 | AE33: =$L33-SUM($O33:AD33) -> 0 | AF33: =$L33-SUM($O33:AE33) -> 0 | AG33: =$L33-SUM($O33:AF33) -> 0 | AH33: =$L33-SUM($O33:AG33) -> 0
B34: 025 | C34: =+VLOOKUP(B34,Liste!B:E,2,FALSE) -> Umbrella Arch Yapılması | I34: m | J34: 0 | K34: =+L34-J34 -> 0 | L34: =+IFERROR(VLOOKUP(B34,Metraj!B:P,15,FALSE),"0") -> 0 | W34: 0 | X34: 0 | Y34: 0 | Z34: =$L34-SUM($O34:Y34) -> 0 | AA34: =$L34-SUM($O34:Z34) -> 0 | AB34: =$L34-SUM($O34:AA34) -> 0 | AC34: =$L34-SUM($O34:AB34) -> 0 | AD34: =$L34-SUM($O34:AC34) -> 0 | AE34: =$L34-SUM($O34:AD34) -> 0 | AF34: =$L34-SUM($O34:AE34) -> 0 | AG34: =$L34-SUM($O34:AF34) -> 0 | AH34: =$L34-SUM($O34:AG34) -> 0
B35: 026.A | C35: =+VLOOKUP(B35,Liste!B:E,2,FALSE) -> Tünel ve şaftlarda su yalıtımı, birim ağırlığı >=500 g/metrekare geotekstil keçe | I35: m² | K35: =+L35-J35 -> #VALUE! | L35: =+IFERROR(VLOOKUP(B35,Metraj!B:P,15,FALSE),"") | W35: 0 | X35: 0 | Y35: 0 | Z35: =+IFERROR($L35-SUM($O35:Y35),0) -> 0 | AA35: =+IFERROR($L35-SUM($O35:Z35),0) -> 0 | AB35: =+IFERROR($L35-SUM($O35:AA35),0) -> 0 | AC35: =+IFERROR($L35-SUM($O35:AB35),0) -> 0 | AD35: =+IFERROR($L35-SUM($O35:AC35),0) -> 0 | AE35: =+IFERROR($L35-SUM($O35:AD35),0) -> 0 | AF35: =+IFERROR($L35-SUM($O35:AE35),0) -> 0 | AG35: =+IFERROR($L35-SUM($O35:AF35),0) -> 0 | AH35: =+IFERROR($L35-SUM($O35:AG35),0) -> 0
B36: 026.B | C36: =+VLOOKUP(B36,Liste!B:E,2,FALSE) -> Tünel ve şaftlarda su yalıtımı, 2mm kalınlıklı PVC membran | I36: m² | K36: =+L36-J36 -> #VALUE! | L36: =+IFERROR(VLOOKUP(B36,Metraj!B:P,15,FALSE),"") | W36: 0 | X36: 0 | Y36: 0 | Z36: =+IFERROR($L36-SUM($O36:Y36),0) -> 0 | AA36: =+IFERROR($L36-SUM($O36:Z36),0) -> 0 | AB36: =+IFERROR($L36-SUM($O36:AA36),0) -> 0 | AC36: =+IFERROR($L36-SUM($O36:AB36),0) -> 0 | AD36: =+IFERROR($L36-SUM($O36:AC36),0) -> 0 | AE36: =+IFERROR($L36-SUM($O36:AD36),0) -> 0 | AF36: =+IFERROR($L36-SUM($O36:AE36),0) -> 0 | AG36: =+IFERROR($L36-SUM($O36:AF36),0) -> 0 | AH36: =+IFERROR($L36-SUM($O36:AG36),0) -> 0
B37: 027 | C37: =+VLOOKUP(B37,Liste!B:E,2,FALSE) -> Su Tutucular (Tünel ve Şaftlarda) | I37: m | K37: =+L37-J37 -> #VALUE! | L37: =+IFERROR(VLOOKUP(B37,Metraj!B:P,15,FALSE),"") | W37: 0 | X37: 0 | Y37: 0 | Z37: =+IFERROR($L37-SUM($O37:Y37),0) -> 0 | AA37: =+IFERROR($L37-SUM($O37:Z37),0) -> 0 | AB37: =+IFERROR($L37-SUM($O37:AA37),0) -> 0 | AC37: =+IFERROR($L37-SUM($O37:AB37),0) -> 0 | AD37: =+IFERROR($L37-SUM($O37:AC37),0) -> 0 | AE37: =+IFERROR($L37-SUM($O37:AD37),0) -> 0 | AF37: =+IFERROR($L37-SUM($O37:AE37),0) -> 0 | AG37: =+IFERROR($L37-SUM($O37:AF37),0) -> 0 | AH37: =+IFERROR($L37-SUM($O37:AG37),0) -> 0
B38: 028.A | C38: =+VLOOKUP(B38,Liste!B:E,2,FALSE) -> Kalıp (invert ve şaft için) | I38: m² | K38: =+L38-J38 -> #VALUE! | L38: =+IFERROR(VLOOKUP(B38,Metraj!B:P,15,FALSE),"") | W38: 0 | X38: 0 | Y38: 0 | Z38: =+IFERROR($L38-SUM($O38:Y38),0) -> 0 | AA38: =+IFERROR($L38-SUM($O38:Z38),0) -> 0 | AB38: =+IFERROR($L38-SUM($O38:AA38),0) -> 0 | AC38: =+IFERROR($L38-SUM($O38:AB38),0) -> 0 | AD38: =+IFERROR($L38-SUM($O38:AC38),0) -> 0 | AE38: =+IFERROR($L38-SUM($O38:AD38),0) -> 0 | AF38: =+IFERROR($L38-SUM($O38:AE38),0) -> 0 | AG38: =+IFERROR($L38-SUM($O38:AF38),0) -> 0 | AH38: =+IFERROR($L38-SUM($O38:AG38),0) -> 0
B39: 028.B | C39: =+VLOOKUP(B39,Liste!B:E,2,FALSE) -> Kalıp (duvar ve kemer İçin) | I39: m² | K39: =+L39-J39 -> #VALUE! | L39: =+IFERROR(VLOOKUP(B39,Metraj!B:P,15,FALSE),"") | W39: 0 | X39: 0 | Y39: 0 | Z39: =+IFERROR($L39-SUM($O39:Y39),0) -> 0 | AA39: =+IFERROR($L39-SUM($O39:Z39),0) -> 0 | AB39: =+IFERROR($L39-SUM($O39:AA39),0) -> 0 | AC39: =+IFERROR($L39-SUM($O39:AB39),0) -> 0 | AD39: =+IFERROR($L39-SUM($O39:AC39),0) -> 0 | AE39: =+IFERROR($L39-SUM($O39:AD39),0) -> 0 | AF39: =+IFERROR($L39-SUM($O39:AE39),0) -> 0 | AG39: =+IFERROR($L39-SUM($O39:AF39),0) -> 0 | AH39: =+IFERROR($L39-SUM($O39:AG39),0) -> 0
B40: 028.C | C40: =+VLOOKUP(B40,Liste!B:E,2,FALSE) -> Tip Kesit Dışı Konstrüksiyon Kalıbı, Tünel Alın Kalıbı | I40: m² | K40: =+L40-J40 -> #VALUE! | L40: =+IFERROR(VLOOKUP(B40,Metraj!B:P,15,FALSE),"") | W40: 0 | X40: 0 | Y40: 0 | Z40: =+IFERROR($L40-SUM($O40:Y40),0) -> 0 | AA40: =+IFERROR($L40-SUM($O40:Z40),0) -> 0 | AB40: =+IFERROR($L40-SUM($O40:AA40),0) -> 0 | AC40: =+IFERROR($L40-SUM($O40:AB40),0) -> 0 | AD40: =+IFERROR($L40-SUM($O40:AC40),0) -> 0 | AE40: =+IFERROR($L40-SUM($O40:AD40),0) -> 0 | AF40: =+IFERROR($L40-SUM($O40:AE40),0) -> 0 | AG40: =+IFERROR($L40-SUM($O40:AF40),0) -> 0 | AH40: =+IFERROR($L40-SUM($O40:AG40),0) -> 0
B41: 029.A | C41: =+VLOOKUP(B41,Liste!B:E,2,FALSE) -> C16 Beton İmali ve Dökülmesi (Tünel ve Şaftlarda) | I41: m³ | K41: =+L41-J41 -> #VALUE! | L41: =+IFERROR(VLOOKUP(B41,Metraj!B:P,15,FALSE),"") | W41: 0 | X41: 0 | Y41: 0 | Z41: =+IFERROR($L41-SUM($O41:Y41),0) -> 0 | AA41: =+IFERROR($L41-SUM($O41:Z41),0) -> 0 | AB41: =+IFERROR($L41-SUM($O41:AA41),0) -> 0 | AC41: =+IFERROR($L41-SUM($O41:AB41),0) -> 0 | AD41: =+IFERROR($L41-SUM($O41:AC41),0) -> 0 | AE41: =+IFERROR($L41-SUM($O41:AD41),0) -> 0 | AF41: =+IFERROR($L41-SUM($O41:AE41),0) -> 0 | AG41: =+IFERROR($L41-SUM($O41:AF41),0) -> 0 | AH41: =+IFERROR($L41-SUM($O41:AG41),0) -> 0
B42: 029.B | C42: =+VLOOKUP(B42,Liste!B:E,2,FALSE) -> C30 Beton İmali ve Dökülmesi (Tünel ve Şaftlarda) Tünel kaplaması, invert ve şaftlardaki alt döşeme | I42: m³ | K42: =+L42-J42 -> #VALUE! | L42: =+IFERROR(VLOOKUP(B42,Metraj!B:P,15,FALSE),"") | W42: 0 | X42: 0 | Y42: 0 | Z42: =+IFERROR($L42-SUM($O42:Y42),0) -> 0 | AA42: =+IFERROR($L42-SUM($O42:Z42),0) -> 0 | AB42: =+IFERROR($L42-SUM($O42:AA42),0) -> 0 | AC42: =+IFERROR($L42-SUM($O42:AB42),0) -> 0 | AD42: =+IFERROR($L42-SUM($O42:AC42),0) -> 0 | AE42: =+IFERROR($L42-SUM($O42:AD42),0) -> 0 | AF42: =+IFERROR($L42-SUM($O42:AE42),0) -> 0 | AG42: =+IFERROR($L42-SUM($O42:AF42),0) -> 0 | AH42: =+IFERROR($L42-SUM($O42:AG42),0) -> 0
B43: 029.C | C43: =+VLOOKUP(B43,Liste!B:E,2,FALSE) -> C30 Beton İmali ve Dökülmesi (Tünel ve Şaftlarda) Yan duvarlar, kemer | I43: m³ | K43: =+L43-J43 -> #VALUE! | L43: =+IFERROR(VLOOKUP(B43,Metraj!B:P,15,FALSE),"") | W43: 0 | X43: 0 | Y43: 0 | Z43: =+IFERROR($L43-SUM($O43:Y43),0) -> 0 | AA43: =+IFERROR($L43-SUM($O43:Z43),0) -> 0 | AB43: =+IFERROR($L43-SUM($O43:AA43),0) -> 0 | AC43: =+IFERROR($L43-SUM($O43:AB43),0) -> 0 | AD43: =+IFERROR($L43-SUM($O43:AC43),0) -> 0 | AE43: =+IFERROR($L43-SUM($O43:AD43),0) -> 0 | AF43: =+IFERROR($L43-SUM($O43:AE43),0) -> 0 | AG43: =+IFERROR($L43-SUM($O43:AF43),0) -> 0 | AH43: =+IFERROR($L43-SUM($O43:AG43),0) -> 0
B44: 029.D | C44: =+VLOOKUP(B44,Liste!B:E,2,FALSE) -> Diğer Kesit Dışındaki Yapıların Betonu C30 | I44: m³ | K44: =+L44-J44 -> #VALUE! | L44: =+IFERROR(VLOOKUP(B44,Metraj!B:P,15,FALSE),"") | W44: 0 | X44: 0 | Y44: 0 | Z44: =+IFERROR($L44-SUM($O44:Y44),0) -> 0 | AA44: =+IFERROR($L44-SUM($O44:Z44),0) -> 0 | AB44: =+IFERROR($L44-SUM($O44:AA44),0) -> 0 | AC44: =+IFERROR($L44-SUM($O44:AB44),0) -> 0 | AD44: =+IFERROR($L44-SUM($O44:AC44),0) -> 0 | AE44: =+IFERROR($L44-SUM($O44:AD44),0) -> 0 | AF44: =+IFERROR($L44-SUM($O44:AE44),0) -> 0 | AG44: =+IFERROR($L44-SUM($O44:AF44),0) -> 0 | AH44: =+IFERROR($L44-SUM($O44:AG44),0) -> 0
B45: 030.A | C45: =+VLOOKUP(B45,Liste!B:E,2,FALSE) -> Çelik Donatı (S220 ) | I45: ton | J45: 0.626 | K45: =+L45-J45 -> 0.034 | L45: =+IFERROR(VLOOKUP(B45,Metraj!B:P,15,FALSE),"0") -> 0.66 | W45: 0.151 | X45: 0.413 | Y45: 0.062 | Z45: =$L45-SUM($O45:Y45) -> 0.034 | AA45: =$L45-SUM($O45:Z45) -> 0 | AB45: =$L45-SUM($O45:AA45) -> 0 | AC45: =$L45-SUM($O45:AB45) -> 0 | AD45: =$L45-SUM($O45:AC45) -> 0 | AE45: =$L45-SUM($O45:AD45) -> 0 | AF45: =$L45-SUM($O45:AE45) -> 0 | AG45: =$L45-SUM($O45:AF45) -> 0 | AH45: =$L45-SUM($O45:AG45) -> 0
B46: 030.B | C46: =+VLOOKUP(B46,Liste!B:E,2,FALSE) -> Çelik Donatı (S420a ) | I46: ton | J46: 0 | K46: =+L46-J46 -> 0 | L46: =+IFERROR(VLOOKUP(B46,Metraj!B:P,15,FALSE),"") -> 0 | W46: 0 | X46: 0 | Y46: 0 | Z46: =+IFERROR($L46-SUM($O46:Y46),0) -> 0 | AA46: =+IFERROR($L46-SUM($O46:Z46),0) -> 0 | AB46: =+IFERROR($L46-SUM($O46:AA46),0) -> 0 | AC46: =+IFERROR($L46-SUM($O46:AB46),0) -> 0 | AD46: =+IFERROR($L46-SUM($O46:AC46),0) -> 0 | AE46: =+IFERROR($L46-SUM($O46:AD46),0) -> 0 | AF46: =+IFERROR($L46-SUM($O46:AE46),0) -> 0 | AG46: =+IFERROR($L46-SUM($O46:AF46),0) -> 0 | AH46: =+IFERROR($L46-SUM($O46:AG46),0) -> 0
B47: 030.C | C47: =+VLOOKUP(B47,Liste!B:E,2,FALSE) -> Çelik hasır (S500 ) | I47: ton | J47: 10.707 | K47: =+L47-J47 -> 1.954 | L47: =+IFERROR(VLOOKUP(B47,Metraj!B:P,15,FALSE),"0") -> 12.661 | W47: 2.765 | X47: 6.906 | Y47: 1.036 | Z47: =$L47-SUM($O47:Y47) -> 1.954 | AA47: =$L47-SUM($O47:Z47) -> 0 | AB47: =$L47-SUM($O47:AA47) -> 0 | AC47: =$L47-SUM($O47:AB47) -> 0 | AD47: =$L47-SUM($O47:AC47) -> 0 | AE47: =$L47-SUM($O47:AD47) -> 0 | AF47: =$L47-SUM($O47:AE47) -> 0 | AG47: =$L47-SUM($O47:AF47) -> 0 | AH47: =$L47-SUM($O47:AG47) -> 0
B48: 030.D | C48: =+VLOOKUP(B48,Liste!B:E,2,FALSE) -> Paslanmaz Çelik Plaka | I48: kg | K48: =+L48-J48 -> #VALUE! | L48: =+IFERROR(VLOOKUP(B48,Metraj!B:P,15,FALSE),"") | W48: 0 | X48: 0 | Y48: 0 | Z48: =+IFERROR($L48-SUM($O48:Y48),0) -> 0 | AA48: =+IFERROR($L48-SUM($O48:Z48),0) -> 0 | AB48: =+IFERROR($L48-SUM($O48:AA48),0) -> 0 | AC48: =+IFERROR($L48-SUM($O48:AB48),0) -> 0 | AD48: =+IFERROR($L48-SUM($O48:AC48),0) -> 0 | AE48: =+IFERROR($L48-SUM($O48:AD48),0) -> 0 | AF48: =+IFERROR($L48-SUM($O48:AE48),0) -> 0 | AG48: =+IFERROR($L48-SUM($O48:AF48),0) -> 0 | AH48: =+IFERROR($L48-SUM($O48:AG48),0) -> 0
B49: 030.E | C49: =+VLOOKUP(B49,Liste!B:E,2,FALSE) -> Block-out Kutusu | I49: kg | K49: =+L49-J49 -> #VALUE! | L49: =+IFERROR(VLOOKUP(B49,Metraj!B:P,15,FALSE),"") | W49: 0 | X49: 0 | Y49: 0 | Z49: =+IFERROR($L49-SUM($O49:Y49),0) -> 0 | AA49: =+IFERROR($L49-SUM($O49:Z49),0) -> 0 | AB49: =+IFERROR($L49-SUM($O49:AA49),0) -> 0 | AC49: =+IFERROR($L49-SUM($O49:AB49),0) -> 0 | AD49: =+IFERROR($L49-SUM($O49:AC49),0) -> 0 | AE49: =+IFERROR($L49-SUM($O49:AD49),0) -> 0 | AF49: =+IFERROR($L49-SUM($O49:AE49),0) -> 0 | AG49: =+IFERROR($L49-SUM($O49:AF49),0) -> 0 | AH49: =+IFERROR($L49-SUM($O49:AG49),0) -> 0

Sheet Metraj
AC1: Önceki Hakediş | AD1: Bu Hakediş Tutarı | AE1: Kümülatif Hakediş
A2: T.C. | AC2: =+SUM(AC17:AC1000) -> 19115442 | AD2: =+SUM(AD17:AD1000) -> 1691836.9 | AE2: =+SUM(AE17:AE1000) -> 20807278
A3: İSTANBUL BÜYÜKŞEHİR BELEDİYESİ
A4: Raylı Sistem Dairesi Başkanlığı Avrupa Yakası Raylı Sistem Şube Müdürlüğü
A7: Kirazlı-Halkalı Üniversite Metro Hattı İnşaat Ve Elektromekanik İşler İle M1 Hattı Elektromekanik Sistemleri Yapım İşi
A9: =+Kapak!A28 -> Barbaros İstasyonu Hat - 2 Kirazlı Yönü P1 Tüneli 4.Aşama
A11: Metraj Sayfası
B13: Hakediş No: | C13: =+İcmal!C15 -> 6
B14: Hakediş Tarihi: | C14: =+İcmal!C16 -> 46142
B16: POZ NO | D16: BİRİM FİYAT ADI | M16: BİRİM | N16: ÖNCEKİ HAKEDİŞ MİKTARI | O16: BU HAKEDİŞ MİKTARI | P16: TOPLAM HAKEDİŞ MİKTARI
B17: 018 | D17: =+VLOOKUP(B17,Liste!B:E,2,FALSE) -> Geleneksel (NATM) Tünel Kazısı | M17: =+VLOOKUP(B17,Liste!B:E,3,FALSE) -> m³ | N17: 799.034 | O17: =+P17-N17 -> 158.213 | P17: =+ROUND(SUM(P18:P50),3) -> 957.247 | AA17: =+VLOOKUP(B17,[1]Liste!$B$2:$F$483,5,FALSE) -> 5075 | AC17: =+AA17*N17 -> 4055097.5 | AD17: =+AA17*O17 -> 802930.97 | AE17: =+AA17*P17 -> 4858028.5
B18: 4.Aşama İmalatları
B19: Hk No | C19: Tutanak Genel No | D19: Tutanak Özel No | H19: KM1 | I19: KM2 | J19: Yeri | K19: Benzer | L19: Boyu | M19: Açıklama | O19: Alanı | P19: Miktarı
B20: 5 | C20: 2026.01-015 | D20: S06.H2.KY.P1.A4.001 | H20: 1292.56 | I20: 1276.24 | J20: Üst Yarı | K20: 3 | L20: 0.75 | M20: P1 - 1 Nolu Tip İksa | O20: 11.385 | P20: =+ROUND(PRODUCT(K20:O20),3) -> 25.616 | S20: =+L20*K20 -> 2.25
B21: 5 | C21: 2026.01-015 | D21: S06.H2.KY.P1.A4.001 | H21: 1292.56 | I21: 1276.24 | J21: Üst Yarı | K21: 3 | L21: 0.75 | M21: P1 - 2 Nolu Tip İksa | O21: 11.709 | P21: =+ROUND(PRODUCT(K21:O21),3) -> 26.345 | S21: =+L21*K21 -> 2.25
B22: 5 | C22: 2026.01-015 | D22: S06.H2.KY.P1.A4.001 | H22: 1292.56 | I22: 1276.24 | J22: Üst Yarı | K22: 3 | L22: 0.75 | M22: P1 - 3 Nolu Tip İksa | O22: 11.793 | P22: =+ROUND(PRODUCT(K22:O22),3) -> 26.534 | S22: =+L22*K22 -> 2.25
B23: 5 | C23: 2026.01-015 | D23: S06.H2.KY.P1.A4.001 | H23: 1292.56 | I23: 1276.24 | J23: Üst Yarı | K23: 4 | L23: 0.75 | M23: P1 - 4 Nolu Tip İksa | O23: 11.767 | P23: =+ROUND(PRODUCT(K23:O23),3) -> 35.301 | S23: =+L23*K23 -> 3
B24: 5 | C24: 2026.01-015 | D24: S06.H2.KY.P1.A4.001 | H24: 1292.56 | I24: 1276.24 | J24: Üst Yarı | K24: 4 | L24: 0.75 | M24: P1 - 5 Nolu Tip İksa | O24: 11.806 | P24: =+ROUND(PRODUCT(K24:O24),3) -> 35.418 | S24: =+L24*K24 -> 3
B25: 5 | C25: 2026.01-015 | D25: S06.H2.KY.P1.A4.001 | H25: 1292.56 | I25: 1276.24 | J25: Üst Yarı | K25: 4 | L25: 0.75 | M25: P1 - 6 Nolu Tip İksa | O25: 11.959 | P25: =+ROUND(PRODUCT(K25:O25),3) -> 35.877 | S25: =+L25*K25 -> 3
B26: 5 | C26: 2026.01-015 | D26: S06.H2.KY.P1.A4.001 | H26: 1292.56 | I26: 1276.24 | J26: Üst Yarı | K26: 1 | L26: 0.57 | M26: P1 - 6 Nolu Tip İksa | O26: 11.959 | P26: =+ROUND(PRODUCT(K26:O26),3) -> 6.817 | S26: =+L26*K26 -> 0.57
B27: 5 | C27: 2026.02-004 | D27: S06.H2.KY.P1.A4.002 | H27: 1337.56 | I27: 1292.56 | J27: Üst Yarı | K27: 10 | L27: 0.75 | M27: P1 - 1 Nolu Tip İksa | O27: 11.385 | P27: =+ROUND(PRODUCT(K27:O27),3) -> 85.388 | S27: =+L27*K27 -> 7.5
B28: 5 | C28: 2026.02-004 | D28: S06.H2.KY.P1.A4.002 | H28: 1337.56 | I28: 1292.56 | J28: Üst Yarı | K28: 10 | L28: 0.75 | M28: P1 - 2 Nolu Tip İksa | O28: 11.709 | P28: =+ROUND(PRODUCT(K28:O28),3) -> 87.818 | S28: =+L28*K28 -> 7.5
B29: 5 | C29: 2026.02-004 | D29: S06.H2.KY.P1.A4.002 | H29: 1337.56 | I29: 1292.56 | J29: Üst Yarı | K29: 10 | L29: 0.75 | M29: P1 - 3 Nolu Tip İksa | O29: 11.793 | P29: =+ROUND(PRODUCT(K29:O29),3) -> 88.448 | S29: =+L29*K29 -> 7.5
B30: 5 | C30: 2026.02-004 | D30: S06.H2.KY.P1.A4.002 | H30: 1337.56 | I30: 1292.56 | J30: Üst Yarı | K30: 10 | L30: 0.75 | M30: P1 - 4 Nolu Tip İksa | O30: 11.767 | P30: =+ROUND(PRODUCT(K30:O30),3) -> 88.253 | S30: =+L30*K30 -> 7.5
B31: 5 | C31: 2026.02-004 | D31: S06.H2.KY.P1.A4.002 | H31: 1337.56 | I31: 1292.56 | J31: Üst Yarı | K31: 10 | L31: 0.75 | M31: P1 - 5 Nolu Tip İksa | O31: 11.806 | P31: =+ROUND(PRODUCT(K31:O31),3) -> 88.545 | S31: =+L31*K31 -> 7.5
... B38: 5 | C38: 2026.03-008 | D38: S06.H2.KY.P1.A4.003 | H38: 1344.31 | I38: 1337.56 | J38: Üst Yarı | K38: 1 | L38: 0.75 | M38: P1 - 6 Nolu Tip İksa | O38: 11.959 | P38: =+ROUND(PRODUCT(K38:O38),3) -> 8.969 | S38: =+L38*K38 -> 0.75
B39: Ayna Kırımları
B40: Hk No | C40: Tutanak Genel No | D40: Ayna Kesit Tipi | I40: Kalınlık | J40: Yeri | K40: Benzer | L40: Eni | M40: Boyu | N40: Yüksekliği | O40: Alanı | P40: Miktarı
B41: 5 | C41: 2026.01-015 | D41: 6 Nolu İksa Tipi Ayna | I41: 30 | J41: Üst Yarı | K41: 0 | M41: =+I41/100 -> 0.3 | O41: 11.959 | P41: =+ROUND(PRODUCT(K41:O41),3) -> 0
B42: 3 | C42: 2025.09-001 | D42: 6 Nolu İksa Tipi Ayna | I42: 0 | J42: Üst Yarı | K42: 0 | M42: 0 | O42: 44.922 | P42: =+ROUND(PRODUCT(K42:O42),3) -> 0
B43: 6 | C43: 2026.04-008 | D43: S06.H2.KY.P1.A4.004 | H43: 1357.04 | I43: 1344.31 | J43: Üst Yarı | K43: 1 | L43: 0.75 | M43: P1 - 1 Nolu Tip İksa | O43: 11.385 | P43: =+ROUND(PRODUCT(K43:O43),3) -> 8.539 | S43: =+L43*K43 -> 0.75
B44: 6 | C44: 2026.04-008 | D44: S06.H2.KY.P1.A4.004 | H44: 1357.04 | I44: 1344.31 | J44: Üst Yarı | K44: 1 | L44: 0.75 | M44: P1 - 2 Nolu Tip İksa | O44: 11.709 | P44: =+ROUND(PRODUCT(K44:O44),3) -> 8.782 | S44: =+L44*K44 -> 0.75
B45: 6 | C45: 2026.04-008 | D45: S06.H2.KY.P1.A4.004 | H45: 1357.04 | I45: 1344.31 | J45: Üst Yarı | K45: 1 | L45: 0.75 | M45: P1 - 3 Nolu Tip İksa | O45: 11.793 | P45: =+ROUND(PRODUCT(K45:O45),3) -> 8.845 | S45: =+L45*K45 -> 0.75
B46: 6 | C46: 2026.04-008 | D46: S06.H2.KY.P1.A4.004 | H46: 1357.04 | I46: 1344.31 | J46: Üst Yarı | K46: 1 | L46: 0.75 | M46: P1 - 4 Nolu Tip İksa | O46: 11.767 | P46: =+ROUND(PRODUCT(K46:O46),3) -> 8.825 | S46: =+L46*K46 -> 0.75
B47: 6 | C47: 2026.04-008 | D47: S06.H2.KY.P1.A4.004 | H47: 1357.04 | I47: 1344.31 | J47: Üst Yarı | K47: 1 | L47: 0.75 | M47: P1 - 5 Nolu Tip İksa | O47: 11.806 | P47: =+ROUND(PRODUCT(K47:O47),3) -> 8.855 | S47: =+L47*K47 -> 0.75
B48: 6 | C48: 2026.04-008 | D48: S06.H2.KY.P1.A4.004 | H48: 1357.04 | I48: 1344.31 | J48: Üst Yarı | K48: 1 | L48: 0.75 | M48: P1 - 6 Nolu Tip İksa | O48: 11.959 | P48: =+ROUND(PRODUCT(K48:O48),3) -> 8.969 | S48: =+L48*K48 -> 0.75
B49: 6 | C49: 2026.04-008 | D49: S06.H2.KY.P1.A4.004 | H49: 1357.04 | I49: 1348.06 | J49: Üst Yarı | K49: 1 | L49: =+H49-I49 -> 8.98 | M49: Ortalama | O49: 11.737 | P49: =+ROUND(PRODUCT(K49:O49),3) -> 105.398 | S49: =+L49*K49 -> 8.98
B52: POZ NO | D52: BİRİM FİYAT ADI | M52: BİRİM | N52: ÖNCEKİ HAKEDİŞ MİKTARI | O52: BU HAKEDİŞ MİKTARI | P52: TOPLAM HAKEDİŞ MİKTARI
B53: 020 | D53: =+VLOOKUP(B53,[2]Liste!B:E,2,FALSE) -> Püskürtme Beton (Tünel ve Şaftlarda) | M53: =+VLOOKUP(B53,[2]Liste!B:E,3,FALSE) -> m³ | N53: 141.551 | O53: =+P53-N53 -> 27.158 | P53: =+ROUND(SUM(P54:P86),3) -> 168.709 | AA53: =+VLOOKUP(B53,[1]Liste!$B$2:$F$483,5,FALSE) -> 15334 | AC53: =+AA53*N53 -> 2170543 | AD53: =+AA53*O53 -> 416440.77 | AE53: =+AA53*P53 -> 2586983.8
B54: 4.Aşama İmalatları
...

Sheet Liste
A1: Sıra No | B1: İş Kalemi No | C1: Açıklama | D1: Birimi | E1: Miktarı | F1: Birim Fiyat | G1: Tutar
A2: 1 | B2: 001 | C2: Binaların Yıkılması | D2: m² | E2: 4600 | F2: 500 | G2: =+E2*F2 -> 2300000
A3: 2 | B3: 002.A | C3: Demirli ve Demirsiz Betonun Kompresörle Kırılması | D3: m³ | E3: 528.66 | F3: 4063 | G3: =+E3*F3 -> 2147945.6
A4: 3 | B4: 002.B | C4: Demirli ve Demirsiz Betonun Ekskavatör veya Benzeri İş Makinesi ile Kırılması | D4: m³ | E4: 550.69 | F4: 2000 | G4: =+E4*F4 -> 1101380
A5: 4 | B5: 002.C | C5: Karot Delme ve Beton Kesme Makineları ile Her Türlü Betonun Kesilmesi | D5: m³ | E5: 440.55 | F5: 10500 | G5: =+E5*F5 -> 4625775
A6: 5 | B6: 003 | C6: Her tip zeminde ve kayada, her derinlikte kazı yapılması (nakliye, döküm ve kazı sırasındaki drenaj dahil) (Açık Alanda) | D6: m³ | E6: 175497.85 | F6: 1485 | G6: =+E6*F6 -> 2.6061431e+08
A7: 6 | B7: 004.A | C7: Kazıdan Çıkan veya Ariyetten Alınan Malzeme ile Dolgu Yapılması | D7: m³ | E7: 26184.71 | F7: 300 | G7: =+E7*F7 -> 7855413
A8: 7 | B8: 004.B | C8: Kum, Çakıl, Kırma Tas ve Benzeri Malzeme ile Dolgu Yapılması | D8: m³ | E8: 27657.96 | F8: 1500 | G8: =+E8*F8 -> 41486940
A9: 8 | B9: 005 | C9: Püskürtme Beton (Açık alanda) | D9: m³ | E9: 1734 | F9: 17500 | G9: =+E9*F9 -> 30345000
A10: 9 | B10: 006.A | C10: 125 mm Delik İçine 14 mm Kalınlığında S420a ile Zemin Çivisi Teşkili | D10: m | E10: 1884 | F10: 1050 | G10: =+E10*F10 -> 1978200
A11: 10 | B11: 006.B | C11: 125 mm Delik İçine 26 mm Kalınlığında S420a ile Zemin Çivisi Teşkili | D11: m | E11: 960 | F11: 1200 | G11: =+E11*F11 -> 1152000
A12: 11 | B12: 007.A | C12: L=3 m Kaya Bulonu | D12: adet | E12: 530 | F12: 2475 | G12: =+E12*F12 -> 1311750
A13: 12 | B13: 007.B | C13: L=4 m Kaya Bulonu | D13: adet | E13: 408 | F13: 3900 | G13: =+E13*F13 -> 1591200
... A49: 48 | B49: 017.E | C49: Halkalı Üniversite İstasyonu Mimari ve İnce İşleri Tasarım Hizmetleri | D49: set | E49: 1 | F49: 4205377 | G49: =+E49*F49 -> 4205377
A50: 49 | B50: 018 | C50: Geleneksel (NATM) Tünel Kazısı | D50: m³ | E50: 186392.65 | F50: 5075 | G50: =+E50*F50 -> 9.459427e+08 | H50: =+İcmal!L20 -> 957.247
A51: 50 | B51: 019.A | C51: Kazıdan çıkan veya Ariyetten alınan malzeme ile geri dolgu yapılması | D51: m³ | E51: 910 | F51: 600 | G51: =+E51*F51 -> 546000 | H51: =+İcmal!L21
A52: 51 | B52: 019.B | C52: Kum, Çakıl, Kırma Tas ve Benzeri Malzeme ile Dolgu Yapılması | D52: m³ | E52: 1785 | F52: 1500 | G52: =+E52*F52 -> 2677500 | H52: =+İcmal!L22
A53: 52 | B53: 020 | C53: Püskürtme Beton (Tünel ve Şaftlarda) | D53: m³ | E53: 38798.59 | F53: 15334 | G53: =+E53*F53 -> 5.9493758e+08 | H53: =+İcmal!L23 -> 168.709
A54: 53 | B54: 021.A | C54: Delgi boyu =< 30m | D54: m | E54: 19569.89 | F54: 248 | G54: =+E54*F54 -> 4853332.7 | H54: =+İcmal!L24
A55: 54 | B55: 021.B | C55: Delgi boyu > 30m | D55: m | E55: 10655.78 | F55: 371 | G55: =+E55*F55 -> 3953294.4 | H55: =+İcmal!L25
A56: 55 | B56: 022.A | C56: L=3 m Kaya Bulonu | D56: adet | E56: 800 | F56: 2250 | G56: =+E56*F56 -> 1800000 | H56: =+İcmal!L26
A57: 56 | B57: 022.B | C57: L=4 m Kaya Bulonu | D57: adet | E57: 2466.42 | F57: 8000 | G57: =+E57*F57 -> 19731360 | H57: =+İcmal!L27 -> 0
A58: 57 | B58: 022.C | C58: L=5 m Kaya Bulonu | D58: adet | E58: 2401.3 | F58: 8288 | G58: =+E58*F58 -> 19901974 | H58: =+İcmal!L28
A59: 58 | B59: 022.D | C59: L=6 m Kaya Bulonu | D59: adet | E59: 2970 | F59: 12000 | G59: =+E59*F59 -> 35640000 | H59: =+İcmal!L29
A60: 59 | B60: 022.E | C60: L=8 m Kaya Bulonu | D60: adet | E60: 7008.23 | F60: 28000 | G60: =+E60*F60 -> 196230440 | H60: =+İcmal!L30 -> 270
A61: 60 | B61: 023.A | C61: 125 mm Delik İçine 14 mm Kalınlığında S420a ile Zemin Çivisi Teşkili | D61: m | E61: 156606.89 | F61: 375 | G61: =+E61*F61 -> 58727584 | H61: =+İcmal!L31 -> 0
... A79: 78 | B79: 030.E | C79: Block-out Kutusu | D79: kg | E79: 4500 | F79: 180 | G79: =+E79*F79 -> 810000 | H79: =+İcmal!L49
A80: 79 | B80: 031 | C80: TBM/EPB Tünel İnşaatı | D80: m | E80: 8960.47 | F80: 340200 | G80: =+E80*F80 -> 3048351894
A81: 80 | B81: 032 | C81: Araştırma Sondajı Yapılması ve Raporları | D81: m | E81: 2750 | F81: 3750 | G81: =+E81*F81 -> 10312500
A82: 81 | B82: 033 | C82: Geomekanik İzleme Aletleri temini ve montajı | D82: set | E82: 1 | F82: 108000000 | G82: =+E82*F82 -> 108000000
A83: 82 | B83: 034 | C83: Geomekanik İzleme için ölçümlerin okunması, işlenmesi, sunumu ve değerlendirilmesi | D83: set | E83: 1 | F83: 42000000 | G83: =+E83*F83 -> 42000000
A84: 83 | B84: 101 | C84: Çimento Esaslı Sürme Su Yalıtımı Yapılması | D84: m² | E84: 3033.68 | F84: 1040 | G84: =+E84*F84 -> 3155027.2
A85: 84 | B85: 102 | C85: SCR.01 - Şap | D85: m² | E85: 23957.52 | F85: 988 | G85: =+E85*F85 -> 23670030
A86: 85 | B86: 103 | C86: Tesviye Tabakası Yapılması | D86: m³ | E86: 958.3 | F86: 4072 | G86: =+E86*F86 -> 3902197.6
A87: 86 | B87: 104.A | C87: PA.01 - 60x60 granit seramik zemin kaplama- Gri (RAL 7026) | D87: m² | E87: 23920.44 | F87: 1849 | G87: =+E87*F87 -> 44228894
A88: 87 | B88: 104.B | C88: PA.02 - 30x30 granit seramik zemin kaplama- Gri (RAL 7026) | D88: m² | E88: 3058.14 | F88: 1849 | G88: =+E88*F88 -> 5654500.9
A89: 88 | B89: 104.C | C89: PA.02B - 30x30 granit seramik duvar kaplama- Gri (RAL 7026) | D89: m² | E89: 3419.9 | F89: 1849 | G89: =+E89*F89 -> 6323395.1
A90: 89 | B90: 105.A | C90: PA.03 - 40x40cm Açık Gri Porselen Karo (Granit seramik)- Dur İkaz/uyarı karosu , Seramik Yapıştırma Harcı dahil | D90: m² | E90: 880.44 | F90: 3999 | G90: =+E90*F90 -> 3520879.6
A91: 90 | B91: 105.B | C91: PA.04 - 40x40cm Açık Gri Porselen Karo (Granit seramik)- Klavuz/yönlendirme Seramik Yapıştırma Harcı | D91: m² | E91: 1076.47 | F91: 3999 | G91: =+E91*F91 -> 4304803.5
... A483: 482 | B483: 1200 | C483: Faturalı Giderler | D483: adet | E483: 1 | F483: 75000000 | G483: =+E483*F483 -> 75000000
...
