Workbook

Sheet Para Yazdırma
A1: =+Kapak!N33 -> 56623824 | B1: =+D3&D4&D5&E5&D6&D7&D8&E8&D9&D10&D11&E11&D12&D13&D14&E14&D15&D16&D17&E17&D18&D19&E19 -> ElliAltıMilyonAltıyüzYirmiÜçBinSekizyüzYirmiDörtLiraYediKuruş
A3: =+A1 -> 56623824 | B3: 100000000000000 | C3: =+ROUNDDOWN(A3/B3,0) -> 0 | D3: =+IF(C3=0,"",VLOOKUP(C3,$K$3:$L$11,2,FALSE)) | G3: 1 | H3: Bir | I3: 1 | J3: On | K3: 1 | L3: Yüz
A4: =+ROUND(A3-B3*C3,2) -> 56623824 | B4: 10000000000000 | C4: =+ROUNDDOWN(A4/B4,0) -> 0 | D4: =+IF(C4=0,"",VLOOKUP(C4,$I$3:$J$11,2,FALSE)) | G4: 2 | H4: İki | I4: 2 | J4: Yirmi | K4: 2 | L4: İkiyüz
A5: =+ROUND(A4-B4*C4,2) -> 56623824 | B5: 1000000000000 | C5: =+ROUNDDOWN(A5/B5,0) -> 0 | D5: =+IF(C5=0,"",VLOOKUP(C5,$G$3:$H$11,2,FALSE)) | E5: =+IF(SUM(C3:C5)>0,"Trilyon","") | G5: 3 | H5: Üç | I5: 3 | J5: Otuz | K5: 3 | L5: Üçyüz
A6: =+ROUND(A5-B5*C5,2) -> 56623824 | B6: 100000000000 | C6: =+ROUNDDOWN(A6/B6,0) -> 0 | D6: =+IF(C6=0,"",VLOOKUP(C6,$K$3:$L$11,2,FALSE)) | G6: 4 | H6: Dört | I6: 4 | J6: Kırk | K6: 4 | L6: Dörtyüz
A7: =+ROUND(A6-B6*C6,2) -> 56623824 | B7: 10000000000 | C7: =+ROUNDDOWN(A7/B7,0) -> 0 | D7: =+IF(C7=0,"",VLOOKUP(C7,$I$3:$J$11,2,FALSE)) | G7: 5 | H7: Beş | I7: 5 | J7: Elli | K7: 5 | L7: Beşyüz
A8: =+ROUND(A7-B7*C7,2) -> 56623824 | B8: 1000000000 | C8: =+ROUNDDOWN(A8/B8,0) -> 0 | D8: =+IF(C8=0,"",VLOOKUP(C8,$G$3:$H$11,2,FALSE)) | E8: =+IF(SUM(C6:C8)>0,"Milyar","") | G8: 6 | H8: Altı | I8: 6 | J8: Altmış | K8: 6 | L8: Altıyüz
A9: =+ROUND(A8-B8*C8,2) -> 56623824 | B9: 100000000 | C9: =+ROUNDDOWN(A9/B9,0) -> 0 | D9: =+IF(C9=0,"",VLOOKUP(C9,$K$3:$L$11,2,FALSE)) | G9: 7 | H9: Yedi | I9: 7 | J9: Yetmiş | K9: 7 | L9: Yediyüz
A10: =+ROUND(A9-B9*C9,2) -> 56623824 | B10: 10000000 | C10: =+ROUNDDOWN(A10/B10,0) -> 5 | D10: =+IF(C10=0,"",VLOOKUP(C10,$I$3:$J$11,2,FALSE)) -> Elli | G10: 8 | H10: Sekiz | I10: 8 | J10: Seksen | K10: 8 | L10: Sekizyüz
A11: =+ROUND(A10-B10*C10,2) -> 6623824.1 | B11: 1000000 | C11: =+ROUNDDOWN(A11/B11,0) -> 6 | D11: =+IF(C11=0,"",VLOOKUP(C11,$G$3:$H$11,2,FALSE)) -> Altı | E11: =+IF(SUM(C9:C11)>0,"Milyon","") -> Milyon | G11: 9 | H11: Dokuz | I11: 9 | J11: Doksan | K11: 9 | L11: Dokuzyüz
A12: =+ROUND(A11-B11*C11,2) -> 623824.07 | B12: 100000 | C12: =+ROUNDDOWN(A12/B12,0) -> 6 | D12: =+IF(C12=0,"",VLOOKUP(C12,$K$3:$L$11,2,FALSE)) -> Altıyüz
A13: =+ROUND(A12-B12*C12,2) -> 23824.07 | B13: 10000 | C13: =+ROUNDDOWN(A13/B13,0) -> 2 | D13: =+IF(C13=0,"",VLOOKUP(C13,$I$3:$J$11,2,FALSE)) -> Yirmi
A14: =+ROUND(A13-B13*C13,2) -> 3824.07 | B14: 1000 | C14: =+ROUNDDOWN(A14/B14,0) -> 3 | D14: =+IF(C14=0,"",VLOOKUP(C14,$G$3:$H$11,2,FALSE)) -> Üç | E14: =+IF(SUM(C12:C14)>0,"Bin","") -> Bin
A15: =+ROUND(A14-B14*C14,2) -> 824.07 | B15: 100 | C15: =+ROUNDDOWN(A15/B15,0) -> 8 | D15: =+IF(C15=0,"",VLOOKUP(C15,$K$3:$L$11,2,FALSE)) -> Sekizyüz
A16: =+ROUND(A15-B15*C15,2) -> 24.07 | B16: 10 | C16: =+ROUNDDOWN(A16/B16,0) -> 2 | D16: =+IF(C16=0,"",VLOOKUP(C16,$I$3:$J$11,2,FALSE)) -> Yirmi
A17: =+ROUND(A16-B16*C16,2) -> 4.07 | B17: 1 | C17: =+ROUNDDOWN(A17/B17,0) -> 4 | D17: =+IF(C17=0,"",VLOOKUP(C17,$G$3:$H$11,2,FALSE)) -> Dört | E17: =+IF(SUM(C3:C17)>0,"Lira","") -> Lira
A18: =+ROUND(A17-B17*C17,2) -> 0.07 | B18: 0.1 | C18: =+ROUNDDOWN(A18/B18,0) -> 0 | D18: =+IF(C18=0,"",VLOOKUP(C18,$I$3:$J$11,2,FALSE))
A19: =+ROUND(A18-B18*C18,2) -> 0.07 | B19: 0.01 | C19: =+ROUNDDOWN(A19/B19,0) -> 7 | D19: =+IF(C19=0,"",VLOOKUP(C19,$G$3:$H$11,2,FALSE)) -> Yedi | E19: =+IF(SUM(C18:C19)>0,"Kuruş","") -> Kuruş

Sheet Veri
A1: GENEL BİLGİLER
A2: Sözleşme Bedeli (Mektup Sayfasına Lazım) | B2: : | C2: 21982861000
A3: İşin Adı | B3: : | C3: Kirazlı-Halkalı Üniversite Metro Hattı İnşaat Ve Elektromekanik İşler İle M1 Hattı Elektromekanik Sistemleri Yapım İşi
A4: İdare Genel Adı | B4: : | C4: T.C. İstanbul Büyükşehir Belediyesi
A5: İdare Müdürlük | B5: : | C5: Raylı Sistem Dairesi Başkanlığı Avrupa Yakası Raylı Sistem Şube Müdürlüğü
A6: İdare Tam Adı | B6: : | C6: =$C$4&", " &$C$5 -> T.C. İstanbul Büyükşehir Belediyesi, Raylı Sistem Dairesi Başkanlığı Avrupa Yakası Raylı Sistem Şube Müdürlüğü
A7: Danışman | B7: : | C7: Yüksel Proje A.Ş.
A8: Yüklenici | B8: : | C8: Kalyon-Özgün Metro İnşaatı Adi Ortaklığı Ticari İşletmesi
A9: İhale Tarihi | B9: : | C9: 45614
A10: İhale Bedeli | B10: : | C10: 21.982.861.000,00 TL + KDV
A11: Sözleşme Tarihi ve No'su | B11: : | C11: 13.12.2024-2024/1524796
A12: Sözleşmenin Noter'ce Tescil Tarihi No'su | B12: : | C12: 13.12.2024/59781
A13: İşyeri Teslim Tarihi | B13: : | C13: 45653
A14: İşe Başlama Tarihi | B14: : | C14: 45653
A15: Sözleşmeye Göre İşin Süresi | B15: : | C15: 1440 gün
A16: Sözleşmeye Göre İşin Bitim Tarihi | B16: : | C16: 47093
A17: Verilen Avanslar Toplamı | B17: : | C17: 0
A19: Bir Önceki Hakediş No | B19: : | C19: 5
A20: Bir Önceki Hakediş Tarihi | B20: : | C20: 01.04.2026
A21: Bu Hakediş No | B21: : | C21: 6
A22: Hakediş Tarihi | B22: : | C22: 46142
A24: İDARE | B24: : | C24: T.C. İSTANBUL BÜYÜKŞEHİR BELEDİYESİ Raylı Sistem Dairesi Başkanlığı Avrupa Yakası Raylı Sistem Şube Müdürlüğü
A25: Raylı Sistem Daire Başkan V. | B25: : | C25: Erman ERYILMAZ
A26: Avrupa Yakası Raylı Sistem Müdürü | B26: : | C26: Ahmet ÖNAL
A27: İnşaat Müdür Yardımcısı | B27: : | C27: Osman ŞAHİN
A28: E&M Müdür Yardımcısı | B28: : | C28: Hakan ARZU
A29: Kontrol Mühendisi | B29: : | C29: Mehmet Zeki ERTÜRK
A30: Kontrol Mühendisi | B30: : | C30: Atilla ALKAN
A31: Kontrol Mühendisi | B31: : | C31: Selçuk ŞİYHAN
A33: Kontrol Mühendisi | B33: : | C33: Ferhat KARAOĞLAN
A34: Kontrol Mühendisi | B34: : | C34: Yavuz TAŞ
A35: Kontrol Mühendisi | B35: : | C35: Uğur ERKEN
A36: Kontrol Mühendisi | B36: : | C36: Özkan SAĞIR
... A44: Proje Müdürü | B44: : | C44: Orhan KOCA
A45: İnşaat Kontrol Amiri | B45: :
A46: Elektromekanik İşler Kontrol Amiri | B46: : | C46: Fatih AYDIN
A47: Hakediş, Mukavele Takip, Kesin Hesap Kontrol Mühendisi | B47: : | C47: Yılmaz SATI
A48: Hakediş, Mukavele Takip, Kesin Hesap Kontrol Mühendisi | B48: : | C48: Aybüke YEĞEN
A50: YÜKLENİCİ | B50: : | C50: KALYON-ÖZGÜN METRO İNŞAATI ADİ ORTAKLIĞI
A51: Proje Müdürü | B51: : | C51: Kemal YERLİ
...

Sheet İmza Matris
E3: Açıkta | F3: Tünel | G3: Jeo | H3: İnce | I3: Elektrik | J3: Sinyal | K3: Haberleşme | L3: Çevresel | M3: Yardımcı | N3: Yürüyen Merdiven | O3: Demiryolu | P3: Sistem Müh | Q3: M1A-M1B | R3: Diğer Kurum
A4: Raylı Sistem Daire Başkanı | B4: Ceyhun AVŞAR | D4: Genel | I4: Yavuz TAŞ | J4: Yavuz TAŞ | K4: Ferhat KARAOĞLAN | L4: M.Zeki ERTÜRK | M4: M.Zeki ERTÜRK | N4: M.Zeki ERTÜRK | P4: Hasan Tecelli TEMÜZ | Q4: M.Zeki ERTÜRK | R4: M.Zeki ERTÜRK
A5: Avrupa Yakası Raylı Sistem Müdürü | B5: Ahmet ÖNAL | D5: Genel | I5: Elektrik Kontrol Mühendisi | J5: Elektrik Kontrol Mühendisi | K5: Elektronik Kontrol Mühendisi | L5: Yavuz TAŞ | M5: Ferhat KARAOĞLAN | P5: İnşaat Kontrol Mühendisi | Q5: Ferhat KARAOĞLAN | R5: Ferhat KARAOĞLAN
A6: İnşaat Müdür Yardımcısı | B6: Osman ŞAHİN | D6: Genel | F6: Yasin YEŞİLDAĞ | G6: Yasin YEŞİLDAĞ | L6: Elektrik Kontrol Mühendisi | M6: Elektronik Kontrol Mühendisi | O6: Hasan Tecelli TEMÜZ | Q6: Elektronik Kontrol Mühendisi | R6: Elektronik Kontrol Mühendisi
A7: E&M Müdür Yardımcısı | B7: Hakan ARZU | D7: Barbaros | E7: Özkan SAĞIR | F7: Maden Kontrol Mühendisi | G7: Maden Kontrol Mühendisi | H7: Hakan KUK | O7: İnşaat Kontrol Mühendisi | R7: Özkan SAĞIR
A8: Kontrol Mühendisi | B8: M.Zeki ERTÜRK | D8: Malazgirt | E8: İnşaat Kontrol Mühendisi | F8: Yasin YEŞİLDAĞ | G8: Yasin YEŞİLDAĞ | H8: Mimar / Kontrol Mühendisi | O8: Hasan Tecelli TEMÜZ | R8: İnşaat Kontrol Mühendisi
A9: Kontrol Mühendisi | B9: Atilla ALKAN | D9: Mimar Sinan | E9: Atilla ALKAN | F9: Maden Kontrol Mühendisi | G9: Maden Kontrol Mühendisi | H9: Ahmet Resul KESKİN | O9: İnşaat Kontrol Mühendisi | R9: Atilla ALKAN
A10: Kontrol Mühendisi | B10: İnşaat Kontrol Mühendisi | D10: Fatih | E10: İnşaat Kontrol Mühendisi | F10: Yasin YEŞİLDAĞ | G10: Yasin YEŞİLDAĞ | H10: Mimar / Kontrol Mühendisi | O10: Hasan Tecelli TEMÜZ | R10: İnşaat Kontrol Mühendisi
A11: Kontrol Mühendisi | B11: Ferhat KARAOĞLAN | D11: Halkalı | E11: Hasan Tecelli TEMÜZ | F11: Maden Kontrol Mühendisi | G11: Maden Kontrol Mühendisi | H11: Ahmet Resul KESKİN | O11: İnşaat Kontrol Mühendisi | R11: Hasan Tecelli TEMÜZ
A12: Kontrol Mühendisi | B12: Elektronik Kontrol Mühendisi | E12: İnşaat Kontrol Mühendisi | H12: Mimar / Kontrol Mühendisi | R12: İnşaat Kontrol Mühendisi
A13: Kontrol Mühendisi | B13: Uğur ERKEN
A14: Kontrol Mühendisi | B14: Harita Kontrol Mühendisi
A15: Kontrol Mühendisi | B15: Hasan Tecelli TEMÜZ
A16: Kontrol Mühendisi | B16: İnşaat Kontrol Mühendisi
A17: Kontrol Mühendisi | B17: Ahmet Resul KESKİN
A18: Kontrol Mühendisi | B18: Mimar / Kontrol Mühendisi
A19: Kontrol Teknikeri | B19: Hasan Fehmi KARACA
B20: İnşaat Kontrol Teknikeri

Sheet İmza

Sheet İmza (2)

Sheet İndeks
A1: =+Veri!$C$6 -> T.C. İstanbul Büyükşehir Belediyesi, Raylı Sistem Dairesi Başkanlığı Avrupa Yakası Raylı Sistem Şube Müdürlüğü
A2: =+Veri!$C$3 -> Kirazlı-Halkalı Üniversite Metro Hattı İnşaat Ve Elektromekanik İşler İle M1 Hattı Elektromekanik Sistemleri Yapım İşi
A3: ="Hakediş No : "&Veri!C21&" ("&TEXT(Veri!C20,"gg.aa.yyyy")&" - "&TEXT(Veri!C22,"gg.aa.yyyy")&")" -> Hakediş No : 6 (01.04.2026 - 30.04.2026)
A4: DİZİ PUSULASI
A5: Sıra No | B5: Açıklama | G5: Sayfa Sayısı
B6: Bütçe Finansman ve Denetim Müdürlüğü'ne yazı | G6: 1
B7: Ödeme Emri Belgesi | G7: 1
B8: Fatura | G8: 1
B9: Vergi ve SGK Borcu Yoktur Yazıları | G9: 2
A11: 1 | B11: Hakediş İtiraz Dilekçeleri | G11: -
A12: =+A11+1 -> 2 | B12: Hakediş Raporu Kapağı ve İcmal | G12: 4
A13: =+A12+1 -> 3 | B13: İhtiyat ve Ek Kesin Teminat Kesintisi Yerine Verilen Teminat Mektupları Listesi, Avans Kesintisi Takip Tablosu | G13: 10 | I13: Elle
A14: =+A13+1 -> 4 | B14: Fiyat Farkı İcmali ve Hesap Tabloları | G14: 5 | I14: Elle
A15: =+A14+1 -> 5 | B15: Yapılan İşler (İcmal Özet + İmalat) | G15: 40
A16: =+A15+1 -> 6 | B16: Yeşil Defter Sayfaları | G16: 26
A17: =+A16+1 -> 7 | B17: Metrajlar | G17: 104 | I17: Elle
A18: =+A17+1 -> 8 | B18: NATM İmalat Tutanakları | L18: =465-G16-G15-G14-G13-G12-G19 -> 354
A19: =+A18+1 -> 9 | B19: NATM İmalat Birim Miktarlar | G19: 26
A20: =+A19+1 -> 10 | B20: Yüklenici Firmadan İşçi Alacağı Olmadığına Dair İlan Tutanağı | G20: 2
A21: =+A20+1 -> 11 | B21: All Risk Sigorta Poliçesi | G21: 29
A22: =+A21+1 -> 12 | B22: Vekaletname | G22: 3
G23: =SUM(G6:G22) -> 254
B27: ="Yalnız "&$A$22&" kalem ve "&G23&" sayfadır." -> Yalnız 12 kalem ve 254 sayfadır.

Sheet İmza Yetkilileri
B1: =+[3]Veri!$C$6 -> T.C. İstanbul Büyükşehir Belediyesi, Raylı Sistem Dairesi Başkanlığı Avrupa Yakası Raylı Sistem Şube Müdürlüğü
B2: =+[3]Veri!$C$3 -> Kirazlı-Halkalı Üniversite Metro Hattı İnşaat Ve Elektromekanik İşler İle M1 Hattı Elektromekanik Sistemleri Yapım İşi
B3: İMZA YETKİLİLERİ LİSTESİ
B4: Açıklama | C4: İmza Yetkilileri (İBB) | D4: Sayfa Numaraları | E4: İmza Yetkilileri (Müşavir) | F4: Sayfa Numaraları | G4: İmza Yetkilileri (Yüklenici) | H4: Sayfa Numaraları
A5: 1 | B5: Hakediş Kapak ve İcmal | C5: Erman ERYILMAZ | D5: Kapak 4 | E5: Orhan KOCA | F5: Kapak 2 - 4 | G5: Kemal YERLİ | H5: Kapak 2 - 4
C6: Ahmet ÖNAL | D6: Kapak 4 | E6: Sinan GENÇTÜRK | F6: Kapak 2 - 4
C7: Osman ŞAHİN | D7: Kapak 2 - 4 | E7: Fatih AYDIN | F7: Kapak 2 - 4
C8: Hakan ARZU | D8: Kapak 2 - 4
C9: Mehmet Zeki ERTÜRK | D9: Kapak 2 - 4
C10: Atilla ALKAN | D10: Kapak 2 - 4
C11: Ferhat KARAOĞLAN | D11: Kapak 2 - 4
C12: Yavuz TAŞ | D12: Kapak 2 - 4
C13: Uğur ERKEN | D13: Kapak 2 - 4
C14: Özkan SAĞIR | D14: Kapak 2 - 4
C15: Hasan Tecelli TEMÜZ | D15: Kapak 2 - 4
C16: Yasin YEŞİLDAĞ | D16: Kapak 2 - 4
C17: Ahmet Resul KESKİN | D17: Kapak 2 - 4
C18: Hakan KUK | D18: Kapak 2 - 4
C19: Hasan Fehmi KARACA | D19: Kapak 2 - 4
A20: 2 | B20: İşçi Alacağı Tutanağı | E20: Fatih AYDIN | F20: 1 | G20: Kemal YERLİ | H20: 1
A22: 3 | B22: Teminat Mektupları İcmalleri Fiyat Farkı İcmali Fiyat Farkı Hesabı Avans Kesintisi Takip Tabloları | C22: Osman ŞAHİN | D22: 3 - 6 | E22: Orhan KOCA | F22: 3 - 6 | G22: Kemal YERLİ | H22: 3 - 6
C23: Hakan ARZU | D23: 3 - 6 | E23: Fatih AYDIN | F23: 3 - 6
C24: Atilla ALKAN | D24: 3 - 4 | E24: Yılmaz SATI | F24: 5 - 6
C25: Yasin YEŞİLDAĞ | D25: 5 - 6 | E25: Aybüke YEĞEN | F25: 5 - 6
A27: 4 | B27: Yapılan İşler İcmali | C27: Osman ŞAHİN | D27: 8 - 17 / 31 / 33 | E27: Orhan KOCA | F27: 8-38 | G27: Kemal YERLİ | H27: 8 - 38
C28: Hakan ARZU | D28: 19 - 30 / 32 - 38 | E28: Fatih AYDIN | F28: 19 - 30 / 32 - 38
C29: Mehmet Zeki ERTÜRK | D29: 27-30 / 37 | E29: Yılmaz SATI | F29: 8-38
C30: Atilla ALKAN | D30: 8 - 10 | E30: Aybüke YEĞEN | F30: 8-38
C31: Ferhat KARAOĞLAN | D31: 23 - 26 / 28
C32: Yavuz TAŞ | D32: 18 - 23 / 26 / 33-36
C33: Özkan SAĞIR | D33: 8 - 12
C34: Hasan Tecelli TEMÜZ | D34: 8 - 10/ 31
C35: Yasin YEŞİLDAĞ | D35: 11 - 12
C36: Ahmet Resul KESKİN | D36: 13 - 17 / 33
C37: Hakan KUK | D37: 13 - 17 / 33
A38: 5 | B38: Yeşil Defter | C38: Osman ŞAHİN | D38: 39 | E38: Orhan KOCA | F38: 39 - 63 | G38: Kemal YERLİ | H38: 41 - 64
C39: Hakan ARZU | D39: 39 / 58 / 63 | E39: Fatih AYDIN | F39: 48-63
C40: Mehmet Zeki ERTÜRK | D40: 39 / 54-56 / 62 | E40: Sinan GENÇTÜRK | F40: 40-47/63
C41: Atilla ALKAN | D41: 39-41 | E41: Selami IŞIK | F41: 41/43
C42: Ferhat KARAOĞLAN | D42: 39 / 51-53 / 55 | E42: Ceyda Sena BALABAN | F42: 41
...

Sheet Ön Yazı
B17: Sözleşmemiz Aylık Hakediş Raporları ve Düzenlenmesi 33.36 maddesine istinaden 12.12.2024 Tarihli Ortaklık Tespit Belgesinde yer alan bilgilerde bugüne kadar değişiklik olmadığını ve ortağımıza ait iş deneyimini gösteren belgelerin tamamını, başka bir tüzel kişiye kullandırılmadığını taahhüt ederiz.

Sheet NT Ksnt Tkp (Çıktı Alınmayacak)
A3: T.C.
A4: İstanbul Büyükşehir Belediyesi
A5: Raylı Sistem Daire Başkanlığı Avrupa Yakası Raylı Sistem Müdürlüğü
A7: Kirazlı-Halkalı Üniversite Metro Hattı İnşaat Ve Elektromekanik İşler İle M1 Hattı Elektromekanik Sistemleri Yapım İşi
A9: NAKİT TEMİNAT KESİNTİ TAKİP TABLOSU
I11: Hakediş No : | J11: =+Veri!$C$21 -> 6
I12: Hakediş Tarihi : | J12: =+Veri!$C$22 -> 46142
B14: Mektup Türü | C14: Mektup Değeri (TL) | D14: Teminat Kümülatif Tutar (TL) | F14: Alınış Tarihi | G14: Geçerlilik Tarihi | H14: Alındığı Banka | I14: Mektup No | J14: Verildiği Hakediş No
B15: Kesin Teminat Mektubu | C15: 164542.47 | D15: =+C15 -> 164542.47 | F15: 45768 | G15: 48233 | H15: Halkbank | I15: 0614MW028860 | J15: 1
B16: Kesin Teminat Mektubu | C16: 329134.32 | D16: =+D15+C16 -> 493676.79 | F16: 45768 | G16: 48233 | H16: Halkbank | I16: 1451MW016535 | J16: 1
B17: Kesin Teminat Mektubu | C17: 349965 | D17: =+D16+C17 -> 843641.79 | F17: 45894 | G17: 48233 | H17: Halkbank | I17: 0614MW029539 | J17: 2
B18: Kesin Teminat Mektubu | C18: 700035 | D18: =+D17+C18 -> 1543676.8 | F18: 45894 | G18: 48233 | H18: Halkbank | I18: 1451MW017242 | J18: 2
B19: Elle girildi | C19: 5627605.6
B30: Toplam Metkup Tutarı: | D30: =SUM(C15:C28) -> 7171282.4
B33: =+Veri!$C$21 -> 6 | F33: =+Kapak!#REF! -> #REF! | G33: TL
B34: =+Veri!$C$21 -> 6 | F34: =+ROUND(F33*0.05,2) -> #REF! | G34: TL (Sözleşme Madde 30.2 Yapılan İmalatlara Ait Tutarın %5'i) | L34: =+F34-F35 -> #REF!
B35: =+Veri!$C$21 -> 6 | F35: =+D30 -> 7171282.4 | G35: TL | M35: =+ROUND(F34-F35,2) -> #REF! | N35: TL TEMİNAT KESİNTİSİ YAPILACAKTIR.
D36: Verilmesi Gereken Toplam Mektup Tutarı | E36: =+IF(F35>F34,"<",IF(F35=F34,"=",">")) -> #REF! | F36: Verilen Toplam Mektup Tutarı olduğu için | M36: TEMİNAT KESİNTİSİ YAPILMAYACAKTIR.
B37: =+IF(M35>0,CONCATENATE(TEXT(M35,"#.##0,00"),N35),M36) -> #REF!
A40: YÜKLENİCİ | D40: DANIŞMAN | H40: İDARE
A41: Kalyon-Özgün Metro İnşaatı Adi Ortaklığı | D41: Yüksel Proje A.Ş. | H41: T.C. İstanbul Büyükşehir Belediyesi
D48: Fatih AYDIN
D49: Elektromekanik Kontrol Amiri
A56: Kemal YERLİ | D56: Orhan KOCA | H56: Osman ŞAHİN | J56: Hakan ARZU
A57: Proje Müdürü | D57: Proje Müdürü | H57: İnşaat Müdür Yardımcısı | J57: E&M Müdür Yardımcısı

Sheet EFF Ksnt Tkp(Çıktı Alınmayacak)
A3: T.C.
A4: İstanbul Büyükşehir Belediyesi
A5: Raylı Sistem Daire Başkanlığı Avrupa Yakası Raylı Sistem Müdürlüğü
A7: Kirazlı-Halkalı Üniversite Metro Hattı İnşaat Ve Elektromekanik İşler İle M1 Hattı Elektromekanik Sistemleri Yapım İşi
A9: FİYAT FARKI EK KESİN TEMİNATI KESİNTİ TAKİP TABLOSU
I11: Hakediş No : | J11: =+Veri!$C$21 -> 6
I12: Hakediş Tarihi : | J12: =+Veri!$C$22 -> 46142
B14: Mektup Türü | C14: Mektup Değeri | D14: Teminat Kümülatif Tutar | F14: Alınış Tarihi | G14: Geçerlilik Tarihi | H14: Alındığı Banka | I14: Mektup No | J14: Verildiği Hakediş No
B15: Fiyat Farkı Ek Kesin Teminat Mektubu | C15: 2913.33 | D15: =+C15 -> 2913.33 | F15: 45768 | G15: 48233 | H15: Halkbank | I15: 0614MW028859 | J15: 1
B16: Fiyat Farkı Ek Kesin Teminat Mektubu | C16: 5827.52 | D16: =+D15+C16 -> 8740.85 | F16: 45768 | G16: 48233 | H16: Halkbank | I16: 1451MW016534 | J16: 1
B17: Fiyat Farkı Ek Kesin Teminat Mektubu | C17: 59994 | D17: =+D16+C17 -> 68734.85 | F17: 45894 | G17: 48233 | H17: Halkbank | I17: 0614MW029540 | J17: 2
B18: Fiyat Farkı Ek Kesin Teminat Mektubu | C18: 120006 | D18: =+D17+C18 -> 188740.85 | F18: 45894 | G18: 48233 | H18: Halkbank | I18: 1451MW017248 | J18: 2
B19: Elle Girildi | C19: 734011.2 | D19: =+D18+C19 -> 922752.05
D20: =+D19+C20 -> 922752.05
D21: =+D20+C21 -> 922752.05
D22: =+D21+C22 -> 922752.05
D23: =+D22+C23 -> 922752.05
D24: =+D23+C24 -> 922752.05
D25: =+D24+C25 -> 922752.05
D26: =+D25+C26 -> 922752.05
D27: =+D26+C27 -> 922752.05
B30: Toplam Metkup Tutarı: | D30: =SUM(C15:C28) -> 922752.05
B33: =+Veri!$C$21 -> 6 | F33: =+#REF! -> #REF! | G33: TL | L33: =+F34-F35 -> #REF!
B34: =+Veri!$C$21 -> 6 | F34: =+ROUND(F33*0.06,2) -> #REF! | G34: TL (Sözleşme Madde 10.2.1 Toplam Fiyat Farkı Tutarının %6'sı)
B35: =+Veri!$C$21 -> 6 | F35: =+D30 -> 922752.05 | G35: TL | M35: =+ROUND(F34-F35,2) -> #REF! | N35: TL TEMİNAT KESİNTİSİ YAPILACAKTIR.
D36: Verilmesi Gereken Toplam Mektup Tutarı | E36: =+IF(F35>F34,"<",IF(F35=F34,"=",">")) -> #REF! | F36: Verilen Toplam Mektup Tutarı olduğu için | M36: TEMİNAT KESİNTİSİ YAPILMAYACAKTIR.
B37: =+IF(M35>0,CONCATENATE(TEXT(M35,"#.##0,00"),N35),M36) -> #REF!
A40: YÜKLENİCİ | D40: DANIŞMAN | H40: İDARE
A41: Kalyon-Özgün Metro İnşaatı Adi Ortaklığı | D41: Yüksel Proje A.Ş. | H41: T.C. İstanbul Büyükşehir Belediyesi
D48: Fatih AYDIN
D49: Elektromekanik Kontrol Amiri
A56: Kemal YERLİ | D56: Orhan KOCA | H56: Osman ŞAHİN | J56: Hakan ARZU
A57: Proje Müdürü | D57: Proje Müdürü | H57: İnşaat Müdür Yardımcısı | J57: E&M Müdür Yardımcısı

Sheet İşçi Alacak
C3: İŞÇİ ALACAĞI OLMADIĞINA DAİR TUTANAK
C6: İşin Adı | D6: : | E6: Kirazlı-Halkalı Üniversite Metro Hattı İnşaat Ve Elektromekanik İşler İle M1 Hattı Elektromekanik Sistemleri Yapım İşi | S6: T.C. İstanbul Büyükşehir Belediye Başkanlığı'nca ihale edilen, Yüklenici Kalyon-Özgün Metro İnşaatı Adi Ortaklığı Ticari İşletmesi'nin taahhüdü altında yapımı devam eden "Kirazlı-Halkalı Üniversite Metro Hattı İnşaat Ve Elektromekanik İşler İle M1 Hattı Elektromekanik Sistemleri Yapım İşi" ile ilgili
C7: İdare | D7: : | E7: T.C. İstanbul Büyükşehir Belediyesi Raylı Sistem Daire Başkanlığı Avrupa Yakası Raylı Sistem Müdürlüğü | S7: =+TEXT(E12,"gg.aa.yyyy") -> 30.04.2026
C8: Danışman | D8: : | E8: Yüksel Proje A.Ş. | S8: tarihi itibarı ile düzenlenecek hakediş için
C9: Yüklenici | D9: : | E9: Kalyon-Özgün Metro İnşaatı Adi Ortaklığı Ticari İşletmesi | S9: =+TEXT(E12-9,"gg.aa.yyyy") -> 21.04.2026
C10: İhale Bedeli | D10: : | E10: 21.982.861.000,00 TL + KDV | S10: tarihinde 4857 sayılı iş kanununun 36. maddesine göre işçi alacakları ile ilgili ilan yapılmıştır.
C11: Tutanak No'su | D11: : | E11: =+Veri!$C$21 -> 6
C12: Tutanak Tarihi | D12: : | E12: =+Veri!C22 -> 46142 | S12: Buna göre,
S13: =+TEXT(E12,"gg.aa.yyyy") -> 30.04.2026
S14: tarihine kadar işçi alacakları ile ilgili herhangi bir müracaat yapılmamıştır.
C15: =+S6&S7&S8&S9&S10 -> T.C. İstanbul Büyükşehir Belediye Başkanlığı'nca ihale edilen, Yüklenici Kalyon-Özgün Metro İnşaatı Adi Ortaklığı Ticari İşletmesi'nin taahhüdü altında yapımı devam eden "Kirazlı-Halkalı Üniversite Metro Hattı İnşaat Ve Elektromekanik İşler İle M1 Hattı Elektromekanik Sistemleri Yapım İşi" ile ilgili 30.04.2026 tarihi itibarı ile düzenlenecek hakediş için 21.04.2026 tarihinde 4857 sayılı iş kanununun 36. maddesine göre işçi alacakları ile ilgili ilan yapılmıştır.
S18: İş bu tutanak taraflarca
C19: =+S12&S13&S14 -> Buna göre, 30.04.2026 tarihine kadar işçi alacakları ile ilgili herhangi bir müracaat yapılmamıştır. | S19: =+TEXT(E12,"gg.aa.yyyy") -> 30.04.2026
S20: tarihinde 6 nüsha olarak tanzim ve imza edilmiştir.
C21: =+S18&S19&S20 -> İş bu tutanak taraflarca 30.04.2026 tarihinde 6 nüsha olarak tanzim ve imza edilmiştir.
C24: İŞÇİ TEMSİLCİSİ | H24: YÜKLENİCİ | L24: DANIŞMAN
C34: Abdulgafur TEKİN | F34: Mehmet Ali AKGÜL | H34: Kemal YERLİ Proje Müdürü | L34: Fatih AYDIN Elektromekanik Kontrol Amiri

Sheet İlan
C4: İLAN TUTANAĞI
C7: =+M7&M8&M9 -> İdare T.C. İSTANBUL BÜYÜKŞEHİR BELEDİYESİ Raylı Sistem Daire Başkanlığı Avrupa Yakası Raylı Sistem Müdürlüğü’nce ihale edilen, Yüklenici "KALYON-ÖZGÜN METRO İNŞAATI ADİ ORTAKLIĞI TİCARİ İŞLETMESİ"nin taahhüdü altında yapımı devam eden "Kirazlı-Halkalı Üniversite Metro Hattı İnşaat Ve Elektromekanik İşler İle M1 Hattı Elektromekanik Sistemleri Yapım İşi" 'nde 6 No’lu hakediş tanzim edilecektir. | M7: İdare T.C. İSTANBUL BÜYÜKŞEHİR BELEDİYESİ Raylı Sistem Daire Başkanlığı Avrupa Yakası Raylı Sistem Müdürlüğü’nce ihale edilen, Yüklenici "KALYON-ÖZGÜN METRO İNŞAATI ADİ ORTAKLIĞI TİCARİ İŞLETMESİ"nin taahhüdü altında yapımı devam eden "Kirazlı-Halkalı Üniversite Metro Hattı İnşaat Ve Elektromekanik İşler İle M1 Hattı Elektromekanik Sistemleri Yapım İşi" 'nde
M8: =+Veri!$C$21 -> 6
M9: No’lu hakediş tanzim edilecektir.
C13: =+M13&M14&M15 -> Adı geçen işte çalışıp, Yüklenici firmadan alacağı bulunan işçilerin, 30.04.2026 tarihine kadar, alacakları olduğuna dair belgeleri ile Danışmanlığımıza müracaatları 4857 sayılı iş kanunun 36.maddesi gereği ilan olunur. | M13: Adı geçen işte çalışıp, Yüklenici firmadan alacağı bulunan işçilerin,
M14: =+TEXT(Veri!$C$22,"gg.aa.yyyy") -> 30.04.2026
M15: tarihine kadar, alacakları olduğuna dair belgeleri ile Danışmanlığımıza müracaatları 4857 sayılı iş kanunun 36.maddesi gereği ilan olunur.
H17: DANIŞMAN
H18: YÜKSEL PROJE A.Ş.

Sheet Kapak
B2: T.C.
B3: İSTANBUL BÜYÜKŞEHİR BELEDİYE BAŞKANLIĞI | U3: T.C.
B4: Raylı Sistem Dairesi Başkanlığı | U4: İSTANBUL BÜYÜKŞEHİR BELEDİYESİ
B5: Avrupa Yakası Raylı Sistem Şube Müdürlüğü
B6: Kirazlı-Halkalı Üniversite Metro Hattı İnşaat Ve Elektromekanik İşler İle M1 Hattı Elektromekanik Sistemleri Yapım İşi | U6: Raylı Sistem Dairesi Başkanlığı
U7: Avrupa Yakası Raylı Sistem Şube Müdürlüğü
I8: HAKEDİŞ NO: | J8: =+Veri!$C$21 -> 6 | U8: Kirazlı-Halkalı Üniversite Metro Hattı İnşaat Ve Elektromekanik İşler İle
B9: =+Veri!$C$22 -> 46142 | U9: M1 Hattı Elektromekanik Sistemleri Yapım İşi
B10: A | C10: )Sözleşme Fiyatlar İle Yapılan İşler Toplam Tutarı | N10: =+İcmal!AE29 -> 37210860 | O10: TL | S10: HAKEDİŞ RAPORU
B11: B | C11: )Fiyat Farkı Tutarı (Fiyat Farkı Sayfasından) | N11: =+İcmal!$AE$35 -> 10372185 | O11: TL
B12: C | C12: )Diğer İşler Tutarı | N12: =+İcmal!N39 -> 0 | O12: TL | Y12: No | Z12: : | AA12: =+Veri!$C$21 -> 6
B13: D | C13: )Toplam Tutarı ( A + B + C ) | N13: =+N10+N11+N12 -> 47583045 | O13: TL
E14: =+Veri!$C$20 -> 01.04.2026 | G14: ile | H14: =+Veri!$C$22 -> 46142 | J14: TARİHLERİ ARASINDA YAPILAN İŞLERİN | Y14: Tarihi | Z14: : | AA14: =+Veri!$C$22 -> 46142
B15: E | C15: =+J8-1 -> 5 | N15: =+İcmal!AC41 -> 0 | O15: TL
B16: F) | C16: Bu Hakedişin Tutarı ( D - E ) | N16: =+N13-N15 -> 47583045 | O16: TL | Y16: Uygulama Yılı | Z16: : | AA16: =+Veri!$C$22 -> 46142
B17: G | C17: Yatırım Teşvik Kapsamında KDV İstisna Tutarı | N17: =SUM(N18:N19) -> 0 | O17: TL
C18: I.1) Yurt İçinden Temin Edilen Makina ve Teçhizat (KDV' siz) | N18: 0 | O18: TL
C19: I.2) Yurt Dışından Temin Edilen Makina ve Teçhizat (KDV' siz) | N19: 0 | O19: TL | AA19: Kirazlı-Halkalı Üniversite Metro Hattı İnşaat Ve Elektromekanik İşler İle M1 Hattı Elektromekanik Sistemleri Yapım İşi
B20: H | C20: )Bu Hakedişte KDV Uygulanacak Tutar ( F - G ) | N20: =+N16-N17 -> 47583045 | O20: TL | S20: Yapılan İşin Adı | Z20: :
B21: I | C21: )K.D.V Tutarı ( H x %20 ) | N21: =+ROUND(N20*0.2,2) -> 9516609.1 | O21: TL
B22: J | C22: )Tahakkuk Tutarı ( H + I ) | N22: =+N16+N21 -> 57099655 | O22: TL | AA22: T.C. İSTANBUL BÜYÜKŞEHİR BELEDİYESİ
B23: K) KESİNTİLER ve MAHSUPLAR | C23: Gelir Vergisi Stopajı (H - Avans Kesintisi) x % 1 | N23: =+ROUND((N16-N28)*0.01,2) -> 475830.45 | O23: TL | S23: İşverenin Adı | Z23: : | AA23: Raylı Sistem Dairesi Başkanlığı
C24: Damga Vergisi (Muaf) | N24: 0 | O24: TL | AA24: Avrupa Yakası Raylı Sistem Şube Müdürlüğü
C25: Sosyal Sigortalar Kurumu Kesintisi | N25: 0 | O25: TL
C26: İdare Makinası Kiraları | N26: 0 | O26: TL | S26: Yüklenicinin Adı | Z26: : | AA26: Kalyon-Özgün Metro İnşaatı Adi Ortaklığı Ticari İşletmesi
C27: Gecikme Cezası | N27: 0 | O27: TL
C28: Sözleşme Avans Mahsubu ( Hakediş ve Avans Kesintisi Takip Cetveli Sayfasından) | N28: 0 | O28: TL | S28: İhale Bedeli | Z28: : | AA28: 21.982.861.000,00 TL + KDV
C29: =+"Sözleşme Nakit Teminat Kesintisi ( "&B13&" x %5 ) " &TEXT(ROUND(N13*5%,2),"0.000,00") & " TL"&" Nakit Teminat Kesintisi yerine teminat mektubu verilmiştir." -> Sözleşme Nakit Teminat Kesintisi ( D x %5 ) 2.379.152,27 TL Nakit Teminat Kesintisi yerine teminat mektubu verilmiştir. | O29: TL
C30: Fiyat Farkı Ek Kesin Teminatı (Sözleşme Madde 10.2.1) (B x %6) (Teminat Mektubu Verildiğinden Uygulanmamıştır.) | O30: TL | S30: İhale Tarihi | Z30: : | AA30: 45614
C31: KDV Kanununa göre yapılacak Tevkifatlar | O31: TL
E32: M) | F32: Kesintiler Toplamı | N32: =SUM(N23:N31) -> 475830.45 | O32: TL | S32: İhale Tenzilatı | Z32: : | AA32: -
L33: YÜKLENİCİYE ÖDENECEK TUTAR ( J - L ) | N33: =+N22-N32 -> 56623824 | O33: TL
N34: =+'Para Yazdırma'!B1 -> ElliAltıMilyonAltıyüzYirmiÜçBinSekizyüzYirmiDörtLiraYediKuruş | O34: # | S34: Sözleşme Tarihi | Z34: : | AA34: 45639
B35: N | C35: =+Veri!$C$21 -> 6 | N35: =+N33-N36 -> 47583045 | O35: TL
B36: O | C36: =+Veri!$C$21 -> 6 | N36: =+N21-N32 -> 9040778.6 | O36: TL | S36: İşyeri Teslim Tarihi | Z36: : | AA36: 45653
S38: İşyeri Başlama Tarihi | Z38: : | AA38: 45653
S40: Sözleşmeye Göre İşin Süresi | Z40: : | AA40: 1440 Gün
S42: Sözleşmeye Göre İşin Bitiş Tarihi | Z42: : | AA42: 47093
S44: Verilen Avanslar Toplamı | Z44: : | AA44: -
S46: Mahsubu Yapılan Avansın Miktarı | Z46: : | AA46: -
...

Sheet İcmal
B2: T.C. | T2: T.C.
B3: İSTANBUL BÜYÜKŞEHİR BELEDİYE BAŞKANLIĞI | T3: İSTANBUL BÜYÜKŞEHİR BELEDİYE BAŞKANLIĞI
B4: Raylı Sistem Daire Başkanlığı | T4: Raylı Sistem Dairesi Başkanlığı
B5: Avrupa Yakası Raylı Sistem Şube Müdürlüğü | T5: Avrupa Yakası Raylı Sistem Şube Müdürlüğü
B6: Kirazlı-Halkalı Üniversite Metro Hattı İnşaat Ve Elektromekanik İşler İle M1 Hattı Elektromekanik Sistemleri Yapım İşi | T6: Kirazlı-Halkalı Üniversite Metro Hattı İnşaat Ve Elektromekanik İşler İle M1 Hattı Elektromekanik Sistemleri Yapım İşi
T7: İCMAL
B8: ="Hakediş No: "&Veri!C21&" Hakediş Tarihi: "&TEXT(Veri!C22,"gg.aa.yyyy") -> Hakediş No: 6 Hakediş Tarihi: 30.04.2026
B9: SIRA NO | C9: İLGİLİ İDARE | F9: İŞİN CİNSİ | J9: HAKEDİŞ NO | L9: FATURA TARİHİ | N9: TUTARI (TL) | U9: ="Hakediş No: "&Veri!C21&" Hakediş Tarihi: "&TEXT(Veri!C22,"gg.aa.yyyy") -> Hakediş No: 6 Hakediş Tarihi: 30.04.2026 | AC9: SÖZLEŞME FİYATLARI İLE YAPILAN İŞİN TUTARLARI (TL)
AB10: SÖZLEŞME BEDELİ (TL) | AC10: ÖNCEKİ HAKEDİŞ KÜMÜLATİF | AD10: BU HAKEDİŞ | AE10: BU HAKEDİŞ KÜMÜLATİF
B11: 1
B13: 2 | U13: 1 | V13: KABA ve İNCE İNŞAAT İŞLERİ | AB13: =SUM(AB14:AB17) -> 1.4142506e+10 | AC13: =+'Yapılan İşler İcmali'!$R$14 -> 0 | AD13: =+AE13-AC13 -> 37210860 | AE13: =+'Yapılan İşler İcmali'!$T$14 -> 37210860
U14: 01.1 | V14: Açıkta İnşaat İşleri | AB14: 4.4056996e+09 | AC14: =+'Yapılan İşler İcmali'!$R$15 -> 0 | AD14: =+AE14-AC14 -> 0 | AE14: =+'Yapılan İşler İcmali'!$T$15 -> 0
B15: 3 | U15: 01.2 | V15: Tünel İnşaat İşleri | AB15: 8.6083815e+09 | AC15: =+'Yapılan İşler İcmali'!$R$115 -> 0 | AD15: =+AE15-AC15 -> 37210860 | AE15: =+'Yapılan İşler İcmali'!$T$115 -> 37210860
U16: 01.3 | V16: Jeoteknik Ölçümler | AB16: 160312500 | AC16: =+'Yapılan İşler İcmali'!$R$158 -> 0 | AD16: =+AE16-AC16 -> 0 | AE16: =+'Yapılan İşler İcmali'!$T$158 -> 0
B17: 4 | U17: 01.4 | V17: İnce İnşaat İşleri | AB17: 9.6811216e+08 | AC17: =+'Yapılan İşler İcmali'!$R$183 -> 0 | AD17: =+AE17-AC17 -> 0 | AE17: =+'Yapılan İşler İcmali'!$T$183 -> 0
U18: 02 | V18: ELEKTRİK İŞLERİ | AB18: 1424774746 | AC18: =+'Yapılan İşler İcmali'!$R$353 -> 0 | AD18: =+AE18-AC18 -> 0 | AE18: =+'Yapılan İşler İcmali'!$T$353 -> 0
B19: 5 | U19: 03 | V19: SİNYALİZASYON SİSTEMİ | AB19: 3338487540 | AC19: =+'Yapılan İşler İcmali'!$R$489 -> 0 | AD19: =+AE19-AC19 -> 0 | AE19: =+'Yapılan İşler İcmali'!$T$489 -> 0
U20: 04 | V20: HABERLEŞME KONTROL VE SİSTEMLERİ | AB20: 419129552 | AC20: =+'Yapılan İşler İcmali'!$R$523 -> 0 | AD20: =+AE20-AC20 -> 0 | AE20: =+'Yapılan İşler İcmali'!$T$523 -> 0
B21: 6 | U21: 05 | V21: ÇEVRESEL KONTROL SİSTEMİ | AB21: 274307568 | AC21: =+'Yapılan İşler İcmali'!$R$659 -> 0 | AD21: =+AE21-AC21 -> 0 | AE21: =+'Yapılan İşler İcmali'!$T$659 -> 0
U22: 06 | V22: YARDIMCI TESİSLER | AB22: 360484829 | AC22: =+'Yapılan İşler İcmali'!$R$693 -> 0 | AD22: =+AE22-AC22 -> 0 | AE22: =+'Yapılan İşler İcmali'!$T$693 -> 0
B23: 7 | U23: 07 | V23: YÜRÜYEN MERDİVEN | AB23: 318420015 | AC23: =+'Yapılan İşler İcmali'!$R$761 -> 0 | AD23: =+AE23-AC23 -> 0 | AE23: =+'Yapılan İşler İcmali'!$T$761 -> 0
U24: 08 | V24: DEMİRYOLU İŞLERİ | AB24: 5.4711241e+08 | AC24: =+'Yapılan İşler İcmali'!$R$795 -> 0 | AD24: =+AE24-AC24 -> 0 | AE24: =+'Yapılan İşler İcmali'!$T$795 -> 0
B25: 8 | U25: 09 | V25: GENEL HİZMETLER | AB25: 221794750 | AC25: =+'Yapılan İşler İcmali'!$R$829 -> 0 | AD25: =+AE25-AC25 -> 0 | AE25: =+'Yapılan İşler İcmali'!$T$829 -> 0
U26: 10 | V26: M1A ve M1B İŞLERİ | AB26: 7.858438e+08 | AC26: =+'Yapılan İşler İcmali'!$R$866 -> 0 | AD26: =+AE26-AC26 -> 0 | AE26: =+'Yapılan İşler İcmali'!$T$866 -> 0
B27: 9 | U27: 11 | V27: DİĞER KURUM VE KURULUŞLARLA İLGİLİ İŞLER | AB27: 75000000 | AC27: =+'Yapılan İşler İcmali'!$R$1036 -> 0 | AD27: =+AE27-AC27 -> 0 | AE27: =+'Yapılan İşler İcmali'!$T$1036 -> 0
U28: 12 | V28: FATURALI GİDERLER | AB28: 75000000 | AC28: =+'Yapılan İşler İcmali'!$R$1038 -> 0 | AD28: =+AE28-AC28 -> 0 | AE28: =+'Yapılan İşler İcmali'!$T$1038 -> 0
B29: 10 | U29: A) | V29: İMALAT İŞLERİ TOPLAMI | AB29: =SUM(AB14:AB28) -> 2.1982861e+10 | AC29: =SUM(AC14:AC28) -> 0 | AD29: =+AE29-AC29 -> 37210860 | AE29: =SUM(AE14:AE28) -> 37210860
U31: B) | V31: İHZARAT İŞLERİ TOPLAMI | AC31: 0 | AD31: =+AE31-AC31 -> 0 | AE31: 0
B32: 11
V33: İMALAT ve İHZARAT TUTARI | AC33: =+AC29+AC31 -> 0 | AD33: =+AE33-AC33 -> 37210860 | AE33: =+AE29+AE31 -> 37210860
U35: C) | V35: FİYAT FARKI (Fiyat Farkı Hesabı Sayfasından) | AC35: =+'Fiyat Farkı İcmal'!P43 -> 0 | AD35: =+'Fiyat Farkı İcmal'!Q43 -> 10372185 | AE35: =+'Fiyat Farkı İcmal'!R43 -> 10372185
L37: TOPLAM | N37: =ROUND(SUM(N11:P36),2) -> 0 | U37: D) | V37: KESİNTİLER | AC37: =SUM(AC38:AC39) -> 0 | AD37: =SUM(AD38:AD39) -> 0 | AE37: =SUM(AE38:AE39) -> 0
L38: ÖNCEKİ HAKEDİŞ | N38: 0 | V38: D.1) Daha Önceki Hakedişlerde Yapılan Kesintiler | AC38: 0 | AD38: 0 | AE38: 0
L39: BU HAKEDİŞ | N39: =ROUND(+N37-N38,2) -> 0 | V39: D.2) Bu hakedişte Yapılan Kesintiler | AC39: 0 | AD39: 0 | AE39: 0
U41: E) | V41: İhale Tenzilatına Tabi Ödemeler Tutarı (A+B+C)-D | AC41: =+AC29+AC31+AC35-AC37 -> 0 | AD41: =+AD29+AD31+AD35-AD37 -> 47583045 | AE41: =+AE29+AE31+AE35-AE37 -> 47583045

Sheet Teminat Mektupları
B2: T.C.
B3: İstanbul Büyükşehir Belediyesi
B4: Raylı Sistem Dairesi Başkanlığı
B5: Avrupa Yakası Raylı Sistem Şube Müdürlüğü
B7: Kirazlı-Halkalı Üniversite Metro Hattı İnşaat Ve Elektromekanik İşler İle M1 Hattı Elektromekanik Sistemleri Yapım İşi
B10: ="Hakediş No: "&Veri!C21&" Hakediş Tarihi: "&TEXT(Veri!C22,"gg.aa.yyyy") -> Hakediş No: 6 Hakediş Tarihi: 30.04.2026
B12: TESLİM EDİLEN TEMİNAT MEKTUPLARI LİSTESİ (İhtiyat Kesintisi)
B13: Sıra No | C13: Teminat Mektubu Tarihi | D13: Teminat Mektubu Sayısı | E13: Teminat Mektubu Tutarı | F13: Teminat Mektubu Kümülatif Tutarı | G13: Teminat Mektubunu Veren Banka | H13: Açıklama | J13: Geçerlilik Tarihi
B14: 1 | M14: =+İcmal!AE41 -> 47583045
B15: 2 | M15: =+M14*0.05 -> 2379152.3
B16: 3 | M16: =+SUM(E14:E39) -> 0
B17: 4 | L17: Verilecek | M17: =+M15-M16 -> 2379152.3
B18: 5
B19: 6
B20: 7
B21: 8
B22: 9
B23: 10
B24: 11
B25: 12
B26: 13
B27: 14
B28: 15
B29: 16
... B39: 26
B40: =+Veri!$C$21 -> 6 | C40: =+"Nolu Hakediş itibarı ile toplam hakediş "&TEXT(İcmal!$AE$41,"#.##0,00")&" TL olup, "&TEXT(İcmal!$AE$41,"#.##0,00")&" x %5 = "&TEXT(ROUND(İcmal!$AE$41*0.05,2),"#.##0,00")&" TL tutarına karşılık Teminat Mektubu verilmiştir" -> Nolu Hakediş itibarı ile toplam hakediş 47.583.045,43 TL olup, 47.583.045,43 x %5 = 2.379.152,27 TL tutarına karşılık Teminat Mektubu verilmiştir
B42: YÜKLENİCİ | E42: DANIŞMAN | G42: İDARE
B43: Kalyon-Özgün Metro İnşaatı Adi Ortaklığı | E43: Yüksel Proje A.Ş. | G43: T.C. İSTANBUL BÜYÜKŞEHİR BELEDİYESİ Raylı Sistem Dairesi Başkanlığı Avrupa Yakası Raylı Sistem Şube Müdürlüğü
E56: Fatih AYDIN | G56: Atilla Alkan
E57: Elektromekanik Kontrol Amiri | G57: İnşaat Kontrol Mühendisi
B64: Kemal YERLİ | E64: Orhan KOCA | G64: Osman ŞAHİN | I64: Hakan ARZU
B65: Proje Müdürü | E65: Proje Müdürü | G65: İnşaat Müdür Yardımcısı | I65: E&M Müdür Yardımcısı

Sheet Teminat Mektupları (FF)
B2: T.C.
B3: İstanbul Büyükşehir Belediyesi
B4: Raylı Sistem Dairesi Başkanlığı
B5: Avrupa Yakası Raylı Sistem Şube Müdürlüğü
B7: Kirazlı-Halkalı Üniversite Metro Hattı İnşaat Ve Elektromekanik İşler İle M1 Hattı Elektromekanik Sistemleri Yapım İşi
B9: ="Hakediş No: "&Veri!C21&" Hakediş Tarihi: "&TEXT(Veri!C22,"gg.aa.yyyy") -> Hakediş No: 6 Hakediş Tarihi: 30.04.2026
B11: TESLİM EDİLEN KESİN TEMİNAT MEKTUPLARI LİSTESİ
B12: Sıra No | C12: Teminat Mektubu Tarihi | D12: Teminat Mektubu Sayısı | E12: Teminat Mektubu Tutarı | F12: Teminat Mektubu Kümülatif Tutarı | G12: Teminat Mektubunu Veren Banka | H12: Açıklama | J12: Geçerlilik Tarihi
B13: 1 | C13: 45639 | D13: 2024121300121256587 | E13: 8.7935841e+08 | F13: =+E13 -> 8.7935841e+08 | G13: Halkbank | J13: 48233
B14: 2 | C14: 45639 | D14: 2024121300121256627 | E14: 4.3961325e+08 | F14: =+F13+E14 -> 1318971660 | G14: Halkbank | J14: 48233
C15: =+"Sözleşme bedeli "&TEXT(Veri!$C$2,"#.##0,00")&" TL olup, "&TEXT(Veri!$C$2,"#.##0,00")&" x %6 = "&TEXT(ROUND(Veri!$C$2*0.06,2),"#.##0,00")&" TL tutarına karşılık Teminat Mektubu verilmiştir" -> Sözleşme bedeli 21.982.861.000,00 TL olup, 21.982.861.000,00 x %6 = 1.318.971.660,00 TL tutarına karşılık Teminat Mektubu verilmiştir
B16: TESLİM EDİLEN KESİN TEMİNAT MEKTUPLARI LİSTESİ (Fiyat Farkı İçin)
B18: Sıra No | C18: Teminat Mektubu Tarihi | D18: Teminat Mektubu Sayısı | E18: Teminat Mektubu Tutarı | F18: Teminat Mektubu Kümülatif Tutarı | G18: Teminat Mektubunu Veren Banka | H18: Açıklama | J18: Geçerlilik Tarihi
B19: 1 | M19: =+İcmal!AE35 -> 10372185
B20: 2 | M20: =+M19*0.06 -> 622331.1
B21: 3 | M21: =+SUM(E19:E37) -> 0
B22: 4 | L22: Verilecek | M22: =+M20-M21 -> 622331.1
B23: 5
B24: 6
B25: 7
B26: 8
B27: 9
B28: 10
B29: 11
B30: 12
B31: 13
B32: 14
B33: 15
B34: 16
... B37: 19
B38: =+Veri!$C$21 -> 6 | C38: ="Nolu Hakediş itibari ile toplam hesaplanan fiyat farkı "&TEXT('Fiyat Farkı İcmal'!$R$43,"#.##0,00")&" TL olup, "&TEXT('Fiyat Farkı İcmal'!$R$43,"#.##0,00")&" x %6 = "&TEXT(ROUND('Fiyat Farkı İcmal'!$R$43*0.06,2),"#.##0,00")&" TL tutarına karşılık Teminat Mektubu verilmiştir" -> Nolu Hakediş itibari ile toplam hesaplanan fiyat farkı 10.372.185,00 TL olup, 10.372.185,00 x %6 = 622.331,10 TL tutarına karşılık Teminat Mektubu verilmiştir
B40: YÜKLENİCİ | E40: DANIŞMAN | G40: İDARE
B41: Kalyon-Özgün Metro İnşaatı Adi Ortaklığı | E41: Yüksel Proje A.Ş. | G41: T.C. İSTANBUL BÜYÜKŞEHİR BELEDİYESİ Raylı Sistem Dairesi Başkanlığı Avrupa Yakası Raylı Sistem Şube Müdürlüğü
E54: Fatih AYDIN | G54: Atilla Alkan
E55: Elektromekanik Kontrol Amiri | G55: İnşaat Kontrol Mühendisi
B62: Kemal YERLİ | E62: Orhan KOCA | G62: Osman ŞAHİN | I62: Hakan ARZU
B63: Proje Müdürü | E63: Proje Müdürü | G63: İnşaat Müdür Yardımcısı | I63: E&M Müdür Yardımcısı

Sheet Fiyat Farkı İcmal
A3: T.C.
A4: İstanbul Büyükşehir Belediyesi
A5: Raylı Sistem Dairesi Başkanlığı
A6: Avrupa Yakası Raylı Sistem Şube Müdürlüğü
A8: Kirazlı-Halkalı Üniversite Metro Hattı İnşaat Ve Elektromekanik İşler İle M1 Hattı Elektromekanik Sistemleri Yapım İşi
A10: FİYAT FARKI İCMALİ
B11: ="Hakediş No: "&[4]Veri!C21&" Hakediş Tarihi: "&TEXT(Veri!C22,"gg.aa.yyyy") -> Hakediş No: 5 Hakediş Tarihi: 30.04.2026
B15: Hakediş No | C15: Hakediş Dönemi | D15: İmalat Dönemi | F15: Hakediş Tutarı ( Aylık ) | G15: Hakediş Tutarı ( Kümülatif ) | H15: Avans Kesintisi Tutarı | I15: Avans Kesintisi Tutarı ( Kümülatif ) | J15: İş Programı Nakit Akış (Ay ) | K15: İş Programı Nakit Akış ( Aylık ) | L15: İş Programı Nakit Akış ( Kümülatif ) | M15: İş Programı Nakit Akışına Göre Hakediş Tutarı | N15: Avans Kesintisi Tutarı | O15: Fiyat Farkına Tabi Tutar ( An ) | P15: Pn | Q15: B=0,90 | R15: B x (Pn-1) | S15: Ödenmesi Gereken Fiyat Farkı Tutarı (F = An x B x ( Pn - 1 )
F16: a | G16: b | H16: c = a x % 15,00 | I16: d | K16: e | L16: f | M16: g | N16: h = g x % 15,00 | O16: a | P16: l | Q16: m | S16: n
B17: 1 | W17: Geoteknik | X17: Tasarım
V18: =SUM(W18:Y18) -> 873600 | W18: 873600
V19: =SUM(W19:Y19) -> 873600 | W19: 873600
V20: =SUM(W20:Y20) -> 947614.63 | W20: 873600 | X20: =ROUND(6167886*0.012,2) -> 74014.63
V21: =SUM(W21:Y21) -> 799585.37 | W21: 873600 | X21: =+SUM('[5]Yapılan İşler İcmali'!T79:T84)-X20 -> -74014.63
B22: 2
B25: 3
Z28: =+H35+H34+H33+H31+H30+H29+H28+H27+H26+H24+H23+H21+H20+H19+H18 -> 0
B32: 4
B36: 5
B41: 6 | C41: 46113 | D41: 46113 | E41: =+'Yapılan İşler İcmali'!S115 -> 37210860 | F41: =+E41 -> 37210860 | J41: 46023 | K41: =+'[6]Ödenek Dağılımı Sonrası 18. (2)'!$U$74 -> 4.6610025e+08 | L41: =+'[6]Ödenek Dağılımı Sonrası 18. (2)'!$V$74 -> 1.5634392e+09 | M41: =+'[6]Ödenek Dağılımı Sonrası 18. (2)'!$V$74 -> 1.5634392e+09 | N41: =+M41*0.15*0 -> 0 | O41: =+F41 -> 37210860 | P41: =+[7]FF!$AC$32 -> 1.309712 | Q41: 0.9 | R41: =+Q41*(P41-1) -> 0.2787408 | S41: =+ROUND(O41*Q41*(P41-1),2) -> 10372185
P42: Önceki Hakediş Kümülatif | Q42: Bu Hakediş | R42: Bu Hakediş Kümülatif
B43: TOPLAM | Q43: =+R43-P43 -> 10372185 | R43: =SUM(S18:S41) -> 10372185
B46: YÜKLENİCİ | I46: DANIŞMAN | O46: İDARE
B47: Kalyon-Özgün Metro İnşaatı Adi Ortaklığı | I47: Yüksel Proje A.Ş. | O47: T.C. İSTANBUL BÜYÜKŞEHİR BELEDİYESİ Raylı Sistem Dairesi Başkanlığı Avrupa Yakası Raylı Sistem Şube Müdürlüğü
I50: Aybüke YEĞEN | L50: Yılmaz SATI
I51: Hakediş, Mukavele Takip, Kesin Hesap Kontrol Mühendisi | L51: Hakediş, Mukavele Takip, Kesin Hesap Kontrol Mühendisi
O55: Yasin YEŞİLDAĞ
I56: Fatih AYDIN | O56: Maden Kontrol Mühendisi
I57: Elektromekanik Kontrol Amiri
B62: Kemal YERLİ | I62: Orhan KOCA | O62: Osman ŞAHİN | S62: Hakan ARZU
B63: Proje Müdürü | I63: Proje Müdürü | O63: İnşaat Müdür Yardımcısı | S63: E&M Müdür Yardımcısı
C67: YÜKLENİCİ | J67: DANIŞMAN | P67: İDARE
C68: Kalyon-Özgün Metro İnşaatı Adi Ortaklığı | J68: Yüksel Proje A.Ş. | P68: T.C. İSTANBUL BÜYÜKŞEHİR BELEDİYESİ Raylı Sistem Dairesi Başkanlığı Avrupa Yakası Raylı Sistem Şube Müdürlüğü
J71: Aybüke YEĞEN | M71: Yılmaz SATI
J72: Hakediş, Mukavele Takip, Kesin Hesap Kontrol Mühendisi | M72: Hakediş, Mukavele Takip, Kesin Hesap Kontrol Mühendisi
P76: Yasin YEŞİLDAĞ
J77: Fatih AYDIN | P77: Maden Kontrol Mühendisi
J78: Elektromekanik Kontrol Amiri
C83: Kemal YERLİ | J83: Orhan KOCA | P83: Osman ŞAHİN | T83: Hakan ARZU
C84: Proje Müdürü | J84: Proje Müdürü | P84: İnşaat Müdür Yardımcısı | T84: E&M Müdür Yardımcısı

Sheet Fiyat Farkı İcmal (2)
A3: T.C.
A4: İstanbul Büyükşehir Belediyesi
A5: Raylı Sistem Dairesi Başkanlığı Avrupa Yakası Raylı Sistem Şube Müdürlüğü
A7: Kirazlı-Halkalı Üniversite Metro Hattı İnşaat Ve Elektromekanik İşler İle M1 Hattı Elektromekanik Sistemleri Yapım İşi
A9: FİYAT FARKI İCMALİ
Q10: Hakediş No : | R10: =+[8]Veri!$C$21 -> 3
Q11: Hakediş Tarihi : | R11: =+[8]Veri!$C$22 -> 45900
B14: Hakediş No | C14: Hakediş Dönemi | D14: İmalat Dönemi | E14: Hakediş Tutarı ( Aylık ) | F14: Hakediş Tutarı ( Kümülatif ) | G14: Avans Kesintisi Tutarı | H14: Avans Kesintisi Tutarı ( Kümülatif ) | I14: İş Programı Nakit Akış (Ay ) | J14: İş Programı Nakit Akış ( Aylık ) | K14: İş Programı Nakit Akış ( Kümülatif ) | L14: İş Programı Nakit Akışına Göre Hakediş Tutarı | M14: Avans Kesintisi Tutarı | N14: Fiyat Farkına Tabi Tutar ( An ) | O14: Pn | P14: B=0,90 | Q14: Ödenmesi Gereken Fiyat Farkı Tutarı (F = An x B x ( Pn - 1 ) | R14: Bir Önceki Hakediş Fiyat Farkı Tutarı | S14: Bu Hakedişte Ödenecek Fiyat Farkı Tutarı
E15: a | F15: b | G15: c = a x % 15,00 | H15: d | J15: e | K15: f | L15: g | M15: h = g x % 15,00 | N15: a | O15: l | P15: m | Q15: n | R15: o | S15: p = n - o
B16: 1 | C16: 45764 | E16: =SUM(E17:E20) -> 9873535.8 | F16: 9873535.8 | G16: =+ROUND(E17*0.15*0,2) -> 0 | H16: =+G16 -> 0 | I16: İş Programı Nakit Akış Diyagramında Bu Döneme Ait Ödenek Yer Almamaktadır. | N16: =SUM(N17:N20) -> 9873535.8 | Q16: =SUM(Q17:Q20) -> 800759.19 | R16: =SUM(R17:R20) -> 800759.19 | S16: =SUM(S17:S20) -> 0 | W16: Geoteknik | X16: Tasarım
D17: 45658 | E17: 873600 | N17: =+E17 -> 873600 | O17: =+[8]FF!$AC$20 -> 1.040261 | P17: 0.9 | Q17: =+ROUND(N17*P17*(O17-1),2) -> 31654.81 | R17: 31654.81 | S17: =+Q17-R17 -> 0 | V17: =SUM(W17:Y17) -> 873600 | W17: 873600
D18: 45689 | E18: 873600 | N18: =+E18 -> 873600 | O18: =+[8]FF!$AC$21 -> 1.061283 | P18: 0.9 | Q18: =+ROUND(N18*P18*(O18-1),2) -> 48183.15 | R18: 48183.15 | S18: =+Q18-R18 -> 0 | V18: =SUM(W18:Y18) -> 873600 | W18: 873600
D19: 45717 | E19: 947614.63 | N19: =+E19 -> 947614.63 | O19: =+[8]FF!$AC$22 -> 1.077203 | P19: 0.9 | Q19: =+ROUND(N19*P19*(O19-1),2) -> 65842.82 | R19: 65842.82 | S19: =+Q19-R19 -> 0 | V19: =SUM(W19:Y19) -> 947614.63 | W19: 873600 | X19: =ROUND(6167886*0.012,2) -> 74014.63
D20: 45748 | E20: 7178721.2 | N20: =+E20 -> 7178721.2 | O20: =+[8]FF!AC23 -> 1.101392 | P20: 0.9 | Q20: =+ROUND(N20*P20*(O20-1),2) -> 655078.41 | R20: 655078.41 | S20: =+Q20-R20 -> 0 | V20: =SUM(W20:Y20) -> 7178721.2 | W20: 873600 | X20: =+SUM('[8]Yapılan İşler İcmali'!Q67:Q72)-X19 -> 6305121.2
B21: 2 | C21: 45838 | E21: =SUM(E22:E23) -> 22146367 | F21: =+[8]İcmal!AA28 -> 32019903 | G21: =+ROUND(E22*0.15*0,2) -> 0 | H21: =+G21 -> 0 | I21: 45778 | J21: 3.4736862e+08 | K21: 3.4736862e+08 | L21: =+J21 -> 3.4736862e+08 | M21: =+L21*0.15*0 -> 0 | N21: =SUM(N22:N23) -> 22146367 | Q21: =SUM(Q22:Q23) -> 2417479.7 | R21: =SUM(R22:R23) -> 2417479.7 | S21: =SUM(S22:S23) -> 0 | V21: =SUM(V17:V20) -> 9873535.8 | W21: =+E16-V21 -> 0
D22: 45778 | E22: 873600 | I22: 45778 | J22: 3.4736862e+08 | K22: 3.4736862e+08 | L22: 3.4736862e+08 | M22: =+L22*0.15*0 -> 0 | N22: =+E22 -> 873600 | O22: =+[8]FF!AC24 -> 1.121288 | P22: 0.9 | Q22: =+ROUND(N22*P22*(O22-1),2) -> 95361.48 | R22: 95361.48 | S22: =+Q22-R22 -> 0
D23: 45809 | E23: 21272767 | M23: =+L23*0.15*0 -> 0 | N23: =+E23 -> 21272767 | O23: =+[8]FF!AC24 -> 1.121288 | P23: 0.9 | Q23: =+ROUND(N23*P23*(O23-1),2) -> 2322118.2 | R23: 2322118.2 | S23: =+Q23-R23 -> 0
B24: 3 | C24: 45839 | E24: =SUM(E25:E27) -> 3.1534872e+08 | F24: =+E16+E21+E24 -> 3.4736862e+08 | I24: 45778 | J24: 3.4736862e+08 | K24: 3.4736862e+08 | L24: 3.4736862e+08 | N24: =+E24 -> 3.1534872e+08 | P24: =+[8]FF!AC24 -> 1.121288 | Q24: =SUM(Q25:Q27) -> 34423214 | R24: =SUM(R25:R27) -> 0 | S24: =+Q24-R24 -> 34423214
D25: 45839 | E25: 1.1121871e+08 | I25: 45778 | J25: 3.4736862e+08 | K25: 3.4736862e+08 | L25: 3.4736862e+08 | M25: =+L25*0.15*0 -> 0 | N25: =+E25 -> 1.1121871e+08 | O25: =+[8]FF!AC24 -> 1.121288 | P25: 0.9 | Q25: =+ROUND(N25*P25*(O25-1),2) -> 12140545 | R25: 0 | S25: =+Q25-R25 -> 12140545
D26: 45870 | E26: 1.8568156e+08 | M26: =+L26*0.15*0 -> 0 | N26: =+E26 -> 1.8568156e+08 | O26: =+[8]FF!AC24 -> 1.121288 | P26: 0.9 | Q26: =+ROUND(N26*P26*(O26-1),2) -> 20268851 | R26: 0 | S26: =+Q26-R26 -> 20268851 | V26: 3.4736862e+08 | W26: =+N25+N26+N23+N22+N20+N19+N18+N17 -> 3.2892017e+08 | X26: =V26-W26 -> 18448449
D27: 45901 | E27: =+X26 -> 18448449 | M27: =+L27*0.15*0 -> 0 | N27: =+E27 -> 18448449 | O27: =+[8]FF!AC24 -> 1.121288 | P27: 0.9 | Q27: =+ROUND(N27*P27*(O27-1),2) -> 2013818 | R27: 0 | S27: =+Q27-R27 -> 2013818 | V27: =+[8]İcmal!AC32 -> 5.5163797e+08 | W27: =V27-V26 -> 2.0426935e+08
E28: =SUM(E29) -> 2.0426935e+08 | F28: =+[8]İcmal!AC28 -> 5.5163797e+08 | I28: 45810 | J28: 4.4097968e+08 | K28: 7.883483e+08 | L28: 7.883483e+08 | N28: =+E28 -> 2.0426935e+08 | P28: =+[8]FF!AC25 -> 1.152263 | Q28: =SUM(Q29) -> 27992397 | R28: =SUM(R29) -> 0 | S28: =+Q28-R28 -> 27992397
D29: 45902 | E29: =+W27 -> 2.0426935e+08 | I29: 45810 | J29: 4.4097968e+08 | K29: 7.883483e+08 | L29: 7.883483e+08 | M29: =+L29*0.15*0 -> 0 | N29: =+E29 -> 2.0426935e+08 | O29: =+[8]FF!AC25 -> 1.152263 | P29: 0.9 | Q29: =+ROUND(N29*P29*(O29-1),2) -> 27992397 | R29: 0 | S29: =+Q29-R29 -> 27992397
B33: TOPLAM | Q33: =+Q16+Q21+Q24+Q28 -> 65633850 | R33: =+R16+R21+R24 -> 3218238.9 | S33: =+S16+S21+S24+S28 -> 62415611
S35: Yapılacak ilk iş programında ödenek dilimleri güncellenecektir.
B40: YÜKLENİCİ | H40: DANIŞMAN | N40: İDARE
B41: Kalyon-Özgün Metro İnşaatı Adi Ortaklığı | H41: Yüksel Proje A.Ş. | N41: T.C. İstanbul Büyükşehir Belediyesi
H48: Sinan GENÇTÜRK | K48: Fatih AYDIN
H49: NATM Tünel Şefi | K49: Elektromekanik Kontrol Amiri
B56: Kemal YERLİ | H56: Orhan KOCA | N56: Osman ŞAHİN | Q56: Hakan ARZU
B57: Proje Müdürü | H57: Proje Müdürü | N57: İnşaat Müdür Yardımcısı | Q57: E&M Müdür Yardımcısı

Sheet FF 2502
B3: T.C.
B4: İstanbul Büyükşehir Belediyesi
B5: Raylı Sistem Daire Başkanlığı Avrupa Yakası Raylı Sistem Müdürlüğü
B7: Kirazlı-Halkalı Üniversite Metro Hattı İnşaat Ve Elektromekanik İşler İle M1 Hattı Elektromekanik Sistemleri Yapım İşi
B9: FİYAT FARKI HESABI
Y10: Hakediş No : | Z10: =+Veri!$C$21 -> 6
I11: ŞUBAT 2025 DÖNEMİ HESAPLAMASI | Y11: Hakediş Tarihi : | Z11: =+Veri!$C$22 -> 46142
C14: Pn | D14: = | E14: a | F14: İn | G14: + | H14: b1 | I14: Çn | J14: + | K14: b2 | L14: Dn | M14: + | N14: b3 | O14: Ayn | P14: + | Q14: b4 | R14: Yn | S14: + | T14: b5 | U14: Kn | V14: + | W14: b6 | X14: Gn | Y14: + | Z14: c | AA14: Mn
F15: İo | I15: Ço | L15: Do | O15: Ayo | R15: Yo | U15: Ko | X15: Go | AA15: Mo
C18: Pn | D18: = | E18: 0.15 | F18: 2883.75 | G18: + | H18: 0.18 | I18: 4641.23 | J18: + | K18: 0.2 | L18: 5462.92 | M18: + | N18: 0.14 | O18: 46.774 | P18: + | Q18: 0.01 | R18: 7114.2 | S18: + | T18: 0.05 | U18: 2936.95 | V18: + | W18: 0.1 | X18: 3943.01 | Y18: + | Z18: 0.17 | AA18: 2808.87 | AD18: =+ROUND((E18*F18/F19+H18*I18/I19+K18*L18/L19+N18*O18/O19+Q18*R18/R19+T18*U18/U19+W18*X18/X19+Z18*AA18/AA19),6) -> 1.061283
F19: 2657.23 | I19: 4382.41 | L19: 5420.45 | O19: 42.87 | R19: 6482.77 | U19: 2785.67 | X19: 3731.43 | AA19: 2592.48
C22: Pn | D22: = | E22: =+AD18 -> 1.061283
A26: YÜKLENİCİ | I26: DANIŞMAN | R26: İDARE
A27: Kalyon-Özgün Metro İnşaatı Adi Ortaklığı | I27: Yüksel Proje A.Ş. | R27: T.C. İstanbul Büyükşehir Belediyesi
I33: Aybüke YEĞEN Hakediş, Mukavele Takip, Kesin Hesap Kontrol Mühendisi
A42: Kemal YERLİ | I42: Osman Taha UYANIK | R42: Osman ŞAHİN | X42: Hakan ARZU
A43: Proje Müdürü | I43: Proje Müdür Vekili | R43: İnşaat Müdür Yardımcısı | X43: E&M Müdür Yardımcısı

Sheet FF 2503
B3: T.C.
B4: İstanbul Büyükşehir Belediyesi
B5: Raylı Sistem Daire Başkanlığı Avrupa Yakası Raylı Sistem Müdürlüğü
B7: Kirazlı-Halkalı Üniversite Metro Hattı İnşaat Ve Elektromekanik İşler İle M1 Hattı Elektromekanik Sistemleri Yapım İşi
B9: FİYAT FARKI HESABI
Y10: Hakediş No : | Z10: =+Veri!$C$21 -> 6
I11: MART 2025 DÖNEMİ HESAPLAMASI | Y11: Hakediş Tarihi : | Z11: =+Veri!$C$22 -> 46142
C14: Pn | D14: = | E14: a | F14: İn | G14: + | H14: b1 | I14: Çn | J14: + | K14: b2 | L14: Dn | M14: + | N14: b3 | O14: Ayn | P14: + | Q14: b4 | R14: Yn | S14: + | T14: b5 | U14: Kn | V14: + | W14: b6 | X14: Gn | Y14: + | Z14: c | AA14: Mn
F15: İo | I15: Ço | L15: Do | O15: Ayo | R15: Yo | U15: Ko | X15: Go | AA15: Mo
C18: Pn | D18: = | E18: 0.15 | F18: 2954.69 | G18: + | H18: 0.18 | I18: 4700.89 | J18: + | K18: 0.2 | L18: 5566.78 | M18: + | N18: 0.14 | O18: 45.9207 | P18: + | Q18: 0.01 | R18: 6895.61 | S18: + | T18: 0.05 | U18: 3052.11 | V18: + | W18: 0.1 | X18: 4017.3 | Y18: + | Z18: 0.17 | AA18: 2880.53 | AD18: =+ROUND((E18*F18/F19+H18*I18/I19+K18*L18/L19+N18*O18/O19+Q18*R18/R19+T18*U18/U19+W18*X18/X19+Z18*AA18/AA19),6) -> 1.077203
F19: 2657.23 | I19: 4382.41 | L19: 5420.45 | O19: 42.87 | R19: 6482.77 | U19: 2785.67 | X19: 3731.43 | AA19: 2592.48
C22: Pn | D22: = | E22: =+AD18 -> 1.077203
A26: YÜKLENİCİ | I26: DANIŞMAN | R26: İDARE
A27: Kalyon-Özgün Metro İnşaatı Adi Ortaklığı | I27: Yüksel Proje A.Ş. | R27: T.C. İstanbul Büyükşehir Belediyesi
I33: Aybüke YEĞEN Hakediş, Mukavele Takip, Kesin Hesap Kontrol Mühendisi
A42: Kemal YERLİ | I42: Osman Taha UYANIK | R42: Osman ŞAHİN | X42: Hakan ARZU
A43: Proje Müdürü | I43: Proje Müdür Vekili | R43: İnşaat Müdür Yardımcısı | X43: E&M Müdür Yardımcısı

Sheet FF
B3: T.C.
B4: İstanbul Büyükşehir Belediyesi
B5: Raylı Sistem Dairesi Başkanlığı Avrupa Yakası Raylı Sistem Şube Müdürlüğü
B7: Kirazlı-Halkalı Üniversite Metro Hattı İnşaat Ve Elektromekanik İşler İle M1 Hattı Elektromekanik Sistemleri Yapım İşi
B9: FİYAT FARKI HESABI
B11: ="Hakediş No: "&[4]Veri!C21&" Hakediş Tarihi: "&TEXT(Veri!C22,"gg.aa.yyyy") -> Hakediş No: 5 Hakediş Tarihi: 30.04.2026
C14: Pn | D14: = | E14: a | F14: İn | G14: + | H14: b1 | I14: Çn | J14: + | K14: b2 | L14: Dn | M14: + | N14: b3 | O14: Ayn | P14: + | Q14: b4 | R14: Yn | S14: + | T14: b5 | U14: Kn | V14: + | W14: b6 | X14: Gn | Y14: + | Z14: c | AA14: Mn
F15: İo | I15: Ço | L15: Do | O15: Ayo | R15: Yo | U15: Ko | X15: Go | AA15: Mo
B17: Fiyat Farkı Dönemi | E17: a | F17: İ | H17: b1 | I17: Ç | K17: b2 | L17: D | N17: b3 | O17: Ay | Q17: b4 | R17: Y | T17: b5 | U17: K | W17: b6 | X17: G | Z17: c | AA17: M | AC17: Pn
B19: Kasım 2024 (o) | E19: 0.15 | F19: 2657.23 | H19: 0.18 | I19: 4382.41 | K19: 0.2 | L19: 5420.45 | N19: 0.14 | O19: 42.87 | Q19: 0.01 | R19: 6482.77 | T19: 0.05 | U19: 2785.67 | W19: 0.1 | X19: 3731.43 | Z19: 0.17 | AA19: 2592.48 | AC19: 1
B20: Ocak 2025 | E20: 0.15 | F20: 2819.65 | H20: 0.18 | I20: 4537.23 | K20: 0.2 | L20: 5406.99 | N20: 0.14 | O20: 46.29363 | Q20: 0.01 | R20: 6911.75 | T20: 0.05 | U20: 2903.1 | W20: 0.1 | X20: 3861.33 | Z20: 0.17 | AA20: 2711.42 | AC20: =+ROUND((E20*F20/$F$19+H20*I20/$I$19+K20*L20/$L$19+N20*O20/$O$19+Q20*R20/$R$19+T20*U20/$U$19+W20*X20/$X$19+Z20*AA20/$AA$19),6) -> 1.040262
B21: Şubat 2025 | E21: 0.15 | F21: 2883.75 | H21: 0.18 | I21: 4641.23 | K21: 0.2 | L21: 5462.92 | N21: 0.14 | O21: 46.77402 | Q21: 0.01 | R21: 7114.2 | T21: 0.05 | U21: 2936.95 | W21: 0.1 | X21: 3943.01 | Z21: 0.17 | AA21: 2808.87 | AC21: =+ROUND((E21*F21/$F$19+H21*I21/$I$19+K21*L21/$L$19+N21*O21/$O$19+Q21*R21/$R$19+T21*U21/$U$19+W21*X21/$X$19+Z21*AA21/$AA$19),6) -> 1.061283
B22: Mart 2025 | E22: 0.15 | F22: 2954.69 | H22: 0.18 | I22: 4700.89 | K22: 0.2 | L22: 5566.78 | N22: 0.14 | O22: 45.92065 | Q22: 0.01 | R22: 6895.61 | T22: 0.05 | U22: 3052.11 | W22: 0.1 | X22: 4017.3 | Z22: 0.17 | AA22: 2880.53 | AC22: =+ROUND((E22*F22/$F$19+H22*I22/$I$19+K22*L22/$L$19+N22*O22/$O$19+Q22*R22/$R$19+T22*U22/$U$19+W22*X22/$X$19+Z22*AA22/$AA$19),6) -> 1.077203
B23: Nisan 2025 | E23: 0.15 | F23: 3043.23 | H23: 0.18 | I23: 4743.75 | K23: 0.2 | L23: 5750.9 | N23: 0.14 | O23: 45.26088 | Q23: 0.01 | R23: 6760.36 | T23: 0.05 | U23: 3183.49 | W23: 0.1 | X23: 4128.19 | Z23: 0.17 | AA23: 2997.5 | AC23: =+ROUND((E23*F23/$F$19+H23*I23/$I$19+K23*L23/$L$19+N23*O23/$O$19+Q23*R23/$R$19+T23*U23/$U$19+W23*X23/$X$19+Z23*AA23/$AA$19),6) -> 1.101392
B24: Mayıs 2025 | E24: 0.15 | F24: 3089.74 | H24: 0.18 | I24: 4808.92 | K24: 0.2 | L24: 5882.18 | N24: 0.14 | O24: 45.45625 | Q24: 0.01 | R24: 6752.22 | T24: 0.05 | U24: 3280.13 | W24: 0.1 | X24: 4230.69 | Z24: 0.17 | AA24: 3068.3 | AC24: =+ROUND((E24*F24/$F$19+H24*I24/$I$19+K24*L24/$L$19+N24*O24/$O$19+Q24*R24/$R$19+T24*U24/$U$19+W24*X24/$X$19+Z24*AA24/$AA$19),6) -> 1.121288
B25: Haziran 2025 | E25: 0.15 | F25: 3132.17 | H25: 0.18 | I25: 4910.55 | K25: 0.2 | L25: 5986.06 | N25: 0.14 | O25: 48.80858 | Q25: 0.01 | R25: 7297.64 | T25: 0.05 | U25: 3375.09 | W25: 0.1 | X25: 4334.94 | Z25: 0.17 | AA25: 3133.65 | AC25: =+ROUND((E25*F25/$F$19+H25*I25/$I$19+K25*L25/$L$19+N25*O25/$O$19+Q25*R25/$R$19+T25*U25/$U$19+W25*X25/$X$19+Z25*AA25/$AA$19),6) -> 1.152263
B26: Temmuz 2025 | E26: 0.15 | F26: 3196.66 | H26: 0.18 | I26: 4972.28 | K26: 0.2 | L26: 6034.24 | N26: 0.14 | O26: 53.14131 | Q26: 0.01 | R26: 7767.87 | T26: 0.05 | U26: 3481.27 | W26: 0.1 | X26: 4409.73 | Z26: 0.17 | AA26: 3218 | AC26: =+ROUND((E26*F26/$F$19+H26*I26/$I$19+K26*L26/$L$19+N26*O26/$O$19+Q26*R26/$R$19+T26*U26/$U$19+W26*X26/$X$19+Z26*AA26/$AA$19),6) -> 1.184532
B27: Ağustos 2025 | E27: 0.15 | F27: 3261.72 | H27: 0.18 | I27: 5053.99 | K27: 0.2 | L27: 6100.24 | N27: 0.14 | O27: 52.3971 | Q27: 0.01 | R27: 7625.39 | T27: 0.05 | U27: 3530.4 | W27: 0.1 | X27: 4518.89 | Z27: 0.17 | AA27: 3259.16 | AC27: =+ROUND((E27*F27/$F$19+H27*I27/$I$19+K27*L27/$L$19+N27*O27/$O$19+Q27*R27/$R$19+T27*U27/$U$19+W27*X27/$X$19+Z27*AA27/$AA$19),6) -> 1.197852
B28: Eylül 2025 | E28: 0.15 | F28: 3367.22 | H28: 0.18 | I28: 5110.09 | K28: 0.2 | L28: 6187.73 | N28: 0.14 | O28: 54.13308 | Q28: 0.01 | R28: 7854.35 | T28: 0.05 | U28: 3572.84 | W28: 0.1 | X28: 4632.89 | Z28: 0.17 | AA28: 3319.76 | AC28: =+ROUND((E28*F28/$F$19+H28*I28/$I$19+K28*L28/$L$19+N28*O28/$O$19+Q28*R28/$R$19+T28*U28/$U$19+W28*X28/$X$19+Z28*AA28/$AA$19),6) -> 1.223153
B29: Ekim 2025 | E29: 0.15 | F29: 3453.09 | H29: 0.18 | I29: 5170.07 | K29: 0.2 | L29: 6350.02 | N29: 0.14 | O29: 53.90374 | Q29: 0.01 | R29: 7797.08 | T29: 0.05 | U29: 3577.46 | W29: 0.1 | X29: 4708.2 | Z29: 0.17 | AA29: 3368.81 | AC29: =+ROUND((E29*F29/$F$19+H29*I29/$I$19+K29*L29/$L$19+N29*O29/$O$19+Q29*R29/$R$19+T29*U29/$U$19+W29*X29/$X$19+Z29*AA29/$AA$19),6) -> 1.240933
B30: Kasım 2025 | E30: 0.15 | F30: 3482.96 | H30: 0.18 | I30: 5216.99 | K30: 0.2 | L30: 6453.42 | N30: 0.14 | O30: 57.07219 | Q30: 0.01 | R30: 8398.17 | T30: 0.05 | U30: 3606.93 | W30: 0.1 | X30: 4747.63 | Z30: 0.17 | AA30: 3419.55 | AC30: =+ROUND((E30*F30/$F$19+H30*I30/$I$19+K30*L30/$L$19+N30*O30/$O$19+Q30*R30/$R$19+T30*U30/$U$19+W30*X30/$X$19+Z30*AA30/$AA$19),6) -> 1.264548
B31: Aralık 2025 | E31: 0.15 | F31: 3513.87 | H31: 0.18 | I31: 5277.72 | K31: 0.2 | L31: 6568.1 | N31: 0.14 | O31: 53.84298 | Q31: 0.01 | R31: 7739.67 | T31: 0.05 | U31: 3667.48 | W31: 0.1 | X31: 4783.04 | Z31: 0.17 | AA31: 3475.04 | AC31: =+ROUND((E31*F31/$F$19+H31*I31/$I$19+K31*L31/$L$19+N31*O31/$O$19+Q31*R31/$R$19+T31*U31/$U$19+W31*X31/$X$19+Z31*AA31/$AA$19),6) -> 1.267132
... B35: Nisan 2026 | E35: 0.15 | F35: 4028.47 | H35: 0.18 | I35: 5841.56 | K35: 0.2 | L35: 7209.79 | N35: 0.14 | O35: 74.17242 | Q35: 0.01 | R35: 14725.17 | T35: 0.05 | U35: 4068.8 | W35: 0.1 | X35: 5308.46 | Z35: 0.17 | AA35: 3813.11 | AC35: =+ROUND((E35*F35/$F$19+H35*I35/$I$19+K35*L35/$L$19+N35*O35/$O$19+Q35*R35/$R$19+T35*U35/$U$19+W35*X35/$X$19+Z35*AA35/$AA$19),6) -> 1.463635
A40: YÜKLENİCİ | I40: DANIŞMAN | R40: İDARE
A41: Kalyon-Özgün Metro İnşaatı Adi Ortaklığı | I41: Yüksel Proje A.Ş. | R41: T.C. İSTANBUL BÜYÜKŞEHİR BELEDİYESİ Raylı Sistem Dairesi Başkanlığı Avrupa Yakası Raylı Sistem Şube Müdürlüğü
I44: Aybüke YEĞEN Hakediş, Mukavele Takip, Kesin Hesap Kontrol Mühendisi | N44: Yılmaz SATI Hakediş, Mukavele Takip, Kesin Hesap Kontrol Mühendisi
I48: Fatih AYDIN | R48: Yasin YEŞİLDAĞ
I49: Elektromekanik Kontrol Amiri | R49: Maden Kontrol Mühendisi
A52: Kemal YERLİ | I52: Orhan KOCA | S52: Osman ŞAHİN | Y52: Hakan ARZU
A53: Proje Müdürü | I53: Proje Müdürü | S53: İnşaat Müdür Yardımcısı | Y53: E&M Müdür Yardımcısı

Sheet Y.İ. KAPAK
A2: T.C.
A3: İSTANBUL BÜYÜKŞEHİR BELEDİYESİ
A4: Raylı Sistem Dairesi Başkanlığı
A5: Avrupa Yakası Raylı Sistem Şube Müdürlüğü
A6: Kirazlı-Halkalı Üniversite Metro Hattı İnşaat Ve Elektromekanik İşler İle M1 Hattı Elektromekanik Sistemleri Yapım İşi
A22: YAPILAN İŞLER
A27: =+Veri!$C$21 -> 6
A30: =+[9]İcmal!B16 -> Hakediş Tarihi: | F30: =Veri!$C$22 -> 46142

Sheet Yapılan İşler Dönemsel
C2: T.C. | W2: =+'Yeşil Defter'!$K$16 -> 0
C3: İSTANBUL BÜYÜKŞEHİR BELEDİYESİ | W3: =+'Yeşil Defter'!$K$17 -> 0
C4: Raylı Sistem Dairesi Başkanlığı Avrupa Yakası Raylı Sistem Şube Müdürlüğü | W4: =+'Yeşil Defter'!$K$18 -> 0
W5: =+'Yeşil Defter'!$K$19 -> 0
C6: Kirazlı-Halkalı Üniversite Metro Hattı İnşaat Ve Elektromekanik İşler İle M1 Hattı Elektromekanik Sistemleri Yapım İşi | W6: =+'Yeşil Defter'!$K$20 -> 0
C7: YAPILAN İŞLER İCMALİ | W7: =+'Yeşil Defter'!$K$21 -> 0
T8: Hakediş Tarihi : | U8: =+Veri!$C$22 -> 46142 | W8: =+'Yeşil Defter'!$K$22 -> 0
T9: Hakediş No : | U9: =+Veri!$C$21 -> 6 | W9: =+'Yeşil Defter'!$K$23 -> 0
W10: =+'Yeşil Defter'!$K$24 -> 0
J11: 46112 | P11: TOPLAM | W11: =+'Yeşil Defter'!$K$25 -> 0
J12: İMALAT MİKTARLARI | M12: TUTAR (TL) | P12: İMALAT MİKTARLARI | S12: TUTAR (TL) | W12: =+'Yeşil Defter'!$K$26 -> 0
C13: SIRA NO | D13: POZ NO | E13: BİRİM FİYAT ADI | H13: BİRİM | I13: BİRİM FİYAT (TL) | J13: ÖNCEKİ DÖNEM | K13: BU DEFA | L13: TOPLAM | M13: ÖNCEKİ DÖNEM (TL) | N13: BU DEFA (TL) | O13: TOPLAM (TL) | P13: ÖNCEKİ DÖNEM | Q13: BU DEFA | R13: TOPLAM | S13: ÖNCEKİ DÖNEM (TL) | T13: BU DEFA (TL) | U13: TOPLAM (TL) | W13: =+'Yeşil Defter'!$K$27 -> 0
A14: Filtre | C14: KİRAZLI-HALKALI ÜNİVERSİTE METRO HATTI İNŞAAT VE ELEKTROMEKANİK İŞLER İLE M1 HATTI ELEKTROMEKANİK SİSTEMLERİ YAPIM İŞİ | W14: =+'Yeşil Defter'!$K$28 -> 0
A15: B | D15: 1- KABA ve İNCE İNŞAAT İŞLERİ | M15: =+M16+M66+M98+M292+M373+M392+M457 -> 1.4738825e+09 | N15: =+N16+N66+N98+N292+N373+N392+N457 -> #REF! | O15: =+O16+O66+O98+O292+O373+O392+O457 -> #REF! | S15: =+M15 -> 1.4738825e+09 | T15: =+T16+T66+T98+T292+T373+T392+T457 -> #REF! | U15: =+O15 -> #REF! | W15: =+'Yeşil Defter'!$K$29 -> 0
A16: 1 | D16: 1.A-AÇIKTA İNŞAAT İŞLERİ | M16: =SUM(M17:M65) -> 8968246.1 | N16: =SUM(N17:N65) -> 0 | O16: =SUM(O17:O65) -> 8968246.1 | S16: =+M16 -> 8968246.1 | T16: =+U16-S16 -> 0 | U16: =+O16 -> 8968246.1 | W16: =+'Yeşil Defter'!$K$30 -> 0
A17: 1.A | C17: 1 | D17: 001 | E17: Binaların Yıkılması | H17: m² | I17: 500 | J17: =+'Yeşil Defter Dönemsel'!L16 -> 0 | K17: =+'Yeşil Defter Dönemsel'!M16 -> 0 | L17: =+'Yeşil Defter Dönemsel'!N16 -> 0 | M17: =+ROUND($I17*J17,2) -> 0 | N17: =+ROUND($I17*K17,2) -> 0 | O17: =+ROUND($I17*L17,2) -> 0 | P17: =+#REF! -> #REF! | Q17: =+R17-P17 -> #REF! | R17: =+#REF! -> #REF! | S17: =+M17 -> 0 | T17: =+U17-S17 -> 0 | U17: =+O17 -> 0 | W17: =+'Yeşil Defter'!$K$31 -> 0 | Y17: =+'Yeşil Defter'!$K$31 -> 0
A18: 1.A | C18: 2 | D18: 002.A | E18: Demirli ve Demirsiz Betonun Kompresörle Kırılması | H18: m³ | I18: 4063 | J18: =+'Yeşil Defter Dönemsel'!L17 -> 0 | K18: =+'Yeşil Defter Dönemsel'!M17 -> 0 | L18: =+'Yeşil Defter Dönemsel'!N17 -> 0 | M18: =+ROUND($I18*J18,2) -> 0 | N18: =+ROUND($I18*K18,2) -> 0 | O18: =+ROUND($I18*L18,2) -> 0 | P18: =+#REF! -> #REF! | Q18: =+R18-P18 -> #REF! | R18: =+#REF! -> #REF! | S18: =+M18 -> 0 | T18: =+U18-S18 -> 0 | U18: =+O18 -> 0 | W18: =+'Yeşil Defter'!$K$32 -> 0
A19: 1.A | C19: 3 | D19: 002.B | E19: Demirli ve Demirsiz Betonun Ekskavatör veya Benzeri İş Makinesi ile Kırılması | H19: m³ | I19: 2000 | J19: =+'Yeşil Defter Dönemsel'!L18 -> 0 | K19: =+'Yeşil Defter Dönemsel'!M18 -> 0 | L19: =+'Yeşil Defter Dönemsel'!N18 -> 0 | M19: =+ROUND($I19*J19,2) -> 0 | N19: =+ROUND($I19*K19,2) -> 0 | O19: =+ROUND($I19*L19,2) -> 0 | P19: =+#REF! -> #REF! | Q19: =+R19-P19 -> #REF! | R19: =+#REF! -> #REF! | S19: =+M19 -> 0 | T19: =+U19-S19 -> 0 | U19: =+O19 -> 0 | W19: =+'Yeşil Defter'!$K$34 -> 0
