Workbook

Sheet Barbaros 1225
A1: 1225
A2: Sıra No | B2: İş Kalemi No | C2: Açıklama | D2: Birimi | E2: Miktarı | F2: Birim Fiyat | G2: Tutar | H2: Toplam Metraj | I2: Toplam Tutar | J2: Hat-1-HY-P1-1.Aşama | K2: Hat-1-HY-P1-2.Aşama | L2: Hat-1-HY-P1-3.Aşama | M2: Hat-1-HY-P1-4.Aşama | N2: Hat-2-HY-P1-1.Aşama | O2: Hat-2-HY-P1-2.Aşama | P2: Hat-2-HY-P1-3.Aşama | Q2: Hat-2-HY-P1-4.Aşama | R2: Hat-1-KY-P1-1.Aşama | S2: Hat-1-KY-P1-2.Aşama | T2: Hat-1-KY-P1-3.Aşama | U2: Hat-1-KY-P1-4.Aşama | V2: Hat-2-KY-P1-1.Aşama | W2: Hat-2-KY-P1-2.Aşama | X2: Hat-2-KY-P1-3.Aşama | Y2: Hat-2-KY-P1-4.Aşama | Z2: Hat-2-B1 Bağlantı-3 P2 Yönü Üstyarı Aşaması (B1-101) | AA2: Hat-2-B1 Bağlantı-3 P2 Yönü Altyarı Aşaması (B1-101) | AB2: Hat1-B1 Bağlantı-3 P2 Yönü Üstyarı Aşaması (B1-102) | AC2: Hat-1-B1 Bağlantı-3 P2 Yönü Alt Yarı Aşaması (B1-102) | AD2: Hat-2-B1 Bağlantı-2 P2 Yönü Üstyarı Aşaması (B1-103) | AE2: Hat-2-B1 Bağlantı-2 P2 Yönü Alt Yarı Aşaması (B1-103) | AF2: Hat-1-B1 Bağlantı-2 P2 Yönü Üstyarı Aşaması (B1-104) | AG2: Hat-1-B1 Bağlantı-2 P2 Yönü Altyarı Aşaması (B1-104) | AH2: Hat-2-B1 Bağlantı-1 P2 Yönü Üstyarı Aşaması (B1-105) | AI2: Hat-2-B1 Bağlantı-2 P2 Yönü Alt Yarı Aşaması (B1-105) | AJ2: Hat-1-B1 Bağlantı-1 P2 Yönü Üstyarı Aşaması (B1-106) | AK2: Hat-1-B1 Bağlantı-1 P2 Yönü Alt Yarı Aşaması (B1-106)
A3: 49 | B3: 018 | C3: Geleneksel (NATM) Tünel Kazısı | D3: m³ | E3: 186392.65 | F3: 5075 | G3: =+E3*F3 -> 9.459427e+08 | H3: =SUM(J3:AT3) -> 3128.87 | I3: =+F3*H3 -> 15879015 | J3: {=+HLOOKUP($A$1,+[2]İcmal!$B$19:$AG$49,ROW(A1)+1,FALSE)} -> 0 | K3: {=+HLOOKUP($A$1,+[3]İcmal!$B$19:$AG$49,ROW(B1)+1,FALSE)} -> 0 | L3: {=+HLOOKUP($A$1,+[4]İcmal!$B$19:$AG$49,ROW(C1)+1,FALSE)} -> 0 | M3: {=+HLOOKUP($A$1,+[5]İcmal!$B$19:$AG$49,ROW(D1)+1,FALSE)} -> 0 | N3: {=+HLOOKUP($A$1,+[6]İcmal!$B$19:$AG$49,ROW(E1)+1,FALSE)} -> 650.046 | O3: {=+HLOOKUP($A$1,+[7]İcmal!$B$19:$AG$49,ROW(F1)+1,FALSE)} -> 731.256 | P3: {=+HLOOKUP($A$1,+[8]İcmal!$B$19:$AG$49,ROW(G1)+1,FALSE)} -> 0 | Q3: {=+HLOOKUP($A$1,+[9]İcmal!$B$19:$AG$49,ROW(H1)+1,FALSE)} -> 0 | R3: {=+HLOOKUP($A$1,+[10]İcmal!$B$19:$AG$49,ROW(I1)+1,FALSE)} -> 620.514 | S3: {=+HLOOKUP($A$1,+[11]İcmal!$B$19:$AG$49,ROW(J1)+1,FALSE)} -> 884.512 | T3: {=+HLOOKUP($A$1,+[12]İcmal!$B$19:$AG$49,ROW(K1)+1,FALSE)} -> 0 | U3: {=+HLOOKUP($A$1,+[13]İcmal!$B$19:$AG$49,ROW(L1)+1,FALSE)} -> 0 | V3: {=+HLOOKUP($A$1,+[14]İcmal!$B$19:$AG$49,ROW(M1)+1,FALSE)} -> 0 | W3: {=+HLOOKUP($A$1,+[15]İcmal!$B$19:$AG$49,ROW(N1)+1,FALSE)} -> 0 | X3: {=+HLOOKUP($A$1,+[16]İcmal!$B$19:$AG$49,ROW(O1)+1,FALSE)} -> 0 | Y3: {=+HLOOKUP($A$1,+[17]İcmal!$B$19:$AG$49,ROW(P1)+1,FALSE)} -> 0 | Z3: {=+HLOOKUP($A$1,+[18]İcmal!$B$19:$AG$49,ROW(Q1)+1,FALSE)} -> 0 | AA3: {=+HLOOKUP($A$1,+[19]İcmal!$B$19:$AG$49,ROW(R1)+1,FALSE)} -> 0 | AB3: {=+HLOOKUP($A$1,+[20]İcmal!$B$19:$AG$49,ROW(S1)+1,FALSE)} -> 10.01 | AC3: {=+HLOOKUP($A$1,+[21]İcmal!$B$19:$AG$49,ROW(T1)+1,FALSE)} -> 0 | AD3: {=+HLOOKUP($A$1,+[22]İcmal!$B$19:$AG$49,ROW(U1)+1,FALSE)} -> 25.29 | AE3: {=+HLOOKUP($A$1,+[23]İcmal!$B$19:$AG$49,ROW(V1)+1,FALSE)} -> 0 | AF3: {=+HLOOKUP($A$1,+[24]İcmal!$B$19:$AG$49,ROW(W1)+1,FALSE)} -> 113.468 | AG3: {=+HLOOKUP($A$1,+[25]İcmal!$B$19:$AG$49,ROW(X1)+1,FALSE)} -> 0 | AH3: {=+HLOOKUP($A$1,+[26]İcmal!$B$19:$AG$49,ROW(Y1)+1,FALSE)} -> 10.01 | AI3: {=+HLOOKUP($A$1,+[27]İcmal!$B$19:$AG$49,ROW(Z1)+1,FALSE)} -> 83.764 | AJ3: {=+HLOOKUP($A$1,+[28]İcmal!$B$19:$AG$49,ROW(AA1)+1,FALSE)} -> 0 | AK3: {=+HLOOKUP($A$1,+[29]İcmal!$B$19:$AG$49,ROW(AB1)+1,FALSE)} -> 0
A4: 50 | B4: 019.A | C4: Kazıdan çıkan veya Ariyetten alınan malzeme ile geri dolgu yapılması | D4: m³ | E4: 910 | F4: 600 | G4: =+E4*F4 -> 546000 | H4: =SUM(J4:AT4) -> 0 | I4: =+F4*H4 -> 0 | J4: {=+HLOOKUP($A$1,+[2]İcmal!$B$19:$AG$49,ROW(A2)+1,FALSE)} -> 0 | K4: {=+HLOOKUP($A$1,+[3]İcmal!$B$19:$AG$49,ROW(B2)+1,FALSE)} -> 0 | L4: {=+HLOOKUP($A$1,+[4]İcmal!$B$19:$AG$49,ROW(C2)+1,FALSE)} -> 0 | M4: {=+HLOOKUP($A$1,+[5]İcmal!$B$19:$AG$49,ROW(D2)+1,FALSE)} -> 0 | N4: {=+HLOOKUP($A$1,+[6]İcmal!$B$19:$AG$49,ROW(E2)+1,FALSE)} -> 0 | O4: {=+HLOOKUP($A$1,+[7]İcmal!$B$19:$AG$49,ROW(F2)+1,FALSE)} -> 0 | P4: {=+HLOOKUP($A$1,+[8]İcmal!$B$19:$AG$49,ROW(G2)+1,FALSE)} -> 0 | Q4: {=+HLOOKUP($A$1,+[9]İcmal!$B$19:$AG$49,ROW(H2)+1,FALSE)} -> 0 | R4: {=+HLOOKUP($A$1,+[10]İcmal!$B$19:$AG$49,ROW(I2)+1,FALSE)} -> 0 | S4: {=+HLOOKUP($A$1,+[11]İcmal!$B$19:$AG$49,ROW(J2)+1,FALSE)} -> 0 | T4: {=+HLOOKUP($A$1,+[12]İcmal!$B$19:$AG$49,ROW(K2)+1,FALSE)} -> 0 | U4: {=+HLOOKUP($A$1,+[13]İcmal!$B$19:$AG$49,ROW(L2)+1,FALSE)} -> 0 | V4: {=+HLOOKUP($A$1,+[14]İcmal!$B$19:$AG$49,ROW(M2)+1,FALSE)} -> 0 | W4: {=+HLOOKUP($A$1,+[15]İcmal!$B$19:$AG$49,ROW(N2)+1,FALSE)} -> 0 | X4: {=+HLOOKUP($A$1,+[16]İcmal!$B$19:$AG$49,ROW(O2)+1,FALSE)} -> 0 | Y4: {=+HLOOKUP($A$1,+[17]İcmal!$B$19:$AG$49,ROW(P2)+1,FALSE)} -> 0 | Z4: {=+HLOOKUP($A$1,+[18]İcmal!$B$19:$AG$49,ROW(Q2)+1,FALSE)} -> 0 | AA4: {=+HLOOKUP($A$1,+[19]İcmal!$B$19:$AG$49,ROW(R2)+1,FALSE)} -> 0 | AB4: {=+HLOOKUP($A$1,+[20]İcmal!$B$19:$AG$49,ROW(S2)+1,FALSE)} -> 0 | AC4: {=+HLOOKUP($A$1,+[21]İcmal!$B$19:$AG$49,ROW(T2)+1,FALSE)} -> 0 | AD4: {=+HLOOKUP($A$1,+[22]İcmal!$B$19:$AG$49,ROW(U2)+1,FALSE)} -> 0 | AE4: {=+HLOOKUP($A$1,+[23]İcmal!$B$19:$AG$49,ROW(V2)+1,FALSE)} -> 0 | AF4: {=+HLOOKUP($A$1,+[24]İcmal!$B$19:$AG$49,ROW(W2)+1,FALSE)} -> 0 | AG4: {=+HLOOKUP($A$1,+[25]İcmal!$B$19:$AG$49,ROW(X2)+1,FALSE)} -> 0 | AH4: {=+HLOOKUP($A$1,+[26]İcmal!$B$19:$AG$49,ROW(Y2)+1,FALSE)} -> 0 | AI4: {=+HLOOKUP($A$1,+[27]İcmal!$B$19:$AG$49,ROW(Z2)+1,FALSE)} -> 0 | AJ4: {=+HLOOKUP($A$1,+[28]İcmal!$B$19:$AG$49,ROW(AA2)+1,FALSE)} -> 0 | AK4: {=+HLOOKUP($A$1,+[29]İcmal!$B$19:$AG$49,ROW(AB2)+1,FALSE)} -> 0
A5: 51 | B5: 019.B | C5: Kum, Çakıl, Kırma Tas ve Benzeri Malzeme ile Dolgu Yapılması | D5: m³ | E5: 1785 | F5: 1500 | G5: =+E5*F5 -> 2677500 | H5: =SUM(J5:AT5) -> 0 | I5: =+F5*H5 -> 0 | J5: {=+HLOOKUP($A$1,+[2]İcmal!$B$19:$AG$49,ROW(A3)+1,FALSE)} -> 0 | K5: {=+HLOOKUP($A$1,+[3]İcmal!$B$19:$AG$49,ROW(B3)+1,FALSE)} -> 0 | L5: {=+HLOOKUP($A$1,+[4]İcmal!$B$19:$AG$49,ROW(C3)+1,FALSE)} -> 0 | M5: {=+HLOOKUP($A$1,+[5]İcmal!$B$19:$AG$49,ROW(D3)+1,FALSE)} -> 0 | N5: {=+HLOOKUP($A$1,+[6]İcmal!$B$19:$AG$49,ROW(E3)+1,FALSE)} -> 0 | O5: {=+HLOOKUP($A$1,+[7]İcmal!$B$19:$AG$49,ROW(F3)+1,FALSE)} -> 0 | P5: {=+HLOOKUP($A$1,+[8]İcmal!$B$19:$AG$49,ROW(G3)+1,FALSE)} -> 0 | Q5: {=+HLOOKUP($A$1,+[9]İcmal!$B$19:$AG$49,ROW(H3)+1,FALSE)} -> 0 | R5: {=+HLOOKUP($A$1,+[10]İcmal!$B$19:$AG$49,ROW(I3)+1,FALSE)} -> 0 | S5: {=+HLOOKUP($A$1,+[11]İcmal!$B$19:$AG$49,ROW(J3)+1,FALSE)} -> 0 | T5: {=+HLOOKUP($A$1,+[12]İcmal!$B$19:$AG$49,ROW(K3)+1,FALSE)} -> 0 | U5: {=+HLOOKUP($A$1,+[13]İcmal!$B$19:$AG$49,ROW(L3)+1,FALSE)} -> 0 | V5: {=+HLOOKUP($A$1,+[14]İcmal!$B$19:$AG$49,ROW(M3)+1,FALSE)} -> 0 | W5: {=+HLOOKUP($A$1,+[15]İcmal!$B$19:$AG$49,ROW(N3)+1,FALSE)} -> 0 | X5: {=+HLOOKUP($A$1,+[16]İcmal!$B$19:$AG$49,ROW(O3)+1,FALSE)} -> 0 | Y5: {=+HLOOKUP($A$1,+[17]İcmal!$B$19:$AG$49,ROW(P3)+1,FALSE)} -> 0 | Z5: {=+HLOOKUP($A$1,+[18]İcmal!$B$19:$AG$49,ROW(Q3)+1,FALSE)} -> 0 | AA5: {=+HLOOKUP($A$1,+[19]İcmal!$B$19:$AG$49,ROW(R3)+1,FALSE)} -> 0 | AB5: {=+HLOOKUP($A$1,+[20]İcmal!$B$19:$AG$49,ROW(S3)+1,FALSE)} -> 0 | AC5: {=+HLOOKUP($A$1,+[21]İcmal!$B$19:$AG$49,ROW(T3)+1,FALSE)} -> 0 | AD5: {=+HLOOKUP($A$1,+[22]İcmal!$B$19:$AG$49,ROW(U3)+1,FALSE)} -> 0 | AE5: {=+HLOOKUP($A$1,+[23]İcmal!$B$19:$AG$49,ROW(V3)+1,FALSE)} -> 0 | AF5: {=+HLOOKUP($A$1,+[24]İcmal!$B$19:$AG$49,ROW(W3)+1,FALSE)} -> 0 | AG5: {=+HLOOKUP($A$1,+[25]İcmal!$B$19:$AG$49,ROW(X3)+1,FALSE)} -> 0 | AH5: {=+HLOOKUP($A$1,+[26]İcmal!$B$19:$AG$49,ROW(Y3)+1,FALSE)} -> 0 | AI5: {=+HLOOKUP($A$1,+[27]İcmal!$B$19:$AG$49,ROW(Z3)+1,FALSE)} -> 0 | AJ5: {=+HLOOKUP($A$1,+[28]İcmal!$B$19:$AG$49,ROW(AA3)+1,FALSE)} -> 0 | AK5: {=+HLOOKUP($A$1,+[29]İcmal!$B$19:$AG$49,ROW(AB3)+1,FALSE)} -> 0
A6: 52 | B6: 020 | C6: Püskürtme Beton (Tünel ve Şaftlarda) | D6: m³ | E6: 38798.59 | F6: 15334 | G6: =+E6*F6 -> 5.9493758e+08 | H6: =SUM(J6:AT6) -> 743.305 | I6: =+F6*H6 -> 11397839 | J6: {=+HLOOKUP($A$1,+[2]İcmal!$B$19:$AG$49,ROW(A4)+1,FALSE)} -> 23.095 | K6: {=+HLOOKUP($A$1,+[3]İcmal!$B$19:$AG$49,ROW(B4)+1,FALSE)} -> 20.188 | L6: {=+HLOOKUP($A$1,+[4]İcmal!$B$19:$AG$49,ROW(C4)+1,FALSE)} -> 0 | M6: {=+HLOOKUP($A$1,+[5]İcmal!$B$19:$AG$49,ROW(D4)+1,FALSE)} -> 0 | N6: {=+HLOOKUP($A$1,+[6]İcmal!$B$19:$AG$49,ROW(E4)+1,FALSE)} -> 147.439 | O6: {=+HLOOKUP($A$1,+[7]İcmal!$B$19:$AG$49,ROW(F4)+1,FALSE)} -> 141.162 | P6: {=+HLOOKUP($A$1,+[8]İcmal!$B$19:$AG$49,ROW(G4)+1,FALSE)} -> 0 | Q6: {=+HLOOKUP($A$1,+[9]İcmal!$B$19:$AG$49,ROW(H4)+1,FALSE)} -> 0 | R6: {=+HLOOKUP($A$1,+[10]İcmal!$B$19:$AG$49,ROW(I4)+1,FALSE)} -> 144.089 | S6: {=+HLOOKUP($A$1,+[11]İcmal!$B$19:$AG$49,ROW(J4)+1,FALSE)} -> 175.476 | T6: {=+HLOOKUP($A$1,+[12]İcmal!$B$19:$AG$49,ROW(K4)+1,FALSE)} -> 0 | U6: {=+HLOOKUP($A$1,+[13]İcmal!$B$19:$AG$49,ROW(L4)+1,FALSE)} -> 0 | V6: {=+HLOOKUP($A$1,+[14]İcmal!$B$19:$AG$49,ROW(M4)+1,FALSE)} -> 0 | W6: {=+HLOOKUP($A$1,+[15]İcmal!$B$19:$AG$49,ROW(N4)+1,FALSE)} -> 0 | X6: {=+HLOOKUP($A$1,+[16]İcmal!$B$19:$AG$49,ROW(O4)+1,FALSE)} -> 0 | Y6: {=+HLOOKUP($A$1,+[17]İcmal!$B$19:$AG$49,ROW(P4)+1,FALSE)} -> 0 | Z6: {=+HLOOKUP($A$1,+[18]İcmal!$B$19:$AG$49,ROW(Q4)+1,FALSE)} -> 0 | AA6: {=+HLOOKUP($A$1,+[19]İcmal!$B$19:$AG$49,ROW(R4)+1,FALSE)} -> 0 | AB6: {=+HLOOKUP($A$1,+[20]İcmal!$B$19:$AG$49,ROW(S4)+1,FALSE)} -> 10.01 | AC6: {=+HLOOKUP($A$1,+[21]İcmal!$B$19:$AG$49,ROW(T4)+1,FALSE)} -> 0 | AD6: {=+HLOOKUP($A$1,+[22]İcmal!$B$19:$AG$49,ROW(U4)+1,FALSE)} -> 21.003 | AE6: {=+HLOOKUP($A$1,+[23]İcmal!$B$19:$AG$49,ROW(V4)+1,FALSE)} -> 0 | AF6: {=+HLOOKUP($A$1,+[24]İcmal!$B$19:$AG$49,ROW(W4)+1,FALSE)} -> 34.325 | AG6: {=+HLOOKUP($A$1,+[25]İcmal!$B$19:$AG$49,ROW(X4)+1,FALSE)} -> 0 | AH6: {=+HLOOKUP($A$1,+[26]İcmal!$B$19:$AG$49,ROW(Y4)+1,FALSE)} -> 10.01 | AI6: {=+HLOOKUP($A$1,+[27]İcmal!$B$19:$AG$49,ROW(Z4)+1,FALSE)} -> 16.508 | AJ6: {=+HLOOKUP($A$1,+[28]İcmal!$B$19:$AG$49,ROW(AA4)+1,FALSE)} -> 0 | AK6: {=+HLOOKUP($A$1,+[29]İcmal!$B$19:$AG$49,ROW(AB4)+1,FALSE)} -> 0
A7: 53 | B7: 021.A | C7: Delgi boyu =< 30m | D7: m | E7: 19569.89 | F7: 248 | G7: =+E7*F7 -> 4853332.7 | H7: =SUM(J7:AT7) -> 0 | I7: =+F7*H7 -> 0 | J7: {=+HLOOKUP($A$1,+[2]İcmal!$B$19:$AG$49,ROW(A5)+1,FALSE)} -> 0 | K7: {=+HLOOKUP($A$1,+[3]İcmal!$B$19:$AG$49,ROW(B5)+1,FALSE)} -> 0 | L7: {=+HLOOKUP($A$1,+[4]İcmal!$B$19:$AG$49,ROW(C5)+1,FALSE)} -> 0 | M7: {=+HLOOKUP($A$1,+[5]İcmal!$B$19:$AG$49,ROW(D5)+1,FALSE)} -> 0 | N7: {=+HLOOKUP($A$1,+[6]İcmal!$B$19:$AG$49,ROW(E5)+1,FALSE)} -> 0 | O7: {=+HLOOKUP($A$1,+[7]İcmal!$B$19:$AG$49,ROW(F5)+1,FALSE)} -> 0 | P7: {=+HLOOKUP($A$1,+[8]İcmal!$B$19:$AG$49,ROW(G5)+1,FALSE)} -> 0 | Q7: {=+HLOOKUP($A$1,+[9]İcmal!$B$19:$AG$49,ROW(H5)+1,FALSE)} -> 0 | R7: {=+HLOOKUP($A$1,+[10]İcmal!$B$19:$AG$49,ROW(I5)+1,FALSE)} -> 0 | S7: {=+HLOOKUP($A$1,+[11]İcmal!$B$19:$AG$49,ROW(J5)+1,FALSE)} -> 0 | T7: {=+HLOOKUP($A$1,+[12]İcmal!$B$19:$AG$49,ROW(K5)+1,FALSE)} -> 0 | U7: {=+HLOOKUP($A$1,+[13]İcmal!$B$19:$AG$49,ROW(L5)+1,FALSE)} -> 0 | V7: {=+HLOOKUP($A$1,+[14]İcmal!$B$19:$AG$49,ROW(M5)+1,FALSE)} -> 0 | W7: {=+HLOOKUP($A$1,+[15]İcmal!$B$19:$AG$49,ROW(N5)+1,FALSE)} -> 0 | X7: {=+HLOOKUP($A$1,+[16]İcmal!$B$19:$AG$49,ROW(O5)+1,FALSE)} -> 0 | Y7: {=+HLOOKUP($A$1,+[17]İcmal!$B$19:$AG$49,ROW(P5)+1,FALSE)} -> 0 | Z7: {=+HLOOKUP($A$1,+[18]İcmal!$B$19:$AG$49,ROW(Q5)+1,FALSE)} -> 0 | AA7: {=+HLOOKUP($A$1,+[19]İcmal!$B$19:$AG$49,ROW(R5)+1,FALSE)} -> 0 | AB7: {=+HLOOKUP($A$1,+[20]İcmal!$B$19:$AG$49,ROW(S5)+1,FALSE)} -> 0 | AC7: {=+HLOOKUP($A$1,+[21]İcmal!$B$19:$AG$49,ROW(T5)+1,FALSE)} -> 0 | AD7: {=+HLOOKUP($A$1,+[22]İcmal!$B$19:$AG$49,ROW(U5)+1,FALSE)} -> 0 | AE7: {=+HLOOKUP($A$1,+[23]İcmal!$B$19:$AG$49,ROW(V5)+1,FALSE)} -> 0 | AF7: {=+HLOOKUP($A$1,+[24]İcmal!$B$19:$AG$49,ROW(W5)+1,FALSE)} -> 0 | AG7: {=+HLOOKUP($A$1,+[25]İcmal!$B$19:$AG$49,ROW(X5)+1,FALSE)} -> 0 | AH7: {=+HLOOKUP($A$1,+[26]İcmal!$B$19:$AG$49,ROW(Y5)+1,FALSE)} -> 0 | AI7: {=+HLOOKUP($A$1,+[27]İcmal!$B$19:$AG$49,ROW(Z5)+1,FALSE)} -> 0 | AJ7: {=+HLOOKUP($A$1,+[28]İcmal!$B$19:$AG$49,ROW(AA5)+1,FALSE)} -> 0 | AK7: {=+HLOOKUP($A$1,+[29]İcmal!$B$19:$AG$49,ROW(AB5)+1,FALSE)} -> 0
A8: 54 | B8: 021.B | C8: Delgi boyu > 30m | D8: m | E8: 10655.78 | F8: 371 | G8: =+E8*F8 -> 3953294.4 | H8: =SUM(J8:AT8) -> 0 | I8: =+F8*H8 -> 0 | J8: {=+HLOOKUP($A$1,+[2]İcmal!$B$19:$AG$49,ROW(A6)+1,FALSE)} -> 0 | K8: {=+HLOOKUP($A$1,+[3]İcmal!$B$19:$AG$49,ROW(B6)+1,FALSE)} -> 0 | L8: {=+HLOOKUP($A$1,+[4]İcmal!$B$19:$AG$49,ROW(C6)+1,FALSE)} -> 0 | M8: {=+HLOOKUP($A$1,+[5]İcmal!$B$19:$AG$49,ROW(D6)+1,FALSE)} -> 0 | N8: {=+HLOOKUP($A$1,+[6]İcmal!$B$19:$AG$49,ROW(E6)+1,FALSE)} -> 0 | O8: {=+HLOOKUP($A$1,+[7]İcmal!$B$19:$AG$49,ROW(F6)+1,FALSE)} -> 0 | P8: {=+HLOOKUP($A$1,+[8]İcmal!$B$19:$AG$49,ROW(G6)+1,FALSE)} -> 0 | Q8: {=+HLOOKUP($A$1,+[9]İcmal!$B$19:$AG$49,ROW(H6)+1,FALSE)} -> 0 | R8: {=+HLOOKUP($A$1,+[10]İcmal!$B$19:$AG$49,ROW(I6)+1,FALSE)} -> 0 | S8: {=+HLOOKUP($A$1,+[11]İcmal!$B$19:$AG$49,ROW(J6)+1,FALSE)} -> 0 | T8: {=+HLOOKUP($A$1,+[12]İcmal!$B$19:$AG$49,ROW(K6)+1,FALSE)} -> 0 | U8: {=+HLOOKUP($A$1,+[13]İcmal!$B$19:$AG$49,ROW(L6)+1,FALSE)} -> 0 | V8: {=+HLOOKUP($A$1,+[14]İcmal!$B$19:$AG$49,ROW(M6)+1,FALSE)} -> 0 | W8: {=+HLOOKUP($A$1,+[15]İcmal!$B$19:$AG$49,ROW(N6)+1,FALSE)} -> 0 | X8: {=+HLOOKUP($A$1,+[16]İcmal!$B$19:$AG$49,ROW(O6)+1,FALSE)} -> 0 | Y8: {=+HLOOKUP($A$1,+[17]İcmal!$B$19:$AG$49,ROW(P6)+1,FALSE)} -> 0 | Z8: {=+HLOOKUP($A$1,+[18]İcmal!$B$19:$AG$49,ROW(Q6)+1,FALSE)} -> 0 | AA8: {=+HLOOKUP($A$1,+[19]İcmal!$B$19:$AG$49,ROW(R6)+1,FALSE)} -> 0 | AB8: {=+HLOOKUP($A$1,+[20]İcmal!$B$19:$AG$49,ROW(S6)+1,FALSE)} -> 0 | AC8: {=+HLOOKUP($A$1,+[21]İcmal!$B$19:$AG$49,ROW(T6)+1,FALSE)} -> 0 | AD8: {=+HLOOKUP($A$1,+[22]İcmal!$B$19:$AG$49,ROW(U6)+1,FALSE)} -> 0 | AE8: {=+HLOOKUP($A$1,+[23]İcmal!$B$19:$AG$49,ROW(V6)+1,FALSE)} -> 0 | AF8: {=+HLOOKUP($A$1,+[24]İcmal!$B$19:$AG$49,ROW(W6)+1,FALSE)} -> 0 | AG8: {=+HLOOKUP($A$1,+[25]İcmal!$B$19:$AG$49,ROW(X6)+1,FALSE)} -> 0 | AH8: {=+HLOOKUP($A$1,+[26]İcmal!$B$19:$AG$49,ROW(Y6)+1,FALSE)} -> 0 | AI8: {=+HLOOKUP($A$1,+[27]İcmal!$B$19:$AG$49,ROW(Z6)+1,FALSE)} -> 0 | AJ8: {=+HLOOKUP($A$1,+[28]İcmal!$B$19:$AG$49,ROW(AA6)+1,FALSE)} -> 0 | AK8: {=+HLOOKUP($A$1,+[29]İcmal!$B$19:$AG$49,ROW(AB6)+1,FALSE)} -> 0
A9: 55 | B9: 022.A | C9: L=3 m Kaya Bulonu | D9: adet | E9: 800 | F9: 2250 | G9: =+E9*F9 -> 1800000 | H9: =SUM(J9:AT9) -> 0 | I9: =+F9*H9 -> 0 | J9: {=+HLOOKUP($A$1,+[2]İcmal!$B$19:$AG$49,ROW(A7)+1,FALSE)} -> 0 | K9: {=+HLOOKUP($A$1,+[3]İcmal!$B$19:$AG$49,ROW(B7)+1,FALSE)} -> 0 | L9: {=+HLOOKUP($A$1,+[4]İcmal!$B$19:$AG$49,ROW(C7)+1,FALSE)} -> 0 | M9: {=+HLOOKUP($A$1,+[5]İcmal!$B$19:$AG$49,ROW(D7)+1,FALSE)} -> 0 | N9: {=+HLOOKUP($A$1,+[6]İcmal!$B$19:$AG$49,ROW(E7)+1,FALSE)} -> 0 | O9: {=+HLOOKUP($A$1,+[7]İcmal!$B$19:$AG$49,ROW(F7)+1,FALSE)} -> 0 | P9: {=+HLOOKUP($A$1,+[8]İcmal!$B$19:$AG$49,ROW(G7)+1,FALSE)} -> 0 | Q9: {=+HLOOKUP($A$1,+[9]İcmal!$B$19:$AG$49,ROW(H7)+1,FALSE)} -> 0 | R9: {=+HLOOKUP($A$1,+[10]İcmal!$B$19:$AG$49,ROW(I7)+1,FALSE)} -> 0 | S9: {=+HLOOKUP($A$1,+[11]İcmal!$B$19:$AG$49,ROW(J7)+1,FALSE)} -> 0 | T9: {=+HLOOKUP($A$1,+[12]İcmal!$B$19:$AG$49,ROW(K7)+1,FALSE)} -> 0 | U9: {=+HLOOKUP($A$1,+[13]İcmal!$B$19:$AG$49,ROW(L7)+1,FALSE)} -> 0 | V9: {=+HLOOKUP($A$1,+[14]İcmal!$B$19:$AG$49,ROW(M7)+1,FALSE)} -> 0 | W9: {=+HLOOKUP($A$1,+[15]İcmal!$B$19:$AG$49,ROW(N7)+1,FALSE)} -> 0 | X9: {=+HLOOKUP($A$1,+[16]İcmal!$B$19:$AG$49,ROW(O7)+1,FALSE)} -> 0 | Y9: {=+HLOOKUP($A$1,+[17]İcmal!$B$19:$AG$49,ROW(P7)+1,FALSE)} -> 0 | Z9: {=+HLOOKUP($A$1,+[18]İcmal!$B$19:$AG$49,ROW(Q7)+1,FALSE)} -> 0 | AA9: {=+HLOOKUP($A$1,+[19]İcmal!$B$19:$AG$49,ROW(R7)+1,FALSE)} -> 0 | AB9: {=+HLOOKUP($A$1,+[20]İcmal!$B$19:$AG$49,ROW(S7)+1,FALSE)} -> 0 | AC9: {=+HLOOKUP($A$1,+[21]İcmal!$B$19:$AG$49,ROW(T7)+1,FALSE)} -> 0 | AD9: {=+HLOOKUP($A$1,+[22]İcmal!$B$19:$AG$49,ROW(U7)+1,FALSE)} -> 0 | AE9: {=+HLOOKUP($A$1,+[23]İcmal!$B$19:$AG$49,ROW(V7)+1,FALSE)} -> 0 | AF9: {=+HLOOKUP($A$1,+[24]İcmal!$B$19:$AG$49,ROW(W7)+1,FALSE)} -> 0 | AG9: {=+HLOOKUP($A$1,+[25]İcmal!$B$19:$AG$49,ROW(X7)+1,FALSE)} -> 0 | AH9: {=+HLOOKUP($A$1,+[26]İcmal!$B$19:$AG$49,ROW(Y7)+1,FALSE)} -> 0 | AI9: {=+HLOOKUP($A$1,+[27]İcmal!$B$19:$AG$49,ROW(Z7)+1,FALSE)} -> 0 | AJ9: {=+HLOOKUP($A$1,+[28]İcmal!$B$19:$AG$49,ROW(AA7)+1,FALSE)} -> 0 | AK9: {=+HLOOKUP($A$1,+[29]İcmal!$B$19:$AG$49,ROW(AB7)+1,FALSE)} -> 0
A10: 56 | B10: 022.B | C10: L=4 m Kaya Bulonu | D10: adet | E10: 2466.42 | F10: 8000 | G10: =+E10*F10 -> 19731360 | H10: =SUM(J10:AT10) -> 252 | I10: =+F10*H10 -> 2016000 | J10: {=+HLOOKUP($A$1,+[2]İcmal!$B$19:$AG$49,ROW(A8)+1,FALSE)} -> 0 | K10: {=+HLOOKUP($A$1,+[3]İcmal!$B$19:$AG$49,ROW(B8)+1,FALSE)} -> 0 | L10: {=+HLOOKUP($A$1,+[4]İcmal!$B$19:$AG$49,ROW(C8)+1,FALSE)} -> 0 | M10: {=+HLOOKUP($A$1,+[5]İcmal!$B$19:$AG$49,ROW(D8)+1,FALSE)} -> 0 | N10: {=+HLOOKUP($A$1,+[6]İcmal!$B$19:$AG$49,ROW(E8)+1,FALSE)} -> 139 | O10: {=+HLOOKUP($A$1,+[7]İcmal!$B$19:$AG$49,ROW(F8)+1,FALSE)} -> 0 | P10: {=+HLOOKUP($A$1,+[8]İcmal!$B$19:$AG$49,ROW(G8)+1,FALSE)} -> 0 | Q10: {=+HLOOKUP($A$1,+[9]İcmal!$B$19:$AG$49,ROW(H8)+1,FALSE)} -> 0 | R10: {=+HLOOKUP($A$1,+[10]İcmal!$B$19:$AG$49,ROW(I8)+1,FALSE)} -> 113 | S10: {=+HLOOKUP($A$1,+[11]İcmal!$B$19:$AG$49,ROW(J8)+1,FALSE)} -> 0 | T10: {=+HLOOKUP($A$1,+[12]İcmal!$B$19:$AG$49,ROW(K8)+1,FALSE)} -> 0 | U10: {=+HLOOKUP($A$1,+[13]İcmal!$B$19:$AG$49,ROW(L8)+1,FALSE)} -> 0 | V10: {=+HLOOKUP($A$1,+[14]İcmal!$B$19:$AG$49,ROW(M8)+1,FALSE)} -> 0 | W10: {=+HLOOKUP($A$1,+[15]İcmal!$B$19:$AG$49,ROW(N8)+1,FALSE)} -> 0 | X10: {=+HLOOKUP($A$1,+[16]İcmal!$B$19:$AG$49,ROW(O8)+1,FALSE)} -> 0 | Y10: {=+HLOOKUP($A$1,+[17]İcmal!$B$19:$AG$49,ROW(P8)+1,FALSE)} -> 0 | Z10: {=+HLOOKUP($A$1,+[18]İcmal!$B$19:$AG$49,ROW(Q8)+1,FALSE)} -> 0 | AA10: {=+HLOOKUP($A$1,+[19]İcmal!$B$19:$AG$49,ROW(R8)+1,FALSE)} -> 0 | AB10: {=+HLOOKUP($A$1,+[20]İcmal!$B$19:$AG$49,ROW(S8)+1,FALSE)} -> 0 | AC10: {=+HLOOKUP($A$1,+[21]İcmal!$B$19:$AG$49,ROW(T8)+1,FALSE)} -> 0 | AD10: {=+HLOOKUP($A$1,+[22]İcmal!$B$19:$AG$49,ROW(U8)+1,FALSE)} -> 0 | AE10: {=+HLOOKUP($A$1,+[23]İcmal!$B$19:$AG$49,ROW(V8)+1,FALSE)} -> 0 | AF10: {=+HLOOKUP($A$1,+[24]İcmal!$B$19:$AG$49,ROW(W8)+1,FALSE)} -> 0 | AG10: {=+HLOOKUP($A$1,+[25]İcmal!$B$19:$AG$49,ROW(X8)+1,FALSE)} -> 0 | AH10: {=+HLOOKUP($A$1,+[26]İcmal!$B$19:$AG$49,ROW(Y8)+1,FALSE)} -> 0 | AI10: {=+HLOOKUP($A$1,+[27]İcmal!$B$19:$AG$49,ROW(Z8)+1,FALSE)} -> 0 | AJ10: {=+HLOOKUP($A$1,+[28]İcmal!$B$19:$AG$49,ROW(AA8)+1,FALSE)} -> 0 | AK10: {=+HLOOKUP($A$1,+[29]İcmal!$B$19:$AG$49,ROW(AB8)+1,FALSE)} -> 0
A11: 57 | B11: 022.C | C11: L=5 m Kaya Bulonu | D11: adet | E11: 2401.3 | F11: 8288 | G11: =+E11*F11 -> 19901974 | H11: =SUM(J11:AT11) -> 0 | I11: =+F11*H11 -> 0 | J11: {=+HLOOKUP($A$1,+[2]İcmal!$B$19:$AG$49,ROW(A9)+1,FALSE)} -> 0 | K11: {=+HLOOKUP($A$1,+[3]İcmal!$B$19:$AG$49,ROW(B9)+1,FALSE)} -> 0 | L11: {=+HLOOKUP($A$1,+[4]İcmal!$B$19:$AG$49,ROW(C9)+1,FALSE)} -> 0 | M11: {=+HLOOKUP($A$1,+[5]İcmal!$B$19:$AG$49,ROW(D9)+1,FALSE)} -> 0 | N11: {=+HLOOKUP($A$1,+[6]İcmal!$B$19:$AG$49,ROW(E9)+1,FALSE)} -> 0 | O11: {=+HLOOKUP($A$1,+[7]İcmal!$B$19:$AG$49,ROW(F9)+1,FALSE)} -> 0 | P11: {=+HLOOKUP($A$1,+[8]İcmal!$B$19:$AG$49,ROW(G9)+1,FALSE)} -> 0 | Q11: {=+HLOOKUP($A$1,+[9]İcmal!$B$19:$AG$49,ROW(H9)+1,FALSE)} -> 0 | R11: {=+HLOOKUP($A$1,+[10]İcmal!$B$19:$AG$49,ROW(I9)+1,FALSE)} -> 0 | S11: {=+HLOOKUP($A$1,+[11]İcmal!$B$19:$AG$49,ROW(J9)+1,FALSE)} -> 0 | T11: {=+HLOOKUP($A$1,+[12]İcmal!$B$19:$AG$49,ROW(K9)+1,FALSE)} -> 0 | U11: {=+HLOOKUP($A$1,+[13]İcmal!$B$19:$AG$49,ROW(L9)+1,FALSE)} -> 0 | V11: {=+HLOOKUP($A$1,+[14]İcmal!$B$19:$AG$49,ROW(M9)+1,FALSE)} -> 0 | W11: {=+HLOOKUP($A$1,+[15]İcmal!$B$19:$AG$49,ROW(N9)+1,FALSE)} -> 0 | X11: {=+HLOOKUP($A$1,+[16]İcmal!$B$19:$AG$49,ROW(O9)+1,FALSE)} -> 0 | Y11: {=+HLOOKUP($A$1,+[17]İcmal!$B$19:$AG$49,ROW(P9)+1,FALSE)} -> 0 | Z11: {=+HLOOKUP($A$1,+[18]İcmal!$B$19:$AG$49,ROW(Q9)+1,FALSE)} -> 0 | AA11: {=+HLOOKUP($A$1,+[19]İcmal!$B$19:$AG$49,ROW(R9)+1,FALSE)} -> 0 | AB11: {=+HLOOKUP($A$1,+[20]İcmal!$B$19:$AG$49,ROW(S9)+1,FALSE)} -> 0 | AC11: {=+HLOOKUP($A$1,+[21]İcmal!$B$19:$AG$49,ROW(T9)+1,FALSE)} -> 0 | AD11: {=+HLOOKUP($A$1,+[22]İcmal!$B$19:$AG$49,ROW(U9)+1,FALSE)} -> 0 | AE11: {=+HLOOKUP($A$1,+[23]İcmal!$B$19:$AG$49,ROW(V9)+1,FALSE)} -> 0 | AF11: {=+HLOOKUP($A$1,+[24]İcmal!$B$19:$AG$49,ROW(W9)+1,FALSE)} -> 0 | AG11: {=+HLOOKUP($A$1,+[25]İcmal!$B$19:$AG$49,ROW(X9)+1,FALSE)} -> 0 | AH11: {=+HLOOKUP($A$1,+[26]İcmal!$B$19:$AG$49,ROW(Y9)+1,FALSE)} -> 0 | AI11: {=+HLOOKUP($A$1,+[27]İcmal!$B$19:$AG$49,ROW(Z9)+1,FALSE)} -> 0 | AJ11: {=+HLOOKUP($A$1,+[28]İcmal!$B$19:$AG$49,ROW(AA9)+1,FALSE)} -> 0 | AK11: {=+HLOOKUP($A$1,+[29]İcmal!$B$19:$AG$49,ROW(AB9)+1,FALSE)} -> 0
A12: 58 | B12: 022.D | C12: L=6 m Kaya Bulonu | D12: adet | E12: 2970 | F12: 12000 | G12: =+E12*F12 -> 35640000 | H12: =SUM(J12:AT12) -> 175 | I12: =+F12*H12 -> 2100000 | J12: {=+HLOOKUP($A$1,+[2]İcmal!$B$19:$AG$49,ROW(A10)+1,FALSE)} -> 0 | K12: {=+HLOOKUP($A$1,+[3]İcmal!$B$19:$AG$49,ROW(B10)+1,FALSE)} -> 0 | L12: {=+HLOOKUP($A$1,+[4]İcmal!$B$19:$AG$49,ROW(C10)+1,FALSE)} -> 0 | M12: {=+HLOOKUP($A$1,+[5]İcmal!$B$19:$AG$49,ROW(D10)+1,FALSE)} -> 0 | N12: {=+HLOOKUP($A$1,+[6]İcmal!$B$19:$AG$49,ROW(E10)+1,FALSE)} -> 0 | O12: {=+HLOOKUP($A$1,+[7]İcmal!$B$19:$AG$49,ROW(F10)+1,FALSE)} -> 0 | P12: {=+HLOOKUP($A$1,+[8]İcmal!$B$19:$AG$49,ROW(G10)+1,FALSE)} -> 0 | Q12: {=+HLOOKUP($A$1,+[9]İcmal!$B$19:$AG$49,ROW(H10)+1,FALSE)} -> 0 | R12: {=+HLOOKUP($A$1,+[10]İcmal!$B$19:$AG$49,ROW(I10)+1,FALSE)} -> 0 | S12: {=+HLOOKUP($A$1,+[11]İcmal!$B$19:$AG$49,ROW(J10)+1,FALSE)} -> 0 | T12: {=+HLOOKUP($A$1,+[12]İcmal!$B$19:$AG$49,ROW(K10)+1,FALSE)} -> 0 | U12: {=+HLOOKUP($A$1,+[13]İcmal!$B$19:$AG$49,ROW(L10)+1,FALSE)} -> 0 | V12: {=+HLOOKUP($A$1,+[14]İcmal!$B$19:$AG$49,ROW(M10)+1,FALSE)} -> 0 | W12: {=+HLOOKUP($A$1,+[15]İcmal!$B$19:$AG$49,ROW(N10)+1,FALSE)} -> 0 | X12: {=+HLOOKUP($A$1,+[16]İcmal!$B$19:$AG$49,ROW(O10)+1,FALSE)} -> 0 | Y12: {=+HLOOKUP($A$1,+[17]İcmal!$B$19:$AG$49,ROW(P10)+1,FALSE)} -> 0 | Z12: {=+HLOOKUP($A$1,+[18]İcmal!$B$19:$AG$49,ROW(Q10)+1,FALSE)} -> 0 | AA12: {=+HLOOKUP($A$1,+[19]İcmal!$B$19:$AG$49,ROW(R10)+1,FALSE)} -> 0 | AB12: {=+HLOOKUP($A$1,+[20]İcmal!$B$19:$AG$49,ROW(S10)+1,FALSE)} -> 0 | AC12: {=+HLOOKUP($A$1,+[21]İcmal!$B$19:$AG$49,ROW(T10)+1,FALSE)} -> 0 | AD12: {=+HLOOKUP($A$1,+[22]İcmal!$B$19:$AG$49,ROW(U10)+1,FALSE)} -> 0 | AE12: {=+HLOOKUP($A$1,+[23]İcmal!$B$19:$AG$49,ROW(V10)+1,FALSE)} -> 0 | AF12: {=+HLOOKUP($A$1,+[24]İcmal!$B$19:$AG$49,ROW(W10)+1,FALSE)} -> 0 | AG12: {=+HLOOKUP($A$1,+[25]İcmal!$B$19:$AG$49,ROW(X10)+1,FALSE)} -> 0 | AH12: {=+HLOOKUP($A$1,+[26]İcmal!$B$19:$AG$49,ROW(Y10)+1,FALSE)} -> 175 | AI12: {=+HLOOKUP($A$1,+[27]İcmal!$B$19:$AG$49,ROW(Z10)+1,FALSE)} -> 0 | AJ12: {=+HLOOKUP($A$1,+[28]İcmal!$B$19:$AG$49,ROW(AA10)+1,FALSE)} -> 0 | AK12: {=+HLOOKUP($A$1,+[29]İcmal!$B$19:$AG$49,ROW(AB10)+1,FALSE)} -> 0
A13: 59 | B13: 022.E | C13: L=8 m Kaya Bulonu | D13: adet | E13: 7008.23 | F13: 28000 | G13: =+E13*F13 -> 196230440 | H13: =SUM(J13:AT13) -> 580 | I13: =+F13*H13 -> 16240000 | J13: {=+HLOOKUP($A$1,+[2]İcmal!$B$19:$AG$49,ROW(A11)+1,FALSE)} -> 0 | K13: {=+HLOOKUP($A$1,+[3]İcmal!$B$19:$AG$49,ROW(B11)+1,FALSE)} -> 182 | L13: {=+HLOOKUP($A$1,+[4]İcmal!$B$19:$AG$49,ROW(C11)+1,FALSE)} -> 0 | M13: {=+HLOOKUP($A$1,+[5]İcmal!$B$19:$AG$49,ROW(D11)+1,FALSE)} -> 0 | N13: {=+HLOOKUP($A$1,+[6]İcmal!$B$19:$AG$49,ROW(E11)+1,FALSE)} -> 93 | O13: {=+HLOOKUP($A$1,+[7]İcmal!$B$19:$AG$49,ROW(F11)+1,FALSE)} -> 105 | P13: {=+HLOOKUP($A$1,+[8]İcmal!$B$19:$AG$49,ROW(G11)+1,FALSE)} -> 0 | Q13: {=+HLOOKUP($A$1,+[9]İcmal!$B$19:$AG$49,ROW(H11)+1,FALSE)} -> 0 | R13: {=+HLOOKUP($A$1,+[10]İcmal!$B$19:$AG$49,ROW(I11)+1,FALSE)} -> 75 | S13: {=+HLOOKUP($A$1,+[11]İcmal!$B$19:$AG$49,ROW(J11)+1,FALSE)} -> 105 | T13: {=+HLOOKUP($A$1,+[12]İcmal!$B$19:$AG$49,ROW(K11)+1,FALSE)} -> 0 | U13: {=+HLOOKUP($A$1,+[13]İcmal!$B$19:$AG$49,ROW(L11)+1,FALSE)} -> 0 | V13: {=+HLOOKUP($A$1,+[14]İcmal!$B$19:$AG$49,ROW(M11)+1,FALSE)} -> 0 | W13: {=+HLOOKUP($A$1,+[15]İcmal!$B$19:$AG$49,ROW(N11)+1,FALSE)} -> 0 | X13: {=+HLOOKUP($A$1,+[16]İcmal!$B$19:$AG$49,ROW(O11)+1,FALSE)} -> 0 | Y13: {=+HLOOKUP($A$1,+[17]İcmal!$B$19:$AG$49,ROW(P11)+1,FALSE)} -> 0 | Z13: {=+HLOOKUP($A$1,+[18]İcmal!$B$19:$AG$49,ROW(Q11)+1,FALSE)} -> 0 | AA13: {=+HLOOKUP($A$1,+[19]İcmal!$B$19:$AG$49,ROW(R11)+1,FALSE)} -> 0 | AB13: {=+HLOOKUP($A$1,+[20]İcmal!$B$19:$AG$49,ROW(S11)+1,FALSE)} -> 0 | AC13: {=+HLOOKUP($A$1,+[21]İcmal!$B$19:$AG$49,ROW(T11)+1,FALSE)} -> 0 | AD13: {=+HLOOKUP($A$1,+[22]İcmal!$B$19:$AG$49,ROW(U11)+1,FALSE)} -> 20 | AE13: {=+HLOOKUP($A$1,+[23]İcmal!$B$19:$AG$49,ROW(V11)+1,FALSE)} -> 0 | AF13: {=+HLOOKUP($A$1,+[24]İcmal!$B$19:$AG$49,ROW(W11)+1,FALSE)} -> 0 | AG13: {=+HLOOKUP($A$1,+[25]İcmal!$B$19:$AG$49,ROW(X11)+1,FALSE)} -> 0 | AH13: {=+HLOOKUP($A$1,+[26]İcmal!$B$19:$AG$49,ROW(Y11)+1,FALSE)} -> 0 | AI13: {=+HLOOKUP($A$1,+[27]İcmal!$B$19:$AG$49,ROW(Z11)+1,FALSE)} -> 0 | AJ13: {=+HLOOKUP($A$1,+[28]İcmal!$B$19:$AG$49,ROW(AA11)+1,FALSE)} -> 0 | AK13: {=+HLOOKUP($A$1,+[29]İcmal!$B$19:$AG$49,ROW(AB11)+1,FALSE)} -> 0
A14: 60 | B14: 023.A | C14: 125 mm Delik İçine 14 mm Kalınlığında S420a ile Zemin Çivisi Teşkili | D14: m | E14: 156606.89 | F14: 375 | G14: =+E14*F14 -> 58727584 | H14: =SUM(J14:AT14) -> 3114 | I14: =+F14*H14 -> 1167750 | J14: {=+HLOOKUP($A$1,+[2]İcmal!$B$19:$AG$49,ROW(A12)+1,FALSE)} -> 0 | K14: {=+HLOOKUP($A$1,+[3]İcmal!$B$19:$AG$49,ROW(B12)+1,FALSE)} -> 0 | L14: {=+HLOOKUP($A$1,+[4]İcmal!$B$19:$AG$49,ROW(C12)+1,FALSE)} -> 0 | M14: {=+HLOOKUP($A$1,+[5]İcmal!$B$19:$AG$49,ROW(D12)+1,FALSE)} -> 0 | N14: {=+HLOOKUP($A$1,+[6]İcmal!$B$19:$AG$49,ROW(E12)+1,FALSE)} -> 396 | O14: {=+HLOOKUP($A$1,+[7]İcmal!$B$19:$AG$49,ROW(F12)+1,FALSE)} -> 972 | P14: {=+HLOOKUP($A$1,+[8]İcmal!$B$19:$AG$49,ROW(G12)+1,FALSE)} -> 0 | Q14: {=+HLOOKUP($A$1,+[9]İcmal!$B$19:$AG$49,ROW(H12)+1,FALSE)} -> 0 | R14: {=+HLOOKUP($A$1,+[10]İcmal!$B$19:$AG$49,ROW(I12)+1,FALSE)} -> 396 | S14: {=+HLOOKUP($A$1,+[11]İcmal!$B$19:$AG$49,ROW(J12)+1,FALSE)} -> 810 | T14: {=+HLOOKUP($A$1,+[12]İcmal!$B$19:$AG$49,ROW(K12)+1,FALSE)} -> 0 | U14: {=+HLOOKUP($A$1,+[13]İcmal!$B$19:$AG$49,ROW(L12)+1,FALSE)} -> 0 | V14: {=+HLOOKUP($A$1,+[14]İcmal!$B$19:$AG$49,ROW(M12)+1,FALSE)} -> 0 | W14: {=+HLOOKUP($A$1,+[15]İcmal!$B$19:$AG$49,ROW(N12)+1,FALSE)} -> 0 | X14: {=+HLOOKUP($A$1,+[16]İcmal!$B$19:$AG$49,ROW(O12)+1,FALSE)} -> 0 | Y14: {=+HLOOKUP($A$1,+[17]İcmal!$B$19:$AG$49,ROW(P12)+1,FALSE)} -> 0 | Z14: {=+HLOOKUP($A$1,+[18]İcmal!$B$19:$AG$49,ROW(Q12)+1,FALSE)} -> 0 | AA14: {=+HLOOKUP($A$1,+[19]İcmal!$B$19:$AG$49,ROW(R12)+1,FALSE)} -> 0 | AB14: {=+HLOOKUP($A$1,+[20]İcmal!$B$19:$AG$49,ROW(S12)+1,FALSE)} -> 180 | AC14: {=+HLOOKUP($A$1,+[21]İcmal!$B$19:$AG$49,ROW(T12)+1,FALSE)} -> 0 | AD14: {=+HLOOKUP($A$1,+[22]İcmal!$B$19:$AG$49,ROW(U12)+1,FALSE)} -> 0 | AE14: {=+HLOOKUP($A$1,+[23]İcmal!$B$19:$AG$49,ROW(V12)+1,FALSE)} -> 0 | AF14: {=+HLOOKUP($A$1,+[24]İcmal!$B$19:$AG$49,ROW(W12)+1,FALSE)} -> 180 | AG14: {=+HLOOKUP($A$1,+[25]İcmal!$B$19:$AG$49,ROW(X12)+1,FALSE)} -> 0 | AH14: {=+HLOOKUP($A$1,+[26]İcmal!$B$19:$AG$49,ROW(Y12)+1,FALSE)} -> 180 | AI14: {=+HLOOKUP($A$1,+[27]İcmal!$B$19:$AG$49,ROW(Z12)+1,FALSE)} -> 0 | AJ14: {=+HLOOKUP($A$1,+[28]İcmal!$B$19:$AG$49,ROW(AA12)+1,FALSE)} -> 0 | AK14: {=+HLOOKUP($A$1,+[29]İcmal!$B$19:$AG$49,ROW(AB12)+1,FALSE)} -> 0
... A32: 78 | B32: 030.E | C32: Block-out Kutusu | D32: kg | E32: 4500 | F32: 180 | G32: =+E32*F32 -> 810000 | H32: =SUM(J32:AT32) -> 0 | I32: =+F32*H32 -> 0 | J32: {=+HLOOKUP($A$1,+[2]İcmal!$B$19:$AG$49,ROW(A30)+1,FALSE)} -> 0 | K32: {=+HLOOKUP($A$1,+[3]İcmal!$B$19:$AG$49,ROW(B30)+1,FALSE)} -> 0 | L32: {=+HLOOKUP($A$1,+[4]İcmal!$B$19:$AG$49,ROW(C30)+1,FALSE)} -> 0 | M32: {=+HLOOKUP($A$1,+[5]İcmal!$B$19:$AG$49,ROW(D30)+1,FALSE)} -> 0 | N32: {=+HLOOKUP($A$1,+[6]İcmal!$B$19:$AG$49,ROW(E30)+1,FALSE)} -> 0 | O32: {=+HLOOKUP($A$1,+[7]İcmal!$B$19:$AG$49,ROW(F30)+1,FALSE)} -> 0 | P32: {=+HLOOKUP($A$1,+[8]İcmal!$B$19:$AG$49,ROW(G30)+1,FALSE)} -> 0 | Q32: {=+HLOOKUP($A$1,+[9]İcmal!$B$19:$AG$49,ROW(H30)+1,FALSE)} -> 0 | R32: {=+HLOOKUP($A$1,+[10]İcmal!$B$19:$AG$49,ROW(I30)+1,FALSE)} -> 0 | S32: {=+HLOOKUP($A$1,+[11]İcmal!$B$19:$AG$49,ROW(J30)+1,FALSE)} -> 0 | T32: {=+HLOOKUP($A$1,+[12]İcmal!$B$19:$AG$49,ROW(K30)+1,FALSE)} -> 0 | U32: {=+HLOOKUP($A$1,+[13]İcmal!$B$19:$AG$49,ROW(L30)+1,FALSE)} -> 0 | V32: {=+HLOOKUP($A$1,+[14]İcmal!$B$19:$AG$49,ROW(M30)+1,FALSE)} -> 0 | W32: {=+HLOOKUP($A$1,+[15]İcmal!$B$19:$AG$49,ROW(N30)+1,FALSE)} -> 0 | X32: {=+HLOOKUP($A$1,+[16]İcmal!$B$19:$AG$49,ROW(O30)+1,FALSE)} -> 0 | Y32: {=+HLOOKUP($A$1,+[17]İcmal!$B$19:$AG$49,ROW(P30)+1,FALSE)} -> 0 | Z32: {=+HLOOKUP($A$1,+[18]İcmal!$B$19:$AG$49,ROW(Q30)+1,FALSE)} -> 0 | AA32: {=+HLOOKUP($A$1,+[19]İcmal!$B$19:$AG$49,ROW(R30)+1,FALSE)} -> 0 | AB32: {=+HLOOKUP($A$1,+[20]İcmal!$B$19:$AG$49,ROW(S30)+1,FALSE)} -> 0 | AC32: {=+HLOOKUP($A$1,+[21]İcmal!$B$19:$AG$49,ROW(T30)+1,FALSE)} -> 0 | AD32: {=+HLOOKUP($A$1,+[22]İcmal!$B$19:$AG$49,ROW(U30)+1,FALSE)} -> 0 | AE32: {=+HLOOKUP($A$1,+[23]İcmal!$B$19:$AG$49,ROW(V30)+1,FALSE)} -> 0 | AF32: {=+HLOOKUP($A$1,+[24]İcmal!$B$19:$AG$49,ROW(W30)+1,FALSE)} -> 0 | AG32: {=+HLOOKUP($A$1,+[25]İcmal!$B$19:$AG$49,ROW(X30)+1,FALSE)} -> 0 | AH32: {=+HLOOKUP($A$1,+[26]İcmal!$B$19:$AG$49,ROW(Y30)+1,FALSE)} -> 0 | AI32: {=+HLOOKUP($A$1,+[27]İcmal!$B$19:$AG$49,ROW(Z30)+1,FALSE)} -> 0 | AJ32: {=+HLOOKUP($A$1,+[28]İcmal!$B$19:$AG$49,ROW(AA30)+1,FALSE)} -> 0 | AK32: {=+HLOOKUP($A$1,+[29]İcmal!$B$19:$AG$49,ROW(AB30)+1,FALSE)} -> 0
I33: =SUM(I3:I32) -> 90228122 | J33: =+SUMPRODUCT(J3:J32,$F$3:$F$32) -> 354138.73 | K33: =+SUMPRODUCT(K3:K32,$F$3:$F$32) -> 5405562.8 | L33: =+SUMPRODUCT(L3:L32,$F$3:$F$32) -> 0 | M33: =+SUMPRODUCT(M3:M32,$F$3:$F$32) -> 0 | N33: =+SUMPRODUCT(N3:N32,$F$3:$F$32) -> 16810799 | O33: =+SUMPRODUCT(O3:O32,$F$3:$F$32) -> 21637470 | P33: =+SUMPRODUCT(P3:P32,$F$3:$F$32) -> 0 | Q33: =+SUMPRODUCT(Q3:Q32,$F$3:$F$32) -> 0 | ... AK33: =+SUMPRODUCT(AK3:AK32,$F$3:$F$32) -> 0 | AS33: =+SUMPRODUCT(AS3:AS32,$F$3:$F$32) -> 0

Sheet Barbaros 1125
A1: 1125
A2: Sıra No | B2: İş Kalemi No | C2: Açıklama | D2: Birimi | E2: Miktarı | F2: Birim Fiyat | G2: Tutar | H2: Toplam Metraj | I2: Toplam Tutar | J2: Hat-1-HY-P1-1.Aşama | K2: Hat-1-HY-P1-2.Aşama | L2: Hat-1-HY-P1-3.Aşama | M2: Hat-1-HY-P1-4.Aşama | N2: Hat-2-HY-P1-1.Aşama | O2: Hat-2-HY-P1-2.Aşama | P2: Hat-2-HY-P1-3.Aşama | Q2: Hat-2-HY-P1-4.Aşama | R2: Hat-1-KY-P1-1.Aşama | S2: Hat-1-KY-P1-2.Aşama | T2: Hat-1-KY-P1-3.Aşama | U2: Hat-1-KY-P1-4.Aşama | V2: Hat-2-KY-P1-1.Aşama | W2: Hat-2-KY-P1-2.Aşama | X2: Hat-2-KY-P1-3.Aşama | Y2: Hat-2-KY-P1-4.Aşama | Z2: Hat-2-B1 Bağlantı-3 P2 Yönü Üstyarı Aşaması (B1-101) | AA2: Hat-2-B1 Bağlantı-3 P2 Yönü Altyarı Aşaması (B1-101) | AB2: Hat1-B1 Bağlantı-3 P2 Yönü Üstyarı Aşaması (B1-102) | AC2: Hat-1-B1 Bağlantı-3 P2 Yönü Alt Yarı Aşaması (B1-102) | AD2: Hat-2-B1 Bağlantı-2 P2 Yönü Üstyarı Aşaması (B1-103) | AE2: Hat-2-B1 Bağlantı-2 P2 Yönü Alt Yarı Aşaması (B1-103) | AF2: Hat-1-B1 Bağlantı-2 P2 Yönü Üstyarı Aşaması (B1-104) | AG2: Hat-1-B1 Bağlantı-2 P2 Yönü Altyarı Aşaması (B1-104) | AH2: Hat-2-B1 Bağlantı-1 P2 Yönü Üstyarı Aşaması (B1-105) | AI2: Hat-2-B1 Bağlantı-2 P2 Yönü Alt Yarı Aşaması (B1-105) | AJ2: Hat-1-B1 Bağlantı-1 P2 Yönü Üstyarı Aşaması (B1-106) | AK2: Hat-1-B1 Bağlantı-1 P2 Yönü Alt Yarı Aşaması (B1-106)
A3: 49 | B3: 018 | C3: Geleneksel (NATM) Tünel Kazısı | D3: m³ | E3: 186392.65 | F3: 5075 | G3: =+E3*F3 -> 9.459427e+08 | H3: =SUM(J3:AT3) -> 3865.12 | I3: =+F3*H3 -> 19615484 | J3: {=+HLOOKUP($A$1,+[2]İcmal!$B$19:$AG$49,ROW(A1)+1,FALSE)} -> 0 | K3: {=+HLOOKUP($A$1,+[3]İcmal!$B$19:$AG$49,ROW(B1)+1,FALSE)} -> 7.128 | L3: {=+HLOOKUP($A$1,+[4]İcmal!$B$19:$AG$49,ROW(C1)+1,FALSE)} -> 0 | M3: {=+HLOOKUP($A$1,+[5]İcmal!$B$19:$AG$49,ROW(D1)+1,FALSE)} -> 0 | N3: {=+HLOOKUP($A$1,+[6]İcmal!$B$19:$AG$49,ROW(E1)+1,FALSE)} -> 910.481 | O3: {=+HLOOKUP($A$1,+[7]İcmal!$B$19:$AG$49,ROW(F1)+1,FALSE)} -> 442.815 | P3: {=+HLOOKUP($A$1,+[8]İcmal!$B$19:$AG$49,ROW(G1)+1,FALSE)} -> 0 | Q3: {=+HLOOKUP($A$1,+[9]İcmal!$B$19:$AG$49,ROW(H1)+1,FALSE)} -> 0 | R3: {=+HLOOKUP($A$1,+[10]İcmal!$B$19:$AG$49,ROW(I1)+1,FALSE)} -> 833.482 | S3: {=+HLOOKUP($A$1,+[11]İcmal!$B$19:$AG$49,ROW(J1)+1,FALSE)} -> 590.007 | T3: {=+HLOOKUP($A$1,+[12]İcmal!$B$19:$AG$49,ROW(K1)+1,FALSE)} -> 0 | U3: {=+HLOOKUP($A$1,+[13]İcmal!$B$19:$AG$49,ROW(L1)+1,FALSE)} -> 0 | V3: {=+HLOOKUP($A$1,+[14]İcmal!$B$19:$AG$49,ROW(M1)+1,FALSE)} -> 0 | W3: {=+HLOOKUP($A$1,+[15]İcmal!$B$19:$AG$49,ROW(N1)+1,FALSE)} -> 163.879 | X3: {=+HLOOKUP($A$1,+[16]İcmal!$B$19:$AG$49,ROW(O1)+1,FALSE)} -> 0 | Y3: {=+HLOOKUP($A$1,+[17]İcmal!$B$19:$AG$49,ROW(P1)+1,FALSE)} -> 0 | Z3: {=+HLOOKUP($A$1,+[18]İcmal!$B$19:$AG$49,ROW(Q1)+1,FALSE)} -> 0 | AA3: {=+HLOOKUP($A$1,+[19]İcmal!$B$19:$AG$49,ROW(R1)+1,FALSE)} -> 0 | AB3: {=+HLOOKUP($A$1,+[20]İcmal!$B$19:$AG$49,ROW(S1)+1,FALSE)} -> 344.86 | AC3: {=+HLOOKUP($A$1,+[21]İcmal!$B$19:$AG$49,ROW(T1)+1,FALSE)} -> 0 | AD3: {=+HLOOKUP($A$1,+[22]İcmal!$B$19:$AG$49,ROW(U1)+1,FALSE)} -> 0 | AE3: {=+HLOOKUP($A$1,+[23]İcmal!$B$19:$AG$49,ROW(V1)+1,FALSE)} -> 0 | AF3: {=+HLOOKUP($A$1,+[24]İcmal!$B$19:$AG$49,ROW(W1)+1,FALSE)} -> 229.907 | AG3: {=+HLOOKUP($A$1,+[25]İcmal!$B$19:$AG$49,ROW(X1)+1,FALSE)} -> 0 | AH3: {=+HLOOKUP($A$1,+[26]İcmal!$B$19:$AG$49,ROW(Y1)+1,FALSE)} -> 342.561 | AI3: {=+HLOOKUP($A$1,+[27]İcmal!$B$19:$AG$49,ROW(Z1)+1,FALSE)} -> 0 | AJ3: {=+HLOOKUP($A$1,+[28]İcmal!$B$19:$AG$49,ROW(AA1)+1,FALSE)} -> 0 | AK3: {=+HLOOKUP($A$1,+[29]İcmal!$B$19:$AG$49,ROW(AB1)+1,FALSE)} -> 0
A4: 50 | B4: 019.A | C4: Kazıdan çıkan veya Ariyetten alınan malzeme ile geri dolgu yapılması | D4: m³ | E4: 910 | F4: 600 | G4: =+E4*F4 -> 546000 | H4: =SUM(J4:AT4) -> 0 | I4: =+F4*H4 -> 0 | J4: {=+HLOOKUP($A$1,+[2]İcmal!$B$19:$AG$49,ROW(A2)+1,FALSE)} -> 0 | K4: {=+HLOOKUP($A$1,+[3]İcmal!$B$19:$AG$49,ROW(B2)+1,FALSE)} -> 0 | L4: {=+HLOOKUP($A$1,+[4]İcmal!$B$19:$AG$49,ROW(C2)+1,FALSE)} -> 0 | M4: {=+HLOOKUP($A$1,+[5]İcmal!$B$19:$AG$49,ROW(D2)+1,FALSE)} -> 0 | N4: {=+HLOOKUP($A$1,+[6]İcmal!$B$19:$AG$49,ROW(E2)+1,FALSE)} -> 0 | O4: {=+HLOOKUP($A$1,+[7]İcmal!$B$19:$AG$49,ROW(F2)+1,FALSE)} -> 0 | P4: {=+HLOOKUP($A$1,+[8]İcmal!$B$19:$AG$49,ROW(G2)+1,FALSE)} -> 0 | Q4: {=+HLOOKUP($A$1,+[9]İcmal!$B$19:$AG$49,ROW(H2)+1,FALSE)} -> 0 | R4: {=+HLOOKUP($A$1,+[10]İcmal!$B$19:$AG$49,ROW(I2)+1,FALSE)} -> 0 | S4: {=+HLOOKUP($A$1,+[11]İcmal!$B$19:$AG$49,ROW(J2)+1,FALSE)} -> 0 | T4: {=+HLOOKUP($A$1,+[12]İcmal!$B$19:$AG$49,ROW(K2)+1,FALSE)} -> 0 | U4: {=+HLOOKUP($A$1,+[13]İcmal!$B$19:$AG$49,ROW(L2)+1,FALSE)} -> 0 | V4: {=+HLOOKUP($A$1,+[14]İcmal!$B$19:$AG$49,ROW(M2)+1,FALSE)} -> 0 | W4: {=+HLOOKUP($A$1,+[15]İcmal!$B$19:$AG$49,ROW(N2)+1,FALSE)} -> 0 | X4: {=+HLOOKUP($A$1,+[16]İcmal!$B$19:$AG$49,ROW(O2)+1,FALSE)} -> 0 | Y4: {=+HLOOKUP($A$1,+[17]İcmal!$B$19:$AG$49,ROW(P2)+1,FALSE)} -> 0 | Z4: {=+HLOOKUP($A$1,+[18]İcmal!$B$19:$AG$49,ROW(Q2)+1,FALSE)} -> 0 | AA4: {=+HLOOKUP($A$1,+[19]İcmal!$B$19:$AG$49,ROW(R2)+1,FALSE)} -> 0 | AB4: {=+HLOOKUP($A$1,+[20]İcmal!$B$19:$AG$49,ROW(S2)+1,FALSE)} -> 0 | AC4: {=+HLOOKUP($A$1,+[21]İcmal!$B$19:$AG$49,ROW(T2)+1,FALSE)} -> 0 | AD4: {=+HLOOKUP($A$1,+[22]İcmal!$B$19:$AG$49,ROW(U2)+1,FALSE)} -> 0 | AE4: {=+HLOOKUP($A$1,+[23]İcmal!$B$19:$AG$49,ROW(V2)+1,FALSE)} -> 0 | AF4: {=+HLOOKUP($A$1,+[24]İcmal!$B$19:$AG$49,ROW(W2)+1,FALSE)} -> 0 | AG4: {=+HLOOKUP($A$1,+[25]İcmal!$B$19:$AG$49,ROW(X2)+1,FALSE)} -> 0 | AH4: {=+HLOOKUP($A$1,+[26]İcmal!$B$19:$AG$49,ROW(Y2)+1,FALSE)} -> 0 | AI4: {=+HLOOKUP($A$1,+[27]İcmal!$B$19:$AG$49,ROW(Z2)+1,FALSE)} -> 0 | AJ4: {=+HLOOKUP($A$1,+[28]İcmal!$B$19:$AG$49,ROW(AA2)+1,FALSE)} -> 0 | AK4: {=+HLOOKUP($A$1,+[29]İcmal!$B$19:$AG$49,ROW(AB2)+1,FALSE)} -> 0
A5: 51 | B5: 019.B | C5: Kum, Çakıl, Kırma Tas ve Benzeri Malzeme ile Dolgu Yapılması | D5: m³ | E5: 1785 | F5: 1500 | G5: =+E5*F5 -> 2677500 | H5: =SUM(J5:AT5) -> 0 | I5: =+F5*H5 -> 0 | J5: {=+HLOOKUP($A$1,+[2]İcmal!$B$19:$AG$49,ROW(A3)+1,FALSE)} -> 0 | K5: {=+HLOOKUP($A$1,+[3]İcmal!$B$19:$AG$49,ROW(B3)+1,FALSE)} -> 0 | L5: {=+HLOOKUP($A$1,+[4]İcmal!$B$19:$AG$49,ROW(C3)+1,FALSE)} -> 0 | M5: {=+HLOOKUP($A$1,+[5]İcmal!$B$19:$AG$49,ROW(D3)+1,FALSE)} -> 0 | N5: {=+HLOOKUP($A$1,+[6]İcmal!$B$19:$AG$49,ROW(E3)+1,FALSE)} -> 0 | O5: {=+HLOOKUP($A$1,+[7]İcmal!$B$19:$AG$49,ROW(F3)+1,FALSE)} -> 0 | P5: {=+HLOOKUP($A$1,+[8]İcmal!$B$19:$AG$49,ROW(G3)+1,FALSE)} -> 0 | Q5: {=+HLOOKUP($A$1,+[9]İcmal!$B$19:$AG$49,ROW(H3)+1,FALSE)} -> 0 | R5: {=+HLOOKUP($A$1,+[10]İcmal!$B$19:$AG$49,ROW(I3)+1,FALSE)} -> 0 | S5: {=+HLOOKUP($A$1,+[11]İcmal!$B$19:$AG$49,ROW(J3)+1,FALSE)} -> 0 | T5: {=+HLOOKUP($A$1,+[12]İcmal!$B$19:$AG$49,ROW(K3)+1,FALSE)} -> 0 | U5: {=+HLOOKUP($A$1,+[13]İcmal!$B$19:$AG$49,ROW(L3)+1,FALSE)} -> 0 | V5: {=+HLOOKUP($A$1,+[14]İcmal!$B$19:$AG$49,ROW(M3)+1,FALSE)} -> 0 | W5: {=+HLOOKUP($A$1,+[15]İcmal!$B$19:$AG$49,ROW(N3)+1,FALSE)} -> 0 | X5: {=+HLOOKUP($A$1,+[16]İcmal!$B$19:$AG$49,ROW(O3)+1,FALSE)} -> 0 | Y5: {=+HLOOKUP($A$1,+[17]İcmal!$B$19:$AG$49,ROW(P3)+1,FALSE)} -> 0 | Z5: {=+HLOOKUP($A$1,+[18]İcmal!$B$19:$AG$49,ROW(Q3)+1,FALSE)} -> 0 | AA5: {=+HLOOKUP($A$1,+[19]İcmal!$B$19:$AG$49,ROW(R3)+1,FALSE)} -> 0 | AB5: {=+HLOOKUP($A$1,+[20]İcmal!$B$19:$AG$49,ROW(S3)+1,FALSE)} -> 0 | AC5: {=+HLOOKUP($A$1,+[21]İcmal!$B$19:$AG$49,ROW(T3)+1,FALSE)} -> 0 | AD5: {=+HLOOKUP($A$1,+[22]İcmal!$B$19:$AG$49,ROW(U3)+1,FALSE)} -> 0 | AE5: {=+HLOOKUP($A$1,+[23]İcmal!$B$19:$AG$49,ROW(V3)+1,FALSE)} -> 0 | AF5: {=+HLOOKUP($A$1,+[24]İcmal!$B$19:$AG$49,ROW(W3)+1,FALSE)} -> 0 | AG5: {=+HLOOKUP($A$1,+[25]İcmal!$B$19:$AG$49,ROW(X3)+1,FALSE)} -> 0 | AH5: {=+HLOOKUP($A$1,+[26]İcmal!$B$19:$AG$49,ROW(Y3)+1,FALSE)} -> 0 | AI5: {=+HLOOKUP($A$1,+[27]İcmal!$B$19:$AG$49,ROW(Z3)+1,FALSE)} -> 0 | AJ5: {=+HLOOKUP($A$1,+[28]İcmal!$B$19:$AG$49,ROW(AA3)+1,FALSE)} -> 0 | AK5: {=+HLOOKUP($A$1,+[29]İcmal!$B$19:$AG$49,ROW(AB3)+1,FALSE)} -> 0
A6: 52 | B6: 020 | C6: Püskürtme Beton (Tünel ve Şaftlarda) | D6: m³ | E6: 38798.59 | F6: 15334 | G6: =+E6*F6 -> 5.9493758e+08 | H6: =SUM(J6:AT6) -> 827.201 | I6: =+F6*H6 -> 12684300 | J6: {=+HLOOKUP($A$1,+[2]İcmal!$B$19:$AG$49,ROW(A4)+1,FALSE)} -> 0 | K6: {=+HLOOKUP($A$1,+[3]İcmal!$B$19:$AG$49,ROW(B4)+1,FALSE)} -> 7.477 | L6: {=+HLOOKUP($A$1,+[4]İcmal!$B$19:$AG$49,ROW(C4)+1,FALSE)} -> 0 | M6: {=+HLOOKUP($A$1,+[5]İcmal!$B$19:$AG$49,ROW(D4)+1,FALSE)} -> 0 | N6: {=+HLOOKUP($A$1,+[6]İcmal!$B$19:$AG$49,ROW(E4)+1,FALSE)} -> 206.152 | O6: {=+HLOOKUP($A$1,+[7]İcmal!$B$19:$AG$49,ROW(F4)+1,FALSE)} -> 85.98 | P6: {=+HLOOKUP($A$1,+[8]İcmal!$B$19:$AG$49,ROW(G4)+1,FALSE)} -> 0 | Q6: {=+HLOOKUP($A$1,+[9]İcmal!$B$19:$AG$49,ROW(H4)+1,FALSE)} -> 0 | R6: {=+HLOOKUP($A$1,+[10]İcmal!$B$19:$AG$49,ROW(I4)+1,FALSE)} -> 204.355 | S6: {=+HLOOKUP($A$1,+[11]İcmal!$B$19:$AG$49,ROW(J4)+1,FALSE)} -> 114.23 | T6: {=+HLOOKUP($A$1,+[12]İcmal!$B$19:$AG$49,ROW(K4)+1,FALSE)} -> 0 | U6: {=+HLOOKUP($A$1,+[13]İcmal!$B$19:$AG$49,ROW(L4)+1,FALSE)} -> 0 | V6: {=+HLOOKUP($A$1,+[14]İcmal!$B$19:$AG$49,ROW(M4)+1,FALSE)} -> 0 | W6: {=+HLOOKUP($A$1,+[15]İcmal!$B$19:$AG$49,ROW(N4)+1,FALSE)} -> 38.564 | X6: {=+HLOOKUP($A$1,+[16]İcmal!$B$19:$AG$49,ROW(O4)+1,FALSE)} -> 0 | Y6: {=+HLOOKUP($A$1,+[17]İcmal!$B$19:$AG$49,ROW(P4)+1,FALSE)} -> 0 | Z6: {=+HLOOKUP($A$1,+[18]İcmal!$B$19:$AG$49,ROW(Q4)+1,FALSE)} -> 0 | AA6: {=+HLOOKUP($A$1,+[19]İcmal!$B$19:$AG$49,ROW(R4)+1,FALSE)} -> 0 | AB6: {=+HLOOKUP($A$1,+[20]İcmal!$B$19:$AG$49,ROW(S4)+1,FALSE)} -> 69.518 | AC6: {=+HLOOKUP($A$1,+[21]İcmal!$B$19:$AG$49,ROW(T4)+1,FALSE)} -> 0 | AD6: {=+HLOOKUP($A$1,+[22]İcmal!$B$19:$AG$49,ROW(U4)+1,FALSE)} -> 0 | AE6: {=+HLOOKUP($A$1,+[23]İcmal!$B$19:$AG$49,ROW(V4)+1,FALSE)} -> 0 | AF6: {=+HLOOKUP($A$1,+[24]İcmal!$B$19:$AG$49,ROW(W4)+1,FALSE)} -> 33.706 | AG6: {=+HLOOKUP($A$1,+[25]İcmal!$B$19:$AG$49,ROW(X4)+1,FALSE)} -> 0 | AH6: {=+HLOOKUP($A$1,+[26]İcmal!$B$19:$AG$49,ROW(Y4)+1,FALSE)} -> 67.219 | AI6: {=+HLOOKUP($A$1,+[27]İcmal!$B$19:$AG$49,ROW(Z4)+1,FALSE)} -> 0 | AJ6: {=+HLOOKUP($A$1,+[28]İcmal!$B$19:$AG$49,ROW(AA4)+1,FALSE)} -> 0 | AK6: {=+HLOOKUP($A$1,+[29]İcmal!$B$19:$AG$49,ROW(AB4)+1,FALSE)} -> 0
A7: 53 | B7: 021.A | C7: Delgi boyu =< 30m | D7: m | E7: 19569.89 | F7: 248 | G7: =+E7*F7 -> 4853332.7 | H7: =SUM(J7:AT7) -> 0 | I7: =+F7*H7 -> 0 | J7: {=+HLOOKUP($A$1,+[2]İcmal!$B$19:$AG$49,ROW(A5)+1,FALSE)} -> 0 | K7: {=+HLOOKUP($A$1,+[3]İcmal!$B$19:$AG$49,ROW(B5)+1,FALSE)} -> 0 | L7: {=+HLOOKUP($A$1,+[4]İcmal!$B$19:$AG$49,ROW(C5)+1,FALSE)} -> 0 | M7: {=+HLOOKUP($A$1,+[5]İcmal!$B$19:$AG$49,ROW(D5)+1,FALSE)} -> 0 | N7: {=+HLOOKUP($A$1,+[6]İcmal!$B$19:$AG$49,ROW(E5)+1,FALSE)} -> 0 | O7: {=+HLOOKUP($A$1,+[7]İcmal!$B$19:$AG$49,ROW(F5)+1,FALSE)} -> 0 | P7: {=+HLOOKUP($A$1,+[8]İcmal!$B$19:$AG$49,ROW(G5)+1,FALSE)} -> 0 | Q7: {=+HLOOKUP($A$1,+[9]İcmal!$B$19:$AG$49,ROW(H5)+1,FALSE)} -> 0 | R7: {=+HLOOKUP($A$1,+[10]İcmal!$B$19:$AG$49,ROW(I5)+1,FALSE)} -> 0 | S7: {=+HLOOKUP($A$1,+[11]İcmal!$B$19:$AG$49,ROW(J5)+1,FALSE)} -> 0 | T7: {=+HLOOKUP($A$1,+[12]İcmal!$B$19:$AG$49,ROW(K5)+1,FALSE)} -> 0 | U7: {=+HLOOKUP($A$1,+[13]İcmal!$B$19:$AG$49,ROW(L5)+1,FALSE)} -> 0 | V7: {=+HLOOKUP($A$1,+[14]İcmal!$B$19:$AG$49,ROW(M5)+1,FALSE)} -> 0 | W7: {=+HLOOKUP($A$1,+[15]İcmal!$B$19:$AG$49,ROW(N5)+1,FALSE)} -> 0 | X7: {=+HLOOKUP($A$1,+[16]İcmal!$B$19:$AG$49,ROW(O5)+1,FALSE)} -> 0 | Y7: {=+HLOOKUP($A$1,+[17]İcmal!$B$19:$AG$49,ROW(P5)+1,FALSE)} -> 0 | Z7: {=+HLOOKUP($A$1,+[18]İcmal!$B$19:$AG$49,ROW(Q5)+1,FALSE)} -> 0 | AA7: {=+HLOOKUP($A$1,+[19]İcmal!$B$19:$AG$49,ROW(R5)+1,FALSE)} -> 0 | AB7: {=+HLOOKUP($A$1,+[20]İcmal!$B$19:$AG$49,ROW(S5)+1,FALSE)} -> 0 | AC7: {=+HLOOKUP($A$1,+[21]İcmal!$B$19:$AG$49,ROW(T5)+1,FALSE)} -> 0 | AD7: {=+HLOOKUP($A$1,+[22]İcmal!$B$19:$AG$49,ROW(U5)+1,FALSE)} -> 0 | AE7: {=+HLOOKUP($A$1,+[23]İcmal!$B$19:$AG$49,ROW(V5)+1,FALSE)} -> 0 | AF7: {=+HLOOKUP($A$1,+[24]İcmal!$B$19:$AG$49,ROW(W5)+1,FALSE)} -> 0 | AG7: {=+HLOOKUP($A$1,+[25]İcmal!$B$19:$AG$49,ROW(X5)+1,FALSE)} -> 0 | AH7: {=+HLOOKUP($A$1,+[26]İcmal!$B$19:$AG$49,ROW(Y5)+1,FALSE)} -> 0 | AI7: {=+HLOOKUP($A$1,+[27]İcmal!$B$19:$AG$49,ROW(Z5)+1,FALSE)} -> 0 | AJ7: {=+HLOOKUP($A$1,+[28]İcmal!$B$19:$AG$49,ROW(AA5)+1,FALSE)} -> 0 | AK7: {=+HLOOKUP($A$1,+[29]İcmal!$B$19:$AG$49,ROW(AB5)+1,FALSE)} -> 0
A8: 54 | B8: 021.B | C8: Delgi boyu > 30m | D8: m | E8: 10655.78 | F8: 371 | G8: =+E8*F8 -> 3953294.4 | H8: =SUM(J8:AT8) -> 0 | I8: =+F8*H8 -> 0 | J8: {=+HLOOKUP($A$1,+[2]İcmal!$B$19:$AG$49,ROW(A6)+1,FALSE)} -> 0 | K8: {=+HLOOKUP($A$1,+[3]İcmal!$B$19:$AG$49,ROW(B6)+1,FALSE)} -> 0 | L8: {=+HLOOKUP($A$1,+[4]İcmal!$B$19:$AG$49,ROW(C6)+1,FALSE)} -> 0 | M8: {=+HLOOKUP($A$1,+[5]İcmal!$B$19:$AG$49,ROW(D6)+1,FALSE)} -> 0 | N8: {=+HLOOKUP($A$1,+[6]İcmal!$B$19:$AG$49,ROW(E6)+1,FALSE)} -> 0 | O8: {=+HLOOKUP($A$1,+[7]İcmal!$B$19:$AG$49,ROW(F6)+1,FALSE)} -> 0 | P8: {=+HLOOKUP($A$1,+[8]İcmal!$B$19:$AG$49,ROW(G6)+1,FALSE)} -> 0 | Q8: {=+HLOOKUP($A$1,+[9]İcmal!$B$19:$AG$49,ROW(H6)+1,FALSE)} -> 0 | R8: {=+HLOOKUP($A$1,+[10]İcmal!$B$19:$AG$49,ROW(I6)+1,FALSE)} -> 0 | S8: {=+HLOOKUP($A$1,+[11]İcmal!$B$19:$AG$49,ROW(J6)+1,FALSE)} -> 0 | T8: {=+HLOOKUP($A$1,+[12]İcmal!$B$19:$AG$49,ROW(K6)+1,FALSE)} -> 0 | U8: {=+HLOOKUP($A$1,+[13]İcmal!$B$19:$AG$49,ROW(L6)+1,FALSE)} -> 0 | V8: {=+HLOOKUP($A$1,+[14]İcmal!$B$19:$AG$49,ROW(M6)+1,FALSE)} -> 0 | W8: {=+HLOOKUP($A$1,+[15]İcmal!$B$19:$AG$49,ROW(N6)+1,FALSE)} -> 0 | X8: {=+HLOOKUP($A$1,+[16]İcmal!$B$19:$AG$49,ROW(O6)+1,FALSE)} -> 0 | Y8: {=+HLOOKUP($A$1,+[17]İcmal!$B$19:$AG$49,ROW(P6)+1,FALSE)} -> 0 | Z8: {=+HLOOKUP($A$1,+[18]İcmal!$B$19:$AG$49,ROW(Q6)+1,FALSE)} -> 0 | AA8: {=+HLOOKUP($A$1,+[19]İcmal!$B$19:$AG$49,ROW(R6)+1,FALSE)} -> 0 | AB8: {=+HLOOKUP($A$1,+[20]İcmal!$B$19:$AG$49,ROW(S6)+1,FALSE)} -> 0 | AC8: {=+HLOOKUP($A$1,+[21]İcmal!$B$19:$AG$49,ROW(T6)+1,FALSE)} -> 0 | AD8: {=+HLOOKUP($A$1,+[22]İcmal!$B$19:$AG$49,ROW(U6)+1,FALSE)} -> 0 | AE8: {=+HLOOKUP($A$1,+[23]İcmal!$B$19:$AG$49,ROW(V6)+1,FALSE)} -> 0 | AF8: {=+HLOOKUP($A$1,+[24]İcmal!$B$19:$AG$49,ROW(W6)+1,FALSE)} -> 0 | AG8: {=+HLOOKUP($A$1,+[25]İcmal!$B$19:$AG$49,ROW(X6)+1,FALSE)} -> 0 | AH8: {=+HLOOKUP($A$1,+[26]İcmal!$B$19:$AG$49,ROW(Y6)+1,FALSE)} -> 0 | AI8: {=+HLOOKUP($A$1,+[27]İcmal!$B$19:$AG$49,ROW(Z6)+1,FALSE)} -> 0 | AJ8: {=+HLOOKUP($A$1,+[28]İcmal!$B$19:$AG$49,ROW(AA6)+1,FALSE)} -> 0 | AK8: {=+HLOOKUP($A$1,+[29]İcmal!$B$19:$AG$49,ROW(AB6)+1,FALSE)} -> 0
A9: 55 | B9: 022.A | C9: L=3 m Kaya Bulonu | D9: adet | E9: 800 | F9: 2250 | G9: =+E9*F9 -> 1800000 | H9: =SUM(J9:AT9) -> 0 | I9: =+F9*H9 -> 0 | J9: {=+HLOOKUP($A$1,+[2]İcmal!$B$19:$AG$49,ROW(A7)+1,FALSE)} -> 0 | K9: {=+HLOOKUP($A$1,+[3]İcmal!$B$19:$AG$49,ROW(B7)+1,FALSE)} -> 0 | L9: {=+HLOOKUP($A$1,+[4]İcmal!$B$19:$AG$49,ROW(C7)+1,FALSE)} -> 0 | M9: {=+HLOOKUP($A$1,+[5]İcmal!$B$19:$AG$49,ROW(D7)+1,FALSE)} -> 0 | N9: {=+HLOOKUP($A$1,+[6]İcmal!$B$19:$AG$49,ROW(E7)+1,FALSE)} -> 0 | O9: {=+HLOOKUP($A$1,+[7]İcmal!$B$19:$AG$49,ROW(F7)+1,FALSE)} -> 0 | P9: {=+HLOOKUP($A$1,+[8]İcmal!$B$19:$AG$49,ROW(G7)+1,FALSE)} -> 0 | Q9: {=+HLOOKUP($A$1,+[9]İcmal!$B$19:$AG$49,ROW(H7)+1,FALSE)} -> 0 | R9: {=+HLOOKUP($A$1,+[10]İcmal!$B$19:$AG$49,ROW(I7)+1,FALSE)} -> 0 | S9: {=+HLOOKUP($A$1,+[11]İcmal!$B$19:$AG$49,ROW(J7)+1,FALSE)} -> 0 | T9: {=+HLOOKUP($A$1,+[12]İcmal!$B$19:$AG$49,ROW(K7)+1,FALSE)} -> 0 | U9: {=+HLOOKUP($A$1,+[13]İcmal!$B$19:$AG$49,ROW(L7)+1,FALSE)} -> 0 | V9: {=+HLOOKUP($A$1,+[14]İcmal!$B$19:$AG$49,ROW(M7)+1,FALSE)} -> 0 | W9: {=+HLOOKUP($A$1,+[15]İcmal!$B$19:$AG$49,ROW(N7)+1,FALSE)} -> 0 | X9: {=+HLOOKUP($A$1,+[16]İcmal!$B$19:$AG$49,ROW(O7)+1,FALSE)} -> 0 | Y9: {=+HLOOKUP($A$1,+[17]İcmal!$B$19:$AG$49,ROW(P7)+1,FALSE)} -> 0 | Z9: {=+HLOOKUP($A$1,+[18]İcmal!$B$19:$AG$49,ROW(Q7)+1,FALSE)} -> 0 | AA9: {=+HLOOKUP($A$1,+[19]İcmal!$B$19:$AG$49,ROW(R7)+1,FALSE)} -> 0 | AB9: {=+HLOOKUP($A$1,+[20]İcmal!$B$19:$AG$49,ROW(S7)+1,FALSE)} -> 0 | AC9: {=+HLOOKUP($A$1,+[21]İcmal!$B$19:$AG$49,ROW(T7)+1,FALSE)} -> 0 | AD9: {=+HLOOKUP($A$1,+[22]İcmal!$B$19:$AG$49,ROW(U7)+1,FALSE)} -> 0 | AE9: {=+HLOOKUP($A$1,+[23]İcmal!$B$19:$AG$49,ROW(V7)+1,FALSE)} -> 0 | AF9: {=+HLOOKUP($A$1,+[24]İcmal!$B$19:$AG$49,ROW(W7)+1,FALSE)} -> 0 | AG9: {=+HLOOKUP($A$1,+[25]İcmal!$B$19:$AG$49,ROW(X7)+1,FALSE)} -> 0 | AH9: {=+HLOOKUP($A$1,+[26]İcmal!$B$19:$AG$49,ROW(Y7)+1,FALSE)} -> 0 | AI9: {=+HLOOKUP($A$1,+[27]İcmal!$B$19:$AG$49,ROW(Z7)+1,FALSE)} -> 0 | AJ9: {=+HLOOKUP($A$1,+[28]İcmal!$B$19:$AG$49,ROW(AA7)+1,FALSE)} -> 0 | AK9: {=+HLOOKUP($A$1,+[29]İcmal!$B$19:$AG$49,ROW(AB7)+1,FALSE)} -> 0
A10: 56 | B10: 022.B | C10: L=4 m Kaya Bulonu | D10: adet | E10: 2466.42 | F10: 8000 | G10: =+E10*F10 -> 19731360 | H10: =SUM(J10:AT10) -> 171 | I10: =+F10*H10 -> 1368000 | J10: {=+HLOOKUP($A$1,+[2]İcmal!$B$19:$AG$49,ROW(A8)+1,FALSE)} -> 0 | K10: {=+HLOOKUP($A$1,+[3]İcmal!$B$19:$AG$49,ROW(B8)+1,FALSE)} -> 0 | L10: {=+HLOOKUP($A$1,+[4]İcmal!$B$19:$AG$49,ROW(C8)+1,FALSE)} -> 0 | M10: {=+HLOOKUP($A$1,+[5]İcmal!$B$19:$AG$49,ROW(D8)+1,FALSE)} -> 0 | N10: {=+HLOOKUP($A$1,+[6]İcmal!$B$19:$AG$49,ROW(E8)+1,FALSE)} -> 86 | O10: {=+HLOOKUP($A$1,+[7]İcmal!$B$19:$AG$49,ROW(F8)+1,FALSE)} -> 0 | P10: {=+HLOOKUP($A$1,+[8]İcmal!$B$19:$AG$49,ROW(G8)+1,FALSE)} -> 0 | Q10: {=+HLOOKUP($A$1,+[9]İcmal!$B$19:$AG$49,ROW(H8)+1,FALSE)} -> 0 | R10: {=+HLOOKUP($A$1,+[10]İcmal!$B$19:$AG$49,ROW(I8)+1,FALSE)} -> 85 | S10: {=+HLOOKUP($A$1,+[11]İcmal!$B$19:$AG$49,ROW(J8)+1,FALSE)} -> 0 | T10: {=+HLOOKUP($A$1,+[12]İcmal!$B$19:$AG$49,ROW(K8)+1,FALSE)} -> 0 | U10: {=+HLOOKUP($A$1,+[13]İcmal!$B$19:$AG$49,ROW(L8)+1,FALSE)} -> 0 | V10: {=+HLOOKUP($A$1,+[14]İcmal!$B$19:$AG$49,ROW(M8)+1,FALSE)} -> 0 | W10: {=+HLOOKUP($A$1,+[15]İcmal!$B$19:$AG$49,ROW(N8)+1,FALSE)} -> 0 | X10: {=+HLOOKUP($A$1,+[16]İcmal!$B$19:$AG$49,ROW(O8)+1,FALSE)} -> 0 | Y10: {=+HLOOKUP($A$1,+[17]İcmal!$B$19:$AG$49,ROW(P8)+1,FALSE)} -> 0 | Z10: {=+HLOOKUP($A$1,+[18]İcmal!$B$19:$AG$49,ROW(Q8)+1,FALSE)} -> 0 | AA10: {=+HLOOKUP($A$1,+[19]İcmal!$B$19:$AG$49,ROW(R8)+1,FALSE)} -> 0 | AB10: {=+HLOOKUP($A$1,+[20]İcmal!$B$19:$AG$49,ROW(S8)+1,FALSE)} -> 0 | AC10: {=+HLOOKUP($A$1,+[21]İcmal!$B$19:$AG$49,ROW(T8)+1,FALSE)} -> 0 | AD10: {=+HLOOKUP($A$1,+[22]İcmal!$B$19:$AG$49,ROW(U8)+1,FALSE)} -> 0 | AE10: {=+HLOOKUP($A$1,+[23]İcmal!$B$19:$AG$49,ROW(V8)+1,FALSE)} -> 0 | AF10: {=+HLOOKUP($A$1,+[24]İcmal!$B$19:$AG$49,ROW(W8)+1,FALSE)} -> 0 | AG10: {=+HLOOKUP($A$1,+[25]İcmal!$B$19:$AG$49,ROW(X8)+1,FALSE)} -> 0 | AH10: {=+HLOOKUP($A$1,+[26]İcmal!$B$19:$AG$49,ROW(Y8)+1,FALSE)} -> 0 | AI10: {=+HLOOKUP($A$1,+[27]İcmal!$B$19:$AG$49,ROW(Z8)+1,FALSE)} -> 0 | AJ10: {=+HLOOKUP($A$1,+[28]İcmal!$B$19:$AG$49,ROW(AA8)+1,FALSE)} -> 0 | AK10: {=+HLOOKUP($A$1,+[29]İcmal!$B$19:$AG$49,ROW(AB8)+1,FALSE)} -> 0
A11: 57 | B11: 022.C | C11: L=5 m Kaya Bulonu | D11: adet | E11: 2401.3 | F11: 8288 | G11: =+E11*F11 -> 19901974 | H11: =SUM(J11:AT11) -> 0 | I11: =+F11*H11 -> 0 | J11: {=+HLOOKUP($A$1,+[2]İcmal!$B$19:$AG$49,ROW(A9)+1,FALSE)} -> 0 | K11: {=+HLOOKUP($A$1,+[3]İcmal!$B$19:$AG$49,ROW(B9)+1,FALSE)} -> 0 | L11: {=+HLOOKUP($A$1,+[4]İcmal!$B$19:$AG$49,ROW(C9)+1,FALSE)} -> 0 | M11: {=+HLOOKUP($A$1,+[5]İcmal!$B$19:$AG$49,ROW(D9)+1,FALSE)} -> 0 | N11: {=+HLOOKUP($A$1,+[6]İcmal!$B$19:$AG$49,ROW(E9)+1,FALSE)} -> 0 | O11: {=+HLOOKUP($A$1,+[7]İcmal!$B$19:$AG$49,ROW(F9)+1,FALSE)} -> 0 | P11: {=+HLOOKUP($A$1,+[8]İcmal!$B$19:$AG$49,ROW(G9)+1,FALSE)} -> 0 | Q11: {=+HLOOKUP($A$1,+[9]İcmal!$B$19:$AG$49,ROW(H9)+1,FALSE)} -> 0 | R11: {=+HLOOKUP($A$1,+[10]İcmal!$B$19:$AG$49,ROW(I9)+1,FALSE)} -> 0 | S11: {=+HLOOKUP($A$1,+[11]İcmal!$B$19:$AG$49,ROW(J9)+1,FALSE)} -> 0 | T11: {=+HLOOKUP($A$1,+[12]İcmal!$B$19:$AG$49,ROW(K9)+1,FALSE)} -> 0 | U11: {=+HLOOKUP($A$1,+[13]İcmal!$B$19:$AG$49,ROW(L9)+1,FALSE)} -> 0 | V11: {=+HLOOKUP($A$1,+[14]İcmal!$B$19:$AG$49,ROW(M9)+1,FALSE)} -> 0 | W11: {=+HLOOKUP($A$1,+[15]İcmal!$B$19:$AG$49,ROW(N9)+1,FALSE)} -> 0 | X11: {=+HLOOKUP($A$1,+[16]İcmal!$B$19:$AG$49,ROW(O9)+1,FALSE)} -> 0 | Y11: {=+HLOOKUP($A$1,+[17]İcmal!$B$19:$AG$49,ROW(P9)+1,FALSE)} -> 0 | Z11: {=+HLOOKUP($A$1,+[18]İcmal!$B$19:$AG$49,ROW(Q9)+1,FALSE)} -> 0 | AA11: {=+HLOOKUP($A$1,+[19]İcmal!$B$19:$AG$49,ROW(R9)+1,FALSE)} -> 0 | AB11: {=+HLOOKUP($A$1,+[20]İcmal!$B$19:$AG$49,ROW(S9)+1,FALSE)} -> 0 | AC11: {=+HLOOKUP($A$1,+[21]İcmal!$B$19:$AG$49,ROW(T9)+1,FALSE)} -> 0 | AD11: {=+HLOOKUP($A$1,+[22]İcmal!$B$19:$AG$49,ROW(U9)+1,FALSE)} -> 0 | AE11: {=+HLOOKUP($A$1,+[23]İcmal!$B$19:$AG$49,ROW(V9)+1,FALSE)} -> 0 | AF11: {=+HLOOKUP($A$1,+[24]İcmal!$B$19:$AG$49,ROW(W9)+1,FALSE)} -> 0 | AG11: {=+HLOOKUP($A$1,+[25]İcmal!$B$19:$AG$49,ROW(X9)+1,FALSE)} -> 0 | AH11: {=+HLOOKUP($A$1,+[26]İcmal!$B$19:$AG$49,ROW(Y9)+1,FALSE)} -> 0 | AI11: {=+HLOOKUP($A$1,+[27]İcmal!$B$19:$AG$49,ROW(Z9)+1,FALSE)} -> 0 | AJ11: {=+HLOOKUP($A$1,+[28]İcmal!$B$19:$AG$49,ROW(AA9)+1,FALSE)} -> 0 | AK11: {=+HLOOKUP($A$1,+[29]İcmal!$B$19:$AG$49,ROW(AB9)+1,FALSE)} -> 0
A12: 58 | B12: 022.D | C12: L=6 m Kaya Bulonu | D12: adet | E12: 2970 | F12: 12000 | G12: =+E12*F12 -> 35640000 | H12: =SUM(J12:AT12) -> 0 | I12: =+F12*H12 -> 0 | J12: {=+HLOOKUP($A$1,+[2]İcmal!$B$19:$AG$49,ROW(A10)+1,FALSE)} -> 0 | K12: {=+HLOOKUP($A$1,+[3]İcmal!$B$19:$AG$49,ROW(B10)+1,FALSE)} -> 0 | L12: {=+HLOOKUP($A$1,+[4]İcmal!$B$19:$AG$49,ROW(C10)+1,FALSE)} -> 0 | M12: {=+HLOOKUP($A$1,+[5]İcmal!$B$19:$AG$49,ROW(D10)+1,FALSE)} -> 0 | N12: {=+HLOOKUP($A$1,+[6]İcmal!$B$19:$AG$49,ROW(E10)+1,FALSE)} -> 0 | O12: {=+HLOOKUP($A$1,+[7]İcmal!$B$19:$AG$49,ROW(F10)+1,FALSE)} -> 0 | P12: {=+HLOOKUP($A$1,+[8]İcmal!$B$19:$AG$49,ROW(G10)+1,FALSE)} -> 0 | Q12: {=+HLOOKUP($A$1,+[9]İcmal!$B$19:$AG$49,ROW(H10)+1,FALSE)} -> 0 | R12: {=+HLOOKUP($A$1,+[10]İcmal!$B$19:$AG$49,ROW(I10)+1,FALSE)} -> 0 | S12: {=+HLOOKUP($A$1,+[11]İcmal!$B$19:$AG$49,ROW(J10)+1,FALSE)} -> 0 | T12: {=+HLOOKUP($A$1,+[12]İcmal!$B$19:$AG$49,ROW(K10)+1,FALSE)} -> 0 | U12: {=+HLOOKUP($A$1,+[13]İcmal!$B$19:$AG$49,ROW(L10)+1,FALSE)} -> 0 | V12: {=+HLOOKUP($A$1,+[14]İcmal!$B$19:$AG$49,ROW(M10)+1,FALSE)} -> 0 | W12: {=+HLOOKUP($A$1,+[15]İcmal!$B$19:$AG$49,ROW(N10)+1,FALSE)} -> 0 | X12: {=+HLOOKUP($A$1,+[16]İcmal!$B$19:$AG$49,ROW(O10)+1,FALSE)} -> 0 | Y12: {=+HLOOKUP($A$1,+[17]İcmal!$B$19:$AG$49,ROW(P10)+1,FALSE)} -> 0 | Z12: {=+HLOOKUP($A$1,+[18]İcmal!$B$19:$AG$49,ROW(Q10)+1,FALSE)} -> 0 | AA12: {=+HLOOKUP($A$1,+[19]İcmal!$B$19:$AG$49,ROW(R10)+1,FALSE)} -> 0 | AB12: {=+HLOOKUP($A$1,+[20]İcmal!$B$19:$AG$49,ROW(S10)+1,FALSE)} -> 0 | AC12: {=+HLOOKUP($A$1,+[21]İcmal!$B$19:$AG$49,ROW(T10)+1,FALSE)} -> 0 | AD12: {=+HLOOKUP($A$1,+[22]İcmal!$B$19:$AG$49,ROW(U10)+1,FALSE)} -> 0 | AE12: {=+HLOOKUP($A$1,+[23]İcmal!$B$19:$AG$49,ROW(V10)+1,FALSE)} -> 0 | AF12: {=+HLOOKUP($A$1,+[24]İcmal!$B$19:$AG$49,ROW(W10)+1,FALSE)} -> 0 | AG12: {=+HLOOKUP($A$1,+[25]İcmal!$B$19:$AG$49,ROW(X10)+1,FALSE)} -> 0 | AH12: {=+HLOOKUP($A$1,+[26]İcmal!$B$19:$AG$49,ROW(Y10)+1,FALSE)} -> 0 | AI12: {=+HLOOKUP($A$1,+[27]İcmal!$B$19:$AG$49,ROW(Z10)+1,FALSE)} -> 0 | AJ12: {=+HLOOKUP($A$1,+[28]İcmal!$B$19:$AG$49,ROW(AA10)+1,FALSE)} -> 0 | AK12: {=+HLOOKUP($A$1,+[29]İcmal!$B$19:$AG$49,ROW(AB10)+1,FALSE)} -> 0
A13: 59 | B13: 022.E | C13: L=8 m Kaya Bulonu | D13: adet | E13: 7008.23 | F13: 28000 | G13: =+E13*F13 -> 196230440 | H13: =SUM(J13:AT13) -> 284 | I13: =+F13*H13 -> 7952000 | J13: {=+HLOOKUP($A$1,+[2]İcmal!$B$19:$AG$49,ROW(A11)+1,FALSE)} -> 10 | K13: {=+HLOOKUP($A$1,+[3]İcmal!$B$19:$AG$49,ROW(B11)+1,FALSE)} -> 27 | L13: {=+HLOOKUP($A$1,+[4]İcmal!$B$19:$AG$49,ROW(C11)+1,FALSE)} -> 0 | M13: {=+HLOOKUP($A$1,+[5]İcmal!$B$19:$AG$49,ROW(D11)+1,FALSE)} -> 0 | N13: {=+HLOOKUP($A$1,+[6]İcmal!$B$19:$AG$49,ROW(E11)+1,FALSE)} -> 57 | O13: {=+HLOOKUP($A$1,+[7]İcmal!$B$19:$AG$49,ROW(F11)+1,FALSE)} -> 36 | P13: {=+HLOOKUP($A$1,+[8]İcmal!$B$19:$AG$49,ROW(G11)+1,FALSE)} -> 0 | Q13: {=+HLOOKUP($A$1,+[9]İcmal!$B$19:$AG$49,ROW(H11)+1,FALSE)} -> 0 | R13: {=+HLOOKUP($A$1,+[10]İcmal!$B$19:$AG$49,ROW(I11)+1,FALSE)} -> 57 | S13: {=+HLOOKUP($A$1,+[11]İcmal!$B$19:$AG$49,ROW(J11)+1,FALSE)} -> 75 | T13: {=+HLOOKUP($A$1,+[12]İcmal!$B$19:$AG$49,ROW(K11)+1,FALSE)} -> 0 | U13: {=+HLOOKUP($A$1,+[13]İcmal!$B$19:$AG$49,ROW(L11)+1,FALSE)} -> 0 | V13: {=+HLOOKUP($A$1,+[14]İcmal!$B$19:$AG$49,ROW(M11)+1,FALSE)} -> 0 | W13: {=+HLOOKUP($A$1,+[15]İcmal!$B$19:$AG$49,ROW(N11)+1,FALSE)} -> 0 | X13: {=+HLOOKUP($A$1,+[16]İcmal!$B$19:$AG$49,ROW(O11)+1,FALSE)} -> 0 | Y13: {=+HLOOKUP($A$1,+[17]İcmal!$B$19:$AG$49,ROW(P11)+1,FALSE)} -> 0 | Z13: {=+HLOOKUP($A$1,+[18]İcmal!$B$19:$AG$49,ROW(Q11)+1,FALSE)} -> 0 | AA13: {=+HLOOKUP($A$1,+[19]İcmal!$B$19:$AG$49,ROW(R11)+1,FALSE)} -> 0 | AB13: {=+HLOOKUP($A$1,+[20]İcmal!$B$19:$AG$49,ROW(S11)+1,FALSE)} -> 22 | AC13: {=+HLOOKUP($A$1,+[21]İcmal!$B$19:$AG$49,ROW(T11)+1,FALSE)} -> 0 | AD13: {=+HLOOKUP($A$1,+[22]İcmal!$B$19:$AG$49,ROW(U11)+1,FALSE)} -> 0 | AE13: {=+HLOOKUP($A$1,+[23]İcmal!$B$19:$AG$49,ROW(V11)+1,FALSE)} -> 0 | AF13: {=+HLOOKUP($A$1,+[24]İcmal!$B$19:$AG$49,ROW(W11)+1,FALSE)} -> 0 | AG13: {=+HLOOKUP($A$1,+[25]İcmal!$B$19:$AG$49,ROW(X11)+1,FALSE)} -> 0 | AH13: {=+HLOOKUP($A$1,+[26]İcmal!$B$19:$AG$49,ROW(Y11)+1,FALSE)} -> 0 | AI13: {=+HLOOKUP($A$1,+[27]İcmal!$B$19:$AG$49,ROW(Z11)+1,FALSE)} -> 0 | AJ13: {=+HLOOKUP($A$1,+[28]İcmal!$B$19:$AG$49,ROW(AA11)+1,FALSE)} -> 0 | AK13: {=+HLOOKUP($A$1,+[29]İcmal!$B$19:$AG$49,ROW(AB11)+1,FALSE)} -> 0
A14: 60 | B14: 023.A | C14: 125 mm Delik İçine 14 mm Kalınlığında S420a ile Zemin Çivisi Teşkili | D14: m | E14: 156606.89 | F14: 375 | G14: =+E14*F14 -> 58727584 | H14: =SUM(J14:AT14) -> 3654 | I14: =+F14*H14 -> 1370250 | J14: {=+HLOOKUP($A$1,+[2]İcmal!$B$19:$AG$49,ROW(A12)+1,FALSE)} -> 0 | K14: {=+HLOOKUP($A$1,+[3]İcmal!$B$19:$AG$49,ROW(B12)+1,FALSE)} -> 0 | L14: {=+HLOOKUP($A$1,+[4]İcmal!$B$19:$AG$49,ROW(C12)+1,FALSE)} -> 0 | M14: {=+HLOOKUP($A$1,+[5]İcmal!$B$19:$AG$49,ROW(D12)+1,FALSE)} -> 0 | N14: {=+HLOOKUP($A$1,+[6]İcmal!$B$19:$AG$49,ROW(E12)+1,FALSE)} -> 990 | O14: {=+HLOOKUP($A$1,+[7]İcmal!$B$19:$AG$49,ROW(F12)+1,FALSE)} -> 486 | P14: {=+HLOOKUP($A$1,+[8]İcmal!$B$19:$AG$49,ROW(G12)+1,FALSE)} -> 0 | Q14: {=+HLOOKUP($A$1,+[9]İcmal!$B$19:$AG$49,ROW(H12)+1,FALSE)} -> 0 | R14: {=+HLOOKUP($A$1,+[10]İcmal!$B$19:$AG$49,ROW(I12)+1,FALSE)} -> 990 | S14: {=+HLOOKUP($A$1,+[11]İcmal!$B$19:$AG$49,ROW(J12)+1,FALSE)} -> 648 | T14: {=+HLOOKUP($A$1,+[12]İcmal!$B$19:$AG$49,ROW(K12)+1,FALSE)} -> 0 | U14: {=+HLOOKUP($A$1,+[13]İcmal!$B$19:$AG$49,ROW(L12)+1,FALSE)} -> 0 | V14: {=+HLOOKUP($A$1,+[14]İcmal!$B$19:$AG$49,ROW(M12)+1,FALSE)} -> 0 | W14: {=+HLOOKUP($A$1,+[15]İcmal!$B$19:$AG$49,ROW(N12)+1,FALSE)} -> 0 | X14: {=+HLOOKUP($A$1,+[16]İcmal!$B$19:$AG$49,ROW(O12)+1,FALSE)} -> 0 | Y14: {=+HLOOKUP($A$1,+[17]İcmal!$B$19:$AG$49,ROW(P12)+1,FALSE)} -> 0 | Z14: {=+HLOOKUP($A$1,+[18]İcmal!$B$19:$AG$49,ROW(Q12)+1,FALSE)} -> 0 | AA14: {=+HLOOKUP($A$1,+[19]İcmal!$B$19:$AG$49,ROW(R12)+1,FALSE)} -> 0 | AB14: {=+HLOOKUP($A$1,+[20]İcmal!$B$19:$AG$49,ROW(S12)+1,FALSE)} -> 180 | AC14: {=+HLOOKUP($A$1,+[21]İcmal!$B$19:$AG$49,ROW(T12)+1,FALSE)} -> 0 | AD14: {=+HLOOKUP($A$1,+[22]İcmal!$B$19:$AG$49,ROW(U12)+1,FALSE)} -> 0 | AE14: {=+HLOOKUP($A$1,+[23]İcmal!$B$19:$AG$49,ROW(V12)+1,FALSE)} -> 0 | AF14: {=+HLOOKUP($A$1,+[24]İcmal!$B$19:$AG$49,ROW(W12)+1,FALSE)} -> 180 | AG14: {=+HLOOKUP($A$1,+[25]İcmal!$B$19:$AG$49,ROW(X12)+1,FALSE)} -> 0 | AH14: {=+HLOOKUP($A$1,+[26]İcmal!$B$19:$AG$49,ROW(Y12)+1,FALSE)} -> 180 | AI14: {=+HLOOKUP($A$1,+[27]İcmal!$B$19:$AG$49,ROW(Z12)+1,FALSE)} -> 0 | AJ14: {=+HLOOKUP($A$1,+[28]İcmal!$B$19:$AG$49,ROW(AA12)+1,FALSE)} -> 0 | AK14: {=+HLOOKUP($A$1,+[29]İcmal!$B$19:$AG$49,ROW(AB12)+1,FALSE)} -> 0
... A32: 78 | B32: 030.E | C32: Block-out Kutusu | D32: kg | E32: 4500 | F32: 180 | G32: =+E32*F32 -> 810000 | H32: =SUM(J32:AT32) -> 0 | I32: =+F32*H32 -> 0 | J32: {=+HLOOKUP($A$1,+[2]İcmal!$B$19:$AG$49,ROW(A30)+1,FALSE)} -> 0 | K32: {=+HLOOKUP($A$1,+[3]İcmal!$B$19:$AG$49,ROW(B30)+1,FALSE)} -> 0 | L32: {=+HLOOKUP($A$1,+[4]İcmal!$B$19:$AG$49,ROW(C30)+1,FALSE)} -> 0 | M32: {=+HLOOKUP($A$1,+[5]İcmal!$B$19:$AG$49,ROW(D30)+1,FALSE)} -> 0 | N32: {=+HLOOKUP($A$1,+[6]İcmal!$B$19:$AG$49,ROW(E30)+1,FALSE)} -> 0 | O32: {=+HLOOKUP($A$1,+[7]İcmal!$B$19:$AG$49,ROW(F30)+1,FALSE)} -> 0 | P32: {=+HLOOKUP($A$1,+[8]İcmal!$B$19:$AG$49,ROW(G30)+1,FALSE)} -> 0 | Q32: {=+HLOOKUP($A$1,+[9]İcmal!$B$19:$AG$49,ROW(H30)+1,FALSE)} -> 0 | R32: {=+HLOOKUP($A$1,+[10]İcmal!$B$19:$AG$49,ROW(I30)+1,FALSE)} -> 0 | S32: {=+HLOOKUP($A$1,+[11]İcmal!$B$19:$AG$49,ROW(J30)+1,FALSE)} -> 0 | T32: {=+HLOOKUP($A$1,+[12]İcmal!$B$19:$AG$49,ROW(K30)+1,FALSE)} -> 0 | U32: {=+HLOOKUP($A$1,+[13]İcmal!$B$19:$AG$49,ROW(L30)+1,FALSE)} -> 0 | V32: {=+HLOOKUP($A$1,+[14]İcmal!$B$19:$AG$49,ROW(M30)+1,FALSE)} -> 0 | W32: {=+HLOOKUP($A$1,+[15]İcmal!$B$19:$AG$49,ROW(N30)+1,FALSE)} -> 0 | X32: {=+HLOOKUP($A$1,+[16]İcmal!$B$19:$AG$49,ROW(O30)+1,FALSE)} -> 0 | Y32: {=+HLOOKUP($A$1,+[17]İcmal!$B$19:$AG$49,ROW(P30)+1,FALSE)} -> 0 | Z32: {=+HLOOKUP($A$1,+[18]İcmal!$B$19:$AG$49,ROW(Q30)+1,FALSE)} -> 0 | AA32: {=+HLOOKUP($A$1,+[19]İcmal!$B$19:$AG$49,ROW(R30)+1,FALSE)} -> 0 | AB32: {=+HLOOKUP($A$1,+[20]İcmal!$B$19:$AG$49,ROW(S30)+1,FALSE)} -> 0 | AC32: {=+HLOOKUP($A$1,+[21]İcmal!$B$19:$AG$49,ROW(T30)+1,FALSE)} -> 0 | AD32: {=+HLOOKUP($A$1,+[22]İcmal!$B$19:$AG$49,ROW(U30)+1,FALSE)} -> 0 | AE32: {=+HLOOKUP($A$1,+[23]İcmal!$B$19:$AG$49,ROW(V30)+1,FALSE)} -> 0 | AF32: {=+HLOOKUP($A$1,+[24]İcmal!$B$19:$AG$49,ROW(W30)+1,FALSE)} -> 0 | AG32: {=+HLOOKUP($A$1,+[25]İcmal!$B$19:$AG$49,ROW(X30)+1,FALSE)} -> 0 | AH32: {=+HLOOKUP($A$1,+[26]İcmal!$B$19:$AG$49,ROW(Y30)+1,FALSE)} -> 0 | AI32: {=+HLOOKUP($A$1,+[27]İcmal!$B$19:$AG$49,ROW(Z30)+1,FALSE)} -> 0 | AJ32: {=+HLOOKUP($A$1,+[28]İcmal!$B$19:$AG$49,ROW(AA30)+1,FALSE)} -> 0 | AK32: {=+HLOOKUP($A$1,+[29]İcmal!$B$19:$AG$49,ROW(AB30)+1,FALSE)} -> 0
I33: =SUM(I3:I32) -> 98792223 | J33: =+SUMPRODUCT(J3:J32,$F$3:$F$32) -> 280000 | K33: =+SUMPRODUCT(K3:K32,$F$3:$F$32) -> 1159449.3 | L33: =+SUMPRODUCT(L3:L32,$F$3:$F$32) -> 0 | M33: =+SUMPRODUCT(M3:M32,$F$3:$F$32) -> 0 | N33: =+SUMPRODUCT(N3:N32,$F$3:$F$32) -> 24879658 | O33: =+SUMPRODUCT(O3:O32,$F$3:$F$32) -> 11406813 | P33: =+SUMPRODUCT(P3:P32,$F$3:$F$32) -> 0 | Q33: =+SUMPRODUCT(Q3:Q32,$F$3:$F$32) -> 0 | ... AK33: =+SUMPRODUCT(AK3:AK32,$F$3:$F$32) -> 0 | AS33: =+SUMPRODUCT(AS3:AS32,$F$3:$F$32) -> 0

Sheet Barbaros 1025
A1: 1025
